Workbook

Sheet ESPANOL
E7: CALCULO DE NOTAS | AO7: Calificacion Final | AP7: % DE ASISTENCIA ANUAL | AR7: CALIFICACION COMPLETIVA | AV7: CALIFICACION EXTRAORDINARIA | AZ7: EVALUACION ESPECIAL | BB7: SITUACIONFINAL EN LA ASIGNATURA
A9: NO | B9: ID | C9: NOMBRES | D9: APELLIDOS | E9: CE - LE1 | M9: CE - LE2, LE3 | U9: CE - LE4, LE6 | AC9: CE - LE5, LE7 | AK9: PCP 1 | AL9: PCP 2 | AM9: PCP 3 | AN9: PCP 4 | AR9: 50% C.F | AS9: C.E.C. | AT9: 50% C.E.C. | AU9: C.C.F | AV9: 30% C.F. | AW9: C.E.EX | AX9: 70% C.E.EX | AY9: C.EX.F | AZ9: C.F. | BA9: C.E. | BB9: A | BC9: R
E10: P1 | F10: RP1 | G10: P2 | H10: RP2 | I10: P3 | J10: RP3 | K10: P4 | L10: RP4 | M10: P1 | N10: RP1 | O10: P2 | P10: RP2 | Q10: P3 | R10: RP3 | S10: P4 | T10: RP4 | U10: P1 | V10: RP1 | W10: P2 | X10: RP3 | Y10: P3 | Z10: RP4 | AA10: P4 | AB10: RP4 | AC10: P1 | AD10: RP1 | AE10: P2 | AF10: RP3 | AG10: P3 | AH10: RP4 | AI10: P4 | AJ10: RP4 | BE10: P1 | BF10: P2 | BG10: P3 | BH10: P4 | BI10: C.F
A11: 1 | B11: 1A-B-01 | C11: LUIS ANGEL | D11: APREDIEU | AK11: =SUMIF(E11:E11, ">=70") / 4 +SUMIF(G11:G11, ">=70") / 4 +SUMIF(I11:I11, ">=70") / 4 +SUMIF(K11:K11, ">=70") / 4 + SUMIF(F11:F11, ">1") / 4 + SUMIF(H11:H11, ">1") / 4 + SUMIF(J11:J11, ">1") / 4 + SUMIF(L11:L11, ">1") / 4 -> 0 | AL11: =SUMIF(M11:M11, ">=70") / 4 +SUMIF(O11:O11, ">=70") / 4 +SUMIF(Q11:Q11, ">=70") / 4 +SUMIF(S11:S11, ">=70") / 4 + SUMIF(N11:N11, ">1") / 4 + SUMIF(P11:P11, ">1") / 4 + SUMIF(R11:R11, ">1") / 4 + SUMIF(T11:T11, ">1") / 4 -> 0 | AM11: =SUMIF(U11:U11, ">=70") / 4 +SUMIF(W11:W11, ">=70") / 4 +SUMIF(Y11:Y11, ">=70") / 4 +SUMIF(AA11:AA11, ">=70") / 4 + SUMIF(V11:V11, ">1") / 4 + SUMIF(X11:X11, ">1") / 4 + SUMIF(Z11:Z11, ">1") / 4 + SUMIF(AB11:AB11, ">1") / 4 -> 0 | AN11: =SUMIF(AC11:AC11, ">=70") / 4 +SUMIF(AE11:AE11, ">=70") / 4 +SUMIF(AG11:AG11, ">=70") / 4 +SUMIF(AI11:AI11, ">=70") / 4 + SUMIF(AD11:AD11, ">1") / 4 + SUMIF(AF11:AF11, ">1") / 4 + SUMIF(AH11:AH11, ">1") / 4 + SUMIF(AJ11:AJ11, ">1") / 4 -> 0 | AO11: =AVERAGE(AK11:AN11) -> 0 | AR11: =IF(AO11<70, AO11*0.5, "") -> 0 | AT11: =AS11*50% -> 0 | AU11: =IF(AS11<>"", IF(AR11="","",AR11+AT11), "") | AV11: =IF(AU11 < 70, AR11*30%, "") | AX11: =AW11*70% -> 0 | AY11: =IF(AW11<>"", IF(AV11="", "", AV11+AX11), "") | AZ11: =IF(AND(AU11<70, AY11<70), AO11, "") | BB11: =IF(AW11<>"", IF(AY11>=70, AY11, IF(AZ11+BA11>=70, AZ11+BA11, "")), IF(AS11<>"", IF(AU11>=70, AU11, ""), IF(AO11>=70, AO11, ""))) | BC11: =IF(AW11<>"", IF(AY11<70, IF(AZ11+BA11<70, AZ11+BA11, ""), ""), IF(AS11<>"", IF(AU11<70, AU11, ""), IF(AO11<70, AO11, ""))) -> 0 | BE11: =SUM(E11+M11+U11+AC11)/4 -> 0 | BF11: =SUM(G11+O11+W11+AE11)/4 -> 0 | BG11: =SUM(I11+Q11+Y11+AG11)/4 -> 0 | BH11: =SUM(K11+S11+AA11+AI11)/4 -> 0 | BI11: =AVERAGE(BE11:BH11) -> 0
A12: 2 | B12: 1A-B-02 | C12: DARIEL | D12: ARCANGEL VASQUEZ | AK12: =SUMIF(E12:E12, ">=70") / 4 +SUMIF(G12:G12, ">=70") / 4 +SUMIF(I12:I12, ">=70") / 4 +SUMIF(K12:K12, ">=70") / 4 + SUMIF(F12:F12, ">1") / 4 + SUMIF(H12:H12, ">1") / 4 + SUMIF(J12:J12, ">1") / 4 + SUMIF(L12:L12, ">1") / 4 -> 0 | AL12: =SUMIF(M12:M12, ">=70") / 4 +SUMIF(O12:O12, ">=70") / 4 +SUMIF(Q12:Q12, ">=70") / 4 +SUMIF(S12:S12, ">=70") / 4 + SUMIF(N12:N12, ">1") / 4 + SUMIF(P12:P12, ">1") / 4 + SUMIF(R12:R12, ">1") / 4 + SUMIF(T12:T12, ">1") / 4 -> 0 | AM12: =SUMIF(U12:U12, ">=70") / 4 +SUMIF(W12:W12, ">=70") / 4 +SUMIF(Y12:Y12, ">=70") / 4 +SUMIF(AA12:AA12, ">=70") / 4 + SUMIF(V12:V12, ">1") / 4 + SUMIF(X12:X12, ">1") / 4 + SUMIF(Z12:Z12, ">1") / 4 + SUMIF(AB12:AB12, ">1") / 4 -> 0 | AN12: =SUMIF(AC12:AC12, ">=65") / 4 +SUMIF(AE12:AE12, ">=65") / 4 +SUMIF(AG12:AG12, ">=65") / 4 +SUMIF(AI12:AI12, ">=65") / 4 + SUMIF(AD12:AD12, ">1") / 4 + SUMIF(AF12:AF12, ">1") / 4 + SUMIF(AH12:AH12, ">1") / 4 + SUMIF(AJ12:AJ12, ">1") / 4 -> 0 | AO12: =AVERAGE(AK12:AN12) -> 0 | AR12: =IF(AO12<70, AO12*0.5, "") -> 0 | AT12: =AS12*50% -> 0 | AU12: =IF(AS12<>"", IF(AR12="","",AR12+AT12), "") | AV12: =IF(AU12 < 70, AR12*30%, "") | AX12: =AW12*70% -> 0 | AY12: =IF(AW12<>"", IF(AV12="", "", AV12+AX12), "") | AZ12: =IF(AND(AU12<70, AY12<70), AO12, "") | BB12: =IF(AW12<>"", IF(AY12>=70, AY12, IF(AZ12+BA12>=70, AZ12+BA12, "")), IF(AS12<>"", IF(AU12>=70, AU12, ""), IF(AO12>=70, AO12, ""))) | BC12: =IF(AW12<>"", IF(AY12<70, IF(AZ12+BA12<70, AZ12+BA12, ""), ""), IF(AS12<>"", IF(AU12<70, AU12, ""), IF(AO12<70, AO12, ""))) -> 0 | BE12: =SUM(E12+M12+U12+AC12)/4 -> 0 | BF12: =SUM(G12+O12+W12+AE12)/4 -> 0 | BG12: =SUM(I12+Q12+Y12+AG12)/4 -> 0 | BH12: =SUM(K12+S12+AA12+AI12)/4 -> 0 | BI12: =AVERAGE(BE12:BH12) -> 0
A13: 3 | B13: 1A-B-03 | C13: ALBERT RAMON | D13: BELTRAN PENA | AK13: =SUMIF(E13:E13, ">=70") / 4 +SUMIF(G13:G13, ">=70") / 4 +SUMIF(I13:I13, ">=70") / 4 +SUMIF(K13:K13, ">=70") / 4 + SUMIF(F13:F13, ">1") / 4 + SUMIF(H13:H13, ">1") / 4 + SUMIF(J13:J13, ">1") / 4 + SUMIF(L13:L13, ">1") / 4 -> 0 | AL13: =SUMIF(M13:M13, ">=70") / 4 +SUMIF(O13:O13, ">=70") / 4 +SUMIF(Q13:Q13, ">=70") / 4 +SUMIF(S13:S13, ">=70") / 4 + SUMIF(N13:N13, ">1") / 4 + SUMIF(P13:P13, ">1") / 4 + SUMIF(R13:R13, ">1") / 4 + SUMIF(T13:T13, ">1") / 4 -> 0 | AM13: =SUMIF(U13:U13, ">=70") / 4 +SUMIF(W13:W13, ">=70") / 4 +SUMIF(Y13:Y13, ">=70") / 4 +SUMIF(AA13:AA13, ">=70") / 4 + SUMIF(V13:V13, ">1") / 4 + SUMIF(X13:X13, ">1") / 4 + SUMIF(Z13:Z13, ">1") / 4 + SUMIF(AB13:AB13, ">1") / 4 -> 0 | AN13: =SUMIF(AC13:AC13, ">=65") / 4 +SUMIF(AE13:AE13, ">=65") / 4 +SUMIF(AG13:AG13, ">=65") / 4 +SUMIF(AI13:AI13, ">=65") / 4 + SUMIF(AD13:AD13, ">1") / 4 + SUMIF(AF13:AF13, ">1") / 4 + SUMIF(AH13:AH13, ">1") / 4 + SUMIF(AJ13:AJ13, ">1") / 4 -> 0 | AO13: =AVERAGE(AK13:AN13) -> 0 | AR13: =IF(AO13<70, AO13*0.5, "") -> 0 | AT13: =AS13*50% -> 0 | AU13: =IF(AS13<>"", IF(AR13="","",AR13+AT13), "") | AV13: =IF(AU13 < 70, AR13*30%, "") | AX13: =AW13*70% -> 0 | AY13: =IF(AW13<>"", IF(AV13="", "", AV13+AX13), "") | AZ13: =IF(AND(AU13<70, AY13<70), AO13, "") | BB13: =IF(AW13<>"", IF(AY13>=70, AY13, IF(AZ13+BA13>=70, AZ13+BA13, "")), IF(AS13<>"", IF(AU13>=70, AU13, ""), IF(AO13>=70, AO13, ""))) | BC13: =IF(AW13<>"", IF(AY13<70, IF(AZ13+BA13<70, AZ13+BA13, ""), ""), IF(AS13<>"", IF(AU13<70, AU13, ""), IF(AO13<70, AO13, ""))) -> 0 | BE13: =SUM(E13+M13+U13+AC13)/4 -> 0 | BF13: =SUM(G13+O13+W13+AE13)/4 -> 0 | BG13: =SUM(I13+Q13+Y13+AG13)/4 -> 0 | BH13: =SUM(K13+S13+AA13+AI13)/4 -> 0 | BI13: =AVERAGE(BE13:BH13) -> 0
A14: 4 | B14: 1A-B-04 | C14: NAYCOL | D14: BELTRES QUEZADA | AK14: =SUMIF(E14:E14, ">=70") / 4 +SUMIF(G14:G14, ">=70") / 4 +SUMIF(I14:I14, ">=70") / 4 +SUMIF(K14:K14, ">=70") / 4 + SUMIF(F14:F14, ">1") / 4 + SUMIF(H14:H14, ">1") / 4 + SUMIF(J14:J14, ">1") / 4 + SUMIF(L14:L14, ">1") / 4 -> 0 | AL14: =SUMIF(M14:M14, ">=70") / 4 +SUMIF(O14:O14, ">=70") / 4 +SUMIF(Q14:Q14, ">=70") / 4 +SUMIF(S14:S14, ">=70") / 4 + SUMIF(N14:N14, ">1") / 4 + SUMIF(P14:P14, ">1") / 4 + SUMIF(R14:R14, ">1") / 4 + SUMIF(T14:T14, ">1") / 4 -> 0 | AM14: =SUMIF(U14:U14, ">=70") / 4 +SUMIF(W14:W14, ">=70") / 4 +SUMIF(Y14:Y14, ">=70") / 4 +SUMIF(AA14:AA14, ">=70") / 4 + SUMIF(V14:V14, ">1") / 4 + SUMIF(X14:X14, ">1") / 4 + SUMIF(Z14:Z14, ">1") / 4 + SUMIF(AB14:AB14, ">1") / 4 -> 0 | AN14: =SUMIF(AC14:AC14, ">=65") / 4 +SUMIF(AE14:AE14, ">=65") / 4 +SUMIF(AG14:AG14, ">=65") / 4 +SUMIF(AI14:AI14, ">=65") / 4 + SUMIF(AD14:AD14, ">1") / 4 + SUMIF(AF14:AF14, ">1") / 4 + SUMIF(AH14:AH14, ">1") / 4 + SUMIF(AJ14:AJ14, ">1") / 4 -> 0 | AO14: =AVERAGE(AK14:AN14) -> 0 | AR14: =IF(AO14<70, AO14*0.5, "") -> 0 | AT14: =AS14*50% -> 0 | AU14: =IF(AS14<>"", IF(AR14="","",AR14+AT14), "") | AV14: =IF(AU14 < 70, AR14*30%, "") | AX14: =AW14*70% -> 0 | AY14: =IF(AW14<>"", IF(AV14="", "", AV14+AX14), "") | AZ14: =IF(AND(AU14<70, AY14<70), AO14, "") | BB14: =IF(AW14<>"", IF(AY14>=70, AY14, IF(AZ14+BA14>=70, AZ14+BA14, "")), IF(AS14<>"", IF(AU14>=70, AU14, ""), IF(AO14>=70, AO14, ""))) | BC14: =IF(AW14<>"", IF(AY14<70, IF(AZ14+BA14<70, AZ14+BA14, ""), ""), IF(AS14<>"", IF(AU14<70, AU14, ""), IF(AO14<70, AO14, ""))) -> 0 | BE14: =SUM(E14+M14+U14+AC14)/4 -> 0 | BF14: =SUM(G14+O14+W14+AE14)/4 -> 0 | BG14: =SUM(I14+Q14+Y14+AG14)/4 -> 0 | BH14: =SUM(K14+S14+AA14+AI14)/4 -> 0 | BI14: =AVERAGE(BE14:BH14) -> 0
A15: 5 | B15: 1A-B-05 | C15: YORDANY | D15: BRAND | AK15: =SUMIF(E15:E15, ">=70") / 4 +SUMIF(G15:G15, ">=70") / 4 +SUMIF(I15:I15, ">=70") / 4 +SUMIF(K15:K15, ">=70") / 4 + SUMIF(F15:F15, ">1") / 4 + SUMIF(H15:H15, ">1") / 4 + SUMIF(J15:J15, ">1") / 4 + SUMIF(L15:L15, ">1") / 4 -> 0 | AL15: =SUMIF(M15:M15, ">=70") / 4 +SUMIF(O15:O15, ">=70") / 4 +SUMIF(Q15:Q15, ">=70") / 4 +SUMIF(S15:S15, ">=70") / 4 + SUMIF(N15:N15, ">1") / 4 + SUMIF(P15:P15, ">1") / 4 + SUMIF(R15:R15, ">1") / 4 + SUMIF(T15:T15, ">1") / 4 -> 0 | AM15: =SUMIF(U15:U15, ">=70") / 4 +SUMIF(W15:W15, ">=70") / 4 +SUMIF(Y15:Y15, ">=70") / 4 +SUMIF(AA15:AA15, ">=70") / 4 + SUMIF(V15:V15, ">1") / 4 + SUMIF(X15:X15, ">1") / 4 + SUMIF(Z15:Z15, ">1") / 4 + SUMIF(AB15:AB15, ">1") / 4 -> 0 | AN15: =SUMIF(AC15:AC15, ">=65") / 4 +SUMIF(AE15:AE15, ">=65") / 4 +SUMIF(AG15:AG15, ">=65") / 4 +SUMIF(AI15:AI15, ">=65") / 4 + SUMIF(AD15:AD15, ">1") / 4 + SUMIF(AF15:AF15, ">1") / 4 + SUMIF(AH15:AH15, ">1") / 4 + SUMIF(AJ15:AJ15, ">1") / 4 -> 0 | AO15: =AVERAGE(AK15:AN15) -> 0 | AR15: =IF(AO15<70, AO15*0.5, "") -> 0 | AT15: =AS15*50% -> 0 | AU15: =IF(AS15<>"", IF(AR15="","",AR15+AT15), "") | AV15: =IF(AU15 < 70, AR15*30%, "") | AX15: =AW15*70% -> 0 | AY15: =IF(AW15<>"", IF(AV15="", "", AV15+AX15), "") | AZ15: =IF(AND(AU15<70, AY15<70), AO15, "") | BB15: =IF(AW15<>"", IF(AY15>=70, AY15, IF(AZ15+BA15>=70, AZ15+BA15, "")), IF(AS15<>"", IF(AU15>=70, AU15, ""), IF(AO15>=70, AO15, ""))) | BC15: =IF(AW15<>"", IF(AY15<70, IF(AZ15+BA15<70, AZ15+BA15, ""), ""), IF(AS15<>"", IF(AU15<70, AU15, ""), IF(AO15<70, AO15, ""))) -> 0 | BE15: =SUM(E15+M15+U15+AC15)/4 -> 0 | BF15: =SUM(G15+O15+W15+AE15)/4 -> 0 | BG15: =SUM(I15+Q15+Y15+AG15)/4 -> 0 | BH15: =SUM(K15+S15+AA15+AI15)/4 -> 0 | BI15: =AVERAGE(BE15:BH15) -> 0
A16: 6 | B16: 1A-B-06 | C16: YEFRI | D16: CABRERA ENCARNACION | AK16: =SUMIF(E16:E16, ">=70") / 4 +SUMIF(G16:G16, ">=70") / 4 +SUMIF(I16:I16, ">=70") / 4 +SUMIF(K16:K16, ">=70") / 4 + SUMIF(F16:F16, ">1") / 4 + SUMIF(H16:H16, ">1") / 4 + SUMIF(J16:J16, ">1") / 4 + SUMIF(L16:L16, ">1") / 4 -> 0 | AL16: =SUMIF(M16:M16, ">=70") / 4 +SUMIF(O16:O16, ">=70") / 4 +SUMIF(Q16:Q16, ">=70") / 4 +SUMIF(S16:S16, ">=70") / 4 + SUMIF(N16:N16, ">1") / 4 + SUMIF(P16:P16, ">1") / 4 + SUMIF(R16:R16, ">1") / 4 + SUMIF(T16:T16, ">1") / 4 -> 0 | AM16: =SUMIF(U16:U16, ">=70") / 4 +SUMIF(W16:W16, ">=70") / 4 +SUMIF(Y16:Y16, ">=70") / 4 +SUMIF(AA16:AA16, ">=70") / 4 + SUMIF(V16:V16, ">1") / 4 + SUMIF(X16:X16, ">1") / 4 + SUMIF(Z16:Z16, ">1") / 4 + SUMIF(AB16:AB16, ">1") / 4 -> 0 | AN16: =SUMIF(AC16:AC16, ">=65") / 4 +SUMIF(AE16:AE16, ">=65") / 4 +SUMIF(AG16:AG16, ">=65") / 4 +SUMIF(AI16:AI16, ">=65") / 4 + SUMIF(AD16:AD16, ">1") / 4 + SUMIF(AF16:AF16, ">1") / 4 + SUMIF(AH16:AH16, ">1") / 4 + SUMIF(AJ16:AJ16, ">1") / 4 -> 0 | AO16: =AVERAGE(AK16:AN16) -> 0 | AR16: =IF(AO16<70, AO16*0.5, "") -> 0 | AT16: =AS16*50% -> 0 | AU16: =IF(AS16<>"", IF(AR16="","",AR16+AT16), "") | AV16: =IF(AU16 < 70, AR16*30%, "") | AX16: =AW16*70% -> 0 | AY16: =IF(AW16<>"", IF(AV16="", "", AV16+AX16), "") | AZ16: =IF(AND(AU16<70, AY16<70), AO16, "") | BB16: =IF(AW16<>"", IF(AY16>=70, AY16, IF(AZ16+BA16>=70, AZ16+BA16, "")), IF(AS16<>"", IF(AU16>=70, AU16, ""), IF(AO16>=70, AO16, ""))) | BC16: =IF(AW16<>"", IF(AY16<70, IF(AZ16+BA16<70, AZ16+BA16, ""), ""), IF(AS16<>"", IF(AU16<70, AU16, ""), IF(AO16<70, AO16, ""))) -> 0 | BE16: =SUM(E16+M16+U16+AC16)/4 -> 0 | BF16: =SUM(G16+O16+W16+AE16)/4 -> 0 | BG16: =SUM(I16+Q16+Y16+AG16)/4 -> 0 | BH16: =SUM(K16+S16+AA16+AI16)/4 -> 0 | BI16: =AVERAGE(BE16:BH16) -> 0
A17: 7 | B17: 1A-B-07 | C17: ROLANDO | D17: CANDELARIO PRENSA | AK17: =SUMIF(E17:E17, ">=70") / 4 +SUMIF(G17:G17, ">=70") / 4 +SUMIF(I17:I17, ">=70") / 4 +SUMIF(K17:K17, ">=70") / 4 + SUMIF(F17:F17, ">1") / 4 + SUMIF(H17:H17, ">1") / 4 + SUMIF(J17:J17, ">1") / 4 + SUMIF(L17:L17, ">1") / 4 -> 0 | AL17: =SUMIF(M17:M17, ">=70") / 4 +SUMIF(O17:O17, ">=70") / 4 +SUMIF(Q17:Q17, ">=70") / 4 +SUMIF(S17:S17, ">=70") / 4 + SUMIF(N17:N17, ">1") / 4 + SUMIF(P17:P17, ">1") / 4 + SUMIF(R17:R17, ">1") / 4 + SUMIF(T17:T17, ">1") / 4 -> 0 | AM17: =SUMIF(U17:U17, ">=70") / 4 +SUMIF(W17:W17, ">=70") / 4 +SUMIF(Y17:Y17, ">=70") / 4 +SUMIF(AA17:AA17, ">=70") / 4 + SUMIF(V17:V17, ">1") / 4 + SUMIF(X17:X17, ">1") / 4 + SUMIF(Z17:Z17, ">1") / 4 + SUMIF(AB17:AB17, ">1") / 4 -> 0 | AN17: =SUMIF(AC17:AC17, ">=65") / 4 +SUMIF(AE17:AE17, ">=65") / 4 +SUMIF(AG17:AG17, ">=65") / 4 +SUMIF(AI17:AI17, ">=65") / 4 + SUMIF(AD17:AD17, ">1") / 4 + SUMIF(AF17:AF17, ">1") / 4 + SUMIF(AH17:AH17, ">1") / 4 + SUMIF(AJ17:AJ17, ">1") / 4 -> 0 | AO17: =AVERAGE(AK17:AN17) -> 0 | AR17: =IF(AO17<70, AO17*0.5, "") -> 0 | AT17: =AS17*50% -> 0 | AU17: =IF(AS17<>"", IF(AR17="","",AR17+AT17), "") | AV17: =IF(AU17 < 70, AR17*30%, "") | AX17: =AW17*70% -> 0 | AY17: =IF(AW17<>"", IF(AV17="", "", AV17+AX17), "") | AZ17: =IF(AND(AU17<70, AY17<70), AO17, "") | BB17: =IF(AW17<>"", IF(AY17>=70, AY17, IF(AZ17+BA17>=70, AZ17+BA17, "")), IF(AS17<>"", IF(AU17>=70, AU17, ""), IF(AO17>=70, AO17, ""))) | BC17: =IF(AW17<>"", IF(AY17<70, IF(AZ17+BA17<70, AZ17+BA17, ""), ""), IF(AS17<>"", IF(AU17<70, AU17, ""), IF(AO17<70, AO17, ""))) -> 0 | BE17: =SUM(E17+M17+U17+AC17)/4 -> 0 | BF17: =SUM(G17+O17+W17+AE17)/4 -> 0 | BG17: =SUM(I17+Q17+Y17+AG17)/4 -> 0 | BH17: =SUM(K17+S17+AA17+AI17)/4 -> 0 | BI17: =AVERAGE(BE17:BH17) -> 0
A18: 8 | B18: 1A-B-08 | C18: ELIAN ERNESTO | D18: CESPEDES CAMINERO | AK18: =SUMIF(E18:E18, ">=70") / 4 +SUMIF(G18:G18, ">=70") / 4 +SUMIF(I18:I18, ">=70") / 4 +SUMIF(K18:K18, ">=70") / 4 + SUMIF(F18:F18, ">1") / 4 + SUMIF(H18:H18, ">1") / 4 + SUMIF(J18:J18, ">1") / 4 + SUMIF(L18:L18, ">1") / 4 -> 0 | AL18: =SUMIF(M18:M18, ">=70") / 4 +SUMIF(O18:O18, ">=70") / 4 +SUMIF(Q18:Q18, ">=70") / 4 +SUMIF(S18:S18, ">=70") / 4 + SUMIF(N18:N18, ">1") / 4 + SUMIF(P18:P18, ">1") / 4 + SUMIF(R18:R18, ">1") / 4 + SUMIF(T18:T18, ">1") / 4 -> 0 | AM18: =SUMIF(U18:U18, ">=70") / 4 +SUMIF(W18:W18, ">=70") / 4 +SUMIF(Y18:Y18, ">=70") / 4 +SUMIF(AA18:AA18, ">=70") / 4 + SUMIF(V18:V18, ">1") / 4 + SUMIF(X18:X18, ">1") / 4 + SUMIF(Z18:Z18, ">1") / 4 + SUMIF(AB18:AB18, ">1") / 4 -> 0 | AN18: =SUMIF(AC18:AC18, ">=65") / 4 +SUMIF(AE18:AE18, ">=65") / 4 +SUMIF(AG18:AG18, ">=65") / 4 +SUMIF(AI18:AI18, ">=65") / 4 + SUMIF(AD18:AD18, ">1") / 4 + SUMIF(AF18:AF18, ">1") / 4 + SUMIF(AH18:AH18, ">1") / 4 + SUMIF(AJ18:AJ18, ">1") / 4 -> 0 | AO18: =AVERAGE(AK18:AN18) -> 0 | AR18: =IF(AO18<70, AO18*0.5, "") -> 0 | AT18: =AS18*50% -> 0 | AU18: =IF(AS18<>"", IF(AR18="","",AR18+AT18), "") | AV18: =IF(AU18 < 70, AR18*30%, "") | AX18: =AW18*70% -> 0 | AY18: =IF(AW18<>"", IF(AV18="", "", AV18+AX18), "") | AZ18: =IF(AND(AU18<70, AY18<70), AO18, "") | BB18: =IF(AW18<>"", IF(AY18>=70, AY18, IF(AZ18+BA18>=70, AZ18+BA18, "")), IF(AS18<>"", IF(AU18>=70, AU18, ""), IF(AO18>=70, AO18, ""))) | BC18: =IF(AW18<>"", IF(AY18<70, IF(AZ18+BA18<70, AZ18+BA18, ""), ""), IF(AS18<>"", IF(AU18<70, AU18, ""), IF(AO18<70, AO18, ""))) -> 0 | BE18: =SUM(E18+M18+U18+AC18)/4 -> 0 | BF18: =SUM(G18+O18+W18+AE18)/4 -> 0 | BG18: =SUM(I18+Q18+Y18+AG18)/4 -> 0 | BH18: =SUM(K18+S18+AA18+AI18)/4 -> 0 | BI18: =AVERAGE(BE18:BH18) -> 0
A19: 9 | B19: 1A-B-09 | C19: JENIA | D19: CHARLES | AK19: =SUMIF(E19:E19, ">=70") / 4 +SUMIF(G19:G19, ">=70") / 4 +SUMIF(I19:I19, ">=70") / 4 +SUMIF(K19:K19, ">=70") / 4 + SUMIF(F19:F19, ">1") / 4 + SUMIF(H19:H19, ">1") / 4 + SUMIF(J19:J19, ">1") / 4 + SUMIF(L19:L19, ">1") / 4 -> 0 | AL19: =SUMIF(M19:M19, ">=70") / 4 +SUMIF(O19:O19, ">=70") / 4 +SUMIF(Q19:Q19, ">=70") / 4 +SUMIF(S19:S19, ">=70") / 4 + SUMIF(N19:N19, ">1") / 4 + SUMIF(P19:P19, ">1") / 4 + SUMIF(R19:R19, ">1") / 4 + SUMIF(T19:T19, ">1") / 4 -> 0 | AM19: =SUMIF(U19:U19, ">=70") / 4 +SUMIF(W19:W19, ">=70") / 4 +SUMIF(Y19:Y19, ">=70") / 4 +SUMIF(AA19:AA19, ">=70") / 4 + SUMIF(V19:V19, ">1") / 4 + SUMIF(X19:X19, ">1") / 4 + SUMIF(Z19:Z19, ">1") / 4 + SUMIF(AB19:AB19, ">1") / 4 -> 0 | AN19: =SUMIF(AC19:AC19, ">=65") / 4 +SUMIF(AE19:AE19, ">=65") / 4 +SUMIF(AG19:AG19, ">=65") / 4 +SUMIF(AI19:AI19, ">=65") / 4 + SUMIF(AD19:AD19, ">1") / 4 + SUMIF(AF19:AF19, ">1") / 4 + SUMIF(AH19:AH19, ">1") / 4 + SUMIF(AJ19:AJ19, ">1") / 4 -> 0 | AO19: =AVERAGE(AK19:AN19) -> 0 | AR19: =IF(AO19<70, AO19*0.5, "") -> 0 | AT19: =AS19*50% -> 0 | AU19: =IF(AS19<>"", IF(AR19="","",AR19+AT19), "") | AV19: =IF(AU19 < 70, AR19*30%, "") | AX19: =AW19*70% -> 0 | AY19: =IF(AW19<>"", IF(AV19="", "", AV19+AX19), "") | AZ19: =IF(AND(AU19<70, AY19<70), AO19, "") | BB19: =IF(AW19<>"", IF(AY19>=70, AY19, IF(AZ19+BA19>=70, AZ19+BA19, "")), IF(AS19<>"", IF(AU19>=70, AU19, ""), IF(AO19>=70, AO19, ""))) | BC19: =IF(AW19<>"", IF(AY19<70, IF(AZ19+BA19<70, AZ19+BA19, ""), ""), IF(AS19<>"", IF(AU19<70, AU19, ""), IF(AO19<70, AO19, ""))) -> 0 | BE19: =SUM(E19+M19+U19+AC19)/4 -> 0 | BF19: =SUM(G19+O19+W19+AE19)/4 -> 0 | BG19: =SUM(I19+Q19+Y19+AG19)/4 -> 0 | BH19: =SUM(K19+S19+AA19+AI19)/4 -> 0 | BI19: =AVERAGE(BE19:BH19) -> 0
A20: 10 | B20: 1A-B-10 | C20: FERMIN YUNIOR | D20: CUSTODIO | AK20: =SUMIF(E20:E20, ">=70") / 4 +SUMIF(G20:G20, ">=70") / 4 +SUMIF(I20:I20, ">=70") / 4 +SUMIF(K20:K20, ">=70") / 4 + SUMIF(F20:F20, ">1") / 4 + SUMIF(H20:H20, ">1") / 4 + SUMIF(J20:J20, ">1") / 4 + SUMIF(L20:L20, ">1") / 4 -> 0 | AL20: =SUMIF(M20:M20, ">=70") / 4 +SUMIF(O20:O20, ">=70") / 4 +SUMIF(Q20:Q20, ">=70") / 4 +SUMIF(S20:S20, ">=70") / 4 + SUMIF(N20:N20, ">1") / 4 + SUMIF(P20:P20, ">1") / 4 + SUMIF(R20:R20, ">1") / 4 + SUMIF(T20:T20, ">1") / 4 -> 0 | AM20: =SUMIF(U20:U20, ">=70") / 4 +SUMIF(W20:W20, ">=70") / 4 +SUMIF(Y20:Y20, ">=70") / 4 +SUMIF(AA20:AA20, ">=70") / 4 + SUMIF(V20:V20, ">1") / 4 + SUMIF(X20:X20, ">1") / 4 + SUMIF(Z20:Z20, ">1") / 4 + SUMIF(AB20:AB20, ">1") / 4 -> 0 | AN20: =SUMIF(AC20:AC20, ">=65") / 4 +SUMIF(AE20:AE20, ">=65") / 4 +SUMIF(AG20:AG20, ">=65") / 4 +SUMIF(AI20:AI20, ">=65") / 4 + SUMIF(AD20:AD20, ">1") / 4 + SUMIF(AF20:AF20, ">1") / 4 + SUMIF(AH20:AH20, ">1") / 4 + SUMIF(AJ20:AJ20, ">1") / 4 -> 0 | AO20: =AVERAGE(AK20:AN20) -> 0 | AR20: =IF(AO20<70, AO20*0.5, "") -> 0 | AT20: =AS20*50% -> 0 | AU20: =IF(AS20<>"", IF(AR20="","",AR20+AT20), "") | AV20: =IF(AU20 < 70, AR20*30%, "") | AX20: =AW20*70% -> 0 | AY20: =IF(AW20<>"", IF(AV20="", "", AV20+AX20), "") | AZ20: =IF(AND(AU20<70, AY20<70), AO20, "") | BB20: =IF(AW20<>"", IF(AY20>=70, AY20, IF(AZ20+BA20>=70, AZ20+BA20, "")), IF(AS20<>"", IF(AU20>=70, AU20, ""), IF(AO20>=70, AO20, ""))) | BC20: =IF(AW20<>"", IF(AY20<70, IF(AZ20+BA20<70, AZ20+BA20, ""), ""), IF(AS20<>"", IF(AU20<70, AU20, ""), IF(AO20<70, AO20, ""))) -> 0 | BE20: =SUM(E20+M20+U20+AC20)/4 -> 0 | BF20: =SUM(G20+O20+W20+AE20)/4 -> 0 | BG20: =SUM(I20+Q20+Y20+AG20)/4 -> 0 | BH20: =SUM(K20+S20+AA20+AI20)/4 -> 0 | BI20: =AVERAGE(BE20:BH20) -> 0
A21: 11 | B21: 1A-B-11 | C21: STIVEN | D21: D´OLEO TORRES | AK21: =SUMIF(E21:E21, ">=70") / 4 +SUMIF(G21:G21, ">=70") / 4 +SUMIF(I21:I21, ">=70") / 4 +SUMIF(K21:K21, ">=70") / 4 + SUMIF(F21:F21, ">1") / 4 + SUMIF(H21:H21, ">1") / 4 + SUMIF(J21:J21, ">1") / 4 + SUMIF(L21:L21, ">1") / 4 -> 0 | AL21: =SUMIF(M21:M21, ">=70") / 4 +SUMIF(O21:O21, ">=70") / 4 +SUMIF(Q21:Q21, ">=70") / 4 +SUMIF(S21:S21, ">=70") / 4 + SUMIF(N21:N21, ">1") / 4 + SUMIF(P21:P21, ">1") / 4 + SUMIF(R21:R21, ">1") / 4 + SUMIF(T21:T21, ">1") / 4 -> 0 | AM21: =SUMIF(U21:U21, ">=70") / 4 +SUMIF(W21:W21, ">=70") / 4 +SUMIF(Y21:Y21, ">=70") / 4 +SUMIF(AA21:AA21, ">=70") / 4 + SUMIF(V21:V21, ">1") / 4 + SUMIF(X21:X21, ">1") / 4 + SUMIF(Z21:Z21, ">1") / 4 + SUMIF(AB21:AB21, ">1") / 4 -> 0 | AN21: =SUMIF(AC21:AC21, ">=65") / 4 +SUMIF(AE21:AE21, ">=65") / 4 +SUMIF(AG21:AG21, ">=65") / 4 +SUMIF(AI21:AI21, ">=65") / 4 + SUMIF(AD21:AD21, ">1") / 4 + SUMIF(AF21:AF21, ">1") / 4 + SUMIF(AH21:AH21, ">1") / 4 + SUMIF(AJ21:AJ21, ">1") / 4 -> 0 | AO21: =AVERAGE(AK21:AN21) -> 0 | AR21: =IF(AO21<70, AO21*0.5, "") -> 0 | AT21: =AS21*50% -> 0 | AU21: =IF(AS21<>"", IF(AR21="","",AR21+AT21), "") | AV21: =IF(AU21 < 70, AR21*30%, "") | AX21: =AW21*70% -> 0 | AY21: =IF(AW21<>"", IF(AV21="", "", AV21+AX21), "") | AZ21: =IF(AND(AU21<70, AY21<70), AO21, "") | BB21: =IF(AW21<>"", IF(AY21>=70, AY21, IF(AZ21+BA21>=70, AZ21+BA21, "")), IF(AS21<>"", IF(AU21>=70, AU21, ""), IF(AO21>=70, AO21, ""))) | BC21: =IF(AW21<>"", IF(AY21<70, IF(AZ21+BA21<70, AZ21+BA21, ""), ""), IF(AS21<>"", IF(AU21<70, AU21, ""), IF(AO21<70, AO21, ""))) -> 0 | BE21: =SUM(E21+M21+U21+AC21)/4 -> 0 | BF21: =SUM(G21+O21+W21+AE21)/4 -> 0 | BG21: =SUM(I21+Q21+Y21+AG21)/4 -> 0 | BH21: =SUM(K21+S21+AA21+AI21)/4 -> 0 | BI21: =AVERAGE(BE21:BH21) -> 0
A22: 12 | B22: 1A-B-12 | C22: JORGE LUIS | D22: DE JESUS DE LA CRUZ | AK22: =SUMIF(E22:E22, ">=70") / 4 +SUMIF(G22:G22, ">=70") / 4 +SUMIF(I22:I22, ">=70") / 4 +SUMIF(K22:K22, ">=70") / 4 + SUMIF(F22:F22, ">1") / 4 + SUMIF(H22:H22, ">1") / 4 + SUMIF(J22:J22, ">1") / 4 + SUMIF(L22:L22, ">1") / 4 -> 0 | AL22: =SUMIF(M22:M22, ">=70") / 4 +SUMIF(O22:O22, ">=70") / 4 +SUMIF(Q22:Q22, ">=70") / 4 +SUMIF(S22:S22, ">=70") / 4 + SUMIF(N22:N22, ">1") / 4 + SUMIF(P22:P22, ">1") / 4 + SUMIF(R22:R22, ">1") / 4 + SUMIF(T22:T22, ">1") / 4 -> 0 | AM22: =SUMIF(U22:U22, ">=70") / 4 +SUMIF(W22:W22, ">=70") / 4 +SUMIF(Y22:Y22, ">=70") / 4 +SUMIF(AA22:AA22, ">=70") / 4 + SUMIF(V22:V22, ">1") / 4 + SUMIF(X22:X22, ">1") / 4 + SUMIF(Z22:Z22, ">1") / 4 + SUMIF(AB22:AB22, ">1") / 4 -> 0 | AN22: =SUMIF(AC22:AC22, ">=65") / 4 +SUMIF(AE22:AE22, ">=65") / 4 +SUMIF(AG22:AG22, ">=65") / 4 +SUMIF(AI22:AI22, ">=65") / 4 + SUMIF(AD22:AD22, ">1") / 4 + SUMIF(AF22:AF22, ">1") / 4 + SUMIF(AH22:AH22, ">1") / 4 + SUMIF(AJ22:AJ22, ">1") / 4 -> 0 | AO22: =AVERAGE(AK22:AN22) -> 0 | AR22: =IF(AO22<70, AO22*0.5, "") -> 0 | AT22: =AS22*50% -> 0 | AU22: =IF(AS22<>"", IF(AR22="","",AR22+AT22), "") | AV22: =IF(AU22 < 70, AR22*30%, "") | AX22: =AW22*70% -> 0 | AY22: =IF(AW22<>"", IF(AV22="", "", AV22+AX22), "") | AZ22: =IF(AND(AU22<70, AY22<70), AO22, "") | BB22: =IF(AW22<>"", IF(AY22>=70, AY22, IF(AZ22+BA22>=70, AZ22+BA22, "")), IF(AS22<>"", IF(AU22>=70, AU22, ""), IF(AO22>=70, AO22, ""))) | BC22: =IF(AW22<>"", IF(AY22<70, IF(AZ22+BA22<70, AZ22+BA22, ""), ""), IF(AS22<>"", IF(AU22<70, AU22, ""), IF(AO22<70, AO22, ""))) -> 0 | BE22: =SUM(E22+M22+U22+AC22)/4 -> 0 | BF22: =SUM(G22+O22+W22+AE22)/4 -> 0 | BG22: =SUM(I22+Q22+Y22+AG22)/4 -> 0 | BH22: =SUM(K22+S22+AA22+AI22)/4 -> 0 | BI22: =AVERAGE(BE22:BH22) -> 0
A23: 13 | B23: 1A-B-13 | C23: JEISY MARIA | D23: DE LOS SANTOS REYES | AK23: =SUMIF(E23:E23, ">=70") / 4 +SUMIF(G23:G23, ">=70") / 4 +SUMIF(I23:I23, ">=70") / 4 +SUMIF(K23:K23, ">=70") / 4 + SUMIF(F23:F23, ">1") / 4 + SUMIF(H23:H23, ">1") / 4 + SUMIF(J23:J23, ">1") / 4 + SUMIF(L23:L23, ">1") / 4 -> 0 | AL23: =SUMIF(M23:M23, ">=70") / 4 +SUMIF(O23:O23, ">=70") / 4 +SUMIF(Q23:Q23, ">=70") / 4 +SUMIF(S23:S23, ">=70") / 4 + SUMIF(N23:N23, ">1") / 4 + SUMIF(P23:P23, ">1") / 4 + SUMIF(R23:R23, ">1") / 4 + SUMIF(T23:T23, ">1") / 4 -> 0 | AM23: =SUMIF(U23:U23, ">=70") / 4 +SUMIF(W23:W23, ">=70") / 4 +SUMIF(Y23:Y23, ">=70") / 4 +SUMIF(AA23:AA23, ">=70") / 4 + SUMIF(V23:V23, ">1") / 4 + SUMIF(X23:X23, ">1") / 4 + SUMIF(Z23:Z23, ">1") / 4 + SUMIF(AB23:AB23, ">1") / 4 -> 0 | AN23: =SUMIF(AC23:AC23, ">=65") / 4 +SUMIF(AE23:AE23, ">=65") / 4 +SUMIF(AG23:AG23, ">=65") / 4 +SUMIF(AI23:AI23, ">=65") / 4 + SUMIF(AD23:AD23, ">1") / 4 + SUMIF(AF23:AF23, ">1") / 4 + SUMIF(AH23:AH23, ">1") / 4 + SUMIF(AJ23:AJ23, ">1") / 4 -> 0 | AO23: =AVERAGE(AK23:AN23) -> 0 | AR23: =IF(AO23<70, AO23*0.5, "") -> 0 | AT23: =AS23*50% -> 0 | AU23: =IF(AS23<>"", IF(AR23="","",AR23+AT23), "") | AV23: =IF(AU23 < 70, AR23*30%, "") | AX23: =AW23*70% -> 0 | AY23: =IF(AW23<>"", IF(AV23="", "", AV23+AX23), "") | AZ23: =IF(AND(AU23<70, AY23<70), AO23, "") | BB23: =IF(AW23<>"", IF(AY23>=70, AY23, IF(AZ23+BA23>=70, AZ23+BA23, "")), IF(AS23<>"", IF(AU23>=70, AU23, ""), IF(AO23>=70, AO23, ""))) | BC23: =IF(AW23<>"", IF(AY23<70, IF(AZ23+BA23<70, AZ23+BA23, ""), ""), IF(AS23<>"", IF(AU23<70, AU23, ""), IF(AO23<70, AO23, ""))) -> 0 | BE23: =SUM(E23+M23+U23+AC23)/4 -> 0 | BF23: =SUM(G23+O23+W23+AE23)/4 -> 0 | BG23: =SUM(I23+Q23+Y23+AG23)/4 -> 0 | BH23: =SUM(K23+S23+AA23+AI23)/4 -> 0 | BI23: =AVERAGE(BE23:BH23) -> 0
... A55: 45 | B55: 1A-B-45 | C55: DILAN | D55: SANTIAGO | AK55: =SUMIF(E55:E55, ">=70") / 4 +SUMIF(G55:G55, ">=70") / 4 +SUMIF(I55:I55, ">=70") / 4 +SUMIF(K55:K55, ">=70") / 4 + SUMIF(F55:F55, ">1") / 4 + SUMIF(H55:H55, ">1") / 4 + SUMIF(J55:J55, ">1") / 4 + SUMIF(L55:L55, ">1") / 4 -> 0 | AL55: =SUMIF(M55:M55, ">=70") / 4 +SUMIF(O55:O55, ">=70") / 4 +SUMIF(Q55:Q55, ">=70") / 4 +SUMIF(S55:S55, ">=70") / 4 + SUMIF(N55:N55, ">1") / 4 + SUMIF(P55:P55, ">1") / 4 + SUMIF(R55:R55, ">1") / 4 + SUMIF(T55:T55, ">1") / 4 -> 0 | AM55: =SUMIF(U55:U55, ">=70") / 4 +SUMIF(W55:W55, ">=70") / 4 +SUMIF(Y55:Y55, ">=70") / 4 +SUMIF(AA55:AA55, ">=70") / 4 + SUMIF(V55:V55, ">1") / 4 + SUMIF(X55:X55, ">1") / 4 + SUMIF(Z55:Z55, ">1") / 4 + SUMIF(AB55:AB55, ">1") / 4 -> 0 | AN55: =SUMIF(AC55:AC55, ">=65") / 4 +SUMIF(AE55:AE55, ">=65") / 4 +SUMIF(AG55:AG55, ">=65") / 4 +SUMIF(AI55:AI55, ">=65") / 4 + SUMIF(AD55:AD55, ">1") / 4 + SUMIF(AF55:AF55, ">1") / 4 + SUMIF(AH55:AH55, ">1") / 4 + SUMIF(AJ55:AJ55, ">1") / 4 -> 0 | AO55: =AVERAGE(AK55:AN55) -> 0 | AR55: =IF(AO55<70, AO55*0.5, "") -> 0 | AT55: =AS55*50% -> 0 | AU55: =IF(AS55<>"", IF(AR55="","",AR55+AT55), "") | AV55: =IF(AU55 < 70, AR55*30%, "") | AX55: =AW55*70% -> 0 | AY55: =IF(AW55<>"", IF(AV55="", "", AV55+AX55), "") | AZ55: =IF(AND(AU55<70, AY55<70), AO55, "") | BB55: =IF(AW55<>"", IF(AY55>=70, AY55, IF(AZ55+BA55>=70, AZ55+BA55, "")), IF(AS55<>"", IF(AU55>=70, AU55, ""), IF(AO55>=70, AO55, ""))) | BC55: =IF(AW55<>"", IF(AY55<70, IF(AZ55+BA55<70, AZ55+BA55, ""), ""), IF(AS55<>"", IF(AU55<70, AU55, ""), IF(AO55<70, AO55, ""))) -> 0 | BE55: =SUM(E55+M55+U55+AC55)/4 -> 0 | BF55: =SUM(G55+O55+W55+AE55)/4 -> 0 | BG55: =SUM(I55+Q55+Y55+AG55)/4 -> 0 | BH55: =SUM(K55+S55+AA55+AI55)/4 -> 0 | BI55: =AVERAGE(BE55:BH55) -> 0

Sheet INGLES
E7: CALCULO DE NOTAS | AO7: Calificacion Final | AP7: % DE ASISTENCIA ANUAL | AR7: CALIFICACION COMPLETIVA | AV7: CALIFICACION EXTRAORDINARIA | AZ7: EVALUACION ESPECIAL | BB7: SITUACIONFINAL EN LA ASIGNATURA
A9: NO | B9: ID | C9: NOMBRES | D9: APELLIDOS | E9: CE - LE1 | M9: CE - LE2, LE3 | U9: CE - LE4, LE6 | AC9: CE - LE5, LE7 | AK9: PCP 1 | AL9: PCP 2 | AM9: PCP 3 | AN9: PCP 4 | AR9: 50% C.F | AS9: C.E.C. | AT9: 50% C.E.C. | AU9: C.C.F | AV9: 30% C.F. | AW9: C.E.EX | AX9: 70% C.E.EX | AY9: C.EX.F | AZ9: C.F. | BA9: C.E. | BB9: A | BC9: R
E10: P1 | F10: RP1 | G10: P2 | H10: RP2 | I10: P3 | J10: RP3 | K10: P4 | L10: RP4 | M10: P1 | N10: RP1 | O10: P2 | P10: RP2 | Q10: P3 | R10: RP3 | S10: P4 | T10: RP4 | U10: P1 | V10: RP1 | W10: P2 | X10: RP3 | Y10: P3 | Z10: RP4 | AA10: P4 | AB10: RP4 | AC10: P1 | AD10: RP1 | AE10: P2 | AF10: RP3 | AG10: P3 | AH10: RP4 | AI10: P4 | AJ10: RP4 | BE10: P1 | BF10: P2 | BG10: P3 | BH10: P4 | BI10: C.F
A11: 1 | B11: 1A-B-01 | C11: LUIS ANGEL | D11: APREDIEU | AK11: =SUMIF(E11:E11, ">=70") / 4 +SUMIF(G11:G11, ">=70") / 4 +SUMIF(I11:I11, ">=70") / 4 +SUMIF(K11:K11, ">=70") / 4 + SUMIF(F11:F11, ">1") / 4 + SUMIF(H11:H11, ">1") / 4 + SUMIF(J11:J11, ">1") / 4 + SUMIF(L11:L11, ">1") / 4 -> 0 | AL11: =SUMIF(M11:M11, ">=70") / 4 +SUMIF(O11:O11, ">=70") / 4 +SUMIF(Q11:Q11, ">=70") / 4 +SUMIF(S11:S11, ">=70") / 4 + SUMIF(N11:N11, ">1") / 4 + SUMIF(P11:P11, ">1") / 4 + SUMIF(R11:R11, ">1") / 4 + SUMIF(T11:T11, ">1") / 4 -> 0 | AM11: =SUMIF(U11:U11, ">=70") / 4 +SUMIF(W11:W11, ">=70") / 4 +SUMIF(Y11:Y11, ">=70") / 4 +SUMIF(AA11:AA11, ">=70") / 4 + SUMIF(V11:V11, ">1") / 4 + SUMIF(X11:X11, ">1") / 4 + SUMIF(Z11:Z11, ">1") / 4 + SUMIF(AB11:AB11, ">1") / 4 -> 0 | AN11: =SUMIF(AC11:AC11, ">=70") / 4 +SUMIF(AE11:AE11, ">=70") / 4 +SUMIF(AG11:AG11, ">=70") / 4 +SUMIF(AI11:AI11, ">=70") / 4 + SUMIF(AD11:AD11, ">1") / 4 + SUMIF(AF11:AF11, ">1") / 4 + SUMIF(AH11:AH11, ">1") / 4 + SUMIF(AJ11:AJ11, ">1") / 4 -> 0 | AO11: =AVERAGE(AK11:AN11) -> 0 | AR11: =IF(AO11<70, AO11*0.5, "") -> 0 | AT11: =AS11*50% -> 0 | AU11: =IF(AS11<>"", IF(AR11="","",AR11+AT11), "") | AV11: =IF(AU11 < 70, AR11*30%, "") | AX11: =AW11*70% -> 0 | AY11: =IF(AW11<>"", IF(AV11="", "", AV11+AX11), "") | AZ11: =IF(AND(AU11<70, AY11<70), AO11, "") | BB11: =IF(AW11<>"", IF(AY11>=70, AY11, IF(AZ11+BA11>=70, AZ11+BA11, "")), IF(AS11<>"", IF(AU11>=70, AU11, ""), IF(AO11>=70, AO11, ""))) | BC11: =IF(AW11<>"", IF(AY11<70, IF(AZ11+BA11<70, AZ11+BA11, ""), ""), IF(AS11<>"", IF(AU11<70, AU11, ""), IF(AO11<70, AO11, ""))) -> 0 | BE11: =SUM(E11+M11+U11+AC11)/4 -> 0 | BF11: =SUM(G11+O11+W11+AE11)/4 -> 0 | BG11: =SUM(I11+Q11+Y11+AG11)/4 -> 0 | BH11: =SUM(K11+S11+AA11+AI11)/4 -> 0 | BI11: =AVERAGE(BE11:BH11) -> 0
A12: 2 | B12: 1A-B-02 | C12: DARIEL | D12: ARCANGEL VASQUEZ | E12: 86 | G12: 85 | I12: 84 | K12: 85 | M12: 88 | O12: 90 | Q12: 87 | S12: 91 | U12: 86 | W12: 88 | Y12: 85 | AA12: 89 | AC12: 87 | AE12: 93 | AG12: 88 | AI12: 92 | AK12: =SUMIF(E12:E12, ">=70") / 4 +SUMIF(G12:G12, ">=70") / 4 +SUMIF(I12:I12, ">=70") / 4 +SUMIF(K12:K12, ">=70") / 4 + SUMIF(F12:F12, ">1") / 4 + SUMIF(H12:H12, ">1") / 4 + SUMIF(J12:J12, ">1") / 4 + SUMIF(L12:L12, ">1") / 4 -> 85 | AL12: =SUMIF(M12:M12, ">=70") / 4 +SUMIF(O12:O12, ">=70") / 4 +SUMIF(Q12:Q12, ">=70") / 4 +SUMIF(S12:S12, ">=70") / 4 + SUMIF(N12:N12, ">1") / 4 + SUMIF(P12:P12, ">1") / 4 + SUMIF(R12:R12, ">1") / 4 + SUMIF(T12:T12, ">1") / 4 -> 89 | AM12: =SUMIF(U12:U12, ">=70") / 4 +SUMIF(W12:W12, ">=70") / 4 +SUMIF(Y12:Y12, ">=70") / 4 +SUMIF(AA12:AA12, ">=70") / 4 + SUMIF(V12:V12, ">1") / 4 + SUMIF(X12:X12, ">1") / 4 + SUMIF(Z12:Z12, ">1") / 4 + SUMIF(AB12:AB12, ">1") / 4 -> 87 | AN12: =SUMIF(AC12:AC12, ">=65") / 4 +SUMIF(AE12:AE12, ">=65") / 4 +SUMIF(AG12:AG12, ">=65") / 4 +SUMIF(AI12:AI12, ">=65") / 4 + SUMIF(AD12:AD12, ">1") / 4 + SUMIF(AF12:AF12, ">1") / 4 + SUMIF(AH12:AH12, ">1") / 4 + SUMIF(AJ12:AJ12, ">1") / 4 -> 90 | AO12: =AVERAGE(AK12:AN12) -> 87.75 | AR12: =IF(AO12<70, AO12*0.5, "") | AT12: =AS12*50% -> 0 | AU12: =IF(AS12<>"", IF(AR12="","",AR12+AT12), "") | AV12: =IF(AU12 < 70, AR12*30%, "") | AX12: =AW12*70% -> 0 | AY12: =IF(AW12<>"", IF(AV12="", "", AV12+AX12), "") | AZ12: =IF(AND(AU12<70, AY12<70), AO12, "") | BB12: =IF(AW12<>"", IF(AY12>=70, AY12, IF(AZ12+BA12>=70, AZ12+BA12, "")), IF(AS12<>"", IF(AU12>=70, AU12, ""), IF(AO12>=70, AO12, ""))) -> 87.75 | BC12: =IF(AW12<>"", IF(AY12<70, IF(AZ12+BA12<70, AZ12+BA12, ""), ""), IF(AS12<>"", IF(AU12<70, AU12, ""), IF(AO12<70, AO12, ""))) | BE12: =SUM(E12+M12+U12+AC12)/4 -> 86.75 | BF12: =SUM(G12+O12+W12+AE12)/4 -> 89 | BG12: =SUM(I12+Q12+Y12+AG12)/4 -> 86 | BH12: =SUM(K12+S12+AA12+AI12)/4 -> 89.25 | BI12: =AVERAGE(BE12:BH12) -> 87.75
A13: 3 | B13: 1A-B-03 | C13: ALBERT RAMON | D13: BELTRAN PENA | E13: 73 | G13: 75 | M13: 75 | O13: 77 | Q13: 75 | U13: 76 | W13: 79 | AC13: 74 | AE13: 78 | AK13: =SUMIF(E13:E13, ">=70") / 4 +SUMIF(G13:G13, ">=70") / 4 +SUMIF(I13:I13, ">=70") / 4 +SUMIF(K13:K13, ">=70") / 4 + SUMIF(F13:F13, ">1") / 4 + SUMIF(H13:H13, ">1") / 4 + SUMIF(J13:J13, ">1") / 4 + SUMIF(L13:L13, ">1") / 4 -> 37 | AL13: =SUMIF(M13:M13, ">=70") / 4 +SUMIF(O13:O13, ">=70") / 4 +SUMIF(Q13:Q13, ">=70") / 4 +SUMIF(S13:S13, ">=70") / 4 + SUMIF(N13:N13, ">1") / 4 + SUMIF(P13:P13, ">1") / 4 + SUMIF(R13:R13, ">1") / 4 + SUMIF(T13:T13, ">1") / 4 -> 56.75 | AM13: =SUMIF(U13:U13, ">=70") / 4 +SUMIF(W13:W13, ">=70") / 4 +SUMIF(Y13:Y13, ">=70") / 4 +SUMIF(AA13:AA13, ">=70") / 4 + SUMIF(V13:V13, ">1") / 4 + SUMIF(X13:X13, ">1") / 4 + SUMIF(Z13:Z13, ">1") / 4 + SUMIF(AB13:AB13, ">1") / 4 -> 38.75 | AN13: =SUMIF(AC13:AC13, ">=65") / 4 +SUMIF(AE13:AE13, ">=65") / 4 +SUMIF(AG13:AG13, ">=65") / 4 +SUMIF(AI13:AI13, ">=65") / 4 + SUMIF(AD13:AD13, ">1") / 4 + SUMIF(AF13:AF13, ">1") / 4 + SUMIF(AH13:AH13, ">1") / 4 + SUMIF(AJ13:AJ13, ">1") / 4 -> 38 | AO13: =AVERAGE(AK13:AN13) -> 42.625 | AR13: =IF(AO13<70, AO13*0.5, "") -> 21.3125 | AT13: =AS13*50% -> 0 | AU13: =IF(AS13<>"", IF(AR13="","",AR13+AT13), "") | AV13: =IF(AU13 < 70, AR13*30%, "") | AX13: =AW13*70% -> 0 | AY13: =IF(AW13<>"", IF(AV13="", "", AV13+AX13), "") | AZ13: =IF(AND(AU13<70, AY13<70), AO13, "") | BB13: =IF(AW13<>"", IF(AY13>=70, AY13, IF(AZ13+BA13>=70, AZ13+BA13, "")), IF(AS13<>"", IF(AU13>=70, AU13, ""), IF(AO13>=70, AO13, ""))) | BC13: =IF(AW13<>"", IF(AY13<70, IF(AZ13+BA13<70, AZ13+BA13, ""), ""), IF(AS13<>"", IF(AU13<70, AU13, ""), IF(AO13<70, AO13, ""))) -> 42.625 | BE13: =SUM(E13+M13+U13+AC13)/4 -> 74.5 | BF13: =SUM(G13+O13+W13+AE13)/4 -> 77.25 | BG13: =SUM(I13+Q13+Y13+AG13)/4 -> 18.75 | BH13: =SUM(K13+S13+AA13+AI13)/4 -> 0 | BI13: =AVERAGE(BE13:BH13) -> 42.625
A14: 4 | B14: 1A-B-04 | C14: NAYCOL | D14: BELTRES QUEZADA | E14: 75 | G14: 77 | I14: 74 | K14: 78 | M14: 79 | O14: 81 | Q14: 78 | S14: 82 | U14: 83 | W14: 85 | Y14: 82 | AA14: 86 | AC14: 87 | AE14: 89 | AG14: 86 | AI14: 90 | AK14: =SUMIF(E14:E14, ">=70") / 4 +SUMIF(G14:G14, ">=70") / 4 +SUMIF(I14:I14, ">=70") / 4 +SUMIF(K14:K14, ">=70") / 4 + SUMIF(F14:F14, ">1") / 4 + SUMIF(H14:H14, ">1") / 4 + SUMIF(J14:J14, ">1") / 4 + SUMIF(L14:L14, ">1") / 4 -> 76 | AL14: =SUMIF(M14:M14, ">=70") / 4 +SUMIF(O14:O14, ">=70") / 4 +SUMIF(Q14:Q14, ">=70") / 4 +SUMIF(S14:S14, ">=70") / 4 + SUMIF(N14:N14, ">1") / 4 + SUMIF(P14:P14, ">1") / 4 + SUMIF(R14:R14, ">1") / 4 + SUMIF(T14:T14, ">1") / 4 -> 80 | AM14: =SUMIF(U14:U14, ">=70") / 4 +SUMIF(W14:W14, ">=70") / 4 +SUMIF(Y14:Y14, ">=70") / 4 +SUMIF(AA14:AA14, ">=70") / 4 + SUMIF(V14:V14, ">1") / 4 + SUMIF(X14:X14, ">1") / 4 + SUMIF(Z14:Z14, ">1") / 4 + SUMIF(AB14:AB14, ">1") / 4 -> 84 | AN14: =SUMIF(AC14:AC14, ">=65") / 4 +SUMIF(AE14:AE14, ">=65") / 4 +SUMIF(AG14:AG14, ">=65") / 4 +SUMIF(AI14:AI14, ">=65") / 4 + SUMIF(AD14:AD14, ">1") / 4 + SUMIF(AF14:AF14, ">1") / 4 + SUMIF(AH14:AH14, ">1") / 4 + SUMIF(AJ14:AJ14, ">1") / 4 -> 88 | AO14: =AVERAGE(AK14:AN14) -> 82 | AR14: =IF(AO14<70, AO14*0.5, "") | AT14: =AS14*50% -> 0 | AU14: =IF(AS14<>"", IF(AR14="","",AR14+AT14), "") | AV14: =IF(AU14 < 70, AR14*30%, "") | AX14: =AW14*70% -> 0 | AY14: =IF(AW14<>"", IF(AV14="", "", AV14+AX14), "") | AZ14: =IF(AND(AU14<70, AY14<70), AO14, "") | BB14: =IF(AW14<>"", IF(AY14>=70, AY14, IF(AZ14+BA14>=70, AZ14+BA14, "")), IF(AS14<>"", IF(AU14>=70, AU14, ""), IF(AO14>=70, AO14, ""))) -> 82 | BC14: =IF(AW14<>"", IF(AY14<70, IF(AZ14+BA14<70, AZ14+BA14, ""), ""), IF(AS14<>"", IF(AU14<70, AU14, ""), IF(AO14<70, AO14, ""))) | BE14: =SUM(E14+M14+U14+AC14)/4 -> 81 | BF14: =SUM(G14+O14+W14+AE14)/4 -> 83 | BG14: =SUM(I14+Q14+Y14+AG14)/4 -> 80 | BH14: =SUM(K14+S14+AA14+AI14)/4 -> 84 | BI14: =AVERAGE(BE14:BH14) -> 82
A15: 5 | B15: 1A-B-05 | C15: YORDANY | D15: BRAND | AK15: =SUMIF(E15:E15, ">=70") / 4 +SUMIF(G15:G15, ">=70") / 4 +SUMIF(I15:I15, ">=70") / 4 +SUMIF(K15:K15, ">=70") / 4 + SUMIF(F15:F15, ">1") / 4 + SUMIF(H15:H15, ">1") / 4 + SUMIF(J15:J15, ">1") / 4 + SUMIF(L15:L15, ">1") / 4 -> 0 | AL15: =SUMIF(M15:M15, ">=70") / 4 +SUMIF(O15:O15, ">=70") / 4 +SUMIF(Q15:Q15, ">=70") / 4 +SUMIF(S15:S15, ">=70") / 4 + SUMIF(N15:N15, ">1") / 4 + SUMIF(P15:P15, ">1") / 4 + SUMIF(R15:R15, ">1") / 4 + SUMIF(T15:T15, ">1") / 4 -> 0 | AM15: =SUMIF(U15:U15, ">=70") / 4 +SUMIF(W15:W15, ">=70") / 4 +SUMIF(Y15:Y15, ">=70") / 4 +SUMIF(AA15:AA15, ">=70") / 4 + SUMIF(V15:V15, ">1") / 4 + SUMIF(X15:X15, ">1") / 4 + SUMIF(Z15:Z15, ">1") / 4 + SUMIF(AB15:AB15, ">1") / 4 -> 0 | AN15: =SUMIF(AC15:AC15, ">=65") / 4 +SUMIF(AE15:AE15, ">=65") / 4 +SUMIF(AG15:AG15, ">=65") / 4 +SUMIF(AI15:AI15, ">=65") / 4 + SUMIF(AD15:AD15, ">1") / 4 + SUMIF(AF15:AF15, ">1") / 4 + SUMIF(AH15:AH15, ">1") / 4 + SUMIF(AJ15:AJ15, ">1") / 4 -> 0 | AO15: =AVERAGE(AK15:AN15) -> 0 | AR15: =IF(AO15<70, AO15*0.5, "") -> 0 | AT15: =AS15*50% -> 0 | AU15: =IF(AS15<>"", IF(AR15="","",AR15+AT15), "") | AV15: =IF(AU15 < 70, AR15*30%, "") | AX15: =AW15*70% -> 0 | AY15: =IF(AW15<>"", IF(AV15="", "", AV15+AX15), "") | AZ15: =IF(AND(AU15<70, AY15<70), AO15, "") | BB15: =IF(AW15<>"", IF(AY15>=70, AY15, IF(AZ15+BA15>=70, AZ15+BA15, "")), IF(AS15<>"", IF(AU15>=70, AU15, ""), IF(AO15>=70, AO15, ""))) | BC15: =IF(AW15<>"", IF(AY15<70, IF(AZ15+BA15<70, AZ15+BA15, ""), ""), IF(AS15<>"", IF(AU15<70, AU15, ""), IF(AO15<70, AO15, ""))) -> 0 | BE15: =SUM(E15+M15+U15+AC15)/4 -> 0 | BF15: =SUM(G15+O15+W15+AE15)/4 -> 0 | BG15: =SUM(I15+Q15+Y15+AG15)/4 -> 0 | BH15: =SUM(K15+S15+AA15+AI15)/4 -> 0 | BI15: =AVERAGE(BE15:BH15) -> 0
A16: 6 | B16: 1A-B-06 | C16: YEFRI | D16: CABRERA ENCARNACION | E16: 81 | G16: 83 | I16: 80 | K16: 84 | M16: 82 | O16: 84 | Q16: 85 | S16: 87 | U16: 83 | W16: 85 | Y16: 82 | AA16: 86 | AC16: 87 | AE16: 89 | AG16: 86 | AI16: 90 | AK16: =SUMIF(E16:E16, ">=70") / 4 +SUMIF(G16:G16, ">=70") / 4 +SUMIF(I16:I16, ">=70") / 4 +SUMIF(K16:K16, ">=70") / 4 + SUMIF(F16:F16, ">1") / 4 + SUMIF(H16:H16, ">1") / 4 + SUMIF(J16:J16, ">1") / 4 + SUMIF(L16:L16, ">1") / 4 -> 82 | AL16: =SUMIF(M16:M16, ">=70") / 4 +SUMIF(O16:O16, ">=70") / 4 +SUMIF(Q16:Q16, ">=70") / 4 +SUMIF(S16:S16, ">=70") / 4 + SUMIF(N16:N16, ">1") / 4 + SUMIF(P16:P16, ">1") / 4 + SUMIF(R16:R16, ">1") / 4 + SUMIF(T16:T16, ">1") / 4 -> 84.5 | AM16: =SUMIF(U16:U16, ">=70") / 4 +SUMIF(W16:W16, ">=70") / 4 +SUMIF(Y16:Y16, ">=70") / 4 +SUMIF(AA16:AA16, ">=70") / 4 + SUMIF(V16:V16, ">1") / 4 + SUMIF(X16:X16, ">1") / 4 + SUMIF(Z16:Z16, ">1") / 4 + SUMIF(AB16:AB16, ">1") / 4 -> 84 | AN16: =SUMIF(AC16:AC16, ">=65") / 4 +SUMIF(AE16:AE16, ">=65") / 4 +SUMIF(AG16:AG16, ">=65") / 4 +SUMIF(AI16:AI16, ">=65") / 4 + SUMIF(AD16:AD16, ">1") / 4 + SUMIF(AF16:AF16, ">1") / 4 + SUMIF(AH16:AH16, ">1") / 4 + SUMIF(AJ16:AJ16, ">1") / 4 -> 88 | AO16: =AVERAGE(AK16:AN16) -> 84.625 | AR16: =IF(AO16<70, AO16*0.5, "") | AT16: =AS16*50% -> 0 | AU16: =IF(AS16<>"", IF(AR16="","",AR16+AT16), "") | AV16: =IF(AU16 < 70, AR16*30%, "") | AX16: =AW16*70% -> 0 | AY16: =IF(AW16<>"", IF(AV16="", "", AV16+AX16), "") | AZ16: =IF(AND(AU16<70, AY16<70), AO16, "") | BB16: =IF(AW16<>"", IF(AY16>=70, AY16, IF(AZ16+BA16>=70, AZ16+BA16, "")), IF(AS16<>"", IF(AU16>=70, AU16, ""), IF(AO16>=70, AO16, ""))) -> 84.625 | BC16: =IF(AW16<>"", IF(AY16<70, IF(AZ16+BA16<70, AZ16+BA16, ""), ""), IF(AS16<>"", IF(AU16<70, AU16, ""), IF(AO16<70, AO16, ""))) | BE16: =SUM(E16+M16+U16+AC16)/4 -> 83.25 | BF16: =SUM(G16+O16+W16+AE16)/4 -> 85.25 | BG16: =SUM(I16+Q16+Y16+AG16)/4 -> 83.25 | BH16: =SUM(K16+S16+AA16+AI16)/4 -> 86.75 | BI16: =AVERAGE(BE16:BH16) -> 84.625
A17: 7 | B17: 1A-B-07 | C17: ROLANDO | D17: CANDELARIO PRENSA | AK17: =SUMIF(E17:E17, ">=70") / 4 +SUMIF(G17:G17, ">=70") / 4 +SUMIF(I17:I17, ">=70") / 4 +SUMIF(K17:K17, ">=70") / 4 + SUMIF(F17:F17, ">1") / 4 + SUMIF(H17:H17, ">1") / 4 + SUMIF(J17:J17, ">1") / 4 + SUMIF(L17:L17, ">1") / 4 -> 0 | AL17: =SUMIF(M17:M17, ">=70") / 4 +SUMIF(O17:O17, ">=70") / 4 +SUMIF(Q17:Q17, ">=70") / 4 +SUMIF(S17:S17, ">=70") / 4 + SUMIF(N17:N17, ">1") / 4 + SUMIF(P17:P17, ">1") / 4 + SUMIF(R17:R17, ">1") / 4 + SUMIF(T17:T17, ">1") / 4 -> 0 | AM17: =SUMIF(U17:U17, ">=70") / 4 +SUMIF(W17:W17, ">=70") / 4 +SUMIF(Y17:Y17, ">=70") / 4 +SUMIF(AA17:AA17, ">=70") / 4 + SUMIF(V17:V17, ">1") / 4 + SUMIF(X17:X17, ">1") / 4 + SUMIF(Z17:Z17, ">1") / 4 + SUMIF(AB17:AB17, ">1") / 4 -> 0 | AN17: =SUMIF(AC17:AC17, ">=65") / 4 +SUMIF(AE17:AE17, ">=65") / 4 +SUMIF(AG17:AG17, ">=65") / 4 +SUMIF(AI17:AI17, ">=65") / 4 + SUMIF(AD17:AD17, ">1") / 4 + SUMIF(AF17:AF17, ">1") / 4 + SUMIF(AH17:AH17, ">1") / 4 + SUMIF(AJ17:AJ17, ">1") / 4 -> 0 | AO17: =AVERAGE(AK17:AN17) -> 0 | AR17: =IF(AO17<70, AO17*0.5, "") -> 0 | AT17: =AS17*50% -> 0 | AU17: =IF(AS17<>"", IF(AR17="","",AR17+AT17), "") | AV17: =IF(AU17 < 70, AR17*30%, "") | AX17: =AW17*70% -> 0 | AY17: =IF(AW17<>"", IF(AV17="", "", AV17+AX17), "") | AZ17: =IF(AND(AU17<70, AY17<70), AO17, "") | BB17: =IF(AW17<>"", IF(AY17>=70, AY17, IF(AZ17+BA17>=70, AZ17+BA17, "")), IF(AS17<>"", IF(AU17>=70, AU17, ""), IF(AO17>=70, AO17, ""))) | BC17: =IF(AW17<>"", IF(AY17<70, IF(AZ17+BA17<70, AZ17+BA17, ""), ""), IF(AS17<>"", IF(AU17<70, AU17, ""), IF(AO17<70, AO17, ""))) -> 0 | BE17: =SUM(E17+M17+U17+AC17)/4 -> 0 | BF17: =SUM(G17+O17+W17+AE17)/4 -> 0 | BG17: =SUM(I17+Q17+Y17+AG17)/4 -> 0 | BH17: =SUM(K17+S17+AA17+AI17)/4 -> 0 | BI17: =AVERAGE(BE17:BH17) -> 0
A18: 8 | B18: 1A-B-08 | C18: ELIAN ERNESTO | D18: CESPEDES CAMINERO | AK18: =SUMIF(E18:E18, ">=70") / 4 +SUMIF(G18:G18, ">=70") / 4 +SUMIF(I18:I18, ">=70") / 4 +SUMIF(K18:K18, ">=70") / 4 + SUMIF(F18:F18, ">1") / 4 + SUMIF(H18:H18, ">1") / 4 + SUMIF(J18:J18, ">1") / 4 + SUMIF(L18:L18, ">1") / 4 -> 0 | AL18: =SUMIF(M18:M18, ">=70") / 4 +SUMIF(O18:O18, ">=70") / 4 +SUMIF(Q18:Q18, ">=70") / 4 +SUMIF(S18:S18, ">=70") / 4 + SUMIF(N18:N18, ">1") / 4 + SUMIF(P18:P18, ">1") / 4 + SUMIF(R18:R18, ">1") / 4 + SUMIF(T18:T18, ">1") / 4 -> 0 | AM18: =SUMIF(U18:U18, ">=70") / 4 +SUMIF(W18:W18, ">=70") / 4 +SUMIF(Y18:Y18, ">=70") / 4 +SUMIF(AA18:AA18, ">=70") / 4 + SUMIF(V18:V18, ">1") / 4 + SUMIF(X18:X18, ">1") / 4 + SUMIF(Z18:Z18, ">1") / 4 + SUMIF(AB18:AB18, ">1") / 4 -> 0 | AN18: =SUMIF(AC18:AC18, ">=65") / 4 +SUMIF(AE18:AE18, ">=65") / 4 +SUMIF(AG18:AG18, ">=65") / 4 +SUMIF(AI18:AI18, ">=65") / 4 + SUMIF(AD18:AD18, ">1") / 4 + SUMIF(AF18:AF18, ">1") / 4 + SUMIF(AH18:AH18, ">1") / 4 + SUMIF(AJ18:AJ18, ">1") / 4 -> 0 | AO18: =AVERAGE(AK18:AN18) -> 0 | AR18: =IF(AO18<70, AO18*0.5, "") -> 0 | AT18: =AS18*50% -> 0 | AU18: =IF(AS18<>"", IF(AR18="","",AR18+AT18), "") | AV18: =IF(AU18 < 70, AR18*30%, "") | AX18: =AW18*70% -> 0 | AY18: =IF(AW18<>"", IF(AV18="", "", AV18+AX18), "") | AZ18: =IF(AND(AU18<70, AY18<70), AO18, "") | BB18: =IF(AW18<>"", IF(AY18>=70, AY18, IF(AZ18+BA18>=70, AZ18+BA18, "")), IF(AS18<>"", IF(AU18>=70, AU18, ""), IF(AO18>=70, AO18, ""))) | BC18: =IF(AW18<>"", IF(AY18<70, IF(AZ18+BA18<70, AZ18+BA18, ""), ""), IF(AS18<>"", IF(AU18<70, AU18, ""), IF(AO18<70, AO18, ""))) -> 0 | BE18: =SUM(E18+M18+U18+AC18)/4 -> 0 | BF18: =SUM(G18+O18+W18+AE18)/4 -> 0 | BG18: =SUM(I18+Q18+Y18+AG18)/4 -> 0 | BH18: =SUM(K18+S18+AA18+AI18)/4 -> 0 | BI18: =AVERAGE(BE18:BH18) -> 0
A19: 9 | B19: 1A-B-09 | C19: JENIA | D19: CHARLES | E19: 74 | G19: 76 | I19: 73 | K19: 77 | M19: 78 | O19: 80 | Q19: 77 | S19: 81 | U19: 80 | W19: 81 | Y19: 82 | AA19: 81 | AC19: 82 | AE19: 88 | AG19: 83 | AI19: 87 | AK19: =SUMIF(E19:E19, ">=70") / 4 +SUMIF(G19:G19, ">=70") / 4 +SUMIF(I19:I19, ">=70") / 4 +SUMIF(K19:K19, ">=70") / 4 + SUMIF(F19:F19, ">1") / 4 + SUMIF(H19:H19, ">1") / 4 + SUMIF(J19:J19, ">1") / 4 + SUMIF(L19:L19, ">1") / 4 -> 75 | AL19: =SUMIF(M19:M19, ">=70") / 4 +SUMIF(O19:O19, ">=70") / 4 +SUMIF(Q19:Q19, ">=70") / 4 +SUMIF(S19:S19, ">=70") / 4 + SUMIF(N19:N19, ">1") / 4 + SUMIF(P19:P19, ">1") / 4 + SUMIF(R19:R19, ">1") / 4 + SUMIF(T19:T19, ">1") / 4 -> 79 | AM19: =SUMIF(U19:U19, ">=70") / 4 +SUMIF(W19:W19, ">=70") / 4 +SUMIF(Y19:Y19, ">=70") / 4 +SUMIF(AA19:AA19, ">=70") / 4 + SUMIF(V19:V19, ">1") / 4 + SUMIF(X19:X19, ">1") / 4 + SUMIF(Z19:Z19, ">1") / 4 + SUMIF(AB19:AB19, ">1") / 4 -> 81 | AN19: =SUMIF(AC19:AC19, ">=65") / 4 +SUMIF(AE19:AE19, ">=65") / 4 +SUMIF(AG19:AG19, ">=65") / 4 +SUMIF(AI19:AI19, ">=65") / 4 + SUMIF(AD19:AD19, ">1") / 4 + SUMIF(AF19:AF19, ">1") / 4 + SUMIF(AH19:AH19, ">1") / 4 + SUMIF(AJ19:AJ19, ">1") / 4 -> 85 | AO19: =AVERAGE(AK19:AN19) -> 80 | AR19: =IF(AO19<70, AO19*0.5, "") | AT19: =AS19*50% -> 0 | AU19: =IF(AS19<>"", IF(AR19="","",AR19+AT19), "") | AV19: =IF(AU19 < 70, AR19*30%, "") | AX19: =AW19*70% -> 0 | AY19: =IF(AW19<>"", IF(AV19="", "", AV19+AX19), "") | AZ19: =IF(AND(AU19<70, AY19<70), AO19, "") | BB19: =IF(AW19<>"", IF(AY19>=70, AY19, IF(AZ19+BA19>=70, AZ19+BA19, "")), IF(AS19<>"", IF(AU19>=70, AU19, ""), IF(AO19>=70, AO19, ""))) -> 80 | BC19: =IF(AW19<>"", IF(AY19<70, IF(AZ19+BA19<70, AZ19+BA19, ""), ""), IF(AS19<>"", IF(AU19<70, AU19, ""), IF(AO19<70, AO19, ""))) | BE19: =SUM(E19+M19+U19+AC19)/4 -> 78.5 | BF19: =SUM(G19+O19+W19+AE19)/4 -> 81.25 | BG19: =SUM(I19+Q19+Y19+AG19)/4 -> 78.75 | BH19: =SUM(K19+S19+AA19+AI19)/4 -> 81.5 | BI19: =AVERAGE(BE19:BH19) -> 80
A20: 10 | B20: 1A-B-10 | C20: FERMIN YUNIOR | D20: CUSTODIO | E20: 90 | G20: 92 | I20: 90 | K20: 92 | M20: 90 | O20: 96 | Q20: 91 | S20: 95 | U20: 88 | W20: 92 | Y20: 89 | AA20: 91 | AC20: 93 | AE20: 95 | AG20: 92 | AI20: 96 | AK20: =SUMIF(E20:E20, ">=70") / 4 +SUMIF(G20:G20, ">=70") / 4 +SUMIF(I20:I20, ">=70") / 4 +SUMIF(K20:K20, ">=70") / 4 + SUMIF(F20:F20, ">1") / 4 + SUMIF(H20:H20, ">1") / 4 + SUMIF(J20:J20, ">1") / 4 + SUMIF(L20:L20, ">1") / 4 -> 91 | AL20: =SUMIF(M20:M20, ">=70") / 4 +SUMIF(O20:O20, ">=70") / 4 +SUMIF(Q20:Q20, ">=70") / 4 +SUMIF(S20:S20, ">=70") / 4 + SUMIF(N20:N20, ">1") / 4 + SUMIF(P20:P20, ">1") / 4 + SUMIF(R20:R20, ">1") / 4 + SUMIF(T20:T20, ">1") / 4 -> 93 | AM20: =SUMIF(U20:U20, ">=70") / 4 +SUMIF(W20:W20, ">=70") / 4 +SUMIF(Y20:Y20, ">=70") / 4 +SUMIF(AA20:AA20, ">=70") / 4 + SUMIF(V20:V20, ">1") / 4 + SUMIF(X20:X20, ">1") / 4 + SUMIF(Z20:Z20, ">1") / 4 + SUMIF(AB20:AB20, ">1") / 4 -> 90 | AN20: =SUMIF(AC20:AC20, ">=65") / 4 +SUMIF(AE20:AE20, ">=65") / 4 +SUMIF(AG20:AG20, ">=65") / 4 +SUMIF(AI20:AI20, ">=65") / 4 + SUMIF(AD20:AD20, ">1") / 4 + SUMIF(AF20:AF20, ">1") / 4 + SUMIF(AH20:AH20, ">1") / 4 + SUMIF(AJ20:AJ20, ">1") / 4 -> 94 | AO20: =AVERAGE(AK20:AN20) -> 92 | AR20: =IF(AO20<70, AO20*0.5, "") | AT20: =AS20*50% -> 0 | AU20: =IF(AS20<>"", IF(AR20="","",AR20+AT20), "") | AV20: =IF(AU20 < 70, AR20*30%, "") | AX20: =AW20*70% -> 0 | AY20: =IF(AW20<>"", IF(AV20="", "", AV20+AX20), "") | AZ20: =IF(AND(AU20<70, AY20<70), AO20, "") | BB20: =IF(AW20<>"", IF(AY20>=70, AY20, IF(AZ20+BA20>=70, AZ20+BA20, "")), IF(AS20<>"", IF(AU20>=70, AU20, ""), IF(AO20>=70, AO20, ""))) -> 92 | BC20: =IF(AW20<>"", IF(AY20<70, IF(AZ20+BA20<70, AZ20+BA20, ""), ""), IF(AS20<>"", IF(AU20<70, AU20, ""), IF(AO20<70, AO20, ""))) | BE20: =SUM(E20+M20+U20+AC20)/4 -> 90.25 | BF20: =SUM(G20+O20+W20+AE20)/4 -> 93.75 | BG20: =SUM(I20+Q20+Y20+AG20)/4 -> 90.5 | BH20: =SUM(K20+S20+AA20+AI20)/4 -> 93.5 | BI20: =AVERAGE(BE20:BH20) -> 92
A21: 11 | B21: 1A-B-11 | C21: STIVEN | D21: D´OLEO TORRES | AK21: =SUMIF(E21:E21, ">=70") / 4 +SUMIF(G21:G21, ">=70") / 4 +SUMIF(I21:I21, ">=70") / 4 +SUMIF(K21:K21, ">=70") / 4 + SUMIF(F21:F21, ">1") / 4 + SUMIF(H21:H21, ">1") / 4 + SUMIF(J21:J21, ">1") / 4 + SUMIF(L21:L21, ">1") / 4 -> 0 | AL21: =SUMIF(M21:M21, ">=70") / 4 +SUMIF(O21:O21, ">=70") / 4 +SUMIF(Q21:Q21, ">=70") / 4 +SUMIF(S21:S21, ">=70") / 4 + SUMIF(N21:N21, ">1") / 4 + SUMIF(P21:P21, ">1") / 4 + SUMIF(R21:R21, ">1") / 4 + SUMIF(T21:T21, ">1") / 4 -> 0 | AM21: =SUMIF(U21:U21, ">=70") / 4 +SUMIF(W21:W21, ">=70") / 4 +SUMIF(Y21:Y21, ">=70") / 4 +SUMIF(AA21:AA21, ">=70") / 4 + SUMIF(V21:V21, ">1") / 4 + SUMIF(X21:X21, ">1") / 4 + SUMIF(Z21:Z21, ">1") / 4 + SUMIF(AB21:AB21, ">1") / 4 -> 0 | AN21: =SUMIF(AC21:AC21, ">=65") / 4 +SUMIF(AE21:AE21, ">=65") / 4 +SUMIF(AG21:AG21, ">=65") / 4 +SUMIF(AI21:AI21, ">=65") / 4 + SUMIF(AD21:AD21, ">1") / 4 + SUMIF(AF21:AF21, ">1") / 4 + SUMIF(AH21:AH21, ">1") / 4 + SUMIF(AJ21:AJ21, ">1") / 4 -> 0 | AO21: =AVERAGE(AK21:AN21) -> 0 | AR21: =IF(AO21<70, AO21*0.5, "") -> 0 | AT21: =AS21*50% -> 0 | AU21: =IF(AS21<>"", IF(AR21="","",AR21+AT21), "") | AV21: =IF(AU21 < 70, AR21*30%, "") | AX21: =AW21*70% -> 0 | AY21: =IF(AW21<>"", IF(AV21="", "", AV21+AX21), "") | AZ21: =IF(AND(AU21<70, AY21<70), AO21, "") | BB21: =IF(AW21<>"", IF(AY21>=70, AY21, IF(AZ21+BA21>=70, AZ21+BA21, "")), IF(AS21<>"", IF(AU21>=70, AU21, ""), IF(AO21>=70, AO21, ""))) | BC21: =IF(AW21<>"", IF(AY21<70, IF(AZ21+BA21<70, AZ21+BA21, ""), ""), IF(AS21<>"", IF(AU21<70, AU21, ""), IF(AO21<70, AO21, ""))) -> 0 | BE21: =SUM(E21+M21+U21+AC21)/4 -> 0 | BF21: =SUM(G21+O21+W21+AE21)/4 -> 0 | BG21: =SUM(I21+Q21+Y21+AG21)/4 -> 0 | BH21: =SUM(K21+S21+AA21+AI21)/4 -> 0 | BI21: =AVERAGE(BE21:BH21) -> 0
A22: 12 | B22: 1A-B-12 | C22: JORGE LUIS | D22: DE JESUS DE LA CRUZ | E22: 75 | G22: 77 | I22: 74 | K22: 78 | M22: 77 | O22: 79 | Q22: 76 | S22: 80 | U22: 77 | W22: 83 | Y22: 78 | AA22: 82 | AC22: 76 | AE22: 80 | AG22: 77 | AI22: 79 | AK22: =SUMIF(E22:E22, ">=70") / 4 +SUMIF(G22:G22, ">=70") / 4 +SUMIF(I22:I22, ">=70") / 4 +SUMIF(K22:K22, ">=70") / 4 + SUMIF(F22:F22, ">1") / 4 + SUMIF(H22:H22, ">1") / 4 + SUMIF(J22:J22, ">1") / 4 + SUMIF(L22:L22, ">1") / 4 -> 76 | AL22: =SUMIF(M22:M22, ">=70") / 4 +SUMIF(O22:O22, ">=70") / 4 +SUMIF(Q22:Q22, ">=70") / 4 +SUMIF(S22:S22, ">=70") / 4 + SUMIF(N22:N22, ">1") / 4 + SUMIF(P22:P22, ">1") / 4 + SUMIF(R22:R22, ">1") / 4 + SUMIF(T22:T22, ">1") / 4 -> 78 | AM22: =SUMIF(U22:U22, ">=70") / 4 +SUMIF(W22:W22, ">=70") / 4 +SUMIF(Y22:Y22, ">=70") / 4 +SUMIF(AA22:AA22, ">=70") / 4 + SUMIF(V22:V22, ">1") / 4 + SUMIF(X22:X22, ">1") / 4 + SUMIF(Z22:Z22, ">1") / 4 + SUMIF(AB22:AB22, ">1") / 4 -> 80 | AN22: =SUMIF(AC22:AC22, ">=65") / 4 +SUMIF(AE22:AE22, ">=65") / 4 +SUMIF(AG22:AG22, ">=65") / 4 +SUMIF(AI22:AI22, ">=65") / 4 + SUMIF(AD22:AD22, ">1") / 4 + SUMIF(AF22:AF22, ">1") / 4 + SUMIF(AH22:AH22, ">1") / 4 + SUMIF(AJ22:AJ22, ">1") / 4 -> 78 | AO22: =AVERAGE(AK22:AN22) -> 78 | AR22: =IF(AO22<70, AO22*0.5, "") | AT22: =AS22*50% -> 0 | AU22: =IF(AS22<>"", IF(AR22="","",AR22+AT22), "") | AV22: =IF(AU22 < 70, AR22*30%, "") | AX22: =AW22*70% -> 0 | AY22: =IF(AW22<>"", IF(AV22="", "", AV22+AX22), "") | AZ22: =IF(AND(AU22<70, AY22<70), AO22, "") | BB22: =IF(AW22<>"", IF(AY22>=70, AY22, IF(AZ22+BA22>=70, AZ22+BA22, "")), IF(AS22<>"", IF(AU22>=70, AU22, ""), IF(AO22>=70, AO22, ""))) -> 78 | BC22: =IF(AW22<>"", IF(AY22<70, IF(AZ22+BA22<70, AZ22+BA22, ""), ""), IF(AS22<>"", IF(AU22<70, AU22, ""), IF(AO22<70, AO22, ""))) | BE22: =SUM(E22+M22+U22+AC22)/4 -> 76.25 | BF22: =SUM(G22+O22+W22+AE22)/4 -> 79.75 | BG22: =SUM(I22+Q22+Y22+AG22)/4 -> 76.25 | BH22: =SUM(K22+S22+AA22+AI22)/4 -> 79.75 | BI22: =AVERAGE(BE22:BH22) -> 78
A23: 13 | B23: 1A-B-13 | C23: JEISY MARIA | D23: DE LOS SANTOS REYES | AK23: =SUMIF(E23:E23, ">=70") / 4 +SUMIF(G23:G23, ">=70") / 4 +SUMIF(I23:I23, ">=70") / 4 +SUMIF(K23:K23, ">=70") / 4 + SUMIF(F23:F23, ">1") / 4 + SUMIF(H23:H23, ">1") / 4 + SUMIF(J23:J23, ">1") / 4 + SUMIF(L23:L23, ">1") / 4 -> 0 | AL23: =SUMIF(M23:M23, ">=70") / 4 +SUMIF(O23:O23, ">=70") / 4 +SUMIF(Q23:Q23, ">=70") / 4 +SUMIF(S23:S23, ">=70") / 4 + SUMIF(N23:N23, ">1") / 4 + SUMIF(P23:P23, ">1") / 4 + SUMIF(R23:R23, ">1") / 4 + SUMIF(T23:T23, ">1") / 4 -> 0 | AM23: =SUMIF(U23:U23, ">=70") / 4 +SUMIF(W23:W23, ">=70") / 4 +SUMIF(Y23:Y23, ">=70") / 4 +SUMIF(AA23:AA23, ">=70") / 4 + SUMIF(V23:V23, ">1") / 4 + SUMIF(X23:X23, ">1") / 4 + SUMIF(Z23:Z23, ">1") / 4 + SUMIF(AB23:AB23, ">1") / 4 -> 0 | AN23: =SUMIF(AC23:AC23, ">=65") / 4 +SUMIF(AE23:AE23, ">=65") / 4 +SUMIF(AG23:AG23, ">=65") / 4 +SUMIF(AI23:AI23, ">=65") / 4 + SUMIF(AD23:AD23, ">1") / 4 + SUMIF(AF23:AF23, ">1") / 4 + SUMIF(AH23:AH23, ">1") / 4 + SUMIF(AJ23:AJ23, ">1") / 4 -> 0 | AO23: =AVERAGE(AK23:AN23) -> 0 | AR23: =IF(AO23<70, AO23*0.5, "") -> 0 | AT23: =AS23*50% -> 0 | AU23: =IF(AS23<>"", IF(AR23="","",AR23+AT23), "") | AV23: =IF(AU23 < 70, AR23*30%, "") | AX23: =AW23*70% -> 0 | AY23: =IF(AW23<>"", IF(AV23="", "", AV23+AX23), "") | AZ23: =IF(AND(AU23<70, AY23<70), AO23, "") | BB23: =IF(AW23<>"", IF(AY23>=70, AY23, IF(AZ23+BA23>=70, AZ23+BA23, "")), IF(AS23<>"", IF(AU23>=70, AU23, ""), IF(AO23>=70, AO23, ""))) | BC23: =IF(AW23<>"", IF(AY23<70, IF(AZ23+BA23<70, AZ23+BA23, ""), ""), IF(AS23<>"", IF(AU23<70, AU23, ""), IF(AO23<70, AO23, ""))) -> 0 | BE23: =SUM(E23+M23+U23+AC23)/4 -> 0 | BF23: =SUM(G23+O23+W23+AE23)/4 -> 0 | BG23: =SUM(I23+Q23+Y23+AG23)/4 -> 0 | BH23: =SUM(K23+S23+AA23+AI23)/4 -> 0 | BI23: =AVERAGE(BE23:BH23) -> 0
A24: 14 | B24: 1A-B-14 | C24: MARTINA ESMERALDA | D24: DE OLEO BOCIO | E24: 75 | G24: 77 | M24: 77 | O24: 83 | U24: 74 | W24: 78 | AC24: 79 | AE24: 81 | AK24: =SUMIF(E24:E24, ">=70") / 4 +SUMIF(G24:G24, ">=70") / 4 +SUMIF(I24:I24, ">=70") / 4 +SUMIF(K24:K24, ">=70") / 4 + SUMIF(F24:F24, ">1") / 4 + SUMIF(H24:H24, ">1") / 4 + SUMIF(J24:J24, ">1") / 4 + SUMIF(L24:L24, ">1") / 4 -> 38 | AL24: =SUMIF(M24:M24, ">=70") / 4 +SUMIF(O24:O24, ">=70") / 4 +SUMIF(Q24:Q24, ">=70") / 4 +SUMIF(S24:S24, ">=70") / 4 + SUMIF(N24:N24, ">1") / 4 + SUMIF(P24:P24, ">1") / 4 + SUMIF(R24:R24, ">1") / 4 + SUMIF(T24:T24, ">1") / 4 -> 40 | AM24: =SUMIF(U24:U24, ">=70") / 4 +SUMIF(W24:W24, ">=70") / 4 +SUMIF(Y24:Y24, ">=70") / 4 +SUMIF(AA24:AA24, ">=70") / 4 + SUMIF(V24:V24, ">1") / 4 + SUMIF(X24:X24, ">1") / 4 + SUMIF(Z24:Z24, ">1") / 4 + SUMIF(AB24:AB24, ">1") / 4 -> 38 | AN24: =SUMIF(AC24:AC24, ">=65") / 4 +SUMIF(AE24:AE24, ">=65") / 4 +SUMIF(AG24:AG24, ">=65") / 4 +SUMIF(AI24:AI24, ">=65") / 4 + SUMIF(AD24:AD24, ">1") / 4 + SUMIF(AF24:AF24, ">1") / 4 + SUMIF(AH24:AH24, ">1") / 4 + SUMIF(AJ24:AJ24, ">1") / 4 -> 40 | AO24: =AVERAGE(AK24:AN24) -> 39 | AR24: =IF(AO24<70, AO24*0.5, "") -> 19.5 | AT24: =AS24*50% -> 0 | AU24: =IF(AS24<>"", IF(AR24="","",AR24+AT24), "") | AV24: =IF(AU24 < 70, AR24*30%, "") | AX24: =AW24*70% -> 0 | AY24: =IF(AW24<>"", IF(AV24="", "", AV24+AX24), "") | AZ24: =IF(AND(AU24<70, AY24<70), AO24, "") | BB24: =IF(AW24<>"", IF(AY24>=70, AY24, IF(AZ24+BA24>=70, AZ24+BA24, "")), IF(AS24<>"", IF(AU24>=70, AU24, ""), IF(AO24>=70, AO24, ""))) | BC24: =IF(AW24<>"", IF(AY24<70, IF(AZ24+BA24<70, AZ24+BA24, ""), ""), IF(AS24<>"", IF(AU24<70, AU24, ""), IF(AO24<70, AO24, ""))) -> 39 | BE24: =SUM(E24+M24+U24+AC24)/4 -> 76.25 | BF24: =SUM(G24+O24+W24+AE24)/4 -> 79.75 | BG24: =SUM(I24+Q24+Y24+AG24)/4 -> 0 | BH24: =SUM(K24+S24+AA24+AI24)/4 -> 0 | BI24: =AVERAGE(BE24:BH24) -> 39
A25: 15 | B25: 1A-B-15 | C25: ANDY JAVIER | D25: DIAZ MENA | E25: 74 | G25: 76 | I25: 72 | K25: 78 | M25: 75 | O25: 79 | Q25: 76 | S25: 78 | U25: 78 | W25: 80 | Y25: 77 | AA25: 81 | AC25: 80 | AE25: 81 | AG25: 82 | AI25: 81 | AK25: =SUMIF(E25:E25, ">=70") / 4 +SUMIF(G25:G25, ">=70") / 4 +SUMIF(I25:I25, ">=70") / 4 +SUMIF(K25:K25, ">=70") / 4 + SUMIF(F25:F25, ">1") / 4 + SUMIF(H25:H25, ">1") / 4 + SUMIF(J25:J25, ">1") / 4 + SUMIF(L25:L25, ">1") / 4 -> 75 | AL25: =SUMIF(M25:M25, ">=70") / 4 +SUMIF(O25:O25, ">=70") / 4 +SUMIF(Q25:Q25, ">=70") / 4 +SUMIF(S25:S25, ">=70") / 4 + SUMIF(N25:N25, ">1") / 4 + SUMIF(P25:P25, ">1") / 4 + SUMIF(R25:R25, ">1") / 4 + SUMIF(T25:T25, ">1") / 4 -> 77 | AM25: =SUMIF(U25:U25, ">=70") / 4 +SUMIF(W25:W25, ">=70") / 4 +SUMIF(Y25:Y25, ">=70") / 4 +SUMIF(AA25:AA25, ">=70") / 4 + SUMIF(V25:V25, ">1") / 4 + SUMIF(X25:X25, ">1") / 4 + SUMIF(Z25:Z25, ">1") / 4 + SUMIF(AB25:AB25, ">1") / 4 -> 79 | AN25: =SUMIF(AC25:AC25, ">=65") / 4 +SUMIF(AE25:AE25, ">=65") / 4 +SUMIF(AG25:AG25, ">=65") / 4 +SUMIF(AI25:AI25, ">=65") / 4 + SUMIF(AD25:AD25, ">1") / 4 + SUMIF(AF25:AF25, ">1") / 4 + SUMIF(AH25:AH25, ">1") / 4 + SUMIF(AJ25:AJ25, ">1") / 4 -> 81 | AO25: =AVERAGE(AK25:AN25) -> 78 | AR25: =IF(AO25<70, AO25*0.5, "") | AT25: =AS25*50% -> 0 | AU25: =IF(AS25<>"", IF(AR25="","",AR25+AT25), "") | AV25: =IF(AU25 < 70, AR25*30%, "") | AX25: =AW25*70% -> 0 | AY25: =IF(AW25<>"", IF(AV25="", "", AV25+AX25), "") | AZ25: =IF(AND(AU25<70, AY25<70), AO25, "") | BB25: =IF(AW25<>"", IF(AY25>=70, AY25, IF(AZ25+BA25>=70, AZ25+BA25, "")), IF(AS25<>"", IF(AU25>=70, AU25, ""), IF(AO25>=70, AO25, ""))) -> 78 | BC25: =IF(AW25<>"", IF(AY25<70, IF(AZ25+BA25<70, AZ25+BA25, ""), ""), IF(AS25<>"", IF(AU25<70, AU25, ""), IF(AO25<70, AO25, ""))) | BE25: =SUM(E25+M25+U25+AC25)/4 -> 76.75 | BF25: =SUM(G25+O25+W25+AE25)/4 -> 79 | BG25: =SUM(I25+Q25+Y25+AG25)/4 -> 76.75 | BH25: =SUM(K25+S25+AA25+AI25)/4 -> 79.5 | BI25: =AVERAGE(BE25:BH25) -> 78
A26: 16 | B26: 1A-B-16 | C26: KEMY MARVENS | D26: DUTERVIL | E26: 76 | G26: 78 | I26: 75 | K26: 79 | M26: 80 | O26: 81 | Q26: 82 | S26: 81 | U26: 78 | W26: 80 | Y26: 77 | AA26: 81 | AC26: 82 | AE26: 84 | AG26: 80 | AI26: 86 | AK26: =SUMIF(E26:E26, ">=70") / 4 +SUMIF(G26:G26, ">=70") / 4 +SUMIF(I26:I26, ">=70") / 4 +SUMIF(K26:K26, ">=70") / 4 + SUMIF(F26:F26, ">1") / 4 + SUMIF(H26:H26, ">1") / 4 + SUMIF(J26:J26, ">1") / 4 + SUMIF(L26:L26, ">1") / 4 -> 77 | AL26: =SUMIF(M26:M26, ">=70") / 4 +SUMIF(O26:O26, ">=70") / 4 +SUMIF(Q26:Q26, ">=70") / 4 +SUMIF(S26:S26, ">=70") / 4 + SUMIF(N26:N26, ">1") / 4 + SUMIF(P26:P26, ">1") / 4 + SUMIF(R26:R26, ">1") / 4 + SUMIF(T26:T26, ">1") / 4 -> 81 | AM26: =SUMIF(U26:U26, ">=70") / 4 +SUMIF(W26:W26, ">=70") / 4 +SUMIF(Y26:Y26, ">=70") / 4 +SUMIF(AA26:AA26, ">=70") / 4 + SUMIF(V26:V26, ">1") / 4 + SUMIF(X26:X26, ">1") / 4 + SUMIF(Z26:Z26, ">1") / 4 + SUMIF(AB26:AB26, ">1") / 4 -> 79 | AN26: =SUMIF(AC26:AC26, ">=65") / 4 +SUMIF(AE26:AE26, ">=65") / 4 +SUMIF(AG26:AG26, ">=65") / 4 +SUMIF(AI26:AI26, ">=65") / 4 + SUMIF(AD26:AD26, ">1") / 4 + SUMIF(AF26:AF26, ">1") / 4 + SUMIF(AH26:AH26, ">1") / 4 + SUMIF(AJ26:AJ26, ">1") / 4 -> 83 | AO26: =AVERAGE(AK26:AN26) -> 80 | AR26: =IF(AO26<70, AO26*0.5, "") | AT26: =AS26*50% -> 0 | AU26: =IF(AS26<>"", IF(AR26="","",AR26+AT26), "") | AV26: =IF(AU26 < 70, AR26*30%, "") | AX26: =AW26*70% -> 0 | AY26: =IF(AW26<>"", IF(AV26="", "", AV26+AX26), "") | AZ26: =IF(AND(AU26<70, AY26<70), AO26, "") | BB26: =IF(AW26<>"", IF(AY26>=70, AY26, IF(AZ26+BA26>=70, AZ26+BA26, "")), IF(AS26<>"", IF(AU26>=70, AU26, ""), IF(AO26>=70, AO26, ""))) -> 80 | BC26: =IF(AW26<>"", IF(AY26<70, IF(AZ26+BA26<70, AZ26+BA26, ""), ""), IF(AS26<>"", IF(AU26<70, AU26, ""), IF(AO26<70, AO26, ""))) | BE26: =SUM(E26+M26+U26+AC26)/4 -> 79 | BF26: =SUM(G26+O26+W26+AE26)/4 -> 80.75 | BG26: =SUM(I26+Q26+Y26+AG26)/4 -> 78.5 | BH26: =SUM(K26+S26+AA26+AI26)/4 -> 81.75 | BI26: =AVERAGE(BE26:BH26) -> 80
A27: 17 | B27: 1A-B-17 | C27: ANGEL LUIS | D27: ENCARNACION RUIZ | AK27: =SUMIF(E27:E27, ">=70") / 4 +SUMIF(G27:G27, ">=70") / 4 +SUMIF(I27:I27, ">=70") / 4 +SUMIF(K27:K27, ">=70") / 4 + SUMIF(F27:F27, ">1") / 4 + SUMIF(H27:H27, ">1") / 4 + SUMIF(J27:J27, ">1") / 4 + SUMIF(L27:L27, ">1") / 4 -> 0 | AL27: =SUMIF(M27:M27, ">=70") / 4 +SUMIF(O27:O27, ">=70") / 4 +SUMIF(Q27:Q27, ">=70") / 4 +SUMIF(S27:S27, ">=70") / 4 + SUMIF(N27:N27, ">1") / 4 + SUMIF(P27:P27, ">1") / 4 + SUMIF(R27:R27, ">1") / 4 + SUMIF(T27:T27, ">1") / 4 -> 0 | AM27: =SUMIF(U27:U27, ">=70") / 4 +SUMIF(W27:W27, ">=70") / 4 +SUMIF(Y27:Y27, ">=70") / 4 +SUMIF(AA27:AA27, ">=70") / 4 + SUMIF(V27:V27, ">1") / 4 + SUMIF(X27:X27, ">1") / 4 + SUMIF(Z27:Z27, ">1") / 4 + SUMIF(AB27:AB27, ">1") / 4 -> 0 | AN27: =SUMIF(AC27:AC27, ">=65") / 4 +SUMIF(AE27:AE27, ">=65") / 4 +SUMIF(AG27:AG27, ">=65") / 4 +SUMIF(AI27:AI27, ">=65") / 4 + SUMIF(AD27:AD27, ">1") / 4 + SUMIF(AF27:AF27, ">1") / 4 + SUMIF(AH27:AH27, ">1") / 4 + SUMIF(AJ27:AJ27, ">1") / 4 -> 0 | AO27: =AVERAGE(AK27:AN27) -> 0 | AR27: =IF(AO27<70, AO27*0.5, "") -> 0 | AT27: =AS27*50% -> 0 | AU27: =IF(AS27<>"", IF(AR27="","",AR27+AT27), "") | AV27: =IF(AU27 < 70, AR27*30%, "") | AX27: =AW27*70% -> 0 | AY27: =IF(AW27<>"", IF(AV27="", "", AV27+AX27), "") | AZ27: =IF(AND(AU27<70, AY27<70), AO27, "") | BB27: =IF(AW27<>"", IF(AY27>=70, AY27, IF(AZ27+BA27>=70, AZ27+BA27, "")), IF(AS27<>"", IF(AU27>=70, AU27, ""), IF(AO27>=70, AO27, ""))) | BC27: =IF(AW27<>"", IF(AY27<70, IF(AZ27+BA27<70, AZ27+BA27, ""), ""), IF(AS27<>"", IF(AU27<70, AU27, ""), IF(AO27<70, AO27, ""))) -> 0 | BE27: =SUM(E27+M27+U27+AC27)/4 -> 0 | BF27: =SUM(G27+O27+W27+AE27)/4 -> 0 | BG27: =SUM(I27+Q27+Y27+AG27)/4 -> 0 | BH27: =SUM(K27+S27+AA27+AI27)/4 -> 0 | BI27: =AVERAGE(BE27:BH27) -> 0
