Workbook

Sheet ESPANOL
E7: CALCULO DE NOTAS | AO7: Calificacion Final | AP7: % DE ASISTENCIA ANUAL | AR7: CALIFICACION COMPLETIVA | AV7: CALIFICACION EXTRAORDINARIA | AZ7: EVALUACION ESPECIAL | BB7: SITUACIONFINAL EN LA ASIGNATURA
A9: NO | B9: ID | C9: NOMBRES | D9: APELLIDOS | E9: CE - LE1 | M9: CE - LE2, LE3 | U9: CE - LE4, LE6 | AC9: CE - LE5, LE7 | AK9: PCP 1 | AL9: PCP 2 | AM9: PCP 3 | AN9: PCP 4 | AR9: 50% C.F | AS9: C.E.C. | AT9: 50% C.E.C. | AU9: C.C.F | AV9: 30% C.F. | AW9: C.E.EX | AX9: 70% C.E.EX | AY9: C.EX.F | AZ9: C.F. | BA9: C.E. | BB9: A | BC9: R
E10: P1 | F10: RP1 | G10: P2 | H10: RP2 | I10: P3 | J10: RP3 | K10: P4 | L10: RP4 | M10: P1 | N10: RP1 | O10: P2 | P10: RP2 | Q10: P3 | R10: RP3 | S10: P4 | T10: RP4 | U10: P1 | V10: RP1 | W10: P2 | X10: RP3 | Y10: P3 | Z10: RP4 | AA10: P4 | AB10: RP4 | AC10: P1 | AD10: RP1 | AE10: P2 | AF10: RP3 | AG10: P3 | AH10: RP4 | AI10: P4 | AJ10: RP4 | BE10: P1 | BF10: P2 | BG10: P3 | BH10: P4 | BI10: C.F
A11: 1 | B11: 1A-A-01 | C11: LUIS ANDRES | D11: ADAMES COLON | E11: 75 | G11: 78 | I11: 77 | K11: 74 | M11: 77 | O11: 82 | Q11: 83 | S11: 78 | U11: 84 | W11: 79 | Y11: 82 | AA11: 87 | AC11: 78 | AE11: 81 | AG11: 84 | AI11: 81 | AK11: =SUMIF(E11:E11, ">=70") / 4 +SUMIF(G11:G11, ">=70") / 4 +SUMIF(I11:I11, ">=70") / 4 +SUMIF(K11:K11, ">=70") / 4 + SUMIF(F11:F11, ">1") / 4 + SUMIF(H11:H11, ">1") / 4 + SUMIF(J11:J11, ">1") / 4 + SUMIF(L11:L11, ">1") / 4 -> 76 | AL11: =SUMIF(M11:M11, ">=70") / 4 +SUMIF(O11:O11, ">=70") / 4 +SUMIF(Q11:Q11, ">=70") / 4 +SUMIF(S11:S11, ">=70") / 4 + SUMIF(N11:N11, ">1") / 4 + SUMIF(P11:P11, ">1") / 4 + SUMIF(R11:R11, ">1") / 4 + SUMIF(T11:T11, ">1") / 4 -> 80 | AM11: =SUMIF(U11:U11, ">=70") / 4 +SUMIF(W11:W11, ">=70") / 4 +SUMIF(Y11:Y11, ">=70") / 4 +SUMIF(AA11:AA11, ">=70") / 4 + SUMIF(V11:V11, ">1") / 4 + SUMIF(X11:X11, ">1") / 4 + SUMIF(Z11:Z11, ">1") / 4 + SUMIF(AB11:AB11, ">1") / 4 -> 83 | AN11: =SUMIF(AC11:AC11, ">=70") / 4 +SUMIF(AE11:AE11, ">=70") / 4 +SUMIF(AG11:AG11, ">=70") / 4 +SUMIF(AI11:AI11, ">=70") / 4 + SUMIF(AD11:AD11, ">1") / 4 + SUMIF(AF11:AF11, ">1") / 4 + SUMIF(AH11:AH11, ">1") / 4 + SUMIF(AJ11:AJ11, ">1") / 4 -> 81 | AO11: =AVERAGE(AK11:AN11) -> 80 | AR11: =IF(AO11<70, AO11*0.5, "") | AT11: =AS11*50% -> 0 | AU11: =IF(AS11<>"", IF(AR11="","",AR11+AT11), "") | AV11: =IF(AU11 < 70, AR11*30%, "") | AX11: =AW11*70% -> 0 | AY11: =IF(AW11<>"", IF(AV11="", "", AV11+AX11), "") | AZ11: =IF(AND(AU11<70, AY11<70), AO11, "") | BB11: =IF(AW11<>"", IF(AY11>=70, AY11, IF(AZ11+BA11>=70, AZ11+BA11, "")), IF(AS11<>"", IF(AU11>=70, AU11, ""), IF(AO11>=70, AO11, ""))) -> 80 | BC11: =IF(AW11<>"", IF(AY11<70, IF(AZ11+BA11<70, AZ11+BA11, ""), ""), IF(AS11<>"", IF(AU11<70, AU11, ""), IF(AO11<70, AO11, ""))) | BE11: =SUM(E11+M11+U11+AC11)/4 -> 78.5 | BF11: =SUM(G11+O11+W11+AE11)/4 -> 80 | BG11: =SUM(I11+Q11+Y11+AG11)/4 -> 81.5 | BH11: =SUM(K11+S11+AA11+AI11)/4 -> 80 | BI11: =AVERAGE(BE11:BH11) -> 80
A12: 2 | B12: 1A-A-02 | C12: ANEURIS | D12: ANDERSON | E12: 83 | G12: 85 | I12: 80 | K12: 88 | M12: 85 | O12: 87 | Q12: 84 | S12: 88 | U12: 82 | W12: 84 | Y12: 80 | AA12: 86 | AC12: 86 | AE12: 88 | AG12: 85 | AI12: 87 | AK12: =SUMIF(E12:E12, ">=70") / 4 +SUMIF(G12:G12, ">=70") / 4 +SUMIF(I12:I12, ">=70") / 4 +SUMIF(K12:K12, ">=70") / 4 + SUMIF(F12:F12, ">1") / 4 + SUMIF(H12:H12, ">1") / 4 + SUMIF(J12:J12, ">1") / 4 + SUMIF(L12:L12, ">1") / 4 -> 84 | AL12: =SUMIF(M12:M12, ">=70") / 4 +SUMIF(O12:O12, ">=70") / 4 +SUMIF(Q12:Q12, ">=70") / 4 +SUMIF(S12:S12, ">=70") / 4 + SUMIF(N12:N12, ">1") / 4 + SUMIF(P12:P12, ">1") / 4 + SUMIF(R12:R12, ">1") / 4 + SUMIF(T12:T12, ">1") / 4 -> 86 | AM12: =SUMIF(U12:U12, ">=70") / 4 +SUMIF(W12:W12, ">=70") / 4 +SUMIF(Y12:Y12, ">=70") / 4 +SUMIF(AA12:AA12, ">=70") / 4 + SUMIF(V12:V12, ">1") / 4 + SUMIF(X12:X12, ">1") / 4 + SUMIF(Z12:Z12, ">1") / 4 + SUMIF(AB12:AB12, ">1") / 4 -> 83 | AN12: =SUMIF(AC12:AC12, ">=65") / 4 +SUMIF(AE12:AE12, ">=65") / 4 +SUMIF(AG12:AG12, ">=65") / 4 +SUMIF(AI12:AI12, ">=65") / 4 + SUMIF(AD12:AD12, ">1") / 4 + SUMIF(AF12:AF12, ">1") / 4 + SUMIF(AH12:AH12, ">1") / 4 + SUMIF(AJ12:AJ12, ">1") / 4 -> 86.5 | AO12: =AVERAGE(AK12:AN12) -> 84.875 | AR12: =IF(AO12<70, AO12*0.5, "") | AT12: =AS12*50% -> 0 | AU12: =IF(AS12<>"", IF(AR12="","",AR12+AT12), "") | AV12: =IF(AU12 < 70, AR12*30%, "") | AX12: =AW12*70% -> 0 | AY12: =IF(AW12<>"", IF(AV12="", "", AV12+AX12), "") | AZ12: =IF(AND(AU12<70, AY12<70), AO12, "") | BB12: =IF(AW12<>"", IF(AY12>=70, AY12, IF(AZ12+BA12>=70, AZ12+BA12, "")), IF(AS12<>"", IF(AU12>=70, AU12, ""), IF(AO12>=70, AO12, ""))) -> 84.875 | BC12: =IF(AW12<>"", IF(AY12<70, IF(AZ12+BA12<70, AZ12+BA12, ""), ""), IF(AS12<>"", IF(AU12<70, AU12, ""), IF(AO12<70, AO12, ""))) | BE12: =SUM(E12+M12+U12+AC12)/4 -> 84 | BF12: =SUM(G12+O12+W12+AE12)/4 -> 86 | BG12: =SUM(I12+Q12+Y12+AG12)/4 -> 82.25 | BH12: =SUM(K12+S12+AA12+AI12)/4 -> 87.25 | BI12: =AVERAGE(BE12:BH12) -> 84.875
A13: 3 | B13: 1A-A-03 | C13: ANGEL ARIEL | D13: AZCONA BALBUENA | E13: 82 | G13: 84 | I13: 86 | K13: 80 | M13: 84 | O13: 86 | Q13: 88 | S13: 82 | U13: 90 | W13: 93 | Y13: 94 | AA13: 91 | AC13: 96 | AE13: 97 | AG13: 92 | AI13: 91 | AK13: =SUMIF(E13:E13, ">=70") / 4 +SUMIF(G13:G13, ">=70") / 4 +SUMIF(I13:I13, ">=70") / 4 +SUMIF(K13:K13, ">=70") / 4 + SUMIF(F13:F13, ">1") / 4 + SUMIF(H13:H13, ">1") / 4 + SUMIF(J13:J13, ">1") / 4 + SUMIF(L13:L13, ">1") / 4 -> 83 | AL13: =SUMIF(M13:M13, ">=70") / 4 +SUMIF(O13:O13, ">=70") / 4 +SUMIF(Q13:Q13, ">=70") / 4 +SUMIF(S13:S13, ">=70") / 4 + SUMIF(N13:N13, ">1") / 4 + SUMIF(P13:P13, ">1") / 4 + SUMIF(R13:R13, ">1") / 4 + SUMIF(T13:T13, ">1") / 4 -> 85 | AM13: =SUMIF(U13:U13, ">=70") / 4 +SUMIF(W13:W13, ">=70") / 4 +SUMIF(Y13:Y13, ">=70") / 4 +SUMIF(AA13:AA13, ">=70") / 4 + SUMIF(V13:V13, ">1") / 4 + SUMIF(X13:X13, ">1") / 4 + SUMIF(Z13:Z13, ">1") / 4 + SUMIF(AB13:AB13, ">1") / 4 -> 92 | AN13: =SUMIF(AC13:AC13, ">=65") / 4 +SUMIF(AE13:AE13, ">=65") / 4 +SUMIF(AG13:AG13, ">=65") / 4 +SUMIF(AI13:AI13, ">=65") / 4 + SUMIF(AD13:AD13, ">1") / 4 + SUMIF(AF13:AF13, ">1") / 4 + SUMIF(AH13:AH13, ">1") / 4 + SUMIF(AJ13:AJ13, ">1") / 4 -> 94 | AO13: =AVERAGE(AK13:AN13) -> 88.5 | AR13: =IF(AO13<70, AO13*0.5, "") | AT13: =AS13*50% -> 0 | AU13: =IF(AS13<>"", IF(AR13="","",AR13+AT13), "") | AV13: =IF(AU13 < 70, AR13*30%, "") | AX13: =AW13*70% -> 0 | AY13: =IF(AW13<>"", IF(AV13="", "", AV13+AX13), "") | AZ13: =IF(AND(AU13<70, AY13<70), AO13, "") | BB13: =IF(AW13<>"", IF(AY13>=70, AY13, IF(AZ13+BA13>=70, AZ13+BA13, "")), IF(AS13<>"", IF(AU13>=70, AU13, ""), IF(AO13>=70, AO13, ""))) -> 88.5 | BC13: =IF(AW13<>"", IF(AY13<70, IF(AZ13+BA13<70, AZ13+BA13, ""), ""), IF(AS13<>"", IF(AU13<70, AU13, ""), IF(AO13<70, AO13, ""))) | BE13: =SUM(E13+M13+U13+AC13)/4 -> 88 | BF13: =SUM(G13+O13+W13+AE13)/4 -> 90 | BG13: =SUM(I13+Q13+Y13+AG13)/4 -> 90 | BH13: =SUM(K13+S13+AA13+AI13)/4 -> 86 | BI13: =AVERAGE(BE13:BH13) -> 88.5
A14: 4 | B14: 1A-A-04 | C14: WISLINE | D14: BERNADEAU | E14: 80 | G14: 85 | I14: 81 | K14: 82 | M14: 84 | O14: 87 | Q14: 85 | S14: 88 | U14: 81 | W14: 84 | Y14: 82 | AA14: 85 | AC14: 83 | AE14: 88 | AG14: 82 | AI14: 87 | AK14: =SUMIF(E14:E14, ">=70") / 4 +SUMIF(G14:G14, ">=70") / 4 +SUMIF(I14:I14, ">=70") / 4 +SUMIF(K14:K14, ">=70") / 4 + SUMIF(F14:F14, ">1") / 4 + SUMIF(H14:H14, ">1") / 4 + SUMIF(J14:J14, ">1") / 4 + SUMIF(L14:L14, ">1") / 4 -> 82 | AL14: =SUMIF(M14:M14, ">=70") / 4 +SUMIF(O14:O14, ">=70") / 4 +SUMIF(Q14:Q14, ">=70") / 4 +SUMIF(S14:S14, ">=70") / 4 + SUMIF(N14:N14, ">1") / 4 + SUMIF(P14:P14, ">1") / 4 + SUMIF(R14:R14, ">1") / 4 + SUMIF(T14:T14, ">1") / 4 -> 86 | AM14: =SUMIF(U14:U14, ">=70") / 4 +SUMIF(W14:W14, ">=70") / 4 +SUMIF(Y14:Y14, ">=70") / 4 +SUMIF(AA14:AA14, ">=70") / 4 + SUMIF(V14:V14, ">1") / 4 + SUMIF(X14:X14, ">1") / 4 + SUMIF(Z14:Z14, ">1") / 4 + SUMIF(AB14:AB14, ">1") / 4 -> 83 | AN14: =SUMIF(AC14:AC14, ">=65") / 4 +SUMIF(AE14:AE14, ">=65") / 4 +SUMIF(AG14:AG14, ">=65") / 4 +SUMIF(AI14:AI14, ">=65") / 4 + SUMIF(AD14:AD14, ">1") / 4 + SUMIF(AF14:AF14, ">1") / 4 + SUMIF(AH14:AH14, ">1") / 4 + SUMIF(AJ14:AJ14, ">1") / 4 -> 85 | AO14: =AVERAGE(AK14:AN14) -> 84 | AR14: =IF(AO14<70, AO14*0.5, "") | AT14: =AS14*50% -> 0 | AU14: =IF(AS14<>"", IF(AR14="","",AR14+AT14), "") | AV14: =IF(AU14 < 70, AR14*30%, "") | AX14: =AW14*70% -> 0 | AY14: =IF(AW14<>"", IF(AV14="", "", AV14+AX14), "") | AZ14: =IF(AND(AU14<70, AY14<70), AO14, "") | BB14: =IF(AW14<>"", IF(AY14>=70, AY14, IF(AZ14+BA14>=70, AZ14+BA14, "")), IF(AS14<>"", IF(AU14>=70, AU14, ""), IF(AO14>=70, AO14, ""))) -> 84 | BC14: =IF(AW14<>"", IF(AY14<70, IF(AZ14+BA14<70, AZ14+BA14, ""), ""), IF(AS14<>"", IF(AU14<70, AU14, ""), IF(AO14<70, AO14, ""))) | BE14: =SUM(E14+M14+U14+AC14)/4 -> 82 | BF14: =SUM(G14+O14+W14+AE14)/4 -> 86 | BG14: =SUM(I14+Q14+Y14+AG14)/4 -> 82.5 | BH14: =SUM(K14+S14+AA14+AI14)/4 -> 85.5 | BI14: =AVERAGE(BE14:BH14) -> 84
A15: 5 | B15: 1A-A-05 | C15: LISAIRY | D15: BREA CONTRERA | E15: 80 | G15: 82 | I15: 80 | K15: 82 | M15: 82 | O15: 84 | Q15: 80 | S15: 86 | U15: 82 | W15: 81 | Y15: 78 | AA15: 79 | AC15: 80 | AE15: 85 | AG15: 88 | AI15: 83 | AK15: =SUMIF(E15:E15, ">=70") / 4 +SUMIF(G15:G15, ">=70") / 4 +SUMIF(I15:I15, ">=70") / 4 +SUMIF(K15:K15, ">=70") / 4 + SUMIF(F15:F15, ">1") / 4 + SUMIF(H15:H15, ">1") / 4 + SUMIF(J15:J15, ">1") / 4 + SUMIF(L15:L15, ">1") / 4 -> 81 | AL15: =SUMIF(M15:M15, ">=70") / 4 +SUMIF(O15:O15, ">=70") / 4 +SUMIF(Q15:Q15, ">=70") / 4 +SUMIF(S15:S15, ">=70") / 4 + SUMIF(N15:N15, ">1") / 4 + SUMIF(P15:P15, ">1") / 4 + SUMIF(R15:R15, ">1") / 4 + SUMIF(T15:T15, ">1") / 4 -> 83 | AM15: =SUMIF(U15:U15, ">=70") / 4 +SUMIF(W15:W15, ">=70") / 4 +SUMIF(Y15:Y15, ">=70") / 4 +SUMIF(AA15:AA15, ">=70") / 4 + SUMIF(V15:V15, ">1") / 4 + SUMIF(X15:X15, ">1") / 4 + SUMIF(Z15:Z15, ">1") / 4 + SUMIF(AB15:AB15, ">1") / 4 -> 80 | AN15: =SUMIF(AC15:AC15, ">=65") / 4 +SUMIF(AE15:AE15, ">=65") / 4 +SUMIF(AG15:AG15, ">=65") / 4 +SUMIF(AI15:AI15, ">=65") / 4 + SUMIF(AD15:AD15, ">1") / 4 + SUMIF(AF15:AF15, ">1") / 4 + SUMIF(AH15:AH15, ">1") / 4 + SUMIF(AJ15:AJ15, ">1") / 4 -> 84 | AO15: =AVERAGE(AK15:AN15) -> 82 | AR15: =IF(AO15<70, AO15*0.5, "") | AT15: =AS15*50% -> 0 | AU15: =IF(AS15<>"", IF(AR15="","",AR15+AT15), "") | AV15: =IF(AU15 < 70, AR15*30%, "") | AX15: =AW15*70% -> 0 | AY15: =IF(AW15<>"", IF(AV15="", "", AV15+AX15), "") | AZ15: =IF(AND(AU15<70, AY15<70), AO15, "") | BB15: =IF(AW15<>"", IF(AY15>=70, AY15, IF(AZ15+BA15>=70, AZ15+BA15, "")), IF(AS15<>"", IF(AU15>=70, AU15, ""), IF(AO15>=70, AO15, ""))) -> 82 | BC15: =IF(AW15<>"", IF(AY15<70, IF(AZ15+BA15<70, AZ15+BA15, ""), ""), IF(AS15<>"", IF(AU15<70, AU15, ""), IF(AO15<70, AO15, ""))) | BE15: =SUM(E15+M15+U15+AC15)/4 -> 81 | BF15: =SUM(G15+O15+W15+AE15)/4 -> 83 | BG15: =SUM(I15+Q15+Y15+AG15)/4 -> 81.5 | BH15: =SUM(K15+S15+AA15+AI15)/4 -> 82.5 | BI15: =AVERAGE(BE15:BH15) -> 82
A16: 6 | B16: 1A-A-06 | C16: RODENEL | D16: CACEUS DABOIS | E16: 75 | G16: 78 | I16: 77 | K16: 74 | M16: 77 | O16: 82 | Q16: 83 | S16: 78 | U16: 84 | W16: 79 | Y16: 82 | AA16: 87 | AC16: 78 | AE16: 81 | AG16: 84 | AI16: 81 | AK16: =SUMIF(E16:E16, ">=70") / 4 +SUMIF(G16:G16, ">=70") / 4 +SUMIF(I16:I16, ">=70") / 4 +SUMIF(K16:K16, ">=70") / 4 + SUMIF(F16:F16, ">1") / 4 + SUMIF(H16:H16, ">1") / 4 + SUMIF(J16:J16, ">1") / 4 + SUMIF(L16:L16, ">1") / 4 -> 76 | AL16: =SUMIF(M16:M16, ">=70") / 4 +SUMIF(O16:O16, ">=70") / 4 +SUMIF(Q16:Q16, ">=70") / 4 +SUMIF(S16:S16, ">=70") / 4 + SUMIF(N16:N16, ">1") / 4 + SUMIF(P16:P16, ">1") / 4 + SUMIF(R16:R16, ">1") / 4 + SUMIF(T16:T16, ">1") / 4 -> 80 | AM16: =SUMIF(U16:U16, ">=70") / 4 +SUMIF(W16:W16, ">=70") / 4 +SUMIF(Y16:Y16, ">=70") / 4 +SUMIF(AA16:AA16, ">=70") / 4 + SUMIF(V16:V16, ">1") / 4 + SUMIF(X16:X16, ">1") / 4 + SUMIF(Z16:Z16, ">1") / 4 + SUMIF(AB16:AB16, ">1") / 4 -> 83 | AN16: =SUMIF(AC16:AC16, ">=65") / 4 +SUMIF(AE16:AE16, ">=65") / 4 +SUMIF(AG16:AG16, ">=65") / 4 +SUMIF(AI16:AI16, ">=65") / 4 + SUMIF(AD16:AD16, ">1") / 4 + SUMIF(AF16:AF16, ">1") / 4 + SUMIF(AH16:AH16, ">1") / 4 + SUMIF(AJ16:AJ16, ">1") / 4 -> 81 | AO16: =AVERAGE(AK16:AN16) -> 80 | AR16: =IF(AO16<70, AO16*0.5, "") | AT16: =AS16*50% -> 0 | AU16: =IF(AS16<>"", IF(AR16="","",AR16+AT16), "") | AV16: =IF(AU16 < 70, AR16*30%, "") | AX16: =AW16*70% -> 0 | AY16: =IF(AW16<>"", IF(AV16="", "", AV16+AX16), "") | AZ16: =IF(AND(AU16<70, AY16<70), AO16, "") | BB16: =IF(AW16<>"", IF(AY16>=70, AY16, IF(AZ16+BA16>=70, AZ16+BA16, "")), IF(AS16<>"", IF(AU16>=70, AU16, ""), IF(AO16>=70, AO16, ""))) -> 80 | BC16: =IF(AW16<>"", IF(AY16<70, IF(AZ16+BA16<70, AZ16+BA16, ""), ""), IF(AS16<>"", IF(AU16<70, AU16, ""), IF(AO16<70, AO16, ""))) | BE16: =SUM(E16+M16+U16+AC16)/4 -> 78.5 | BF16: =SUM(G16+O16+W16+AE16)/4 -> 80 | BG16: =SUM(I16+Q16+Y16+AG16)/4 -> 81.5 | BH16: =SUM(K16+S16+AA16+AI16)/4 -> 80 | BI16: =AVERAGE(BE16:BH16) -> 80
A17: 7 | B17: 1A-A-07 | C17: MARY LUZ | D17: CAMILO ESPINAL | E17: 83 | G17: 85 | I17: 80 | K17: 88 | M17: 85 | O17: 87 | Q17: 84 | S17: 88 | U17: 82 | W17: 84 | Y17: 80 | AA17: 86 | AC17: 86 | AE17: 88 | AG17: 85 | AI17: 87 | AK17: =SUMIF(E17:E17, ">=70") / 4 +SUMIF(G17:G17, ">=70") / 4 +SUMIF(I17:I17, ">=70") / 4 +SUMIF(K17:K17, ">=70") / 4 + SUMIF(F17:F17, ">1") / 4 + SUMIF(H17:H17, ">1") / 4 + SUMIF(J17:J17, ">1") / 4 + SUMIF(L17:L17, ">1") / 4 -> 84 | AL17: =SUMIF(M17:M17, ">=70") / 4 +SUMIF(O17:O17, ">=70") / 4 +SUMIF(Q17:Q17, ">=70") / 4 +SUMIF(S17:S17, ">=70") / 4 + SUMIF(N17:N17, ">1") / 4 + SUMIF(P17:P17, ">1") / 4 + SUMIF(R17:R17, ">1") / 4 + SUMIF(T17:T17, ">1") / 4 -> 86 | AM17: =SUMIF(U17:U17, ">=70") / 4 +SUMIF(W17:W17, ">=70") / 4 +SUMIF(Y17:Y17, ">=70") / 4 +SUMIF(AA17:AA17, ">=70") / 4 + SUMIF(V17:V17, ">1") / 4 + SUMIF(X17:X17, ">1") / 4 + SUMIF(Z17:Z17, ">1") / 4 + SUMIF(AB17:AB17, ">1") / 4 -> 83 | AN17: =SUMIF(AC17:AC17, ">=65") / 4 +SUMIF(AE17:AE17, ">=65") / 4 +SUMIF(AG17:AG17, ">=65") / 4 +SUMIF(AI17:AI17, ">=65") / 4 + SUMIF(AD17:AD17, ">1") / 4 + SUMIF(AF17:AF17, ">1") / 4 + SUMIF(AH17:AH17, ">1") / 4 + SUMIF(AJ17:AJ17, ">1") / 4 -> 86.5 | AO17: =AVERAGE(AK17:AN17) -> 84.875 | AR17: =IF(AO17<70, AO17*0.5, "") | AT17: =AS17*50% -> 0 | AU17: =IF(AS17<>"", IF(AR17="","",AR17+AT17), "") | AV17: =IF(AU17 < 70, AR17*30%, "") | AX17: =AW17*70% -> 0 | AY17: =IF(AW17<>"", IF(AV17="", "", AV17+AX17), "") | AZ17: =IF(AND(AU17<70, AY17<70), AO17, "") | BB17: =IF(AW17<>"", IF(AY17>=70, AY17, IF(AZ17+BA17>=70, AZ17+BA17, "")), IF(AS17<>"", IF(AU17>=70, AU17, ""), IF(AO17>=70, AO17, ""))) -> 84.875 | BC17: =IF(AW17<>"", IF(AY17<70, IF(AZ17+BA17<70, AZ17+BA17, ""), ""), IF(AS17<>"", IF(AU17<70, AU17, ""), IF(AO17<70, AO17, ""))) | BE17: =SUM(E17+M17+U17+AC17)/4 -> 84 | BF17: =SUM(G17+O17+W17+AE17)/4 -> 86 | BG17: =SUM(I17+Q17+Y17+AG17)/4 -> 82.25 | BH17: =SUM(K17+S17+AA17+AI17)/4 -> 87.25 | BI17: =AVERAGE(BE17:BH17) -> 84.875
A18: 8 | B18: 1A-A-08 | C18: ANA ROSA | D18: CARRION VILORIO | E18: 82 | G18: 84 | I18: 86 | K18: 80 | M18: 84 | O18: 86 | Q18: 88 | S18: 82 | U18: 90 | W18: 93 | Y18: 94 | AA18: 91 | AC18: 96 | AE18: 97 | AG18: 92 | AI18: 91 | AK18: =SUMIF(E18:E18, ">=70") / 4 +SUMIF(G18:G18, ">=70") / 4 +SUMIF(I18:I18, ">=70") / 4 +SUMIF(K18:K18, ">=70") / 4 + SUMIF(F18:F18, ">1") / 4 + SUMIF(H18:H18, ">1") / 4 + SUMIF(J18:J18, ">1") / 4 + SUMIF(L18:L18, ">1") / 4 -> 83 | AL18: =SUMIF(M18:M18, ">=70") / 4 +SUMIF(O18:O18, ">=70") / 4 +SUMIF(Q18:Q18, ">=70") / 4 +SUMIF(S18:S18, ">=70") / 4 + SUMIF(N18:N18, ">1") / 4 + SUMIF(P18:P18, ">1") / 4 + SUMIF(R18:R18, ">1") / 4 + SUMIF(T18:T18, ">1") / 4 -> 85 | AM18: =SUMIF(U18:U18, ">=70") / 4 +SUMIF(W18:W18, ">=70") / 4 +SUMIF(Y18:Y18, ">=70") / 4 +SUMIF(AA18:AA18, ">=70") / 4 + SUMIF(V18:V18, ">1") / 4 + SUMIF(X18:X18, ">1") / 4 + SUMIF(Z18:Z18, ">1") / 4 + SUMIF(AB18:AB18, ">1") / 4 -> 92 | AN18: =SUMIF(AC18:AC18, ">=65") / 4 +SUMIF(AE18:AE18, ">=65") / 4 +SUMIF(AG18:AG18, ">=65") / 4 +SUMIF(AI18:AI18, ">=65") / 4 + SUMIF(AD18:AD18, ">1") / 4 + SUMIF(AF18:AF18, ">1") / 4 + SUMIF(AH18:AH18, ">1") / 4 + SUMIF(AJ18:AJ18, ">1") / 4 -> 94 | AO18: =AVERAGE(AK18:AN18) -> 88.5 | AR18: =IF(AO18<70, AO18*0.5, "") | AT18: =AS18*50% -> 0 | AU18: =IF(AS18<>"", IF(AR18="","",AR18+AT18), "") | AV18: =IF(AU18 < 70, AR18*30%, "") | AX18: =AW18*70% -> 0 | AY18: =IF(AW18<>"", IF(AV18="", "", AV18+AX18), "") | AZ18: =IF(AND(AU18<70, AY18<70), AO18, "") | BB18: =IF(AW18<>"", IF(AY18>=70, AY18, IF(AZ18+BA18>=70, AZ18+BA18, "")), IF(AS18<>"", IF(AU18>=70, AU18, ""), IF(AO18>=70, AO18, ""))) -> 88.5 | BC18: =IF(AW18<>"", IF(AY18<70, IF(AZ18+BA18<70, AZ18+BA18, ""), ""), IF(AS18<>"", IF(AU18<70, AU18, ""), IF(AO18<70, AO18, ""))) | BE18: =SUM(E18+M18+U18+AC18)/4 -> 88 | BF18: =SUM(G18+O18+W18+AE18)/4 -> 90 | BG18: =SUM(I18+Q18+Y18+AG18)/4 -> 90 | BH18: =SUM(K18+S18+AA18+AI18)/4 -> 86 | BI18: =AVERAGE(BE18:BH18) -> 88.5
A19: 9 | B19: 1A-A-09 | C19: WILDIANA | D19: CASSEUS | E19: 80 | G19: 85 | I19: 81 | K19: 82 | M19: 84 | O19: 87 | Q19: 85 | S19: 88 | U19: 81 | W19: 84 | Y19: 82 | AA19: 85 | AC19: 83 | AE19: 88 | AG19: 82 | AI19: 87 | AK19: =SUMIF(E19:E19, ">=70") / 4 +SUMIF(G19:G19, ">=70") / 4 +SUMIF(I19:I19, ">=70") / 4 +SUMIF(K19:K19, ">=70") / 4 + SUMIF(F19:F19, ">1") / 4 + SUMIF(H19:H19, ">1") / 4 + SUMIF(J19:J19, ">1") / 4 + SUMIF(L19:L19, ">1") / 4 -> 82 | AL19: =SUMIF(M19:M19, ">=70") / 4 +SUMIF(O19:O19, ">=70") / 4 +SUMIF(Q19:Q19, ">=70") / 4 +SUMIF(S19:S19, ">=70") / 4 + SUMIF(N19:N19, ">1") / 4 + SUMIF(P19:P19, ">1") / 4 + SUMIF(R19:R19, ">1") / 4 + SUMIF(T19:T19, ">1") / 4 -> 86 | AM19: =SUMIF(U19:U19, ">=70") / 4 +SUMIF(W19:W19, ">=70") / 4 +SUMIF(Y19:Y19, ">=70") / 4 +SUMIF(AA19:AA19, ">=70") / 4 + SUMIF(V19:V19, ">1") / 4 + SUMIF(X19:X19, ">1") / 4 + SUMIF(Z19:Z19, ">1") / 4 + SUMIF(AB19:AB19, ">1") / 4 -> 83 | AN19: =SUMIF(AC19:AC19, ">=65") / 4 +SUMIF(AE19:AE19, ">=65") / 4 +SUMIF(AG19:AG19, ">=65") / 4 +SUMIF(AI19:AI19, ">=65") / 4 + SUMIF(AD19:AD19, ">1") / 4 + SUMIF(AF19:AF19, ">1") / 4 + SUMIF(AH19:AH19, ">1") / 4 + SUMIF(AJ19:AJ19, ">1") / 4 -> 85 | AO19: =AVERAGE(AK19:AN19) -> 84 | AR19: =IF(AO19<70, AO19*0.5, "") | AT19: =AS19*50% -> 0 | AU19: =IF(AS19<>"", IF(AR19="","",AR19+AT19), "") | AV19: =IF(AU19 < 70, AR19*30%, "") | AX19: =AW19*70% -> 0 | AY19: =IF(AW19<>"", IF(AV19="", "", AV19+AX19), "") | AZ19: =IF(AND(AU19<70, AY19<70), AO19, "") | BB19: =IF(AW19<>"", IF(AY19>=70, AY19, IF(AZ19+BA19>=70, AZ19+BA19, "")), IF(AS19<>"", IF(AU19>=70, AU19, ""), IF(AO19>=70, AO19, ""))) -> 84 | BC19: =IF(AW19<>"", IF(AY19<70, IF(AZ19+BA19<70, AZ19+BA19, ""), ""), IF(AS19<>"", IF(AU19<70, AU19, ""), IF(AO19<70, AO19, ""))) | BE19: =SUM(E19+M19+U19+AC19)/4 -> 82 | BF19: =SUM(G19+O19+W19+AE19)/4 -> 86 | BG19: =SUM(I19+Q19+Y19+AG19)/4 -> 82.5 | BH19: =SUM(K19+S19+AA19+AI19)/4 -> 85.5 | BI19: =AVERAGE(BE19:BH19) -> 84
A20: 10 | B20: 1A-A-10 | C20: JERVIN | D20: CASTRO ALMONTE | E20: 75 | G20: 78 | I20: 77 | K20: 74 | M20: 77 | O20: 82 | Q20: 83 | S20: 78 | U20: 84 | W20: 79 | Y20: 82 | AA20: 87 | AC20: 78 | AE20: 81 | AG20: 84 | AI20: 81 | AK20: =SUMIF(E20:E20, ">=70") / 4 +SUMIF(G20:G20, ">=70") / 4 +SUMIF(I20:I20, ">=70") / 4 +SUMIF(K20:K20, ">=70") / 4 + SUMIF(F20:F20, ">1") / 4 + SUMIF(H20:H20, ">1") / 4 + SUMIF(J20:J20, ">1") / 4 + SUMIF(L20:L20, ">1") / 4 -> 76 | AL20: =SUMIF(M20:M20, ">=70") / 4 +SUMIF(O20:O20, ">=70") / 4 +SUMIF(Q20:Q20, ">=70") / 4 +SUMIF(S20:S20, ">=70") / 4 + SUMIF(N20:N20, ">1") / 4 + SUMIF(P20:P20, ">1") / 4 + SUMIF(R20:R20, ">1") / 4 + SUMIF(T20:T20, ">1") / 4 -> 80 | AM20: =SUMIF(U20:U20, ">=70") / 4 +SUMIF(W20:W20, ">=70") / 4 +SUMIF(Y20:Y20, ">=70") / 4 +SUMIF(AA20:AA20, ">=70") / 4 + SUMIF(V20:V20, ">1") / 4 + SUMIF(X20:X20, ">1") / 4 + SUMIF(Z20:Z20, ">1") / 4 + SUMIF(AB20:AB20, ">1") / 4 -> 83 | AN20: =SUMIF(AC20:AC20, ">=65") / 4 +SUMIF(AE20:AE20, ">=65") / 4 +SUMIF(AG20:AG20, ">=65") / 4 +SUMIF(AI20:AI20, ">=65") / 4 + SUMIF(AD20:AD20, ">1") / 4 + SUMIF(AF20:AF20, ">1") / 4 + SUMIF(AH20:AH20, ">1") / 4 + SUMIF(AJ20:AJ20, ">1") / 4 -> 81 | AO20: =AVERAGE(AK20:AN20) -> 80 | AR20: =IF(AO20<70, AO20*0.5, "") | AT20: =AS20*50% -> 0 | AU20: =IF(AS20<>"", IF(AR20="","",AR20+AT20), "") | AV20: =IF(AU20 < 70, AR20*30%, "") | AX20: =AW20*70% -> 0 | AY20: =IF(AW20<>"", IF(AV20="", "", AV20+AX20), "") | AZ20: =IF(AND(AU20<70, AY20<70), AO20, "") | BB20: =IF(AW20<>"", IF(AY20>=70, AY20, IF(AZ20+BA20>=70, AZ20+BA20, "")), IF(AS20<>"", IF(AU20>=70, AU20, ""), IF(AO20>=70, AO20, ""))) -> 80 | BC20: =IF(AW20<>"", IF(AY20<70, IF(AZ20+BA20<70, AZ20+BA20, ""), ""), IF(AS20<>"", IF(AU20<70, AU20, ""), IF(AO20<70, AO20, ""))) | BE20: =SUM(E20+M20+U20+AC20)/4 -> 78.5 | BF20: =SUM(G20+O20+W20+AE20)/4 -> 80 | BG20: =SUM(I20+Q20+Y20+AG20)/4 -> 81.5 | BH20: =SUM(K20+S20+AA20+AI20)/4 -> 80 | BI20: =AVERAGE(BE20:BH20) -> 80
A21: 11 | B21: 1A-A-11 | C21: SONDJY | D21: CESAIRE | E21: 73 | G21: 75 | I21: 70 | K21: 78 | M21: 75 | O21: 77 | Q21: 74 | S21: 78 | U21: 71 | W21: 73 | Y21: 70 | AA21: 74 | AC21: 76 | AE21: 80 | AG21: 77 | AI21: 79 | AK21: =SUMIF(E21:E21, ">=70") / 4 +SUMIF(G21:G21, ">=70") / 4 +SUMIF(I21:I21, ">=70") / 4 +SUMIF(K21:K21, ">=70") / 4 + SUMIF(F21:F21, ">1") / 4 + SUMIF(H21:H21, ">1") / 4 + SUMIF(J21:J21, ">1") / 4 + SUMIF(L21:L21, ">1") / 4 -> 74 | AL21: =SUMIF(M21:M21, ">=70") / 4 +SUMIF(O21:O21, ">=70") / 4 +SUMIF(Q21:Q21, ">=70") / 4 +SUMIF(S21:S21, ">=70") / 4 + SUMIF(N21:N21, ">1") / 4 + SUMIF(P21:P21, ">1") / 4 + SUMIF(R21:R21, ">1") / 4 + SUMIF(T21:T21, ">1") / 4 -> 76 | AM21: =SUMIF(U21:U21, ">=70") / 4 +SUMIF(W21:W21, ">=70") / 4 +SUMIF(Y21:Y21, ">=70") / 4 +SUMIF(AA21:AA21, ">=70") / 4 + SUMIF(V21:V21, ">1") / 4 + SUMIF(X21:X21, ">1") / 4 + SUMIF(Z21:Z21, ">1") / 4 + SUMIF(AB21:AB21, ">1") / 4 -> 72 | AN21: =SUMIF(AC21:AC21, ">=65") / 4 +SUMIF(AE21:AE21, ">=65") / 4 +SUMIF(AG21:AG21, ">=65") / 4 +SUMIF(AI21:AI21, ">=65") / 4 + SUMIF(AD21:AD21, ">1") / 4 + SUMIF(AF21:AF21, ">1") / 4 + SUMIF(AH21:AH21, ">1") / 4 + SUMIF(AJ21:AJ21, ">1") / 4 -> 78 | AO21: =AVERAGE(AK21:AN21) -> 75 | AR21: =IF(AO21<70, AO21*0.5, "") | AT21: =AS21*50% -> 0 | AU21: =IF(AS21<>"", IF(AR21="","",AR21+AT21), "") | AV21: =IF(AU21 < 70, AR21*30%, "") | AX21: =AW21*70% -> 0 | AY21: =IF(AW21<>"", IF(AV21="", "", AV21+AX21), "") | AZ21: =IF(AND(AU21<70, AY21<70), AO21, "") | BB21: =IF(AW21<>"", IF(AY21>=70, AY21, IF(AZ21+BA21>=70, AZ21+BA21, "")), IF(AS21<>"", IF(AU21>=70, AU21, ""), IF(AO21>=70, AO21, ""))) -> 75 | BC21: =IF(AW21<>"", IF(AY21<70, IF(AZ21+BA21<70, AZ21+BA21, ""), ""), IF(AS21<>"", IF(AU21<70, AU21, ""), IF(AO21<70, AO21, ""))) | BE21: =SUM(E21+M21+U21+AC21)/4 -> 73.75 | BF21: =SUM(G21+O21+W21+AE21)/4 -> 76.25 | BG21: =SUM(I21+Q21+Y21+AG21)/4 -> 72.75 | BH21: =SUM(K21+S21+AA21+AI21)/4 -> 77.25 | BI21: =AVERAGE(BE21:BH21) -> 75
A22: 12 | B22: 1A-A-12 | C22: ANDERSON | D22: CHARLES | E22: 82 | G22: 84 | I22: 80 | K22: 86 | M22: 84 | O22: 86 | Q22: 82 | S22: 88 | U22: 87 | W22: 88 | Y22: 86 | AA22: 87 | AC22: 85 | AE22: 87 | AG22: 85 | AI22: 83 | AK22: =SUMIF(E22:E22, ">=70") / 4 +SUMIF(G22:G22, ">=70") / 4 +SUMIF(I22:I22, ">=70") / 4 +SUMIF(K22:K22, ">=70") / 4 + SUMIF(F22:F22, ">1") / 4 + SUMIF(H22:H22, ">1") / 4 + SUMIF(J22:J22, ">1") / 4 + SUMIF(L22:L22, ">1") / 4 -> 83 | AL22: =SUMIF(M22:M22, ">=70") / 4 +SUMIF(O22:O22, ">=70") / 4 +SUMIF(Q22:Q22, ">=70") / 4 +SUMIF(S22:S22, ">=70") / 4 + SUMIF(N22:N22, ">1") / 4 + SUMIF(P22:P22, ">1") / 4 + SUMIF(R22:R22, ">1") / 4 + SUMIF(T22:T22, ">1") / 4 -> 85 | AM22: =SUMIF(U22:U22, ">=70") / 4 +SUMIF(W22:W22, ">=70") / 4 +SUMIF(Y22:Y22, ">=70") / 4 +SUMIF(AA22:AA22, ">=70") / 4 + SUMIF(V22:V22, ">1") / 4 + SUMIF(X22:X22, ">1") / 4 + SUMIF(Z22:Z22, ">1") / 4 + SUMIF(AB22:AB22, ">1") / 4 -> 87 | AN22: =SUMIF(AC22:AC22, ">=65") / 4 +SUMIF(AE22:AE22, ">=65") / 4 +SUMIF(AG22:AG22, ">=65") / 4 +SUMIF(AI22:AI22, ">=65") / 4 + SUMIF(AD22:AD22, ">1") / 4 + SUMIF(AF22:AF22, ">1") / 4 + SUMIF(AH22:AH22, ">1") / 4 + SUMIF(AJ22:AJ22, ">1") / 4 -> 85 | AO22: =AVERAGE(AK22:AN22) -> 85 | AR22: =IF(AO22<70, AO22*0.5, "") | AT22: =AS22*50% -> 0 | AU22: =IF(AS22<>"", IF(AR22="","",AR22+AT22), "") | AV22: =IF(AU22 < 70, AR22*30%, "") | AX22: =AW22*70% -> 0 | AY22: =IF(AW22<>"", IF(AV22="", "", AV22+AX22), "") | AZ22: =IF(AND(AU22<70, AY22<70), AO22, "") | BB22: =IF(AW22<>"", IF(AY22>=70, AY22, IF(AZ22+BA22>=70, AZ22+BA22, "")), IF(AS22<>"", IF(AU22>=70, AU22, ""), IF(AO22>=70, AO22, ""))) -> 85 | BC22: =IF(AW22<>"", IF(AY22<70, IF(AZ22+BA22<70, AZ22+BA22, ""), ""), IF(AS22<>"", IF(AU22<70, AU22, ""), IF(AO22<70, AO22, ""))) | BE22: =SUM(E22+M22+U22+AC22)/4 -> 84.5 | BF22: =SUM(G22+O22+W22+AE22)/4 -> 86.25 | BG22: =SUM(I22+Q22+Y22+AG22)/4 -> 83.25 | BH22: =SUM(K22+S22+AA22+AI22)/4 -> 86 | BI22: =AVERAGE(BE22:BH22) -> 85
A23: 13 | B23: 1A-A-13 | C23: SALOMON MANUEL | D23: DE JESUS MANZUETA | E23: 75 | G23: 78 | I23: 77 | K23: 74 | M23: 77 | O23: 82 | Q23: 83 | S23: 78 | U23: 84 | W23: 79 | Y23: 82 | AA23: 87 | AC23: 78 | AE23: 81 | AG23: 84 | AI23: 81 | AK23: =SUMIF(E23:E23, ">=70") / 4 +SUMIF(G23:G23, ">=70") / 4 +SUMIF(I23:I23, ">=70") / 4 +SUMIF(K23:K23, ">=70") / 4 + SUMIF(F23:F23, ">1") / 4 + SUMIF(H23:H23, ">1") / 4 + SUMIF(J23:J23, ">1") / 4 + SUMIF(L23:L23, ">1") / 4 -> 76 | AL23: =SUMIF(M23:M23, ">=70") / 4 +SUMIF(O23:O23, ">=70") / 4 +SUMIF(Q23:Q23, ">=70") / 4 +SUMIF(S23:S23, ">=70") / 4 + SUMIF(N23:N23, ">1") / 4 + SUMIF(P23:P23, ">1") / 4 + SUMIF(R23:R23, ">1") / 4 + SUMIF(T23:T23, ">1") / 4 -> 80 | AM23: =SUMIF(U23:U23, ">=70") / 4 +SUMIF(W23:W23, ">=70") / 4 +SUMIF(Y23:Y23, ">=70") / 4 +SUMIF(AA23:AA23, ">=70") / 4 + SUMIF(V23:V23, ">1") / 4 + SUMIF(X23:X23, ">1") / 4 + SUMIF(Z23:Z23, ">1") / 4 + SUMIF(AB23:AB23, ">1") / 4 -> 83 | AN23: =SUMIF(AC23:AC23, ">=65") / 4 +SUMIF(AE23:AE23, ">=65") / 4 +SUMIF(AG23:AG23, ">=65") / 4 +SUMIF(AI23:AI23, ">=65") / 4 + SUMIF(AD23:AD23, ">1") / 4 + SUMIF(AF23:AF23, ">1") / 4 + SUMIF(AH23:AH23, ">1") / 4 + SUMIF(AJ23:AJ23, ">1") / 4 -> 81 | AO23: =AVERAGE(AK23:AN23) -> 80 | AR23: =IF(AO23<70, AO23*0.5, "") | AT23: =AS23*50% -> 0 | AU23: =IF(AS23<>"", IF(AR23="","",AR23+AT23), "") | AV23: =IF(AU23 < 70, AR23*30%, "") | AX23: =AW23*70% -> 0 | AY23: =IF(AW23<>"", IF(AV23="", "", AV23+AX23), "") | AZ23: =IF(AND(AU23<70, AY23<70), AO23, "") | BB23: =IF(AW23<>"", IF(AY23>=70, AY23, IF(AZ23+BA23>=70, AZ23+BA23, "")), IF(AS23<>"", IF(AU23>=70, AU23, ""), IF(AO23>=70, AO23, ""))) -> 80 | BC23: =IF(AW23<>"", IF(AY23<70, IF(AZ23+BA23<70, AZ23+BA23, ""), ""), IF(AS23<>"", IF(AU23<70, AU23, ""), IF(AO23<70, AO23, ""))) | BE23: =SUM(E23+M23+U23+AC23)/4 -> 78.5 | BF23: =SUM(G23+O23+W23+AE23)/4 -> 80 | BG23: =SUM(I23+Q23+Y23+AG23)/4 -> 81.5 | BH23: =SUM(K23+S23+AA23+AI23)/4 -> 80 | BI23: =AVERAGE(BE23:BH23) -> 80
... A55: 45 | B55: 1A-A-45 | C55: RANYELINA | D55: SINE | E55: 81 | G55: 85 | I55: 80 | K55: 82 | M55: 83 | O55: 87 | Q55: 85 | S55: 89 | U55: 90 | W55: 94 | Y55: 90 | AA55: 94 | AC55: 94 | AE55: 98 | AG55: 90 | AI55: 94 | AK55: =SUMIF(E55:E55, ">=70") / 4 +SUMIF(G55:G55, ">=70") / 4 +SUMIF(I55:I55, ">=70") / 4 +SUMIF(K55:K55, ">=70") / 4 + SUMIF(F55:F55, ">1") / 4 + SUMIF(H55:H55, ">1") / 4 + SUMIF(J55:J55, ">1") / 4 + SUMIF(L55:L55, ">1") / 4 -> 82 | AL55: =SUMIF(M55:M55, ">=70") / 4 +SUMIF(O55:O55, ">=70") / 4 +SUMIF(Q55:Q55, ">=70") / 4 +SUMIF(S55:S55, ">=70") / 4 + SUMIF(N55:N55, ">1") / 4 + SUMIF(P55:P55, ">1") / 4 + SUMIF(R55:R55, ">1") / 4 + SUMIF(T55:T55, ">1") / 4 -> 86 | AM55: =SUMIF(U55:U55, ">=70") / 4 +SUMIF(W55:W55, ">=70") / 4 +SUMIF(Y55:Y55, ">=70") / 4 +SUMIF(AA55:AA55, ">=70") / 4 + SUMIF(V55:V55, ">1") / 4 + SUMIF(X55:X55, ">1") / 4 + SUMIF(Z55:Z55, ">1") / 4 + SUMIF(AB55:AB55, ">1") / 4 -> 92 | AN55: =SUMIF(AC55:AC55, ">=65") / 4 +SUMIF(AE55:AE55, ">=65") / 4 +SUMIF(AG55:AG55, ">=65") / 4 +SUMIF(AI55:AI55, ">=65") / 4 + SUMIF(AD55:AD55, ">1") / 4 + SUMIF(AF55:AF55, ">1") / 4 + SUMIF(AH55:AH55, ">1") / 4 + SUMIF(AJ55:AJ55, ">1") / 4 -> 94 | AO55: =AVERAGE(AK55:AN55) -> 88.5 | AR55: =IF(AO55<70, AO55*0.5, "") | AT55: =AS55*50% -> 0 | AU55: =IF(AS55<>"", IF(AR55="","",AR55+AT55), "") | AV55: =IF(AU55 < 70, AR55*30%, "") | AX55: =AW55*70% -> 0 | AY55: =IF(AW55<>"", IF(AV55="", "", AV55+AX55), "") | AZ55: =IF(AND(AU55<70, AY55<70), AO55, "") | BB55: =IF(AW55<>"", IF(AY55>=70, AY55, IF(AZ55+BA55>=70, AZ55+BA55, "")), IF(AS55<>"", IF(AU55>=70, AU55, ""), IF(AO55>=70, AO55, ""))) -> 88.5 | BC55: =IF(AW55<>"", IF(AY55<70, IF(AZ55+BA55<70, AZ55+BA55, ""), ""), IF(AS55<>"", IF(AU55<70, AU55, ""), IF(AO55<70, AO55, ""))) | BE55: =SUM(E55+M55+U55+AC55)/4 -> 87 | BF55: =SUM(G55+O55+W55+AE55)/4 -> 91 | BG55: =SUM(I55+Q55+Y55+AG55)/4 -> 86.25 | BH55: =SUM(K55+S55+AA55+AI55)/4 -> 89.75 | BI55: =AVERAGE(BE55:BH55) -> 88.5

Sheet INGLES
E7: CALCULO DE NOTAS | AO7: Calificacion Final | AP7: % DE ASISTENCIA ANUAL | AR7: CALIFICACION COMPLETIVA | AV7: CALIFICACION EXTRAORDINARIA | AZ7: EVALUACION ESPECIAL | BB7: SITUACIONFINAL EN LA ASIGNATURA
A9: NO | B9: ID | C9: NOMBRES | D9: APELLIDOS | E9: CE - LE1 | M9: CE - LE2, LE3 | U9: CE - LE4, LE6 | AC9: CE - LE5, LE7 | AK9: PCP 1 | AL9: PCP 2 | AM9: PCP 3 | AN9: PCP 4 | AR9: 50% C.F | AS9: C.E.C. | AT9: 50% C.E.C. | AU9: C.C.F | AV9: 30% C.F. | AW9: C.E.EX | AX9: 70% C.E.EX | AY9: C.EX.F | AZ9: C.F. | BA9: C.E. | BB9: A | BC9: R
E10: P1 | F10: RP1 | G10: P2 | H10: RP2 | I10: P3 | J10: RP3 | K10: P4 | L10: RP4 | M10: P1 | N10: RP1 | O10: P2 | P10: RP2 | Q10: P3 | R10: RP3 | S10: P4 | T10: RP4 | U10: P1 | V10: RP1 | W10: P2 | X10: RP3 | Y10: P3 | Z10: RP4 | AA10: P4 | AB10: RP4 | AC10: P1 | AD10: RP1 | AE10: P2 | AF10: RP3 | AG10: P3 | AH10: RP4 | AI10: P4 | AJ10: RP4 | BE10: P1 | BF10: P2 | BG10: P3 | BH10: P4 | BI10: C.F
A11: 1 | B11: 1A-A-01 | C11: LUIS ANDRES | D11: ADAMES COLON | E11: 82 | G11: 86 | I11: 80 | K11: 84 | M11: 84 | O11: 88 | Q11: 90 | S11: 86 | U11: 80 | W11: 80 | Y11: 72 | AA11: 72 | AC11: 86 | AE11: 89 | AG11: 76 | AI11: 75 | AK11: =SUMIF(E11:E11, ">=70") / 4 +SUMIF(G11:G11, ">=70") / 4 +SUMIF(I11:I11, ">=70") / 4 +SUMIF(K11:K11, ">=70") / 4 + SUMIF(F11:F11, ">1") / 4 + SUMIF(H11:H11, ">1") / 4 + SUMIF(J11:J11, ">1") / 4 + SUMIF(L11:L11, ">1") / 4 -> 83 | AL11: =SUMIF(M11:M11, ">=70") / 4 +SUMIF(O11:O11, ">=70") / 4 +SUMIF(Q11:Q11, ">=70") / 4 +SUMIF(S11:S11, ">=70") / 4 + SUMIF(N11:N11, ">1") / 4 + SUMIF(P11:P11, ">1") / 4 + SUMIF(R11:R11, ">1") / 4 + SUMIF(T11:T11, ">1") / 4 -> 87 | AM11: =SUMIF(U11:U11, ">=70") / 4 +SUMIF(W11:W11, ">=70") / 4 +SUMIF(Y11:Y11, ">=70") / 4 +SUMIF(AA11:AA11, ">=70") / 4 + SUMIF(V11:V11, ">1") / 4 + SUMIF(X11:X11, ">1") / 4 + SUMIF(Z11:Z11, ">1") / 4 + SUMIF(AB11:AB11, ">1") / 4 -> 76 | AN11: =SUMIF(AC11:AC11, ">=70") / 4 +SUMIF(AE11:AE11, ">=70") / 4 +SUMIF(AG11:AG11, ">=70") / 4 +SUMIF(AI11:AI11, ">=70") / 4 + SUMIF(AD11:AD11, ">1") / 4 + SUMIF(AF11:AF11, ">1") / 4 + SUMIF(AH11:AH11, ">1") / 4 + SUMIF(AJ11:AJ11, ">1") / 4 -> 81.5 | AO11: =AVERAGE(AK11:AN11) -> 81.875 | AR11: =IF(AO11<70, AO11*0.5, "") | AT11: =AS11*50% -> 0 | AU11: =IF(AS11<>"", IF(AR11="","",AR11+AT11), "") | AV11: =IF(AU11 < 70, AR11*30%, "") | AX11: =AW11*70% -> 0 | AY11: =IF(AW11<>"", IF(AV11="", "", AV11+AX11), "") | AZ11: =IF(AND(AU11<70, AY11<70), AO11, "") | BB11: =IF(AW11<>"", IF(AY11>=70, AY11, IF(AZ11+BA11>=70, AZ11+BA11, "")), IF(AS11<>"", IF(AU11>=70, AU11, ""), IF(AO11>=70, AO11, ""))) -> 81.875 | BC11: =IF(AW11<>"", IF(AY11<70, IF(AZ11+BA11<70, AZ11+BA11, ""), ""), IF(AS11<>"", IF(AU11<70, AU11, ""), IF(AO11<70, AO11, ""))) | BE11: =SUM(E11+M11+U11+AC11)/4 -> 83 | BF11: =SUM(G11+O11+W11+AE11)/4 -> 85.75 | BG11: =SUM(I11+Q11+Y11+AG11)/4 -> 79.5 | BH11: =SUM(K11+S11+AA11+AI11)/4 -> 79.25 | BI11: =AVERAGE(BE11:BH11) -> 81.875
A12: 2 | B12: 1A-A-02 | C12: ANEURIS | D12: ANDERSON | E12: 81 | G12: 85 | I12: 80 | K12: 82 | M12: 83 | O12: 87 | Q12: 85 | S12: 89 | U12: 84 | W12: 88 | Y12: 74 | AA12: 81 | AC12: 80 | AE12: 84 | AG12: 89 | AI12: 87 | AK12: =SUMIF(E12:E12, ">=70") / 4 +SUMIF(G12:G12, ">=70") / 4 +SUMIF(I12:I12, ">=70") / 4 +SUMIF(K12:K12, ">=70") / 4 + SUMIF(F12:F12, ">1") / 4 + SUMIF(H12:H12, ">1") / 4 + SUMIF(J12:J12, ">1") / 4 + SUMIF(L12:L12, ">1") / 4 -> 82 | AL12: =SUMIF(M12:M12, ">=70") / 4 +SUMIF(O12:O12, ">=70") / 4 +SUMIF(Q12:Q12, ">=70") / 4 +SUMIF(S12:S12, ">=70") / 4 + SUMIF(N12:N12, ">1") / 4 + SUMIF(P12:P12, ">1") / 4 + SUMIF(R12:R12, ">1") / 4 + SUMIF(T12:T12, ">1") / 4 -> 86 | AM12: =SUMIF(U12:U12, ">=70") / 4 +SUMIF(W12:W12, ">=70") / 4 +SUMIF(Y12:Y12, ">=70") / 4 +SUMIF(AA12:AA12, ">=70") / 4 + SUMIF(V12:V12, ">1") / 4 + SUMIF(X12:X12, ">1") / 4 + SUMIF(Z12:Z12, ">1") / 4 + SUMIF(AB12:AB12, ">1") / 4 -> 81.75 | AN12: =SUMIF(AC12:AC12, ">=65") / 4 +SUMIF(AE12:AE12, ">=65") / 4 +SUMIF(AG12:AG12, ">=65") / 4 +SUMIF(AI12:AI12, ">=65") / 4 + SUMIF(AD12:AD12, ">1") / 4 + SUMIF(AF12:AF12, ">1") / 4 + SUMIF(AH12:AH12, ">1") / 4 + SUMIF(AJ12:AJ12, ">1") / 4 -> 85 | AO12: =AVERAGE(AK12:AN12) -> 83.6875 | AR12: =IF(AO12<70, AO12*0.5, "") | AT12: =AS12*50% -> 0 | AU12: =IF(AS12<>"", IF(AR12="","",AR12+AT12), "") | AV12: =IF(AU12 < 70, AR12*30%, "") | AX12: =AW12*70% -> 0 | AY12: =IF(AW12<>"", IF(AV12="", "", AV12+AX12), "") | AZ12: =IF(AND(AU12<70, AY12<70), AO12, "") | BB12: =IF(AW12<>"", IF(AY12>=70, AY12, IF(AZ12+BA12>=70, AZ12+BA12, "")), IF(AS12<>"", IF(AU12>=70, AU12, ""), IF(AO12>=70, AO12, ""))) -> 83.6875 | BC12: =IF(AW12<>"", IF(AY12<70, IF(AZ12+BA12<70, AZ12+BA12, ""), ""), IF(AS12<>"", IF(AU12<70, AU12, ""), IF(AO12<70, AO12, ""))) | BE12: =SUM(E12+M12+U12+AC12)/4 -> 82 | BF12: =SUM(G12+O12+W12+AE12)/4 -> 86 | BG12: =SUM(I12+Q12+Y12+AG12)/4 -> 82 | BH12: =SUM(K12+S12+AA12+AI12)/4 -> 84.75 | BI12: =AVERAGE(BE12:BH12) -> 83.6875
A13: 3 | B13: 1A-A-03 | C13: ANGEL ARIEL | D13: AZCONA BALBUENA | E13: 86 | G13: 88 | I13: 85 | K13: 89 | M13: 88 | O13: 90 | Q13: 87 | S13: 91 | U13: 85 | W13: 87 | Y13: 84 | AA13: 88 | AC13: 89 | AE13: 91 | AG13: 88 | AI13: 92 | AK13: =SUMIF(E13:E13, ">=70") / 4 +SUMIF(G13:G13, ">=70") / 4 +SUMIF(I13:I13, ">=70") / 4 +SUMIF(K13:K13, ">=70") / 4 + SUMIF(F13:F13, ">1") / 4 + SUMIF(H13:H13, ">1") / 4 + SUMIF(J13:J13, ">1") / 4 + SUMIF(L13:L13, ">1") / 4 -> 87 | AL13: =SUMIF(M13:M13, ">=70") / 4 +SUMIF(O13:O13, ">=70") / 4 +SUMIF(Q13:Q13, ">=70") / 4 +SUMIF(S13:S13, ">=70") / 4 + SUMIF(N13:N13, ">1") / 4 + SUMIF(P13:P13, ">1") / 4 + SUMIF(R13:R13, ">1") / 4 + SUMIF(T13:T13, ">1") / 4 -> 89 | AM13: =SUMIF(U13:U13, ">=70") / 4 +SUMIF(W13:W13, ">=70") / 4 +SUMIF(Y13:Y13, ">=70") / 4 +SUMIF(AA13:AA13, ">=70") / 4 + SUMIF(V13:V13, ">1") / 4 + SUMIF(X13:X13, ">1") / 4 + SUMIF(Z13:Z13, ">1") / 4 + SUMIF(AB13:AB13, ">1") / 4 -> 86 | AN13: =SUMIF(AC13:AC13, ">=65") / 4 +SUMIF(AE13:AE13, ">=65") / 4 +SUMIF(AG13:AG13, ">=65") / 4 +SUMIF(AI13:AI13, ">=65") / 4 + SUMIF(AD13:AD13, ">1") / 4 + SUMIF(AF13:AF13, ">1") / 4 + SUMIF(AH13:AH13, ">1") / 4 + SUMIF(AJ13:AJ13, ">1") / 4 -> 90 | AO13: =AVERAGE(AK13:AN13) -> 88 | AR13: =IF(AO13<70, AO13*0.5, "") | AT13: =AS13*50% -> 0 | AU13: =IF(AS13<>"", IF(AR13="","",AR13+AT13), "") | AV13: =IF(AU13 < 70, AR13*30%, "") | AX13: =AW13*70% -> 0 | AY13: =IF(AW13<>"", IF(AV13="", "", AV13+AX13), "") | AZ13: =IF(AND(AU13<70, AY13<70), AO13, "") | BB13: =IF(AW13<>"", IF(AY13>=70, AY13, IF(AZ13+BA13>=70, AZ13+BA13, "")), IF(AS13<>"", IF(AU13>=70, AU13, ""), IF(AO13>=70, AO13, ""))) -> 88 | BC13: =IF(AW13<>"", IF(AY13<70, IF(AZ13+BA13<70, AZ13+BA13, ""), ""), IF(AS13<>"", IF(AU13<70, AU13, ""), IF(AO13<70, AO13, ""))) | BE13: =SUM(E13+M13+U13+AC13)/4 -> 87 | BF13: =SUM(G13+O13+W13+AE13)/4 -> 89 | BG13: =SUM(I13+Q13+Y13+AG13)/4 -> 86 | BH13: =SUM(K13+S13+AA13+AI13)/4 -> 90 | BI13: =AVERAGE(BE13:BH13) -> 88
A14: 4 | B14: 1A-A-04 | C14: WISLINE | D14: BERNADEAU | E14: 85 | G14: 88 | I14: 86 | K14: 89 | M14: 89 | O14: 90 | Q14: 88 | S14: 89 | U14: 86 | W14: 87 | Y14: 85 | AA14: 86 | AC14: 88 | AE14: 91 | AG14: 89 | AI14: 92 | AK14: =SUMIF(E14:E14, ">=70") / 4 +SUMIF(G14:G14, ">=70") / 4 +SUMIF(I14:I14, ">=70") / 4 +SUMIF(K14:K14, ">=70") / 4 + SUMIF(F14:F14, ">1") / 4 + SUMIF(H14:H14, ">1") / 4 + SUMIF(J14:J14, ">1") / 4 + SUMIF(L14:L14, ">1") / 4 -> 87 | AL14: =SUMIF(M14:M14, ">=70") / 4 +SUMIF(O14:O14, ">=70") / 4 +SUMIF(Q14:Q14, ">=70") / 4 +SUMIF(S14:S14, ">=70") / 4 + SUMIF(N14:N14, ">1") / 4 + SUMIF(P14:P14, ">1") / 4 + SUMIF(R14:R14, ">1") / 4 + SUMIF(T14:T14, ">1") / 4 -> 89 | AM14: =SUMIF(U14:U14, ">=70") / 4 +SUMIF(W14:W14, ">=70") / 4 +SUMIF(Y14:Y14, ">=70") / 4 +SUMIF(AA14:AA14, ">=70") / 4 + SUMIF(V14:V14, ">1") / 4 + SUMIF(X14:X14, ">1") / 4 + SUMIF(Z14:Z14, ">1") / 4 + SUMIF(AB14:AB14, ">1") / 4 -> 86 | AN14: =SUMIF(AC14:AC14, ">=65") / 4 +SUMIF(AE14:AE14, ">=65") / 4 +SUMIF(AG14:AG14, ">=65") / 4 +SUMIF(AI14:AI14, ">=65") / 4 + SUMIF(AD14:AD14, ">1") / 4 + SUMIF(AF14:AF14, ">1") / 4 + SUMIF(AH14:AH14, ">1") / 4 + SUMIF(AJ14:AJ14, ">1") / 4 -> 90 | AO14: =AVERAGE(AK14:AN14) -> 88 | AR14: =IF(AO14<70, AO14*0.5, "") | AT14: =AS14*50% -> 0 | AU14: =IF(AS14<>"", IF(AR14="","",AR14+AT14), "") | AV14: =IF(AU14 < 70, AR14*30%, "") | AX14: =AW14*70% -> 0 | AY14: =IF(AW14<>"", IF(AV14="", "", AV14+AX14), "") | AZ14: =IF(AND(AU14<70, AY14<70), AO14, "") | BB14: =IF(AW14<>"", IF(AY14>=70, AY14, IF(AZ14+BA14>=70, AZ14+BA14, "")), IF(AS14<>"", IF(AU14>=70, AU14, ""), IF(AO14>=70, AO14, ""))) -> 88 | BC14: =IF(AW14<>"", IF(AY14<70, IF(AZ14+BA14<70, AZ14+BA14, ""), ""), IF(AS14<>"", IF(AU14<70, AU14, ""), IF(AO14<70, AO14, ""))) | BE14: =SUM(E14+M14+U14+AC14)/4 -> 87 | BF14: =SUM(G14+O14+W14+AE14)/4 -> 89 | BG14: =SUM(I14+Q14+Y14+AG14)/4 -> 87 | BH14: =SUM(K14+S14+AA14+AI14)/4 -> 89 | BI14: =AVERAGE(BE14:BH14) -> 88
A15: 5 | B15: 1A-A-05 | C15: LISAIRY | D15: BREA CONTRERA | E15: 75 | G15: 78 | I15: 77 | K15: 74 | M15: 77 | O15: 82 | Q15: 83 | S15: 78 | U15: 84 | W15: 79 | Y15: 82 | AA15: 87 | AC15: 78 | AE15: 81 | AG15: 84 | AI15: 81 | AK15: =SUMIF(E15:E15, ">=70") / 4 +SUMIF(G15:G15, ">=70") / 4 +SUMIF(I15:I15, ">=70") / 4 +SUMIF(K15:K15, ">=70") / 4 + SUMIF(F15:F15, ">1") / 4 + SUMIF(H15:H15, ">1") / 4 + SUMIF(J15:J15, ">1") / 4 + SUMIF(L15:L15, ">1") / 4 -> 76 | AL15: =SUMIF(M15:M15, ">=70") / 4 +SUMIF(O15:O15, ">=70") / 4 +SUMIF(Q15:Q15, ">=70") / 4 +SUMIF(S15:S15, ">=70") / 4 + SUMIF(N15:N15, ">1") / 4 + SUMIF(P15:P15, ">1") / 4 + SUMIF(R15:R15, ">1") / 4 + SUMIF(T15:T15, ">1") / 4 -> 80 | AM15: =SUMIF(U15:U15, ">=70") / 4 +SUMIF(W15:W15, ">=70") / 4 +SUMIF(Y15:Y15, ">=70") / 4 +SUMIF(AA15:AA15, ">=70") / 4 + SUMIF(V15:V15, ">1") / 4 + SUMIF(X15:X15, ">1") / 4 + SUMIF(Z15:Z15, ">1") / 4 + SUMIF(AB15:AB15, ">1") / 4 -> 83 | AN15: =SUMIF(AC15:AC15, ">=65") / 4 +SUMIF(AE15:AE15, ">=65") / 4 +SUMIF(AG15:AG15, ">=65") / 4 +SUMIF(AI15:AI15, ">=65") / 4 + SUMIF(AD15:AD15, ">1") / 4 + SUMIF(AF15:AF15, ">1") / 4 + SUMIF(AH15:AH15, ">1") / 4 + SUMIF(AJ15:AJ15, ">1") / 4 -> 81 | AO15: =AVERAGE(AK15:AN15) -> 80 | AR15: =IF(AO15<70, AO15*0.5, "") | AT15: =AS15*50% -> 0 | AU15: =IF(AS15<>"", IF(AR15="","",AR15+AT15), "") | AV15: =IF(AU15 < 70, AR15*30%, "") | AX15: =AW15*70% -> 0 | AY15: =IF(AW15<>"", IF(AV15="", "", AV15+AX15), "") | AZ15: =IF(AND(AU15<70, AY15<70), AO15, "") | BB15: =IF(AW15<>"", IF(AY15>=70, AY15, IF(AZ15+BA15>=70, AZ15+BA15, "")), IF(AS15<>"", IF(AU15>=70, AU15, ""), IF(AO15>=70, AO15, ""))) -> 80 | BC15: =IF(AW15<>"", IF(AY15<70, IF(AZ15+BA15<70, AZ15+BA15, ""), ""), IF(AS15<>"", IF(AU15<70, AU15, ""), IF(AO15<70, AO15, ""))) | BE15: =SUM(E15+M15+U15+AC15)/4 -> 78.5 | BF15: =SUM(G15+O15+W15+AE15)/4 -> 80 | BG15: =SUM(I15+Q15+Y15+AG15)/4 -> 81.5 | BH15: =SUM(K15+S15+AA15+AI15)/4 -> 80 | BI15: =AVERAGE(BE15:BH15) -> 80
A16: 6 | B16: 1A-A-06 | C16: RODENEL | D16: CACEUS DABOIS | E16: 75 | G16: 78 | I16: 77 | K16: 74 | M16: 77 | O16: 82 | Q16: 83 | S16: 78 | U16: 84 | W16: 79 | Y16: 82 | AA16: 87 | AC16: 78 | AE16: 81 | AG16: 84 | AI16: 81 | AK16: =SUMIF(E16:E16, ">=70") / 4 +SUMIF(G16:G16, ">=70") / 4 +SUMIF(I16:I16, ">=70") / 4 +SUMIF(K16:K16, ">=70") / 4 + SUMIF(F16:F16, ">1") / 4 + SUMIF(H16:H16, ">1") / 4 + SUMIF(J16:J16, ">1") / 4 + SUMIF(L16:L16, ">1") / 4 -> 76 | AL16: =SUMIF(M16:M16, ">=70") / 4 +SUMIF(O16:O16, ">=70") / 4 +SUMIF(Q16:Q16, ">=70") / 4 +SUMIF(S16:S16, ">=70") / 4 + SUMIF(N16:N16, ">1") / 4 + SUMIF(P16:P16, ">1") / 4 + SUMIF(R16:R16, ">1") / 4 + SUMIF(T16:T16, ">1") / 4 -> 80 | AM16: =SUMIF(U16:U16, ">=70") / 4 +SUMIF(W16:W16, ">=70") / 4 +SUMIF(Y16:Y16, ">=70") / 4 +SUMIF(AA16:AA16, ">=70") / 4 + SUMIF(V16:V16, ">1") / 4 + SUMIF(X16:X16, ">1") / 4 + SUMIF(Z16:Z16, ">1") / 4 + SUMIF(AB16:AB16, ">1") / 4 -> 83 | AN16: =SUMIF(AC16:AC16, ">=65") / 4 +SUMIF(AE16:AE16, ">=65") / 4 +SUMIF(AG16:AG16, ">=65") / 4 +SUMIF(AI16:AI16, ">=65") / 4 + SUMIF(AD16:AD16, ">1") / 4 + SUMIF(AF16:AF16, ">1") / 4 + SUMIF(AH16:AH16, ">1") / 4 + SUMIF(AJ16:AJ16, ">1") / 4 -> 81 | AO16: =AVERAGE(AK16:AN16) -> 80 | AR16: =IF(AO16<70, AO16*0.5, "") | AT16: =AS16*50% -> 0 | AU16: =IF(AS16<>"", IF(AR16="","",AR16+AT16), "") | AV16: =IF(AU16 < 70, AR16*30%, "") | AX16: =AW16*70% -> 0 | AY16: =IF(AW16<>"", IF(AV16="", "", AV16+AX16), "") | AZ16: =IF(AND(AU16<70, AY16<70), AO16, "") | BB16: =IF(AW16<>"", IF(AY16>=70, AY16, IF(AZ16+BA16>=70, AZ16+BA16, "")), IF(AS16<>"", IF(AU16>=70, AU16, ""), IF(AO16>=70, AO16, ""))) -> 80 | BC16: =IF(AW16<>"", IF(AY16<70, IF(AZ16+BA16<70, AZ16+BA16, ""), ""), IF(AS16<>"", IF(AU16<70, AU16, ""), IF(AO16<70, AO16, ""))) | BE16: =SUM(E16+M16+U16+AC16)/4 -> 78.5 | BF16: =SUM(G16+O16+W16+AE16)/4 -> 80 | BG16: =SUM(I16+Q16+Y16+AG16)/4 -> 81.5 | BH16: =SUM(K16+S16+AA16+AI16)/4 -> 80 | BI16: =AVERAGE(BE16:BH16) -> 80
A17: 7 | B17: 1A-A-07 | C17: MARY LUZ | D17: CAMILO ESPINAL | E17: 82 | G17: 86 | I17: 80 | K17: 84 | M17: 84 | O17: 88 | Q17: 90 | S17: 86 | U17: 80 | W17: 80 | Y17: 72 | AA17: 72 | AC17: 86 | AE17: 89 | AG17: 76 | AI17: 75 | AK17: =SUMIF(E17:E17, ">=70") / 4 +SUMIF(G17:G17, ">=70") / 4 +SUMIF(I17:I17, ">=70") / 4 +SUMIF(K17:K17, ">=70") / 4 + SUMIF(F17:F17, ">1") / 4 + SUMIF(H17:H17, ">1") / 4 + SUMIF(J17:J17, ">1") / 4 + SUMIF(L17:L17, ">1") / 4 -> 83 | AL17: =SUMIF(M17:M17, ">=70") / 4 +SUMIF(O17:O17, ">=70") / 4 +SUMIF(Q17:Q17, ">=70") / 4 +SUMIF(S17:S17, ">=70") / 4 + SUMIF(N17:N17, ">1") / 4 + SUMIF(P17:P17, ">1") / 4 + SUMIF(R17:R17, ">1") / 4 + SUMIF(T17:T17, ">1") / 4 -> 87 | AM17: =SUMIF(U17:U17, ">=70") / 4 +SUMIF(W17:W17, ">=70") / 4 +SUMIF(Y17:Y17, ">=70") / 4 +SUMIF(AA17:AA17, ">=70") / 4 + SUMIF(V17:V17, ">1") / 4 + SUMIF(X17:X17, ">1") / 4 + SUMIF(Z17:Z17, ">1") / 4 + SUMIF(AB17:AB17, ">1") / 4 -> 76 | AN17: =SUMIF(AC17:AC17, ">=65") / 4 +SUMIF(AE17:AE17, ">=65") / 4 +SUMIF(AG17:AG17, ">=65") / 4 +SUMIF(AI17:AI17, ">=65") / 4 + SUMIF(AD17:AD17, ">1") / 4 + SUMIF(AF17:AF17, ">1") / 4 + SUMIF(AH17:AH17, ">1") / 4 + SUMIF(AJ17:AJ17, ">1") / 4 -> 81.5 | AO17: =AVERAGE(AK17:AN17) -> 81.875 | AR17: =IF(AO17<70, AO17*0.5, "") | AT17: =AS17*50% -> 0 | AU17: =IF(AS17<>"", IF(AR17="","",AR17+AT17), "") | AV17: =IF(AU17 < 70, AR17*30%, "") | AX17: =AW17*70% -> 0 | AY17: =IF(AW17<>"", IF(AV17="", "", AV17+AX17), "") | AZ17: =IF(AND(AU17<70, AY17<70), AO17, "") | BB17: =IF(AW17<>"", IF(AY17>=70, AY17, IF(AZ17+BA17>=70, AZ17+BA17, "")), IF(AS17<>"", IF(AU17>=70, AU17, ""), IF(AO17>=70, AO17, ""))) -> 81.875 | BC17: =IF(AW17<>"", IF(AY17<70, IF(AZ17+BA17<70, AZ17+BA17, ""), ""), IF(AS17<>"", IF(AU17<70, AU17, ""), IF(AO17<70, AO17, ""))) | BE17: =SUM(E17+M17+U17+AC17)/4 -> 83 | BF17: =SUM(G17+O17+W17+AE17)/4 -> 85.75 | BG17: =SUM(I17+Q17+Y17+AG17)/4 -> 79.5 | BH17: =SUM(K17+S17+AA17+AI17)/4 -> 79.25 | BI17: =AVERAGE(BE17:BH17) -> 81.875
A18: 8 | B18: 1A-A-08 | C18: ANA ROSA | D18: CARRION VILORIO | E18: 81 | G18: 85 | I18: 80 | K18: 82 | M18: 83 | O18: 87 | Q18: 85 | S18: 89 | U18: 84 | W18: 88 | Y18: 74 | AA18: 81 | AC18: 80 | AE18: 84 | AG18: 89 | AI18: 87 | AK18: =SUMIF(E18:E18, ">=70") / 4 +SUMIF(G18:G18, ">=70") / 4 +SUMIF(I18:I18, ">=70") / 4 +SUMIF(K18:K18, ">=70") / 4 + SUMIF(F18:F18, ">1") / 4 + SUMIF(H18:H18, ">1") / 4 + SUMIF(J18:J18, ">1") / 4 + SUMIF(L18:L18, ">1") / 4 -> 82 | AL18: =SUMIF(M18:M18, ">=70") / 4 +SUMIF(O18:O18, ">=70") / 4 +SUMIF(Q18:Q18, ">=70") / 4 +SUMIF(S18:S18, ">=70") / 4 + SUMIF(N18:N18, ">1") / 4 + SUMIF(P18:P18, ">1") / 4 + SUMIF(R18:R18, ">1") / 4 + SUMIF(T18:T18, ">1") / 4 -> 86 | AM18: =SUMIF(U18:U18, ">=70") / 4 +SUMIF(W18:W18, ">=70") / 4 +SUMIF(Y18:Y18, ">=70") / 4 +SUMIF(AA18:AA18, ">=70") / 4 + SUMIF(V18:V18, ">1") / 4 + SUMIF(X18:X18, ">1") / 4 + SUMIF(Z18:Z18, ">1") / 4 + SUMIF(AB18:AB18, ">1") / 4 -> 81.75 | AN18: =SUMIF(AC18:AC18, ">=65") / 4 +SUMIF(AE18:AE18, ">=65") / 4 +SUMIF(AG18:AG18, ">=65") / 4 +SUMIF(AI18:AI18, ">=65") / 4 + SUMIF(AD18:AD18, ">1") / 4 + SUMIF(AF18:AF18, ">1") / 4 + SUMIF(AH18:AH18, ">1") / 4 + SUMIF(AJ18:AJ18, ">1") / 4 -> 85 | AO18: =AVERAGE(AK18:AN18) -> 83.6875 | AR18: =IF(AO18<70, AO18*0.5, "") | AT18: =AS18*50% -> 0 | AU18: =IF(AS18<>"", IF(AR18="","",AR18+AT18), "") | AV18: =IF(AU18 < 70, AR18*30%, "") | AX18: =AW18*70% -> 0 | AY18: =IF(AW18<>"", IF(AV18="", "", AV18+AX18), "") | AZ18: =IF(AND(AU18<70, AY18<70), AO18, "") | BB18: =IF(AW18<>"", IF(AY18>=70, AY18, IF(AZ18+BA18>=70, AZ18+BA18, "")), IF(AS18<>"", IF(AU18>=70, AU18, ""), IF(AO18>=70, AO18, ""))) -> 83.6875 | BC18: =IF(AW18<>"", IF(AY18<70, IF(AZ18+BA18<70, AZ18+BA18, ""), ""), IF(AS18<>"", IF(AU18<70, AU18, ""), IF(AO18<70, AO18, ""))) | BE18: =SUM(E18+M18+U18+AC18)/4 -> 82 | BF18: =SUM(G18+O18+W18+AE18)/4 -> 86 | BG18: =SUM(I18+Q18+Y18+AG18)/4 -> 82 | BH18: =SUM(K18+S18+AA18+AI18)/4 -> 84.75 | BI18: =AVERAGE(BE18:BH18) -> 83.6875
A19: 9 | B19: 1A-A-09 | C19: WILDIANA | D19: CASSEUS | E19: 86 | G19: 88 | I19: 85 | K19: 89 | M19: 88 | O19: 90 | Q19: 87 | S19: 91 | U19: 85 | W19: 87 | Y19: 84 | AA19: 88 | AC19: 89 | AE19: 91 | AG19: 88 | AI19: 92 | AK19: =SUMIF(E19:E19, ">=70") / 4 +SUMIF(G19:G19, ">=70") / 4 +SUMIF(I19:I19, ">=70") / 4 +SUMIF(K19:K19, ">=70") / 4 + SUMIF(F19:F19, ">1") / 4 + SUMIF(H19:H19, ">1") / 4 + SUMIF(J19:J19, ">1") / 4 + SUMIF(L19:L19, ">1") / 4 -> 87 | AL19: =SUMIF(M19:M19, ">=70") / 4 +SUMIF(O19:O19, ">=70") / 4 +SUMIF(Q19:Q19, ">=70") / 4 +SUMIF(S19:S19, ">=70") / 4 + SUMIF(N19:N19, ">1") / 4 + SUMIF(P19:P19, ">1") / 4 + SUMIF(R19:R19, ">1") / 4 + SUMIF(T19:T19, ">1") / 4 -> 89 | AM19: =SUMIF(U19:U19, ">=70") / 4 +SUMIF(W19:W19, ">=70") / 4 +SUMIF(Y19:Y19, ">=70") / 4 +SUMIF(AA19:AA19, ">=70") / 4 + SUMIF(V19:V19, ">1") / 4 + SUMIF(X19:X19, ">1") / 4 + SUMIF(Z19:Z19, ">1") / 4 + SUMIF(AB19:AB19, ">1") / 4 -> 86 | AN19: =SUMIF(AC19:AC19, ">=65") / 4 +SUMIF(AE19:AE19, ">=65") / 4 +SUMIF(AG19:AG19, ">=65") / 4 +SUMIF(AI19:AI19, ">=65") / 4 + SUMIF(AD19:AD19, ">1") / 4 + SUMIF(AF19:AF19, ">1") / 4 + SUMIF(AH19:AH19, ">1") / 4 + SUMIF(AJ19:AJ19, ">1") / 4 -> 90 | AO19: =AVERAGE(AK19:AN19) -> 88 | AR19: =IF(AO19<70, AO19*0.5, "") | AT19: =AS19*50% -> 0 | AU19: =IF(AS19<>"", IF(AR19="","",AR19+AT19), "") | AV19: =IF(AU19 < 70, AR19*30%, "") | AX19: =AW19*70% -> 0 | AY19: =IF(AW19<>"", IF(AV19="", "", AV19+AX19), "") | AZ19: =IF(AND(AU19<70, AY19<70), AO19, "") | BB19: =IF(AW19<>"", IF(AY19>=70, AY19, IF(AZ19+BA19>=70, AZ19+BA19, "")), IF(AS19<>"", IF(AU19>=70, AU19, ""), IF(AO19>=70, AO19, ""))) -> 88 | BC19: =IF(AW19<>"", IF(AY19<70, IF(AZ19+BA19<70, AZ19+BA19, ""), ""), IF(AS19<>"", IF(AU19<70, AU19, ""), IF(AO19<70, AO19, ""))) | BE19: =SUM(E19+M19+U19+AC19)/4 -> 87 | BF19: =SUM(G19+O19+W19+AE19)/4 -> 89 | BG19: =SUM(I19+Q19+Y19+AG19)/4 -> 86 | BH19: =SUM(K19+S19+AA19+AI19)/4 -> 90 | BI19: =AVERAGE(BE19:BH19) -> 88
A20: 10 | B20: 1A-A-10 | C20: JERVIN | D20: CASTRO ALMONTE | E20: 82 | G20: 86 | I20: 80 | K20: 84 | M20: 84 | O20: 88 | Q20: 90 | S20: 86 | U20: 80 | W20: 80 | Y20: 72 | AA20: 72 | AC20: 86 | AE20: 89 | AG20: 76 | AI20: 75 | AK20: =SUMIF(E20:E20, ">=70") / 4 +SUMIF(G20:G20, ">=70") / 4 +SUMIF(I20:I20, ">=70") / 4 +SUMIF(K20:K20, ">=70") / 4 + SUMIF(F20:F20, ">1") / 4 + SUMIF(H20:H20, ">1") / 4 + SUMIF(J20:J20, ">1") / 4 + SUMIF(L20:L20, ">1") / 4 -> 83 | AL20: =SUMIF(M20:M20, ">=70") / 4 +SUMIF(O20:O20, ">=70") / 4 +SUMIF(Q20:Q20, ">=70") / 4 +SUMIF(S20:S20, ">=70") / 4 + SUMIF(N20:N20, ">1") / 4 + SUMIF(P20:P20, ">1") / 4 + SUMIF(R20:R20, ">1") / 4 + SUMIF(T20:T20, ">1") / 4 -> 87 | AM20: =SUMIF(U20:U20, ">=70") / 4 +SUMIF(W20:W20, ">=70") / 4 +SUMIF(Y20:Y20, ">=70") / 4 +SUMIF(AA20:AA20, ">=70") / 4 + SUMIF(V20:V20, ">1") / 4 + SUMIF(X20:X20, ">1") / 4 + SUMIF(Z20:Z20, ">1") / 4 + SUMIF(AB20:AB20, ">1") / 4 -> 76 | AN20: =SUMIF(AC20:AC20, ">=65") / 4 +SUMIF(AE20:AE20, ">=65") / 4 +SUMIF(AG20:AG20, ">=65") / 4 +SUMIF(AI20:AI20, ">=65") / 4 + SUMIF(AD20:AD20, ">1") / 4 + SUMIF(AF20:AF20, ">1") / 4 + SUMIF(AH20:AH20, ">1") / 4 + SUMIF(AJ20:AJ20, ">1") / 4 -> 81.5 | AO20: =AVERAGE(AK20:AN20) -> 81.875 | AR20: =IF(AO20<70, AO20*0.5, "") | AT20: =AS20*50% -> 0 | AU20: =IF(AS20<>"", IF(AR20="","",AR20+AT20), "") | AV20: =IF(AU20 < 70, AR20*30%, "") | AX20: =AW20*70% -> 0 | AY20: =IF(AW20<>"", IF(AV20="", "", AV20+AX20), "") | AZ20: =IF(AND(AU20<70, AY20<70), AO20, "") | BB20: =IF(AW20<>"", IF(AY20>=70, AY20, IF(AZ20+BA20>=70, AZ20+BA20, "")), IF(AS20<>"", IF(AU20>=70, AU20, ""), IF(AO20>=70, AO20, ""))) -> 81.875 | BC20: =IF(AW20<>"", IF(AY20<70, IF(AZ20+BA20<70, AZ20+BA20, ""), ""), IF(AS20<>"", IF(AU20<70, AU20, ""), IF(AO20<70, AO20, ""))) | BE20: =SUM(E20+M20+U20+AC20)/4 -> 83 | BF20: =SUM(G20+O20+W20+AE20)/4 -> 85.75 | BG20: =SUM(I20+Q20+Y20+AG20)/4 -> 79.5 | BH20: =SUM(K20+S20+AA20+AI20)/4 -> 79.25 | BI20: =AVERAGE(BE20:BH20) -> 81.875
A21: 11 | B21: 1A-A-11 | C21: SONDJY | D21: CESAIRE | E21: 81 | G21: 85 | I21: 80 | K21: 82 | M21: 83 | O21: 87 | Q21: 85 | S21: 89 | U21: 84 | W21: 88 | Y21: 74 | AA21: 81 | AC21: 80 | AE21: 84 | AG21: 89 | AI21: 87 | AK21: =SUMIF(E21:E21, ">=70") / 4 +SUMIF(G21:G21, ">=70") / 4 +SUMIF(I21:I21, ">=70") / 4 +SUMIF(K21:K21, ">=70") / 4 + SUMIF(F21:F21, ">1") / 4 + SUMIF(H21:H21, ">1") / 4 + SUMIF(J21:J21, ">1") / 4 + SUMIF(L21:L21, ">1") / 4 -> 82 | AL21: =SUMIF(M21:M21, ">=70") / 4 +SUMIF(O21:O21, ">=70") / 4 +SUMIF(Q21:Q21, ">=70") / 4 +SUMIF(S21:S21, ">=70") / 4 + SUMIF(N21:N21, ">1") / 4 + SUMIF(P21:P21, ">1") / 4 + SUMIF(R21:R21, ">1") / 4 + SUMIF(T21:T21, ">1") / 4 -> 86 | AM21: =SUMIF(U21:U21, ">=70") / 4 +SUMIF(W21:W21, ">=70") / 4 +SUMIF(Y21:Y21, ">=70") / 4 +SUMIF(AA21:AA21, ">=70") / 4 + SUMIF(V21:V21, ">1") / 4 + SUMIF(X21:X21, ">1") / 4 + SUMIF(Z21:Z21, ">1") / 4 + SUMIF(AB21:AB21, ">1") / 4 -> 81.75 | AN21: =SUMIF(AC21:AC21, ">=65") / 4 +SUMIF(AE21:AE21, ">=65") / 4 +SUMIF(AG21:AG21, ">=65") / 4 +SUMIF(AI21:AI21, ">=65") / 4 + SUMIF(AD21:AD21, ">1") / 4 + SUMIF(AF21:AF21, ">1") / 4 + SUMIF(AH21:AH21, ">1") / 4 + SUMIF(AJ21:AJ21, ">1") / 4 -> 85 | AO21: =AVERAGE(AK21:AN21) -> 83.6875 | AR21: =IF(AO21<70, AO21*0.5, "") | AT21: =AS21*50% -> 0 | AU21: =IF(AS21<>"", IF(AR21="","",AR21+AT21), "") | AV21: =IF(AU21 < 70, AR21*30%, "") | AX21: =AW21*70% -> 0 | AY21: =IF(AW21<>"", IF(AV21="", "", AV21+AX21), "") | AZ21: =IF(AND(AU21<70, AY21<70), AO21, "") | BB21: =IF(AW21<>"", IF(AY21>=70, AY21, IF(AZ21+BA21>=70, AZ21+BA21, "")), IF(AS21<>"", IF(AU21>=70, AU21, ""), IF(AO21>=70, AO21, ""))) -> 83.6875 | BC21: =IF(AW21<>"", IF(AY21<70, IF(AZ21+BA21<70, AZ21+BA21, ""), ""), IF(AS21<>"", IF(AU21<70, AU21, ""), IF(AO21<70, AO21, ""))) | BE21: =SUM(E21+M21+U21+AC21)/4 -> 82 | BF21: =SUM(G21+O21+W21+AE21)/4 -> 86 | BG21: =SUM(I21+Q21+Y21+AG21)/4 -> 82 | BH21: =SUM(K21+S21+AA21+AI21)/4 -> 84.75 | BI21: =AVERAGE(BE21:BH21) -> 83.6875
A22: 12 | B22: 1A-A-12 | C22: ANDERSON | D22: CHARLES | E22: 86 | G22: 88 | I22: 85 | K22: 89 | M22: 88 | O22: 90 | Q22: 87 | S22: 91 | U22: 85 | W22: 87 | Y22: 84 | AA22: 88 | AC22: 89 | AE22: 91 | AG22: 88 | AI22: 92 | AK22: =SUMIF(E22:E22, ">=70") / 4 +SUMIF(G22:G22, ">=70") / 4 +SUMIF(I22:I22, ">=70") / 4 +SUMIF(K22:K22, ">=70") / 4 + SUMIF(F22:F22, ">1") / 4 + SUMIF(H22:H22, ">1") / 4 + SUMIF(J22:J22, ">1") / 4 + SUMIF(L22:L22, ">1") / 4 -> 87 | AL22: =SUMIF(M22:M22, ">=70") / 4 +SUMIF(O22:O22, ">=70") / 4 +SUMIF(Q22:Q22, ">=70") / 4 +SUMIF(S22:S22, ">=70") / 4 + SUMIF(N22:N22, ">1") / 4 + SUMIF(P22:P22, ">1") / 4 + SUMIF(R22:R22, ">1") / 4 + SUMIF(T22:T22, ">1") / 4 -> 89 | AM22: =SUMIF(U22:U22, ">=70") / 4 +SUMIF(W22:W22, ">=70") / 4 +SUMIF(Y22:Y22, ">=70") / 4 +SUMIF(AA22:AA22, ">=70") / 4 + SUMIF(V22:V22, ">1") / 4 + SUMIF(X22:X22, ">1") / 4 + SUMIF(Z22:Z22, ">1") / 4 + SUMIF(AB22:AB22, ">1") / 4 -> 86 | AN22: =SUMIF(AC22:AC22, ">=65") / 4 +SUMIF(AE22:AE22, ">=65") / 4 +SUMIF(AG22:AG22, ">=65") / 4 +SUMIF(AI22:AI22, ">=65") / 4 + SUMIF(AD22:AD22, ">1") / 4 + SUMIF(AF22:AF22, ">1") / 4 + SUMIF(AH22:AH22, ">1") / 4 + SUMIF(AJ22:AJ22, ">1") / 4 -> 90 | AO22: =AVERAGE(AK22:AN22) -> 88 | AR22: =IF(AO22<70, AO22*0.5, "") | AT22: =AS22*50% -> 0 | AU22: =IF(AS22<>"", IF(AR22="","",AR22+AT22), "") | AV22: =IF(AU22 < 70, AR22*30%, "") | AX22: =AW22*70% -> 0 | AY22: =IF(AW22<>"", IF(AV22="", "", AV22+AX22), "") | AZ22: =IF(AND(AU22<70, AY22<70), AO22, "") | BB22: =IF(AW22<>"", IF(AY22>=70, AY22, IF(AZ22+BA22>=70, AZ22+BA22, "")), IF(AS22<>"", IF(AU22>=70, AU22, ""), IF(AO22>=70, AO22, ""))) -> 88 | BC22: =IF(AW22<>"", IF(AY22<70, IF(AZ22+BA22<70, AZ22+BA22, ""), ""), IF(AS22<>"", IF(AU22<70, AU22, ""), IF(AO22<70, AO22, ""))) | BE22: =SUM(E22+M22+U22+AC22)/4 -> 87 | BF22: =SUM(G22+O22+W22+AE22)/4 -> 89 | BG22: =SUM(I22+Q22+Y22+AG22)/4 -> 86 | BH22: =SUM(K22+S22+AA22+AI22)/4 -> 90 | BI22: =AVERAGE(BE22:BH22) -> 88
A23: 13 | B23: 1A-A-13 | C23: SALOMON MANUEL | D23: DE JESUS MANZUETA | E23: 75 | G23: 78 | I23: 77 | K23: 74 | M23: 77 | O23: 82 | Q23: 83 | S23: 78 | U23: 84 | W23: 79 | Y23: 82 | AA23: 87 | AC23: 78 | AE23: 81 | AG23: 84 | AI23: 81 | AK23: =SUMIF(E23:E23, ">=70") / 4 +SUMIF(G23:G23, ">=70") / 4 +SUMIF(I23:I23, ">=70") / 4 +SUMIF(K23:K23, ">=70") / 4 + SUMIF(F23:F23, ">1") / 4 + SUMIF(H23:H23, ">1") / 4 + SUMIF(J23:J23, ">1") / 4 + SUMIF(L23:L23, ">1") / 4 -> 76 | AL23: =SUMIF(M23:M23, ">=70") / 4 +SUMIF(O23:O23, ">=70") / 4 +SUMIF(Q23:Q23, ">=70") / 4 +SUMIF(S23:S23, ">=70") / 4 + SUMIF(N23:N23, ">1") / 4 + SUMIF(P23:P23, ">1") / 4 + SUMIF(R23:R23, ">1") / 4 + SUMIF(T23:T23, ">1") / 4 -> 80 | AM23: =SUMIF(U23:U23, ">=70") / 4 +SUMIF(W23:W23, ">=70") / 4 +SUMIF(Y23:Y23, ">=70") / 4 +SUMIF(AA23:AA23, ">=70") / 4 + SUMIF(V23:V23, ">1") / 4 + SUMIF(X23:X23, ">1") / 4 + SUMIF(Z23:Z23, ">1") / 4 + SUMIF(AB23:AB23, ">1") / 4 -> 83 | AN23: =SUMIF(AC23:AC23, ">=65") / 4 +SUMIF(AE23:AE23, ">=65") / 4 +SUMIF(AG23:AG23, ">=65") / 4 +SUMIF(AI23:AI23, ">=65") / 4 + SUMIF(AD23:AD23, ">1") / 4 + SUMIF(AF23:AF23, ">1") / 4 + SUMIF(AH23:AH23, ">1") / 4 + SUMIF(AJ23:AJ23, ">1") / 4 -> 81 | AO23: =AVERAGE(AK23:AN23) -> 80 | AR23: =IF(AO23<70, AO23*0.5, "") | AT23: =AS23*50% -> 0 | AU23: =IF(AS23<>"", IF(AR23="","",AR23+AT23), "") | AV23: =IF(AU23 < 70, AR23*30%, "") | AX23: =AW23*70% -> 0 | AY23: =IF(AW23<>"", IF(AV23="", "", AV23+AX23), "") | AZ23: =IF(AND(AU23<70, AY23<70), AO23, "") | BB23: =IF(AW23<>"", IF(AY23>=70, AY23, IF(AZ23+BA23>=70, AZ23+BA23, "")), IF(AS23<>"", IF(AU23>=70, AU23, ""), IF(AO23>=70, AO23, ""))) -> 80 | BC23: =IF(AW23<>"", IF(AY23<70, IF(AZ23+BA23<70, AZ23+BA23, ""), ""), IF(AS23<>"", IF(AU23<70, AU23, ""), IF(AO23<70, AO23, ""))) | BE23: =SUM(E23+M23+U23+AC23)/4 -> 78.5 | BF23: =SUM(G23+O23+W23+AE23)/4 -> 80 | BG23: =SUM(I23+Q23+Y23+AG23)/4 -> 81.5 | BH23: =SUM(K23+S23+AA23+AI23)/4 -> 80 | BI23: =AVERAGE(BE23:BH23) -> 80
... A55: 45 | B55: 1A-A-45 | C55: RANYELINA | D55: SINE | E55: 75 | G55: 78 | I55: 77 | K55: 74 | M55: 77 | O55: 82 | Q55: 83 | S55: 78 | U55: 84 | W55: 79 | Y55: 82 | AA55: 87 | AC55: 78 | AE55: 81 | AG55: 84 | AI55: 81 | AK55: =SUMIF(E55:E55, ">=70") / 4 +SUMIF(G55:G55, ">=70") / 4 +SUMIF(I55:I55, ">=70") / 4 +SUMIF(K55:K55, ">=70") / 4 + SUMIF(F55:F55, ">1") / 4 + SUMIF(H55:H55, ">1") / 4 + SUMIF(J55:J55, ">1") / 4 + SUMIF(L55:L55, ">1") / 4 -> 76 | AL55: =SUMIF(M55:M55, ">=70") / 4 +SUMIF(O55:O55, ">=70") / 4 +SUMIF(Q55:Q55, ">=70") / 4 +SUMIF(S55:S55, ">=70") / 4 + SUMIF(N55:N55, ">1") / 4 + SUMIF(P55:P55, ">1") / 4 + SUMIF(R55:R55, ">1") / 4 + SUMIF(T55:T55, ">1") / 4 -> 80 | AM55: =SUMIF(U55:U55, ">=70") / 4 +SUMIF(W55:W55, ">=70") / 4 +SUMIF(Y55:Y55, ">=70") / 4 +SUMIF(AA55:AA55, ">=70") / 4 + SUMIF(V55:V55, ">1") / 4 + SUMIF(X55:X55, ">1") / 4 + SUMIF(Z55:Z55, ">1") / 4 + SUMIF(AB55:AB55, ">1") / 4 -> 83 | AN55: =SUMIF(AC55:AC55, ">=65") / 4 +SUMIF(AE55:AE55, ">=65") / 4 +SUMIF(AG55:AG55, ">=65") / 4 +SUMIF(AI55:AI55, ">=65") / 4 + SUMIF(AD55:AD55, ">1") / 4 + SUMIF(AF55:AF55, ">1") / 4 + SUMIF(AH55:AH55, ">1") / 4 + SUMIF(AJ55:AJ55, ">1") / 4 -> 81 | AO55: =AVERAGE(AK55:AN55) -> 80 | AR55: =IF(AO55<70, AO55*0.5, "") | AT55: =AS55*50% -> 0 | AU55: =IF(AS55<>"", IF(AR55="","",AR55+AT55), "") | AV55: =IF(AU55 < 70, AR55*30%, "") | AX55: =AW55*70% -> 0 | AY55: =IF(AW55<>"", IF(AV55="", "", AV55+AX55), "") | AZ55: =IF(AND(AU55<70, AY55<70), AO55, "") | BB55: =IF(AW55<>"", IF(AY55>=70, AY55, IF(AZ55+BA55>=70, AZ55+BA55, "")), IF(AS55<>"", IF(AU55>=70, AU55, ""), IF(AO55>=70, AO55, ""))) -> 80 | BC55: =IF(AW55<>"", IF(AY55<70, IF(AZ55+BA55<70, AZ55+BA55, ""), ""), IF(AS55<>"", IF(AU55<70, AU55, ""), IF(AO55<70, AO55, ""))) | BE55: =SUM(E55+M55+U55+AC55)/4 -> 78.5 | BF55: =SUM(G55+O55+W55+AE55)/4 -> 80 | BG55: =SUM(I55+Q55+Y55+AG55)/4 -> 81.5 | BH55: =SUM(K55+S55+AA55+AI55)/4 -> 80 | BI55: =AVERAGE(BE55:BH55) -> 80

Sheet MATEMATICA
E7: CALCULO DE NOTAS | AO7: Calificacion Final | AP7: % DE ASISTENCIA ANUAL | AR7: CALIFICACION COMPLETIVA | AV7: CALIFICACION EXTRAORDINARIA | AZ7: EVALUACION ESPECIAL | BB7: SITUACIONFINAL EN LA ASIGNATURA
A9: NO | B9: ID | C9: NOMBRES | D9: APELLIDOS | E9: CE - LE1 | M9: CE - LE2, LE3 | U9: CE - LE4, LE6 | AC9: CE - LE5, LE7 | AK9: PCP 1 | AL9: PCP 2 | AM9: PCP 3 | AN9: PCP 4 | AR9: 50% C.F | AS9: C.E.C. | AT9: 50% C.E.C. | AU9: C.C.F | AV9: 30% C.F. | AW9: C.E.EX | AX9: 70% C.E.EX | AY9: C.EX.F | AZ9: C.F. | BA9: C.E. | BB9: A | BC9: R
E10: P1 | F10: RP1 | G10: P2 | H10: RP2 | I10: P3 | J10: RP3 | K10: P4 | L10: RP4 | M10: P1 | N10: RP1 | O10: P2 | P10: RP2 | Q10: P3 | R10: RP3 | S10: P4 | T10: RP4 | U10: P1 | V10: RP1 | W10: P2 | X10: RP3 | Y10: P3 | Z10: RP4 | AA10: P4 | AB10: RP4 | AC10: P1 | AD10: RP1 | AE10: P2 | AF10: RP3 | AG10: P3 | AH10: RP4 | AI10: P4 | AJ10: RP4 | BE10: P1 | BF10: P2 | BG10: P3 | BH10: P4 | BI10: C.F
A11: 1 | B11: 1A-A-01 | C11: LUIS ANDRES | D11: ADAMES COLON | E11: 82 | G11: 86 | I11: 80 | K11: 84 | M11: 84 | O11: 88 | Q11: 90 | S11: 86 | U11: 80 | W11: 80 | Y11: 72 | AA11: 72 | AC11: 86 | AE11: 89 | AG11: 76 | AI11: 75 | AK11: =SUMIF(E11:E11, ">=70") / 4 +SUMIF(G11:G11, ">=70") / 4 +SUMIF(I11:I11, ">=70") / 4 +SUMIF(K11:K11, ">=70") / 4 + SUMIF(F11:F11, ">1") / 4 + SUMIF(H11:H11, ">1") / 4 + SUMIF(J11:J11, ">1") / 4 + SUMIF(L11:L11, ">1") / 4 -> 83 | AL11: =SUMIF(M11:M11, ">=70") / 4 +SUMIF(O11:O11, ">=70") / 4 +SUMIF(Q11:Q11, ">=70") / 4 +SUMIF(S11:S11, ">=70") / 4 + SUMIF(N11:N11, ">1") / 4 + SUMIF(P11:P11, ">1") / 4 + SUMIF(R11:R11, ">1") / 4 + SUMIF(T11:T11, ">1") / 4 -> 87 | AM11: =SUMIF(U11:U11, ">=70") / 4 +SUMIF(W11:W11, ">=70") / 4 +SUMIF(Y11:Y11, ">=70") / 4 +SUMIF(AA11:AA11, ">=70") / 4 + SUMIF(V11:V11, ">1") / 4 + SUMIF(X11:X11, ">1") / 4 + SUMIF(Z11:Z11, ">1") / 4 + SUMIF(AB11:AB11, ">1") / 4 -> 76 | AN11: =SUMIF(AC11:AC11, ">=70") / 4 +SUMIF(AE11:AE11, ">=70") / 4 +SUMIF(AG11:AG11, ">=70") / 4 +SUMIF(AI11:AI11, ">=70") / 4 + SUMIF(AD11:AD11, ">1") / 4 + SUMIF(AF11:AF11, ">1") / 4 + SUMIF(AH11:AH11, ">1") / 4 + SUMIF(AJ11:AJ11, ">1") / 4 -> 81.5 | AO11: =AVERAGE(AK11:AN11) -> 81.875 | AR11: =IF(AO11<70, AO11*0.5, "") | AT11: =AS11*50% -> 0 | AU11: =IF(AS11<>"", IF(AR11="","",AR11+AT11), "") | AV11: =IF(AU11 < 70, AR11*30%, "") | AX11: =AW11*70% -> 0 | AY11: =IF(AW11<>"", IF(AV11="", "", AV11+AX11), "") | AZ11: =IF(AND(AU11<70, AY11<70), AO11, "") | BB11: =IF(AW11<>"", IF(AY11>=70, AY11, IF(AZ11+BA11>=70, AZ11+BA11, "")), IF(AS11<>"", IF(AU11>=70, AU11, ""), IF(AO11>=70, AO11, ""))) -> 81.875 | BC11: =IF(AW11<>"", IF(AY11<70, IF(AZ11+BA11<70, AZ11+BA11, ""), ""), IF(AS11<>"", IF(AU11<70, AU11, ""), IF(AO11<70, AO11, ""))) | BE11: =SUM(E11+M11+U11+AC11)/4 -> 83 | BF11: =SUM(G11+O11+W11+AE11)/4 -> 85.75 | BG11: =SUM(I11+Q11+Y11+AG11)/4 -> 79.5 | BH11: =SUM(K11+S11+AA11+AI11)/4 -> 79.25 | BI11: =AVERAGE(BE11:BH11) -> 81.875
