Workbook

Sheet ESPANOL
E7: CALCULO DE NOTAS | AO7: Calificacion Final | AP7: % DE ASISTENCIA ANUAL | AR7: CALIFICACION COMPLETIVA | AV7: CALIFICACION EXTRAORDINARIA | AZ7: EVALUACION ESPECIAL | BB7: SITUACIONFINAL EN LA ASIGNATURA
A9: NO | B9: ID | C9: NOMBRES | D9: APELLIDOS | E9: CE - LE1 | M9: CE - LE2, LE3 | U9: CE - LE4, LE6 | AC9: CE - LE5, LE7 | AK9: PCP 1 | AL9: PCP 2 | AM9: PCP 3 | AN9: PCP 4 | AR9: 50% C.F | AS9: C.E.C. | AT9: 50% C.E.C. | AU9: C.C.F | AV9: 30% C.F. | AW9: C.E.EX | AX9: 70% C.E.EX | AY9: C.EX.F | AZ9: C.F. | BA9: C.E. | BB9: A | BC9: R
E10: P1 | F10: RP1 | G10: P2 | H10: RP2 | I10: P3 | J10: RP3 | K10: P4 | L10: RP4 | M10: P1 | N10: RP1 | O10: P2 | P10: RP2 | Q10: P3 | R10: RP3 | S10: P4 | T10: RP4 | U10: P1 | V10: RP1 | W10: P2 | X10: RP3 | Y10: P3 | Z10: RP4 | AA10: P4 | AB10: RP4 | AC10: P1 | AD10: RP1 | AE10: P2 | AF10: RP3 | AG10: P3 | AH10: RP4 | AI10: P4 | AJ10: RP4 | BE10: P1 | BF10: P2 | BG10: P3 | BH10: P4 | BI10: C.F
A11: 1 | B11: 2A-D-01 | C11: AMADOR | D11: ABEL JOHAN | AK11: =SUMIF(E11:E11, ">=70") / 4 +SUMIF(G11:G11, ">=70") / 4 +SUMIF(I11:I11, ">=70") / 4 +SUMIF(K11:K11, ">=70") / 4 + SUMIF(F11:F11, ">1") / 4 + SUMIF(H11:H11, ">1") / 4 + SUMIF(J11:J11, ">1") / 4 + SUMIF(L11:L11, ">1") / 4 -> 0 | AL11: =SUMIF(M11:M11, ">=70") / 4 +SUMIF(O11:O11, ">=70") / 4 +SUMIF(Q11:Q11, ">=70") / 4 +SUMIF(S11:S11, ">=70") / 4 + SUMIF(N11:N11, ">1") / 4 + SUMIF(P11:P11, ">1") / 4 + SUMIF(R11:R11, ">1") / 4 + SUMIF(T11:T11, ">1") / 4 -> 0 | AM11: =SUMIF(U11:U11, ">=70") / 4 +SUMIF(W11:W11, ">=70") / 4 +SUMIF(Y11:Y11, ">=70") / 4 +SUMIF(AA11:AA11, ">=70") / 4 + SUMIF(V11:V11, ">1") / 4 + SUMIF(X11:X11, ">1") / 4 + SUMIF(Z11:Z11, ">1") / 4 + SUMIF(AB11:AB11, ">1") / 4 -> 0 | AN11: =SUMIF(AC11:AC11, ">=70") / 4 +SUMIF(AE11:AE11, ">=70") / 4 +SUMIF(AG11:AG11, ">=70") / 4 +SUMIF(AI11:AI11, ">=70") / 4 + SUMIF(AD11:AD11, ">1") / 4 + SUMIF(AF11:AF11, ">1") / 4 + SUMIF(AH11:AH11, ">1") / 4 + SUMIF(AJ11:AJ11, ">1") / 4 -> 0 | AO11: =AVERAGE(AK11:AN11) -> 0 | AR11: =IF(AO11<70, AO11*0.5, "") -> 0 | AT11: =AS11*50% -> 0 | AU11: =IF(AS11<>"", IF(AR11="","",AR11+AT11), "") | AV11: =IF(AU11 < 70, AR11*30%, "") | AX11: =AW11*70% -> 0 | AY11: =IF(AW11<>"", IF(AV11="", "", AV11+AX11), "") | AZ11: =IF(AND(AU11<70, AY11<70), AO11, "") | BB11: =IF(AW11<>"", IF(AY11>=70, AY11, IF(AZ11+BA11>=70, AZ11+BA11, "")), IF(AS11<>"", IF(AU11>=70, AU11, ""), IF(AO11>=70, AO11, ""))) | BC11: =IF(AW11<>"", IF(AY11<70, IF(AZ11+BA11<70, AZ11+BA11, ""), ""), IF(AS11<>"", IF(AU11<70, AU11, ""), IF(AO11<70, AO11, ""))) -> 0 | BE11: =SUM(E11+M11+U11+AC11)/4 -> 0 | BF11: =SUM(G11+O11+W11+AE11)/4 -> 0 | BG11: =SUM(I11+Q11+Y11+AG11)/4 -> 0 | BH11: =SUM(K11+S11+AA11+AI11)/4 -> 0 | BI11: =AVERAGE(BE11:BH11) -> 0
A12: 2 | B12: 2A-D-02 | C12: AMPARO RODRIGUEZ | D12: ANGEL LUCIANO | AK12: =SUMIF(E12:E12, ">=70") / 4 +SUMIF(G12:G12, ">=70") / 4 +SUMIF(I12:I12, ">=70") / 4 +SUMIF(K12:K12, ">=70") / 4 + SUMIF(F12:F12, ">1") / 4 + SUMIF(H12:H12, ">1") / 4 + SUMIF(J12:J12, ">1") / 4 + SUMIF(L12:L12, ">1") / 4 -> 0 | AL12: =SUMIF(M12:M12, ">=70") / 4 +SUMIF(O12:O12, ">=70") / 4 +SUMIF(Q12:Q12, ">=70") / 4 +SUMIF(S12:S12, ">=70") / 4 + SUMIF(N12:N12, ">1") / 4 + SUMIF(P12:P12, ">1") / 4 + SUMIF(R12:R12, ">1") / 4 + SUMIF(T12:T12, ">1") / 4 -> 0 | AM12: =SUMIF(U12:U12, ">=70") / 4 +SUMIF(W12:W12, ">=70") / 4 +SUMIF(Y12:Y12, ">=70") / 4 +SUMIF(AA12:AA12, ">=70") / 4 + SUMIF(V12:V12, ">1") / 4 + SUMIF(X12:X12, ">1") / 4 + SUMIF(Z12:Z12, ">1") / 4 + SUMIF(AB12:AB12, ">1") / 4 -> 0 | AN12: =SUMIF(AC12:AC12, ">=65") / 4 +SUMIF(AE12:AE12, ">=65") / 4 +SUMIF(AG12:AG12, ">=65") / 4 +SUMIF(AI12:AI12, ">=65") / 4 + SUMIF(AD12:AD12, ">1") / 4 + SUMIF(AF12:AF12, ">1") / 4 + SUMIF(AH12:AH12, ">1") / 4 + SUMIF(AJ12:AJ12, ">1") / 4 -> 0 | AO12: =AVERAGE(AK12:AN12) -> 0 | AR12: =IF(AO12<70, AO12*0.5, "") -> 0 | AT12: =AS12*50% -> 0 | AU12: =IF(AS12<>"", IF(AR12="","",AR12+AT12), "") | AV12: =IF(AU12 < 70, AR12*30%, "") | AX12: =AW12*70% -> 0 | AY12: =IF(AW12<>"", IF(AV12="", "", AV12+AX12), "") | AZ12: =IF(AND(AU12<70, AY12<70), AO12, "") | BB12: =IF(AW12<>"", IF(AY12>=70, AY12, IF(AZ12+BA12>=70, AZ12+BA12, "")), IF(AS12<>"", IF(AU12>=70, AU12, ""), IF(AO12>=70, AO12, ""))) | BC12: =IF(AW12<>"", IF(AY12<70, IF(AZ12+BA12<70, AZ12+BA12, ""), ""), IF(AS12<>"", IF(AU12<70, AU12, ""), IF(AO12<70, AO12, ""))) -> 0 | BE12: =SUM(E12+M12+U12+AC12)/4 -> 0 | BF12: =SUM(G12+O12+W12+AE12)/4 -> 0 | BG12: =SUM(I12+Q12+Y12+AG12)/4 -> 0 | BH12: =SUM(K12+S12+AA12+AI12)/4 -> 0 | BI12: =AVERAGE(BE12:BH12) -> 0
A13: 3 | B13: 2A-D-03 | C13: BISCAINO | D13: STEPHANIE | AK13: =SUMIF(E13:E13, ">=70") / 4 +SUMIF(G13:G13, ">=70") / 4 +SUMIF(I13:I13, ">=70") / 4 +SUMIF(K13:K13, ">=70") / 4 + SUMIF(F13:F13, ">1") / 4 + SUMIF(H13:H13, ">1") / 4 + SUMIF(J13:J13, ">1") / 4 + SUMIF(L13:L13, ">1") / 4 -> 0 | AL13: =SUMIF(M13:M13, ">=70") / 4 +SUMIF(O13:O13, ">=70") / 4 +SUMIF(Q13:Q13, ">=70") / 4 +SUMIF(S13:S13, ">=70") / 4 + SUMIF(N13:N13, ">1") / 4 + SUMIF(P13:P13, ">1") / 4 + SUMIF(R13:R13, ">1") / 4 + SUMIF(T13:T13, ">1") / 4 -> 0 | AM13: =SUMIF(U13:U13, ">=70") / 4 +SUMIF(W13:W13, ">=70") / 4 +SUMIF(Y13:Y13, ">=70") / 4 +SUMIF(AA13:AA13, ">=70") / 4 + SUMIF(V13:V13, ">1") / 4 + SUMIF(X13:X13, ">1") / 4 + SUMIF(Z13:Z13, ">1") / 4 + SUMIF(AB13:AB13, ">1") / 4 -> 0 | AN13: =SUMIF(AC13:AC13, ">=65") / 4 +SUMIF(AE13:AE13, ">=65") / 4 +SUMIF(AG13:AG13, ">=65") / 4 +SUMIF(AI13:AI13, ">=65") / 4 + SUMIF(AD13:AD13, ">1") / 4 + SUMIF(AF13:AF13, ">1") / 4 + SUMIF(AH13:AH13, ">1") / 4 + SUMIF(AJ13:AJ13, ">1") / 4 -> 0 | AO13: =AVERAGE(AK13:AN13) -> 0 | AR13: =IF(AO13<70, AO13*0.5, "") -> 0 | AT13: =AS13*50% -> 0 | AU13: =IF(AS13<>"", IF(AR13="","",AR13+AT13), "") | AV13: =IF(AU13 < 70, AR13*30%, "") | AX13: =AW13*70% -> 0 | AY13: =IF(AW13<>"", IF(AV13="", "", AV13+AX13), "") | AZ13: =IF(AND(AU13<70, AY13<70), AO13, "") | BB13: =IF(AW13<>"", IF(AY13>=70, AY13, IF(AZ13+BA13>=70, AZ13+BA13, "")), IF(AS13<>"", IF(AU13>=70, AU13, ""), IF(AO13>=70, AO13, ""))) | BC13: =IF(AW13<>"", IF(AY13<70, IF(AZ13+BA13<70, AZ13+BA13, ""), ""), IF(AS13<>"", IF(AU13<70, AU13, ""), IF(AO13<70, AO13, ""))) -> 0 | BE13: =SUM(E13+M13+U13+AC13)/4 -> 0 | BF13: =SUM(G13+O13+W13+AE13)/4 -> 0 | BG13: =SUM(I13+Q13+Y13+AG13)/4 -> 0 | BH13: =SUM(K13+S13+AA13+AI13)/4 -> 0 | BI13: =AVERAGE(BE13:BH13) -> 0
A14: 4 | B14: 2A-D-04 | C14: BOZIER CASSENAC | D14: JOEL ENRIQUE | AK14: =SUMIF(E14:E14, ">=70") / 4 +SUMIF(G14:G14, ">=70") / 4 +SUMIF(I14:I14, ">=70") / 4 +SUMIF(K14:K14, ">=70") / 4 + SUMIF(F14:F14, ">1") / 4 + SUMIF(H14:H14, ">1") / 4 + SUMIF(J14:J14, ">1") / 4 + SUMIF(L14:L14, ">1") / 4 -> 0 | AL14: =SUMIF(M14:M14, ">=70") / 4 +SUMIF(O14:O14, ">=70") / 4 +SUMIF(Q14:Q14, ">=70") / 4 +SUMIF(S14:S14, ">=70") / 4 + SUMIF(N14:N14, ">1") / 4 + SUMIF(P14:P14, ">1") / 4 + SUMIF(R14:R14, ">1") / 4 + SUMIF(T14:T14, ">1") / 4 -> 0 | AM14: =SUMIF(U14:U14, ">=70") / 4 +SUMIF(W14:W14, ">=70") / 4 +SUMIF(Y14:Y14, ">=70") / 4 +SUMIF(AA14:AA14, ">=70") / 4 + SUMIF(V14:V14, ">1") / 4 + SUMIF(X14:X14, ">1") / 4 + SUMIF(Z14:Z14, ">1") / 4 + SUMIF(AB14:AB14, ">1") / 4 -> 0 | AN14: =SUMIF(AC14:AC14, ">=65") / 4 +SUMIF(AE14:AE14, ">=65") / 4 +SUMIF(AG14:AG14, ">=65") / 4 +SUMIF(AI14:AI14, ">=65") / 4 + SUMIF(AD14:AD14, ">1") / 4 + SUMIF(AF14:AF14, ">1") / 4 + SUMIF(AH14:AH14, ">1") / 4 + SUMIF(AJ14:AJ14, ">1") / 4 -> 0 | AO14: =AVERAGE(AK14:AN14) -> 0 | AR14: =IF(AO14<70, AO14*0.5, "") -> 0 | AT14: =AS14*50% -> 0 | AU14: =IF(AS14<>"", IF(AR14="","",AR14+AT14), "") | AV14: =IF(AU14 < 70, AR14*30%, "") | AX14: =AW14*70% -> 0 | AY14: =IF(AW14<>"", IF(AV14="", "", AV14+AX14), "") | AZ14: =IF(AND(AU14<70, AY14<70), AO14, "") | BB14: =IF(AW14<>"", IF(AY14>=70, AY14, IF(AZ14+BA14>=70, AZ14+BA14, "")), IF(AS14<>"", IF(AU14>=70, AU14, ""), IF(AO14>=70, AO14, ""))) | BC14: =IF(AW14<>"", IF(AY14<70, IF(AZ14+BA14<70, AZ14+BA14, ""), ""), IF(AS14<>"", IF(AU14<70, AU14, ""), IF(AO14<70, AO14, ""))) -> 0 | BE14: =SUM(E14+M14+U14+AC14)/4 -> 0 | BF14: =SUM(G14+O14+W14+AE14)/4 -> 0 | BG14: =SUM(I14+Q14+Y14+AG14)/4 -> 0 | BH14: =SUM(K14+S14+AA14+AI14)/4 -> 0 | BI14: =AVERAGE(BE14:BH14) -> 0
A15: 5 | B15: 2A-D-05 | C15: BRAZOBAN LORENZO | D15: ROSA IRIS | E15: 80 | G15: 85 | I15: 87 | K15: 89 | M15: 88 | O15: 86 | Q15: 85 | S15: 87 | U15: 86 | W15: 88 | Y15: 90 | AA15: 84 | AC15: 88 | AE15: 90 | AG15: 91 | AI15: 92 | AK15: =SUMIF(E15:E15, ">=70") / 4 +SUMIF(G15:G15, ">=70") / 4 +SUMIF(I15:I15, ">=70") / 4 +SUMIF(K15:K15, ">=70") / 4 + SUMIF(F15:F15, ">1") / 4 + SUMIF(H15:H15, ">1") / 4 + SUMIF(J15:J15, ">1") / 4 + SUMIF(L15:L15, ">1") / 4 -> 85.25 | AL15: =SUMIF(M15:M15, ">=70") / 4 +SUMIF(O15:O15, ">=70") / 4 +SUMIF(Q15:Q15, ">=70") / 4 +SUMIF(S15:S15, ">=70") / 4 + SUMIF(N15:N15, ">1") / 4 + SUMIF(P15:P15, ">1") / 4 + SUMIF(R15:R15, ">1") / 4 + SUMIF(T15:T15, ">1") / 4 -> 86.5 | AM15: =SUMIF(U15:U15, ">=70") / 4 +SUMIF(W15:W15, ">=70") / 4 +SUMIF(Y15:Y15, ">=70") / 4 +SUMIF(AA15:AA15, ">=70") / 4 + SUMIF(V15:V15, ">1") / 4 + SUMIF(X15:X15, ">1") / 4 + SUMIF(Z15:Z15, ">1") / 4 + SUMIF(AB15:AB15, ">1") / 4 -> 87 | AN15: =SUMIF(AC15:AC15, ">=65") / 4 +SUMIF(AE15:AE15, ">=65") / 4 +SUMIF(AG15:AG15, ">=65") / 4 +SUMIF(AI15:AI15, ">=65") / 4 + SUMIF(AD15:AD15, ">1") / 4 + SUMIF(AF15:AF15, ">1") / 4 + SUMIF(AH15:AH15, ">1") / 4 + SUMIF(AJ15:AJ15, ">1") / 4 -> 90.25 | AO15: =AVERAGE(AK15:AN15) -> 87.25 | AR15: =IF(AO15<70, AO15*0.5, "") | AT15: =AS15*50% -> 0 | AU15: =IF(AS15<>"", IF(AR15="","",AR15+AT15), "") | AV15: =IF(AU15 < 70, AR15*30%, "") | AX15: =AW15*70% -> 0 | AY15: =IF(AW15<>"", IF(AV15="", "", AV15+AX15), "") | AZ15: =IF(AND(AU15<70, AY15<70), AO15, "") | BB15: =IF(AW15<>"", IF(AY15>=70, AY15, IF(AZ15+BA15>=70, AZ15+BA15, "")), IF(AS15<>"", IF(AU15>=70, AU15, ""), IF(AO15>=70, AO15, ""))) -> 87.25 | BC15: =IF(AW15<>"", IF(AY15<70, IF(AZ15+BA15<70, AZ15+BA15, ""), ""), IF(AS15<>"", IF(AU15<70, AU15, ""), IF(AO15<70, AO15, ""))) | BE15: =SUM(E15+M15+U15+AC15)/4 -> 85.5 | BF15: =SUM(G15+O15+W15+AE15)/4 -> 87.25 | BG15: =SUM(I15+Q15+Y15+AG15)/4 -> 88.25 | BH15: =SUM(K15+S15+AA15+AI15)/4 -> 88 | BI15: =AVERAGE(BE15:BH15) -> 87.25
A16: 6 | B16: 2A-D-06 | C16: DE JESUS DE LEON | D16: VICTOR MANUEL | AK16: =SUMIF(E16:E16, ">=70") / 4 +SUMIF(G16:G16, ">=70") / 4 +SUMIF(I16:I16, ">=70") / 4 +SUMIF(K16:K16, ">=70") / 4 + SUMIF(F16:F16, ">1") / 4 + SUMIF(H16:H16, ">1") / 4 + SUMIF(J16:J16, ">1") / 4 + SUMIF(L16:L16, ">1") / 4 -> 0 | AL16: =SUMIF(M16:M16, ">=70") / 4 +SUMIF(O16:O16, ">=70") / 4 +SUMIF(Q16:Q16, ">=70") / 4 +SUMIF(S16:S16, ">=70") / 4 + SUMIF(N16:N16, ">1") / 4 + SUMIF(P16:P16, ">1") / 4 + SUMIF(R16:R16, ">1") / 4 + SUMIF(T16:T16, ">1") / 4 -> 0 | AM16: =SUMIF(U16:U16, ">=70") / 4 +SUMIF(W16:W16, ">=70") / 4 +SUMIF(Y16:Y16, ">=70") / 4 +SUMIF(AA16:AA16, ">=70") / 4 + SUMIF(V16:V16, ">1") / 4 + SUMIF(X16:X16, ">1") / 4 + SUMIF(Z16:Z16, ">1") / 4 + SUMIF(AB16:AB16, ">1") / 4 -> 0 | AN16: =SUMIF(AC16:AC16, ">=65") / 4 +SUMIF(AE16:AE16, ">=65") / 4 +SUMIF(AG16:AG16, ">=65") / 4 +SUMIF(AI16:AI16, ">=65") / 4 + SUMIF(AD16:AD16, ">1") / 4 + SUMIF(AF16:AF16, ">1") / 4 + SUMIF(AH16:AH16, ">1") / 4 + SUMIF(AJ16:AJ16, ">1") / 4 -> 0 | AO16: =AVERAGE(AK16:AN16) -> 0 | AR16: =IF(AO16<70, AO16*0.5, "") -> 0 | AT16: =AS16*50% -> 0 | AU16: =IF(AS16<>"", IF(AR16="","",AR16+AT16), "") | AV16: =IF(AU16 < 70, AR16*30%, "") | AX16: =AW16*70% -> 0 | AY16: =IF(AW16<>"", IF(AV16="", "", AV16+AX16), "") | AZ16: =IF(AND(AU16<70, AY16<70), AO16, "") | BB16: =IF(AW16<>"", IF(AY16>=70, AY16, IF(AZ16+BA16>=70, AZ16+BA16, "")), IF(AS16<>"", IF(AU16>=70, AU16, ""), IF(AO16>=70, AO16, ""))) | BC16: =IF(AW16<>"", IF(AY16<70, IF(AZ16+BA16<70, AZ16+BA16, ""), ""), IF(AS16<>"", IF(AU16<70, AU16, ""), IF(AO16<70, AO16, ""))) -> 0 | BE16: =SUM(E16+M16+U16+AC16)/4 -> 0 | BF16: =SUM(G16+O16+W16+AE16)/4 -> 0 | BG16: =SUM(I16+Q16+Y16+AG16)/4 -> 0 | BH16: =SUM(K16+S16+AA16+AI16)/4 -> 0 | BI16: =AVERAGE(BE16:BH16) -> 0
A17: 7 | B17: 2A-D-07 | C17: DE LA CRUZ SELMO | D17: ROSALBA | AK17: =SUMIF(E17:E17, ">=70") / 4 +SUMIF(G17:G17, ">=70") / 4 +SUMIF(I17:I17, ">=70") / 4 +SUMIF(K17:K17, ">=70") / 4 + SUMIF(F17:F17, ">1") / 4 + SUMIF(H17:H17, ">1") / 4 + SUMIF(J17:J17, ">1") / 4 + SUMIF(L17:L17, ">1") / 4 -> 0 | AL17: =SUMIF(M17:M17, ">=70") / 4 +SUMIF(O17:O17, ">=70") / 4 +SUMIF(Q17:Q17, ">=70") / 4 +SUMIF(S17:S17, ">=70") / 4 + SUMIF(N17:N17, ">1") / 4 + SUMIF(P17:P17, ">1") / 4 + SUMIF(R17:R17, ">1") / 4 + SUMIF(T17:T17, ">1") / 4 -> 0 | AM17: =SUMIF(U17:U17, ">=70") / 4 +SUMIF(W17:W17, ">=70") / 4 +SUMIF(Y17:Y17, ">=70") / 4 +SUMIF(AA17:AA17, ">=70") / 4 + SUMIF(V17:V17, ">1") / 4 + SUMIF(X17:X17, ">1") / 4 + SUMIF(Z17:Z17, ">1") / 4 + SUMIF(AB17:AB17, ">1") / 4 -> 0 | AN17: =SUMIF(AC17:AC17, ">=65") / 4 +SUMIF(AE17:AE17, ">=65") / 4 +SUMIF(AG17:AG17, ">=65") / 4 +SUMIF(AI17:AI17, ">=65") / 4 + SUMIF(AD17:AD17, ">1") / 4 + SUMIF(AF17:AF17, ">1") / 4 + SUMIF(AH17:AH17, ">1") / 4 + SUMIF(AJ17:AJ17, ">1") / 4 -> 0 | AO17: =AVERAGE(AK17:AN17) -> 0 | AR17: =IF(AO17<70, AO17*0.5, "") -> 0 | AT17: =AS17*50% -> 0 | AU17: =IF(AS17<>"", IF(AR17="","",AR17+AT17), "") | AV17: =IF(AU17 < 70, AR17*30%, "") | AX17: =AW17*70% -> 0 | AY17: =IF(AW17<>"", IF(AV17="", "", AV17+AX17), "") | AZ17: =IF(AND(AU17<70, AY17<70), AO17, "") | BB17: =IF(AW17<>"", IF(AY17>=70, AY17, IF(AZ17+BA17>=70, AZ17+BA17, "")), IF(AS17<>"", IF(AU17>=70, AU17, ""), IF(AO17>=70, AO17, ""))) | BC17: =IF(AW17<>"", IF(AY17<70, IF(AZ17+BA17<70, AZ17+BA17, ""), ""), IF(AS17<>"", IF(AU17<70, AU17, ""), IF(AO17<70, AO17, ""))) -> 0 | BE17: =SUM(E17+M17+U17+AC17)/4 -> 0 | BF17: =SUM(G17+O17+W17+AE17)/4 -> 0 | BG17: =SUM(I17+Q17+Y17+AG17)/4 -> 0 | BH17: =SUM(K17+S17+AA17+AI17)/4 -> 0 | BI17: =AVERAGE(BE17:BH17) -> 0
A18: 8 | B18: 2A-D-08 | C18: DE LA CRUZ | D18: JUAN MANUEL | AK18: =SUMIF(E18:E18, ">=70") / 4 +SUMIF(G18:G18, ">=70") / 4 +SUMIF(I18:I18, ">=70") / 4 +SUMIF(K18:K18, ">=70") / 4 + SUMIF(F18:F18, ">1") / 4 + SUMIF(H18:H18, ">1") / 4 + SUMIF(J18:J18, ">1") / 4 + SUMIF(L18:L18, ">1") / 4 -> 0 | AL18: =SUMIF(M18:M18, ">=70") / 4 +SUMIF(O18:O18, ">=70") / 4 +SUMIF(Q18:Q18, ">=70") / 4 +SUMIF(S18:S18, ">=70") / 4 + SUMIF(N18:N18, ">1") / 4 + SUMIF(P18:P18, ">1") / 4 + SUMIF(R18:R18, ">1") / 4 + SUMIF(T18:T18, ">1") / 4 -> 0 | AM18: =SUMIF(U18:U18, ">=70") / 4 +SUMIF(W18:W18, ">=70") / 4 +SUMIF(Y18:Y18, ">=70") / 4 +SUMIF(AA18:AA18, ">=70") / 4 + SUMIF(V18:V18, ">1") / 4 + SUMIF(X18:X18, ">1") / 4 + SUMIF(Z18:Z18, ">1") / 4 + SUMIF(AB18:AB18, ">1") / 4 -> 0 | AN18: =SUMIF(AC18:AC18, ">=65") / 4 +SUMIF(AE18:AE18, ">=65") / 4 +SUMIF(AG18:AG18, ">=65") / 4 +SUMIF(AI18:AI18, ">=65") / 4 + SUMIF(AD18:AD18, ">1") / 4 + SUMIF(AF18:AF18, ">1") / 4 + SUMIF(AH18:AH18, ">1") / 4 + SUMIF(AJ18:AJ18, ">1") / 4 -> 0 | AO18: =AVERAGE(AK18:AN18) -> 0 | AR18: =IF(AO18<70, AO18*0.5, "") -> 0 | AT18: =AS18*50% -> 0 | AU18: =IF(AS18<>"", IF(AR18="","",AR18+AT18), "") | AV18: =IF(AU18 < 70, AR18*30%, "") | AX18: =AW18*70% -> 0 | AY18: =IF(AW18<>"", IF(AV18="", "", AV18+AX18), "") | AZ18: =IF(AND(AU18<70, AY18<70), AO18, "") | BB18: =IF(AW18<>"", IF(AY18>=70, AY18, IF(AZ18+BA18>=70, AZ18+BA18, "")), IF(AS18<>"", IF(AU18>=70, AU18, ""), IF(AO18>=70, AO18, ""))) | BC18: =IF(AW18<>"", IF(AY18<70, IF(AZ18+BA18<70, AZ18+BA18, ""), ""), IF(AS18<>"", IF(AU18<70, AU18, ""), IF(AO18<70, AO18, ""))) -> 0 | BE18: =SUM(E18+M18+U18+AC18)/4 -> 0 | BF18: =SUM(G18+O18+W18+AE18)/4 -> 0 | BG18: =SUM(I18+Q18+Y18+AG18)/4 -> 0 | BH18: =SUM(K18+S18+AA18+AI18)/4 -> 0 | BI18: =AVERAGE(BE18:BH18) -> 0
A19: 9 | B19: 2A-D-09 | C19: DE LA NIEVE | D19: DANIEL OMAR | AK19: =SUMIF(E19:E19, ">=70") / 4 +SUMIF(G19:G19, ">=70") / 4 +SUMIF(I19:I19, ">=70") / 4 +SUMIF(K19:K19, ">=70") / 4 + SUMIF(F19:F19, ">1") / 4 + SUMIF(H19:H19, ">1") / 4 + SUMIF(J19:J19, ">1") / 4 + SUMIF(L19:L19, ">1") / 4 -> 0 | AL19: =SUMIF(M19:M19, ">=70") / 4 +SUMIF(O19:O19, ">=70") / 4 +SUMIF(Q19:Q19, ">=70") / 4 +SUMIF(S19:S19, ">=70") / 4 + SUMIF(N19:N19, ">1") / 4 + SUMIF(P19:P19, ">1") / 4 + SUMIF(R19:R19, ">1") / 4 + SUMIF(T19:T19, ">1") / 4 -> 0 | AM19: =SUMIF(U19:U19, ">=70") / 4 +SUMIF(W19:W19, ">=70") / 4 +SUMIF(Y19:Y19, ">=70") / 4 +SUMIF(AA19:AA19, ">=70") / 4 + SUMIF(V19:V19, ">1") / 4 + SUMIF(X19:X19, ">1") / 4 + SUMIF(Z19:Z19, ">1") / 4 + SUMIF(AB19:AB19, ">1") / 4 -> 0 | AN19: =SUMIF(AC19:AC19, ">=65") / 4 +SUMIF(AE19:AE19, ">=65") / 4 +SUMIF(AG19:AG19, ">=65") / 4 +SUMIF(AI19:AI19, ">=65") / 4 + SUMIF(AD19:AD19, ">1") / 4 + SUMIF(AF19:AF19, ">1") / 4 + SUMIF(AH19:AH19, ">1") / 4 + SUMIF(AJ19:AJ19, ">1") / 4 -> 0 | AO19: =AVERAGE(AK19:AN19) -> 0 | AR19: =IF(AO19<70, AO19*0.5, "") -> 0 | AT19: =AS19*50% -> 0 | AU19: =IF(AS19<>"", IF(AR19="","",AR19+AT19), "") | AV19: =IF(AU19 < 70, AR19*30%, "") | AX19: =AW19*70% -> 0 | AY19: =IF(AW19<>"", IF(AV19="", "", AV19+AX19), "") | AZ19: =IF(AND(AU19<70, AY19<70), AO19, "") | BB19: =IF(AW19<>"", IF(AY19>=70, AY19, IF(AZ19+BA19>=70, AZ19+BA19, "")), IF(AS19<>"", IF(AU19>=70, AU19, ""), IF(AO19>=70, AO19, ""))) | BC19: =IF(AW19<>"", IF(AY19<70, IF(AZ19+BA19<70, AZ19+BA19, ""), ""), IF(AS19<>"", IF(AU19<70, AU19, ""), IF(AO19<70, AO19, ""))) -> 0 | BE19: =SUM(E19+M19+U19+AC19)/4 -> 0 | BF19: =SUM(G19+O19+W19+AE19)/4 -> 0 | BG19: =SUM(I19+Q19+Y19+AG19)/4 -> 0 | BH19: =SUM(K19+S19+AA19+AI19)/4 -> 0 | BI19: =AVERAGE(BE19:BH19) -> 0
A20: 10 | B20: 2A-D-10 | C20: DE LA ROSA ROJAS | D20: EMMANUEL JESUS | AK20: =SUMIF(E20:E20, ">=70") / 4 +SUMIF(G20:G20, ">=70") / 4 +SUMIF(I20:I20, ">=70") / 4 +SUMIF(K20:K20, ">=70") / 4 + SUMIF(F20:F20, ">1") / 4 + SUMIF(H20:H20, ">1") / 4 + SUMIF(J20:J20, ">1") / 4 + SUMIF(L20:L20, ">1") / 4 -> 0 | AL20: =SUMIF(M20:M20, ">=70") / 4 +SUMIF(O20:O20, ">=70") / 4 +SUMIF(Q20:Q20, ">=70") / 4 +SUMIF(S20:S20, ">=70") / 4 + SUMIF(N20:N20, ">1") / 4 + SUMIF(P20:P20, ">1") / 4 + SUMIF(R20:R20, ">1") / 4 + SUMIF(T20:T20, ">1") / 4 -> 0 | AM20: =SUMIF(U20:U20, ">=70") / 4 +SUMIF(W20:W20, ">=70") / 4 +SUMIF(Y20:Y20, ">=70") / 4 +SUMIF(AA20:AA20, ">=70") / 4 + SUMIF(V20:V20, ">1") / 4 + SUMIF(X20:X20, ">1") / 4 + SUMIF(Z20:Z20, ">1") / 4 + SUMIF(AB20:AB20, ">1") / 4 -> 0 | AN20: =SUMIF(AC20:AC20, ">=65") / 4 +SUMIF(AE20:AE20, ">=65") / 4 +SUMIF(AG20:AG20, ">=65") / 4 +SUMIF(AI20:AI20, ">=65") / 4 + SUMIF(AD20:AD20, ">1") / 4 + SUMIF(AF20:AF20, ">1") / 4 + SUMIF(AH20:AH20, ">1") / 4 + SUMIF(AJ20:AJ20, ">1") / 4 -> 0 | AO20: =AVERAGE(AK20:AN20) -> 0 | AR20: =IF(AO20<70, AO20*0.5, "") -> 0 | AT20: =AS20*50% -> 0 | AU20: =IF(AS20<>"", IF(AR20="","",AR20+AT20), "") | AV20: =IF(AU20 < 70, AR20*30%, "") | AX20: =AW20*70% -> 0 | AY20: =IF(AW20<>"", IF(AV20="", "", AV20+AX20), "") | AZ20: =IF(AND(AU20<70, AY20<70), AO20, "") | BB20: =IF(AW20<>"", IF(AY20>=70, AY20, IF(AZ20+BA20>=70, AZ20+BA20, "")), IF(AS20<>"", IF(AU20>=70, AU20, ""), IF(AO20>=70, AO20, ""))) | BC20: =IF(AW20<>"", IF(AY20<70, IF(AZ20+BA20<70, AZ20+BA20, ""), ""), IF(AS20<>"", IF(AU20<70, AU20, ""), IF(AO20<70, AO20, ""))) -> 0 | BE20: =SUM(E20+M20+U20+AC20)/4 -> 0 | BF20: =SUM(G20+O20+W20+AE20)/4 -> 0 | BG20: =SUM(I20+Q20+Y20+AG20)/4 -> 0 | BH20: =SUM(K20+S20+AA20+AI20)/4 -> 0 | BI20: =AVERAGE(BE20:BH20) -> 0
A21: 11 | B21: 2A-D-11 | C21: DE LEON | D21: LUIS KENDRY | AK21: =SUMIF(E21:E21, ">=70") / 4 +SUMIF(G21:G21, ">=70") / 4 +SUMIF(I21:I21, ">=70") / 4 +SUMIF(K21:K21, ">=70") / 4 + SUMIF(F21:F21, ">1") / 4 + SUMIF(H21:H21, ">1") / 4 + SUMIF(J21:J21, ">1") / 4 + SUMIF(L21:L21, ">1") / 4 -> 0 | AL21: =SUMIF(M21:M21, ">=70") / 4 +SUMIF(O21:O21, ">=70") / 4 +SUMIF(Q21:Q21, ">=70") / 4 +SUMIF(S21:S21, ">=70") / 4 + SUMIF(N21:N21, ">1") / 4 + SUMIF(P21:P21, ">1") / 4 + SUMIF(R21:R21, ">1") / 4 + SUMIF(T21:T21, ">1") / 4 -> 0 | AM21: =SUMIF(U21:U21, ">=70") / 4 +SUMIF(W21:W21, ">=70") / 4 +SUMIF(Y21:Y21, ">=70") / 4 +SUMIF(AA21:AA21, ">=70") / 4 + SUMIF(V21:V21, ">1") / 4 + SUMIF(X21:X21, ">1") / 4 + SUMIF(Z21:Z21, ">1") / 4 + SUMIF(AB21:AB21, ">1") / 4 -> 0 | AN21: =SUMIF(AC21:AC21, ">=65") / 4 +SUMIF(AE21:AE21, ">=65") / 4 +SUMIF(AG21:AG21, ">=65") / 4 +SUMIF(AI21:AI21, ">=65") / 4 + SUMIF(AD21:AD21, ">1") / 4 + SUMIF(AF21:AF21, ">1") / 4 + SUMIF(AH21:AH21, ">1") / 4 + SUMIF(AJ21:AJ21, ">1") / 4 -> 0 | AO21: =AVERAGE(AK21:AN21) -> 0 | AR21: =IF(AO21<70, AO21*0.5, "") -> 0 | AT21: =AS21*50% -> 0 | AU21: =IF(AS21<>"", IF(AR21="","",AR21+AT21), "") | AV21: =IF(AU21 < 70, AR21*30%, "") | AX21: =AW21*70% -> 0 | AY21: =IF(AW21<>"", IF(AV21="", "", AV21+AX21), "") | AZ21: =IF(AND(AU21<70, AY21<70), AO21, "") | BB21: =IF(AW21<>"", IF(AY21>=70, AY21, IF(AZ21+BA21>=70, AZ21+BA21, "")), IF(AS21<>"", IF(AU21>=70, AU21, ""), IF(AO21>=70, AO21, ""))) | BC21: =IF(AW21<>"", IF(AY21<70, IF(AZ21+BA21<70, AZ21+BA21, ""), ""), IF(AS21<>"", IF(AU21<70, AU21, ""), IF(AO21<70, AO21, ""))) -> 0 | BE21: =SUM(E21+M21+U21+AC21)/4 -> 0 | BF21: =SUM(G21+O21+W21+AE21)/4 -> 0 | BG21: =SUM(I21+Q21+Y21+AG21)/4 -> 0 | BH21: =SUM(K21+S21+AA21+AI21)/4 -> 0 | BI21: =AVERAGE(BE21:BH21) -> 0
A22: 12 | B22: 2A-D-12 | C22: DELOSSANTE | D22: MIRDALENE | AK22: =SUMIF(E22:E22, ">=70") / 4 +SUMIF(G22:G22, ">=70") / 4 +SUMIF(I22:I22, ">=70") / 4 +SUMIF(K22:K22, ">=70") / 4 + SUMIF(F22:F22, ">1") / 4 + SUMIF(H22:H22, ">1") / 4 + SUMIF(J22:J22, ">1") / 4 + SUMIF(L22:L22, ">1") / 4 -> 0 | AL22: =SUMIF(M22:M22, ">=70") / 4 +SUMIF(O22:O22, ">=70") / 4 +SUMIF(Q22:Q22, ">=70") / 4 +SUMIF(S22:S22, ">=70") / 4 + SUMIF(N22:N22, ">1") / 4 + SUMIF(P22:P22, ">1") / 4 + SUMIF(R22:R22, ">1") / 4 + SUMIF(T22:T22, ">1") / 4 -> 0 | AM22: =SUMIF(U22:U22, ">=70") / 4 +SUMIF(W22:W22, ">=70") / 4 +SUMIF(Y22:Y22, ">=70") / 4 +SUMIF(AA22:AA22, ">=70") / 4 + SUMIF(V22:V22, ">1") / 4 + SUMIF(X22:X22, ">1") / 4 + SUMIF(Z22:Z22, ">1") / 4 + SUMIF(AB22:AB22, ">1") / 4 -> 0 | AN22: =SUMIF(AC22:AC22, ">=65") / 4 +SUMIF(AE22:AE22, ">=65") / 4 +SUMIF(AG22:AG22, ">=65") / 4 +SUMIF(AI22:AI22, ">=65") / 4 + SUMIF(AD22:AD22, ">1") / 4 + SUMIF(AF22:AF22, ">1") / 4 + SUMIF(AH22:AH22, ">1") / 4 + SUMIF(AJ22:AJ22, ">1") / 4 -> 0 | AO22: =AVERAGE(AK22:AN22) -> 0 | AR22: =IF(AO22<70, AO22*0.5, "") -> 0 | AT22: =AS22*50% -> 0 | AU22: =IF(AS22<>"", IF(AR22="","",AR22+AT22), "") | AV22: =IF(AU22 < 70, AR22*30%, "") | AX22: =AW22*70% -> 0 | AY22: =IF(AW22<>"", IF(AV22="", "", AV22+AX22), "") | AZ22: =IF(AND(AU22<70, AY22<70), AO22, "") | BB22: =IF(AW22<>"", IF(AY22>=70, AY22, IF(AZ22+BA22>=70, AZ22+BA22, "")), IF(AS22<>"", IF(AU22>=70, AU22, ""), IF(AO22>=70, AO22, ""))) | BC22: =IF(AW22<>"", IF(AY22<70, IF(AZ22+BA22<70, AZ22+BA22, ""), ""), IF(AS22<>"", IF(AU22<70, AU22, ""), IF(AO22<70, AO22, ""))) -> 0 | BE22: =SUM(E22+M22+U22+AC22)/4 -> 0 | BF22: =SUM(G22+O22+W22+AE22)/4 -> 0 | BG22: =SUM(I22+Q22+Y22+AG22)/4 -> 0 | BH22: =SUM(K22+S22+AA22+AI22)/4 -> 0 | BI22: =AVERAGE(BE22:BH22) -> 0
A23: 13 | B23: 2A-D-13 | C23: DOMINGUEZ MONTERO | D23: JADE YASELY | AK23: =SUMIF(E23:E23, ">=70") / 4 +SUMIF(G23:G23, ">=70") / 4 +SUMIF(I23:I23, ">=70") / 4 +SUMIF(K23:K23, ">=70") / 4 + SUMIF(F23:F23, ">1") / 4 + SUMIF(H23:H23, ">1") / 4 + SUMIF(J23:J23, ">1") / 4 + SUMIF(L23:L23, ">1") / 4 -> 0 | AL23: =SUMIF(M23:M23, ">=70") / 4 +SUMIF(O23:O23, ">=70") / 4 +SUMIF(Q23:Q23, ">=70") / 4 +SUMIF(S23:S23, ">=70") / 4 + SUMIF(N23:N23, ">1") / 4 + SUMIF(P23:P23, ">1") / 4 + SUMIF(R23:R23, ">1") / 4 + SUMIF(T23:T23, ">1") / 4 -> 0 | AM23: =SUMIF(U23:U23, ">=70") / 4 +SUMIF(W23:W23, ">=70") / 4 +SUMIF(Y23:Y23, ">=70") / 4 +SUMIF(AA23:AA23, ">=70") / 4 + SUMIF(V23:V23, ">1") / 4 + SUMIF(X23:X23, ">1") / 4 + SUMIF(Z23:Z23, ">1") / 4 + SUMIF(AB23:AB23, ">1") / 4 -> 0 | AN23: =SUMIF(AC23:AC23, ">=65") / 4 +SUMIF(AE23:AE23, ">=65") / 4 +SUMIF(AG23:AG23, ">=65") / 4 +SUMIF(AI23:AI23, ">=65") / 4 + SUMIF(AD23:AD23, ">1") / 4 + SUMIF(AF23:AF23, ">1") / 4 + SUMIF(AH23:AH23, ">1") / 4 + SUMIF(AJ23:AJ23, ">1") / 4 -> 0 | AO23: =AVERAGE(AK23:AN23) -> 0 | AR23: =IF(AO23<70, AO23*0.5, "") -> 0 | AT23: =AS23*50% -> 0 | AU23: =IF(AS23<>"", IF(AR23="","",AR23+AT23), "") | AV23: =IF(AU23 < 70, AR23*30%, "") | AX23: =AW23*70% -> 0 | AY23: =IF(AW23<>"", IF(AV23="", "", AV23+AX23), "") | AZ23: =IF(AND(AU23<70, AY23<70), AO23, "") | BB23: =IF(AW23<>"", IF(AY23>=70, AY23, IF(AZ23+BA23>=70, AZ23+BA23, "")), IF(AS23<>"", IF(AU23>=70, AU23, ""), IF(AO23>=70, AO23, ""))) | BC23: =IF(AW23<>"", IF(AY23<70, IF(AZ23+BA23<70, AZ23+BA23, ""), ""), IF(AS23<>"", IF(AU23<70, AU23, ""), IF(AO23<70, AO23, ""))) -> 0 | BE23: =SUM(E23+M23+U23+AC23)/4 -> 0 | BF23: =SUM(G23+O23+W23+AE23)/4 -> 0 | BG23: =SUM(I23+Q23+Y23+AG23)/4 -> 0 | BH23: =SUM(K23+S23+AA23+AI23)/4 -> 0 | BI23: =AVERAGE(BE23:BH23) -> 0
A24: 14 | B24: 2A-D-14 | C24: FERNANDEZ CUELLO | D24: JUAN FRANCISCO | AK24: =SUMIF(E24:E24, ">=70") / 4 +SUMIF(G24:G24, ">=70") / 4 +SUMIF(I24:I24, ">=70") / 4 +SUMIF(K24:K24, ">=70") / 4 + SUMIF(F24:F24, ">1") / 4 + SUMIF(H24:H24, ">1") / 4 + SUMIF(J24:J24, ">1") / 4 + SUMIF(L24:L24, ">1") / 4 -> 0 | AL24: =SUMIF(M24:M24, ">=70") / 4 +SUMIF(O24:O24, ">=70") / 4 +SUMIF(Q24:Q24, ">=70") / 4 +SUMIF(S24:S24, ">=70") / 4 + SUMIF(N24:N24, ">1") / 4 + SUMIF(P24:P24, ">1") / 4 + SUMIF(R24:R24, ">1") / 4 + SUMIF(T24:T24, ">1") / 4 -> 0 | AM24: =SUMIF(U24:U24, ">=70") / 4 +SUMIF(W24:W24, ">=70") / 4 +SUMIF(Y24:Y24, ">=70") / 4 +SUMIF(AA24:AA24, ">=70") / 4 + SUMIF(V24:V24, ">1") / 4 + SUMIF(X24:X24, ">1") / 4 + SUMIF(Z24:Z24, ">1") / 4 + SUMIF(AB24:AB24, ">1") / 4 -> 0 | AN24: =SUMIF(AC24:AC24, ">=65") / 4 +SUMIF(AE24:AE24, ">=65") / 4 +SUMIF(AG24:AG24, ">=65") / 4 +SUMIF(AI24:AI24, ">=65") / 4 + SUMIF(AD24:AD24, ">1") / 4 + SUMIF(AF24:AF24, ">1") / 4 + SUMIF(AH24:AH24, ">1") / 4 + SUMIF(AJ24:AJ24, ">1") / 4 -> 0 | AO24: =AVERAGE(AK24:AN24) -> 0 | AR24: =IF(AO24<70, AO24*0.5, "") -> 0 | AT24: =AS24*50% -> 0 | AU24: =IF(AS24<>"", IF(AR24="","",AR24+AT24), "") | AV24: =IF(AU24 < 70, AR24*30%, "") | AX24: =AW24*70% -> 0 | AY24: =IF(AW24<>"", IF(AV24="", "", AV24+AX24), "") | AZ24: =IF(AND(AU24<70, AY24<70), AO24, "") | BB24: =IF(AW24<>"", IF(AY24>=70, AY24, IF(AZ24+BA24>=70, AZ24+BA24, "")), IF(AS24<>"", IF(AU24>=70, AU24, ""), IF(AO24>=70, AO24, ""))) | BC24: =IF(AW24<>"", IF(AY24<70, IF(AZ24+BA24<70, AZ24+BA24, ""), ""), IF(AS24<>"", IF(AU24<70, AU24, ""), IF(AO24<70, AO24, ""))) -> 0 | BE24: =SUM(E24+M24+U24+AC24)/4 -> 0 | BF24: =SUM(G24+O24+W24+AE24)/4 -> 0 | BG24: =SUM(I24+Q24+Y24+AG24)/4 -> 0 | BH24: =SUM(K24+S24+AA24+AI24)/4 -> 0 | BI24: =AVERAGE(BE24:BH24) -> 0
A25: 15 | B25: 2A-D-15 | C25: GOIN HIPPOLYTE | D25: ABIGAELLE | AK25: =SUMIF(E25:E25, ">=70") / 4 +SUMIF(G25:G25, ">=70") / 4 +SUMIF(I25:I25, ">=70") / 4 +SUMIF(K25:K25, ">=70") / 4 + SUMIF(F25:F25, ">1") / 4 + SUMIF(H25:H25, ">1") / 4 + SUMIF(J25:J25, ">1") / 4 + SUMIF(L25:L25, ">1") / 4 -> 0 | AL25: =SUMIF(M25:M25, ">=70") / 4 +SUMIF(O25:O25, ">=70") / 4 +SUMIF(Q25:Q25, ">=70") / 4 +SUMIF(S25:S25, ">=70") / 4 + SUMIF(N25:N25, ">1") / 4 + SUMIF(P25:P25, ">1") / 4 + SUMIF(R25:R25, ">1") / 4 + SUMIF(T25:T25, ">1") / 4 -> 0 | AM25: =SUMIF(U25:U25, ">=70") / 4 +SUMIF(W25:W25, ">=70") / 4 +SUMIF(Y25:Y25, ">=70") / 4 +SUMIF(AA25:AA25, ">=70") / 4 + SUMIF(V25:V25, ">1") / 4 + SUMIF(X25:X25, ">1") / 4 + SUMIF(Z25:Z25, ">1") / 4 + SUMIF(AB25:AB25, ">1") / 4 -> 0 | AN25: =SUMIF(AC25:AC25, ">=65") / 4 +SUMIF(AE25:AE25, ">=65") / 4 +SUMIF(AG25:AG25, ">=65") / 4 +SUMIF(AI25:AI25, ">=65") / 4 + SUMIF(AD25:AD25, ">1") / 4 + SUMIF(AF25:AF25, ">1") / 4 + SUMIF(AH25:AH25, ">1") / 4 + SUMIF(AJ25:AJ25, ">1") / 4 -> 0 | AO25: =AVERAGE(AK25:AN25) -> 0 | AR25: =IF(AO25<70, AO25*0.5, "") -> 0 | AT25: =AS25*50% -> 0 | AU25: =IF(AS25<>"", IF(AR25="","",AR25+AT25), "") | AV25: =IF(AU25 < 70, AR25*30%, "") | AX25: =AW25*70% -> 0 | AY25: =IF(AW25<>"", IF(AV25="", "", AV25+AX25), "") | AZ25: =IF(AND(AU25<70, AY25<70), AO25, "") | BB25: =IF(AW25<>"", IF(AY25>=70, AY25, IF(AZ25+BA25>=70, AZ25+BA25, "")), IF(AS25<>"", IF(AU25>=70, AU25, ""), IF(AO25>=70, AO25, ""))) | BC25: =IF(AW25<>"", IF(AY25<70, IF(AZ25+BA25<70, AZ25+BA25, ""), ""), IF(AS25<>"", IF(AU25<70, AU25, ""), IF(AO25<70, AO25, ""))) -> 0 | BE25: =SUM(E25+M25+U25+AC25)/4 -> 0 | BF25: =SUM(G25+O25+W25+AE25)/4 -> 0 | BG25: =SUM(I25+Q25+Y25+AG25)/4 -> 0 | BH25: =SUM(K25+S25+AA25+AI25)/4 -> 0 | BI25: =AVERAGE(BE25:BH25) -> 0
A26: 16 | B26: 2A-D-16 | C26: HERNANDEZ SORIANO | D26: ELIAN | AK26: =SUMIF(E26:E26, ">=70") / 4 +SUMIF(G26:G26, ">=70") / 4 +SUMIF(I26:I26, ">=70") / 4 +SUMIF(K26:K26, ">=70") / 4 + SUMIF(F26:F26, ">1") / 4 + SUMIF(H26:H26, ">1") / 4 + SUMIF(J26:J26, ">1") / 4 + SUMIF(L26:L26, ">1") / 4 -> 0 | AL26: =SUMIF(M26:M26, ">=70") / 4 +SUMIF(O26:O26, ">=70") / 4 +SUMIF(Q26:Q26, ">=70") / 4 +SUMIF(S26:S26, ">=70") / 4 + SUMIF(N26:N26, ">1") / 4 + SUMIF(P26:P26, ">1") / 4 + SUMIF(R26:R26, ">1") / 4 + SUMIF(T26:T26, ">1") / 4 -> 0 | AM26: =SUMIF(U26:U26, ">=70") / 4 +SUMIF(W26:W26, ">=70") / 4 +SUMIF(Y26:Y26, ">=70") / 4 +SUMIF(AA26:AA26, ">=70") / 4 + SUMIF(V26:V26, ">1") / 4 + SUMIF(X26:X26, ">1") / 4 + SUMIF(Z26:Z26, ">1") / 4 + SUMIF(AB26:AB26, ">1") / 4 -> 0 | AN26: =SUMIF(AC26:AC26, ">=65") / 4 +SUMIF(AE26:AE26, ">=65") / 4 +SUMIF(AG26:AG26, ">=65") / 4 +SUMIF(AI26:AI26, ">=65") / 4 + SUMIF(AD26:AD26, ">1") / 4 + SUMIF(AF26:AF26, ">1") / 4 + SUMIF(AH26:AH26, ">1") / 4 + SUMIF(AJ26:AJ26, ">1") / 4 -> 0 | AO26: =AVERAGE(AK26:AN26) -> 0 | AR26: =IF(AO26<70, AO26*0.5, "") -> 0 | AT26: =AS26*50% -> 0 | AU26: =IF(AS26<>"", IF(AR26="","",AR26+AT26), "") | AV26: =IF(AU26 < 70, AR26*30%, "") | AX26: =AW26*70% -> 0 | AY26: =IF(AW26<>"", IF(AV26="", "", AV26+AX26), "") | AZ26: =IF(AND(AU26<70, AY26<70), AO26, "") | BB26: =IF(AW26<>"", IF(AY26>=70, AY26, IF(AZ26+BA26>=70, AZ26+BA26, "")), IF(AS26<>"", IF(AU26>=70, AU26, ""), IF(AO26>=70, AO26, ""))) | BC26: =IF(AW26<>"", IF(AY26<70, IF(AZ26+BA26<70, AZ26+BA26, ""), ""), IF(AS26<>"", IF(AU26<70, AU26, ""), IF(AO26<70, AO26, ""))) -> 0 | BE26: =SUM(E26+M26+U26+AC26)/4 -> 0 | BF26: =SUM(G26+O26+W26+AE26)/4 -> 0 | BG26: =SUM(I26+Q26+Y26+AG26)/4 -> 0 | BH26: =SUM(K26+S26+AA26+AI26)/4 -> 0 | BI26: =AVERAGE(BE26:BH26) -> 0
A27: 17 | B27: 2A-D-17 | C27: JANVIER CORASME | D27: GISELENE | AK27: =SUMIF(E27:E27, ">=70") / 4 +SUMIF(G27:G27, ">=70") / 4 +SUMIF(I27:I27, ">=70") / 4 +SUMIF(K27:K27, ">=70") / 4 + SUMIF(F27:F27, ">1") / 4 + SUMIF(H27:H27, ">1") / 4 + SUMIF(J27:J27, ">1") / 4 + SUMIF(L27:L27, ">1") / 4 -> 0 | AL27: =SUMIF(M27:M27, ">=70") / 4 +SUMIF(O27:O27, ">=70") / 4 +SUMIF(Q27:Q27, ">=70") / 4 +SUMIF(S27:S27, ">=70") / 4 + SUMIF(N27:N27, ">1") / 4 + SUMIF(P27:P27, ">1") / 4 + SUMIF(R27:R27, ">1") / 4 + SUMIF(T27:T27, ">1") / 4 -> 0 | AM27: =SUMIF(U27:U27, ">=70") / 4 +SUMIF(W27:W27, ">=70") / 4 +SUMIF(Y27:Y27, ">=70") / 4 +SUMIF(AA27:AA27, ">=70") / 4 + SUMIF(V27:V27, ">1") / 4 + SUMIF(X27:X27, ">1") / 4 + SUMIF(Z27:Z27, ">1") / 4 + SUMIF(AB27:AB27, ">1") / 4 -> 0 | AN27: =SUMIF(AC27:AC27, ">=65") / 4 +SUMIF(AE27:AE27, ">=65") / 4 +SUMIF(AG27:AG27, ">=65") / 4 +SUMIF(AI27:AI27, ">=65") / 4 + SUMIF(AD27:AD27, ">1") / 4 + SUMIF(AF27:AF27, ">1") / 4 + SUMIF(AH27:AH27, ">1") / 4 + SUMIF(AJ27:AJ27, ">1") / 4 -> 0 | AO27: =AVERAGE(AK27:AN27) -> 0 | AR27: =IF(AO27<70, AO27*0.5, "") -> 0 | AT27: =AS27*50% -> 0 | AU27: =IF(AS27<>"", IF(AR27="","",AR27+AT27), "") | AV27: =IF(AU27 < 70, AR27*30%, "") | AX27: =AW27*70% -> 0 | AY27: =IF(AW27<>"", IF(AV27="", "", AV27+AX27), "") | AZ27: =IF(AND(AU27<70, AY27<70), AO27, "") | BB27: =IF(AW27<>"", IF(AY27>=70, AY27, IF(AZ27+BA27>=70, AZ27+BA27, "")), IF(AS27<>"", IF(AU27>=70, AU27, ""), IF(AO27>=70, AO27, ""))) | BC27: =IF(AW27<>"", IF(AY27<70, IF(AZ27+BA27<70, AZ27+BA27, ""), ""), IF(AS27<>"", IF(AU27<70, AU27, ""), IF(AO27<70, AO27, ""))) -> 0 | BE27: =SUM(E27+M27+U27+AC27)/4 -> 0 | BF27: =SUM(G27+O27+W27+AE27)/4 -> 0 | BG27: =SUM(I27+Q27+Y27+AG27)/4 -> 0 | BH27: =SUM(K27+S27+AA27+AI27)/4 -> 0 | BI27: =AVERAGE(BE27:BH27) -> 0
A28: 18 | B28: 2A-D-18 | C28: JEAN BAPTISTE | D28: ESTEICI | E28: 80 | G28: 83 | I28: 85 | K28: 84 | M28: 81 | O28: 84 | Q28: 83 | S28: 82 | U28: 80 | W28: 84 | Y28: 85 | AA28: 83 | AC28: 80 | AE28: 84 | AG28: 82 | AI28: 81 | AK28: =SUMIF(E28:E28, ">=70") / 4 +SUMIF(G28:G28, ">=70") / 4 +SUMIF(I28:I28, ">=70") / 4 +SUMIF(K28:K28, ">=70") / 4 + SUMIF(F28:F28, ">1") / 4 + SUMIF(H28:H28, ">1") / 4 + SUMIF(J28:J28, ">1") / 4 + SUMIF(L28:L28, ">1") / 4 -> 83 | AL28: =SUMIF(M28:M28, ">=70") / 4 +SUMIF(O28:O28, ">=70") / 4 +SUMIF(Q28:Q28, ">=70") / 4 +SUMIF(S28:S28, ">=70") / 4 + SUMIF(N28:N28, ">1") / 4 + SUMIF(P28:P28, ">1") / 4 + SUMIF(R28:R28, ">1") / 4 + SUMIF(T28:T28, ">1") / 4 -> 82.5 | AM28: =SUMIF(U28:U28, ">=70") / 4 +SUMIF(W28:W28, ">=70") / 4 +SUMIF(Y28:Y28, ">=70") / 4 +SUMIF(AA28:AA28, ">=70") / 4 + SUMIF(V28:V28, ">1") / 4 + SUMIF(X28:X28, ">1") / 4 + SUMIF(Z28:Z28, ">1") / 4 + SUMIF(AB28:AB28, ">1") / 4 -> 83 | AN28: =SUMIF(AC28:AC28, ">=65") / 4 +SUMIF(AE28:AE28, ">=65") / 4 +SUMIF(AG28:AG28, ">=65") / 4 +SUMIF(AI28:AI28, ">=65") / 4 + SUMIF(AD28:AD28, ">1") / 4 + SUMIF(AF28:AF28, ">1") / 4 + SUMIF(AH28:AH28, ">1") / 4 + SUMIF(AJ28:AJ28, ">1") / 4 -> 81.75 | AO28: =AVERAGE(AK28:AN28) -> 82.5625 | AR28: =IF(AO28<70, AO28*0.5, "") | AT28: =AS28*50% -> 0 | AU28: =IF(AS28<>"", IF(AR28="","",AR28+AT28), "") | AV28: =IF(AU28 < 70, AR28*30%, "") | AX28: =AW28*70% -> 0 | AY28: =IF(AW28<>"", IF(AV28="", "", AV28+AX28), "") | AZ28: =IF(AND(AU28<70, AY28<70), AO28, "") | BB28: =IF(AW28<>"", IF(AY28>=70, AY28, IF(AZ28+BA28>=70, AZ28+BA28, "")), IF(AS28<>"", IF(AU28>=70, AU28, ""), IF(AO28>=70, AO28, ""))) -> 82.5625 | BC28: =IF(AW28<>"", IF(AY28<70, IF(AZ28+BA28<70, AZ28+BA28, ""), ""), IF(AS28<>"", IF(AU28<70, AU28, ""), IF(AO28<70, AO28, ""))) | BE28: =SUM(E28+M28+U28+AC28)/4 -> 80.25 | BF28: =SUM(G28+O28+W28+AE28)/4 -> 83.75 | BG28: =SUM(I28+Q28+Y28+AG28)/4 -> 83.75 | BH28: =SUM(K28+S28+AA28+AI28)/4 -> 82.5 | BI28: =AVERAGE(BE28:BH28) -> 82.5625
A29: 19 | B29: 2A-D-19 | C29: JIMENEZ PAYANO | D29: ANDY JUNIOR | AK29: =SUMIF(E29:E29, ">=70") / 4 +SUMIF(G29:G29, ">=70") / 4 +SUMIF(I29:I29, ">=70") / 4 +SUMIF(K29:K29, ">=70") / 4 + SUMIF(F29:F29, ">1") / 4 + SUMIF(H29:H29, ">1") / 4 + SUMIF(J29:J29, ">1") / 4 + SUMIF(L29:L29, ">1") / 4 -> 0 | AL29: =SUMIF(M29:M29, ">=70") / 4 +SUMIF(O29:O29, ">=70") / 4 +SUMIF(Q29:Q29, ">=70") / 4 +SUMIF(S29:S29, ">=70") / 4 + SUMIF(N29:N29, ">1") / 4 + SUMIF(P29:P29, ">1") / 4 + SUMIF(R29:R29, ">1") / 4 + SUMIF(T29:T29, ">1") / 4 -> 0 | AM29: =SUMIF(U29:U29, ">=70") / 4 +SUMIF(W29:W29, ">=70") / 4 +SUMIF(Y29:Y29, ">=70") / 4 +SUMIF(AA29:AA29, ">=70") / 4 + SUMIF(V29:V29, ">1") / 4 + SUMIF(X29:X29, ">1") / 4 + SUMIF(Z29:Z29, ">1") / 4 + SUMIF(AB29:AB29, ">1") / 4 -> 0 | AN29: =SUMIF(AC29:AC29, ">=65") / 4 +SUMIF(AE29:AE29, ">=65") / 4 +SUMIF(AG29:AG29, ">=65") / 4 +SUMIF(AI29:AI29, ">=65") / 4 + SUMIF(AD29:AD29, ">1") / 4 + SUMIF(AF29:AF29, ">1") / 4 + SUMIF(AH29:AH29, ">1") / 4 + SUMIF(AJ29:AJ29, ">1") / 4 -> 0 | AO29: =AVERAGE(AK29:AN29) -> 0 | AR29: =IF(AO29<70, AO29*0.5, "") -> 0 | AT29: =AS29*50% -> 0 | AU29: =IF(AS29<>"", IF(AR29="","",AR29+AT29), "") | AV29: =IF(AU29 < 70, AR29*30%, "") | AX29: =AW29*70% -> 0 | AY29: =IF(AW29<>"", IF(AV29="", "", AV29+AX29), "") | AZ29: =IF(AND(AU29<70, AY29<70), AO29, "") | BB29: =IF(AW29<>"", IF(AY29>=70, AY29, IF(AZ29+BA29>=70, AZ29+BA29, "")), IF(AS29<>"", IF(AU29>=70, AU29, ""), IF(AO29>=70, AO29, ""))) | BC29: =IF(AW29<>"", IF(AY29<70, IF(AZ29+BA29<70, AZ29+BA29, ""), ""), IF(AS29<>"", IF(AU29<70, AU29, ""), IF(AO29<70, AO29, ""))) -> 0 | BE29: =SUM(E29+M29+U29+AC29)/4 -> 0 | BF29: =SUM(G29+O29+W29+AE29)/4 -> 0 | BG29: =SUM(I29+Q29+Y29+AG29)/4 -> 0 | BH29: =SUM(K29+S29+AA29+AI29)/4 -> 0 | BI29: =AVERAGE(BE29:BH29) -> 0
A30: 20 | B30: 2A-D-20 | C30: MONTAS LOPEZ | D30: EDUARDO AUGUSTO | AK30: =SUMIF(E30:E30, ">=70") / 4 +SUMIF(G30:G30, ">=70") / 4 +SUMIF(I30:I30, ">=70") / 4 +SUMIF(K30:K30, ">=70") / 4 + SUMIF(F30:F30, ">1") / 4 + SUMIF(H30:H30, ">1") / 4 + SUMIF(J30:J30, ">1") / 4 + SUMIF(L30:L30, ">1") / 4 -> 0 | AL30: =SUMIF(M30:M30, ">=70") / 4 +SUMIF(O30:O30, ">=70") / 4 +SUMIF(Q30:Q30, ">=70") / 4 +SUMIF(S30:S30, ">=70") / 4 + SUMIF(N30:N30, ">1") / 4 + SUMIF(P30:P30, ">1") / 4 + SUMIF(R30:R30, ">1") / 4 + SUMIF(T30:T30, ">1") / 4 -> 0 | AM30: =SUMIF(U30:U30, ">=70") / 4 +SUMIF(W30:W30, ">=70") / 4 +SUMIF(Y30:Y30, ">=70") / 4 +SUMIF(AA30:AA30, ">=70") / 4 + SUMIF(V30:V30, ">1") / 4 + SUMIF(X30:X30, ">1") / 4 + SUMIF(Z30:Z30, ">1") / 4 + SUMIF(AB30:AB30, ">1") / 4 -> 0 | AN30: =SUMIF(AC30:AC30, ">=65") / 4 +SUMIF(AE30:AE30, ">=65") / 4 +SUMIF(AG30:AG30, ">=65") / 4 +SUMIF(AI30:AI30, ">=65") / 4 + SUMIF(AD30:AD30, ">1") / 4 + SUMIF(AF30:AF30, ">1") / 4 + SUMIF(AH30:AH30, ">1") / 4 + SUMIF(AJ30:AJ30, ">1") / 4 -> 0 | AO30: =AVERAGE(AK30:AN30) -> 0 | AR30: =IF(AO30<70, AO30*0.5, "") -> 0 | AT30: =AS30*50% -> 0 | AU30: =IF(AS30<>"", IF(AR30="","",AR30+AT30), "") | AV30: =IF(AU30 < 70, AR30*30%, "") | AX30: =AW30*70% -> 0 | AY30: =IF(AW30<>"", IF(AV30="", "", AV30+AX30), "") | AZ30: =IF(AND(AU30<70, AY30<70), AO30, "") | BB30: =IF(AW30<>"", IF(AY30>=70, AY30, IF(AZ30+BA30>=70, AZ30+BA30, "")), IF(AS30<>"", IF(AU30>=70, AU30, ""), IF(AO30>=70, AO30, ""))) | BC30: =IF(AW30<>"", IF(AY30<70, IF(AZ30+BA30<70, AZ30+BA30, ""), ""), IF(AS30<>"", IF(AU30<70, AU30, ""), IF(AO30<70, AO30, ""))) -> 0 | BE30: =SUM(E30+M30+U30+AC30)/4 -> 0 | BF30: =SUM(G30+O30+W30+AE30)/4 -> 0 | BG30: =SUM(I30+Q30+Y30+AG30)/4 -> 0 | BH30: =SUM(K30+S30+AA30+AI30)/4 -> 0 | BI30: =AVERAGE(BE30:BH30) -> 0
A31: 21 | B31: 2A-D-21 | C31: MORALES DE LA CRUZ | D31: FREDELIN NATANAEL | AK31: =SUMIF(E31:E31, ">=70") / 4 +SUMIF(G31:G31, ">=70") / 4 +SUMIF(I31:I31, ">=70") / 4 +SUMIF(K31:K31, ">=70") / 4 + SUMIF(F31:F31, ">1") / 4 + SUMIF(H31:H31, ">1") / 4 + SUMIF(J31:J31, ">1") / 4 + SUMIF(L31:L31, ">1") / 4 -> 0 | AL31: =SUMIF(M31:M31, ">=70") / 4 +SUMIF(O31:O31, ">=70") / 4 +SUMIF(Q31:Q31, ">=70") / 4 +SUMIF(S31:S31, ">=70") / 4 + SUMIF(N31:N31, ">1") / 4 + SUMIF(P31:P31, ">1") / 4 + SUMIF(R31:R31, ">1") / 4 + SUMIF(T31:T31, ">1") / 4 -> 0 | AM31: =SUMIF(U31:U31, ">=70") / 4 +SUMIF(W31:W31, ">=70") / 4 +SUMIF(Y31:Y31, ">=70") / 4 +SUMIF(AA31:AA31, ">=70") / 4 + SUMIF(V31:V31, ">1") / 4 + SUMIF(X31:X31, ">1") / 4 + SUMIF(Z31:Z31, ">1") / 4 + SUMIF(AB31:AB31, ">1") / 4 -> 0 | AN31: =SUMIF(AC31:AC31, ">=65") / 4 +SUMIF(AE31:AE31, ">=65") / 4 +SUMIF(AG31:AG31, ">=65") / 4 +SUMIF(AI31:AI31, ">=65") / 4 + SUMIF(AD31:AD31, ">1") / 4 + SUMIF(AF31:AF31, ">1") / 4 + SUMIF(AH31:AH31, ">1") / 4 + SUMIF(AJ31:AJ31, ">1") / 4 -> 0 | AO31: =AVERAGE(AK31:AN31) -> 0 | AR31: =IF(AO31<70, AO31*0.5, "") -> 0 | AT31: =AS31*50% -> 0 | AU31: =IF(AS31<>"", IF(AR31="","",AR31+AT31), "") | AV31: =IF(AU31 < 70, AR31*30%, "") | AX31: =AW31*70% -> 0 | AY31: =IF(AW31<>"", IF(AV31="", "", AV31+AX31), "") | AZ31: =IF(AND(AU31<70, AY31<70), AO31, "") | BB31: =IF(AW31<>"", IF(AY31>=70, AY31, IF(AZ31+BA31>=70, AZ31+BA31, "")), IF(AS31<>"", IF(AU31>=70, AU31, ""), IF(AO31>=70, AO31, ""))) | BC31: =IF(AW31<>"", IF(AY31<70, IF(AZ31+BA31<70, AZ31+BA31, ""), ""), IF(AS31<>"", IF(AU31<70, AU31, ""), IF(AO31<70, AO31, ""))) -> 0 | BE31: =SUM(E31+M31+U31+AC31)/4 -> 0 | BF31: =SUM(G31+O31+W31+AE31)/4 -> 0 | BG31: =SUM(I31+Q31+Y31+AG31)/4 -> 0 | BH31: =SUM(K31+S31+AA31+AI31)/4 -> 0 | BI31: =AVERAGE(BE31:BH31) -> 0
A32: 22 | B32: 2A-D-22 | C32: ORTIZ | D32: GERMAYORI | E32: 81 | G32: 83 | I32: 84 | K32: 86 | M32: 87 | O32: 83 | Q32: 84 | S32: 86 | U32: 85 | W32: 86 | Y32: 84 | AA32: 86 | AC32: 88 | AE32: 86 | AG32: 87 | AI32: 88 | AK32: =SUMIF(E32:E32, ">=70") / 4 +SUMIF(G32:G32, ">=70") / 4 +SUMIF(I32:I32, ">=70") / 4 +SUMIF(K32:K32, ">=70") / 4 + SUMIF(F32:F32, ">1") / 4 + SUMIF(H32:H32, ">1") / 4 + SUMIF(J32:J32, ">1") / 4 + SUMIF(L32:L32, ">1") / 4 -> 83.5 | AL32: =SUMIF(M32:M32, ">=70") / 4 +SUMIF(O32:O32, ">=70") / 4 +SUMIF(Q32:Q32, ">=70") / 4 +SUMIF(S32:S32, ">=70") / 4 + SUMIF(N32:N32, ">1") / 4 + SUMIF(P32:P32, ">1") / 4 + SUMIF(R32:R32, ">1") / 4 + SUMIF(T32:T32, ">1") / 4 -> 85 | AM32: =SUMIF(U32:U32, ">=70") / 4 +SUMIF(W32:W32, ">=70") / 4 +SUMIF(Y32:Y32, ">=70") / 4 +SUMIF(AA32:AA32, ">=70") / 4 + SUMIF(V32:V32, ">1") / 4 + SUMIF(X32:X32, ">1") / 4 + SUMIF(Z32:Z32, ">1") / 4 + SUMIF(AB32:AB32, ">1") / 4 -> 85.25 | AN32: =SUMIF(AC32:AC32, ">=65") / 4 +SUMIF(AE32:AE32, ">=65") / 4 +SUMIF(AG32:AG32, ">=65") / 4 +SUMIF(AI32:AI32, ">=65") / 4 + SUMIF(AD32:AD32, ">1") / 4 + SUMIF(AF32:AF32, ">1") / 4 + SUMIF(AH32:AH32, ">1") / 4 + SUMIF(AJ32:AJ32, ">1") / 4 -> 87.25 | AO32: =AVERAGE(AK32:AN32) -> 85.25 | AR32: =IF(AO32<70, AO32*0.5, "") | AT32: =AS32*50% -> 0 | AU32: =IF(AS32<>"", IF(AR32="","",AR32+AT32), "") | AV32: =IF(AU32 < 70, AR32*30%, "") | AX32: =AW32*70% -> 0 | AY32: =IF(AW32<>"", IF(AV32="", "", AV32+AX32), "") | AZ32: =IF(AND(AU32<70, AY32<70), AO32, "") | BB32: =IF(AW32<>"", IF(AY32>=70, AY32, IF(AZ32+BA32>=70, AZ32+BA32, "")), IF(AS32<>"", IF(AU32>=70, AU32, ""), IF(AO32>=70, AO32, ""))) -> 85.25 | BC32: =IF(AW32<>"", IF(AY32<70, IF(AZ32+BA32<70, AZ32+BA32, ""), ""), IF(AS32<>"", IF(AU32<70, AU32, ""), IF(AO32<70, AO32, ""))) | BE32: =SUM(E32+M32+U32+AC32)/4 -> 85.25 | BF32: =SUM(G32+O32+W32+AE32)/4 -> 84.5 | BG32: =SUM(I32+Q32+Y32+AG32)/4 -> 84.75 | BH32: =SUM(K32+S32+AA32+AI32)/4 -> 86.5 | BI32: =AVERAGE(BE32:BH32) -> 85.25
A33: 23 | B33: 2A-D-23 | C33: PAYANO BURGOS | D33: JONAS | AK33: =SUMIF(E33:E33, ">=70") / 4 +SUMIF(G33:G33, ">=70") / 4 +SUMIF(I33:I33, ">=70") / 4 +SUMIF(K33:K33, ">=70") / 4 + SUMIF(F33:F33, ">1") / 4 + SUMIF(H33:H33, ">1") / 4 + SUMIF(J33:J33, ">1") / 4 + SUMIF(L33:L33, ">1") / 4 -> 0 | AL33: =SUMIF(M33:M33, ">=70") / 4 +SUMIF(O33:O33, ">=70") / 4 +SUMIF(Q33:Q33, ">=70") / 4 +SUMIF(S33:S33, ">=70") / 4 + SUMIF(N33:N33, ">1") / 4 + SUMIF(P33:P33, ">1") / 4 + SUMIF(R33:R33, ">1") / 4 + SUMIF(T33:T33, ">1") / 4 -> 0 | AM33: =SUMIF(U33:U33, ">=70") / 4 +SUMIF(W33:W33, ">=70") / 4 +SUMIF(Y33:Y33, ">=70") / 4 +SUMIF(AA33:AA33, ">=70") / 4 + SUMIF(V33:V33, ">1") / 4 + SUMIF(X33:X33, ">1") / 4 + SUMIF(Z33:Z33, ">1") / 4 + SUMIF(AB33:AB33, ">1") / 4 -> 0 | AN33: =SUMIF(AC33:AC33, ">=65") / 4 +SUMIF(AE33:AE33, ">=65") / 4 +SUMIF(AG33:AG33, ">=65") / 4 +SUMIF(AI33:AI33, ">=65") / 4 + SUMIF(AD33:AD33, ">1") / 4 + SUMIF(AF33:AF33, ">1") / 4 + SUMIF(AH33:AH33, ">1") / 4 + SUMIF(AJ33:AJ33, ">1") / 4 -> 0 | AO33: =AVERAGE(AK33:AN33) -> 0 | AR33: =IF(AO33<70, AO33*0.5, "") -> 0 | AT33: =AS33*50% -> 0 | AU33: =IF(AS33<>"", IF(AR33="","",AR33+AT33), "") | AV33: =IF(AU33 < 70, AR33*30%, "") | AX33: =AW33*70% -> 0 | AY33: =IF(AW33<>"", IF(AV33="", "", AV33+AX33), "") | AZ33: =IF(AND(AU33<70, AY33<70), AO33, "") | BB33: =IF(AW33<>"", IF(AY33>=70, AY33, IF(AZ33+BA33>=70, AZ33+BA33, "")), IF(AS33<>"", IF(AU33>=70, AU33, ""), IF(AO33>=70, AO33, ""))) | BC33: =IF(AW33<>"", IF(AY33<70, IF(AZ33+BA33<70, AZ33+BA33, ""), ""), IF(AS33<>"", IF(AU33<70, AU33, ""), IF(AO33<70, AO33, ""))) -> 0 | BE33: =SUM(E33+M33+U33+AC33)/4 -> 0 | BF33: =SUM(G33+O33+W33+AE33)/4 -> 0 | BG33: =SUM(I33+Q33+Y33+AG33)/4 -> 0 | BH33: =SUM(K33+S33+AA33+AI33)/4 -> 0 | BI33: =AVERAGE(BE33:BH33) -> 0
A34: 24 | B34: 2A-D-24 | C34: PEREZ ROSARIO | D34: HANSEL JUAN | AK34: =SUMIF(E34:E34, ">=70") / 4 +SUMIF(G34:G34, ">=70") / 4 +SUMIF(I34:I34, ">=70") / 4 +SUMIF(K34:K34, ">=70") / 4 + SUMIF(F34:F34, ">1") / 4 + SUMIF(H34:H34, ">1") / 4 + SUMIF(J34:J34, ">1") / 4 + SUMIF(L34:L34, ">1") / 4 -> 0 | AL34: =SUMIF(M34:M34, ">=70") / 4 +SUMIF(O34:O34, ">=70") / 4 +SUMIF(Q34:Q34, ">=70") / 4 +SUMIF(S34:S34, ">=70") / 4 + SUMIF(N34:N34, ">1") / 4 + SUMIF(P34:P34, ">1") / 4 + SUMIF(R34:R34, ">1") / 4 + SUMIF(T34:T34, ">1") / 4 -> 0 | AM34: =SUMIF(U34:U34, ">=70") / 4 +SUMIF(W34:W34, ">=70") / 4 +SUMIF(Y34:Y34, ">=70") / 4 +SUMIF(AA34:AA34, ">=70") / 4 + SUMIF(V34:V34, ">1") / 4 + SUMIF(X34:X34, ">1") / 4 + SUMIF(Z34:Z34, ">1") / 4 + SUMIF(AB34:AB34, ">1") / 4 -> 0 | AN34: =SUMIF(AC34:AC34, ">=65") / 4 +SUMIF(AE34:AE34, ">=65") / 4 +SUMIF(AG34:AG34, ">=65") / 4 +SUMIF(AI34:AI34, ">=65") / 4 + SUMIF(AD34:AD34, ">1") / 4 + SUMIF(AF34:AF34, ">1") / 4 + SUMIF(AH34:AH34, ">1") / 4 + SUMIF(AJ34:AJ34, ">1") / 4 -> 0 | AO34: =AVERAGE(AK34:AN34) -> 0 | AR34: =IF(AO34<70, AO34*0.5, "") -> 0 | AT34: =AS34*50% -> 0 | AU34: =IF(AS34<>"", IF(AR34="","",AR34+AT34), "") | AV34: =IF(AU34 < 70, AR34*30%, "") | AX34: =AW34*70% -> 0 | AY34: =IF(AW34<>"", IF(AV34="", "", AV34+AX34), "") | AZ34: =IF(AND(AU34<70, AY34<70), AO34, "") | BB34: =IF(AW34<>"", IF(AY34>=70, AY34, IF(AZ34+BA34>=70, AZ34+BA34, "")), IF(AS34<>"", IF(AU34>=70, AU34, ""), IF(AO34>=70, AO34, ""))) | BC34: =IF(AW34<>"", IF(AY34<70, IF(AZ34+BA34<70, AZ34+BA34, ""), ""), IF(AS34<>"", IF(AU34<70, AU34, ""), IF(AO34<70, AO34, ""))) -> 0 | BE34: =SUM(E34+M34+U34+AC34)/4 -> 0 | BF34: =SUM(G34+O34+W34+AE34)/4 -> 0 | BG34: =SUM(I34+Q34+Y34+AG34)/4 -> 0 | BH34: =SUM(K34+S34+AA34+AI34)/4 -> 0 | BI34: =AVERAGE(BE34:BH34) -> 0
A35: 25 | B35: 2A-D-25 | C35: PIERRE | D35: MALAIKA | AK35: =SUMIF(E35:E35, ">=70") / 4 +SUMIF(G35:G35, ">=70") / 4 +SUMIF(I35:I35, ">=70") / 4 +SUMIF(K35:K35, ">=70") / 4 + SUMIF(F35:F35, ">1") / 4 + SUMIF(H35:H35, ">1") / 4 + SUMIF(J35:J35, ">1") / 4 + SUMIF(L35:L35, ">1") / 4 -> 0 | AL35: =SUMIF(M35:M35, ">=70") / 4 +SUMIF(O35:O35, ">=70") / 4 +SUMIF(Q35:Q35, ">=70") / 4 +SUMIF(S35:S35, ">=70") / 4 + SUMIF(N35:N35, ">1") / 4 + SUMIF(P35:P35, ">1") / 4 + SUMIF(R35:R35, ">1") / 4 + SUMIF(T35:T35, ">1") / 4 -> 0 | AM35: =SUMIF(U35:U35, ">=70") / 4 +SUMIF(W35:W35, ">=70") / 4 +SUMIF(Y35:Y35, ">=70") / 4 +SUMIF(AA35:AA35, ">=70") / 4 + SUMIF(V35:V35, ">1") / 4 + SUMIF(X35:X35, ">1") / 4 + SUMIF(Z35:Z35, ">1") / 4 + SUMIF(AB35:AB35, ">1") / 4 -> 0 | AN35: =SUMIF(AC35:AC35, ">=65") / 4 +SUMIF(AE35:AE35, ">=65") / 4 +SUMIF(AG35:AG35, ">=65") / 4 +SUMIF(AI35:AI35, ">=65") / 4 + SUMIF(AD35:AD35, ">1") / 4 + SUMIF(AF35:AF35, ">1") / 4 + SUMIF(AH35:AH35, ">1") / 4 + SUMIF(AJ35:AJ35, ">1") / 4 -> 0 | AO35: =AVERAGE(AK35:AN35) -> 0 | AR35: =IF(AO35<70, AO35*0.5, "") -> 0 | AT35: =AS35*50% -> 0 | AU35: =IF(AS35<>"", IF(AR35="","",AR35+AT35), "") | AV35: =IF(AU35 < 70, AR35*30%, "") | AX35: =AW35*70% -> 0 | AY35: =IF(AW35<>"", IF(AV35="", "", AV35+AX35), "") | AZ35: =IF(AND(AU35<70, AY35<70), AO35, "") | BB35: =IF(AW35<>"", IF(AY35>=70, AY35, IF(AZ35+BA35>=70, AZ35+BA35, "")), IF(AS35<>"", IF(AU35>=70, AU35, ""), IF(AO35>=70, AO35, ""))) | BC35: =IF(AW35<>"", IF(AY35<70, IF(AZ35+BA35<70, AZ35+BA35, ""), ""), IF(AS35<>"", IF(AU35<70, AU35, ""), IF(AO35<70, AO35, ""))) -> 0 | BE35: =SUM(E35+M35+U35+AC35)/4 -> 0 | BF35: =SUM(G35+O35+W35+AE35)/4 -> 0 | BG35: =SUM(I35+Q35+Y35+AG35)/4 -> 0 | BH35: =SUM(K35+S35+AA35+AI35)/4 -> 0 | BI35: =AVERAGE(BE35:BH35) -> 0
A36: 26 | B36: 2A-D-26 | C36: PIERRE | D36: WILMELISA | AK36: =SUMIF(E36:E36, ">=70") / 4 +SUMIF(G36:G36, ">=70") / 4 +SUMIF(I36:I36, ">=70") / 4 +SUMIF(K36:K36, ">=70") / 4 + SUMIF(F36:F36, ">1") / 4 + SUMIF(H36:H36, ">1") / 4 + SUMIF(J36:J36, ">1") / 4 + SUMIF(L36:L36, ">1") / 4 -> 0 | AL36: =SUMIF(M36:M36, ">=70") / 4 +SUMIF(O36:O36, ">=70") / 4 +SUMIF(Q36:Q36, ">=70") / 4 +SUMIF(S36:S36, ">=70") / 4 + SUMIF(N36:N36, ">1") / 4 + SUMIF(P36:P36, ">1") / 4 + SUMIF(R36:R36, ">1") / 4 + SUMIF(T36:T36, ">1") / 4 -> 0 | AM36: =SUMIF(U36:U36, ">=70") / 4 +SUMIF(W36:W36, ">=70") / 4 +SUMIF(Y36:Y36, ">=70") / 4 +SUMIF(AA36:AA36, ">=70") / 4 + SUMIF(V36:V36, ">1") / 4 + SUMIF(X36:X36, ">1") / 4 + SUMIF(Z36:Z36, ">1") / 4 + SUMIF(AB36:AB36, ">1") / 4 -> 0 | AN36: =SUMIF(AC36:AC36, ">=65") / 4 +SUMIF(AE36:AE36, ">=65") / 4 +SUMIF(AG36:AG36, ">=65") / 4 +SUMIF(AI36:AI36, ">=65") / 4 + SUMIF(AD36:AD36, ">1") / 4 + SUMIF(AF36:AF36, ">1") / 4 + SUMIF(AH36:AH36, ">1") / 4 + SUMIF(AJ36:AJ36, ">1") / 4 -> 0 | AO36: =AVERAGE(AK36:AN36) -> 0 | AR36: =IF(AO36<70, AO36*0.5, "") -> 0 | AT36: =AS36*50% -> 0 | AU36: =IF(AS36<>"", IF(AR36="","",AR36+AT36), "") | AV36: =IF(AU36 < 70, AR36*30%, "") | AX36: =AW36*70% -> 0 | AY36: =IF(AW36<>"", IF(AV36="", "", AV36+AX36), "") | AZ36: =IF(AND(AU36<70, AY36<70), AO36, "") | BB36: =IF(AW36<>"", IF(AY36>=70, AY36, IF(AZ36+BA36>=70, AZ36+BA36, "")), IF(AS36<>"", IF(AU36>=70, AU36, ""), IF(AO36>=70, AO36, ""))) | BC36: =IF(AW36<>"", IF(AY36<70, IF(AZ36+BA36<70, AZ36+BA36, ""), ""), IF(AS36<>"", IF(AU36<70, AU36, ""), IF(AO36<70, AO36, ""))) -> 0 | BE36: =SUM(E36+M36+U36+AC36)/4 -> 0 | BF36: =SUM(G36+O36+W36+AE36)/4 -> 0 | BG36: =SUM(I36+Q36+Y36+AG36)/4 -> 0 | BH36: =SUM(K36+S36+AA36+AI36)/4 -> 0 | BI36: =AVERAGE(BE36:BH36) -> 0
A37: 27 | B37: 2A-D-27 | C37: POZO PEREZ | D37: YAFREISY | E37: 88 | G37: 90 | I37: 92 | K37: 91 | M37: 93 | O37: 91 | Q37: 90 | S37: 92 | U37: 93 | W37: 92 | Y37: 94 | AA37: 91 | AC37: 93 | AE37: 90 | AG37: 92 | AI37: 95 | AK37: =SUMIF(E37:E37, ">=70") / 4 +SUMIF(G37:G37, ">=70") / 4 +SUMIF(I37:I37, ">=70") / 4 +SUMIF(K37:K37, ">=70") / 4 + SUMIF(F37:F37, ">1") / 4 + SUMIF(H37:H37, ">1") / 4 + SUMIF(J37:J37, ">1") / 4 + SUMIF(L37:L37, ">1") / 4 -> 90.25 | AL37: =SUMIF(M37:M37, ">=70") / 4 +SUMIF(O37:O37, ">=70") / 4 +SUMIF(Q37:Q37, ">=70") / 4 +SUMIF(S37:S37, ">=70") / 4 + SUMIF(N37:N37, ">1") / 4 + SUMIF(P37:P37, ">1") / 4 + SUMIF(R37:R37, ">1") / 4 + SUMIF(T37:T37, ">1") / 4 -> 91.5 | AM37: =SUMIF(U37:U37, ">=70") / 4 +SUMIF(W37:W37, ">=70") / 4 +SUMIF(Y37:Y37, ">=70") / 4 +SUMIF(AA37:AA37, ">=70") / 4 + SUMIF(V37:V37, ">1") / 4 + SUMIF(X37:X37, ">1") / 4 + SUMIF(Z37:Z37, ">1") / 4 + SUMIF(AB37:AB37, ">1") / 4 -> 92.5 | AN37: =SUMIF(AC37:AC37, ">=65") / 4 +SUMIF(AE37:AE37, ">=65") / 4 +SUMIF(AG37:AG37, ">=65") / 4 +SUMIF(AI37:AI37, ">=65") / 4 + SUMIF(AD37:AD37, ">1") / 4 + SUMIF(AF37:AF37, ">1") / 4 + SUMIF(AH37:AH37, ">1") / 4 + SUMIF(AJ37:AJ37, ">1") / 4 -> 92.5 | AO37: =AVERAGE(AK37:AN37) -> 91.6875 | AR37: =IF(AO37<70, AO37*0.5, "") | AT37: =AS37*50% -> 0 | AU37: =IF(AS37<>"", IF(AR37="","",AR37+AT37), "") | AV37: =IF(AU37 < 70, AR37*30%, "") | AX37: =AW37*70% -> 0 | AY37: =IF(AW37<>"", IF(AV37="", "", AV37+AX37), "") | AZ37: =IF(AND(AU37<70, AY37<70), AO37, "") | BB37: =IF(AW37<>"", IF(AY37>=70, AY37, IF(AZ37+BA37>=70, AZ37+BA37, "")), IF(AS37<>"", IF(AU37>=70, AU37, ""), IF(AO37>=70, AO37, ""))) -> 91.6875 | BC37: =IF(AW37<>"", IF(AY37<70, IF(AZ37+BA37<70, AZ37+BA37, ""), ""), IF(AS37<>"", IF(AU37<70, AU37, ""), IF(AO37<70, AO37, ""))) | BE37: =SUM(E37+M37+U37+AC37)/4 -> 91.75 | BF37: =SUM(G37+O37+W37+AE37)/4 -> 90.75 | BG37: =SUM(I37+Q37+Y37+AG37)/4 -> 92 | BH37: =SUM(K37+S37+AA37+AI37)/4 -> 92.25 | BI37: =AVERAGE(BE37:BH37) -> 91.6875
A38: 28 | B38: 2A-D-28 | C38: RAMIREZ MATOS | D38: ANA DANIELA | E38: 96 | G38: 95 | I38: 97 | K38: 96 | M38: 98 | O38: 99 | Q38: 95 | S38: 98 | U38: 96 | W38: 97 | Y38: 99 | AA38: 98 | AC38: 96 | AE38: 95 | AG38: 97 | AI38: 96 | AK38: =SUMIF(E38:E38, ">=70") / 4 +SUMIF(G38:G38, ">=70") / 4 +SUMIF(I38:I38, ">=70") / 4 +SUMIF(K38:K38, ">=70") / 4 + SUMIF(F38:F38, ">1") / 4 + SUMIF(H38:H38, ">1") / 4 + SUMIF(J38:J38, ">1") / 4 + SUMIF(L38:L38, ">1") / 4 -> 96 | AL38: =SUMIF(M38:M38, ">=70") / 4 +SUMIF(O38:O38, ">=70") / 4 +SUMIF(Q38:Q38, ">=70") / 4 +SUMIF(S38:S38, ">=70") / 4 + SUMIF(N38:N38, ">1") / 4 + SUMIF(P38:P38, ">1") / 4 + SUMIF(R38:R38, ">1") / 4 + SUMIF(T38:T38, ">1") / 4 -> 97.5 | AM38: =SUMIF(U38:U38, ">=70") / 4 +SUMIF(W38:W38, ">=70") / 4 +SUMIF(Y38:Y38, ">=70") / 4 +SUMIF(AA38:AA38, ">=70") / 4 + SUMIF(V38:V38, ">1") / 4 + SUMIF(X38:X38, ">1") / 4 + SUMIF(Z38:Z38, ">1") / 4 + SUMIF(AB38:AB38, ">1") / 4 -> 97.5 | AN38: =SUMIF(AC38:AC38, ">=65") / 4 +SUMIF(AE38:AE38, ">=65") / 4 +SUMIF(AG38:AG38, ">=65") / 4 +SUMIF(AI38:AI38, ">=65") / 4 + SUMIF(AD38:AD38, ">1") / 4 + SUMIF(AF38:AF38, ">1") / 4 + SUMIF(AH38:AH38, ">1") / 4 + SUMIF(AJ38:AJ38, ">1") / 4 -> 96 | AO38: =AVERAGE(AK38:AN38) -> 96.75 | AR38: =IF(AO38<70, AO38*0.5, "") | AT38: =AS38*50% -> 0 | AU38: =IF(AS38<>"", IF(AR38="","",AR38+AT38), "") | AV38: =IF(AU38 < 70, AR38*30%, "") | AX38: =AW38*70% -> 0 | AY38: =IF(AW38<>"", IF(AV38="", "", AV38+AX38), "") | AZ38: =IF(AND(AU38<70, AY38<70), AO38, "") | BB38: =IF(AW38<>"", IF(AY38>=70, AY38, IF(AZ38+BA38>=70, AZ38+BA38, "")), IF(AS38<>"", IF(AU38>=70, AU38, ""), IF(AO38>=70, AO38, ""))) -> 96.75 | BC38: =IF(AW38<>"", IF(AY38<70, IF(AZ38+BA38<70, AZ38+BA38, ""), ""), IF(AS38<>"", IF(AU38<70, AU38, ""), IF(AO38<70, AO38, ""))) | BE38: =SUM(E38+M38+U38+AC38)/4 -> 96.5 | BF38: =SUM(G38+O38+W38+AE38)/4 -> 96.5 | BG38: =SUM(I38+Q38+Y38+AG38)/4 -> 97 | BH38: =SUM(K38+S38+AA38+AI38)/4 -> 97 | BI38: =AVERAGE(BE38:BH38) -> 96.75
A39: 29 | B39: 2A-D-29 | C39: REGALADO | D39: LEONELI | AK39: =SUMIF(E39:E39, ">=70") / 4 +SUMIF(G39:G39, ">=70") / 4 +SUMIF(I39:I39, ">=70") / 4 +SUMIF(K39:K39, ">=70") / 4 + SUMIF(F39:F39, ">1") / 4 + SUMIF(H39:H39, ">1") / 4 + SUMIF(J39:J39, ">1") / 4 + SUMIF(L39:L39, ">1") / 4 -> 0 | AL39: =SUMIF(M39:M39, ">=70") / 4 +SUMIF(O39:O39, ">=70") / 4 +SUMIF(Q39:Q39, ">=70") / 4 +SUMIF(S39:S39, ">=70") / 4 + SUMIF(N39:N39, ">1") / 4 + SUMIF(P39:P39, ">1") / 4 + SUMIF(R39:R39, ">1") / 4 + SUMIF(T39:T39, ">1") / 4 -> 0 | AM39: =SUMIF(U39:U39, ">=70") / 4 +SUMIF(W39:W39, ">=70") / 4 +SUMIF(Y39:Y39, ">=70") / 4 +SUMIF(AA39:AA39, ">=70") / 4 + SUMIF(V39:V39, ">1") / 4 + SUMIF(X39:X39, ">1") / 4 + SUMIF(Z39:Z39, ">1") / 4 + SUMIF(AB39:AB39, ">1") / 4 -> 0 | AN39: =SUMIF(AC39:AC39, ">=65") / 4 +SUMIF(AE39:AE39, ">=65") / 4 +SUMIF(AG39:AG39, ">=65") / 4 +SUMIF(AI39:AI39, ">=65") / 4 + SUMIF(AD39:AD39, ">1") / 4 + SUMIF(AF39:AF39, ">1") / 4 + SUMIF(AH39:AH39, ">1") / 4 + SUMIF(AJ39:AJ39, ">1") / 4 -> 0 | AO39: =AVERAGE(AK39:AN39) -> 0 | AR39: =IF(AO39<70, AO39*0.5, "") -> 0 | AT39: =AS39*50% -> 0 | AU39: =IF(AS39<>"", IF(AR39="","",AR39+AT39), "") | AV39: =IF(AU39 < 70, AR39*30%, "") | AX39: =AW39*70% -> 0 | AY39: =IF(AW39<>"", IF(AV39="", "", AV39+AX39), "") | AZ39: =IF(AND(AU39<70, AY39<70), AO39, "") | BB39: =IF(AW39<>"", IF(AY39>=70, AY39, IF(AZ39+BA39>=70, AZ39+BA39, "")), IF(AS39<>"", IF(AU39>=70, AU39, ""), IF(AO39>=70, AO39, ""))) | BC39: =IF(AW39<>"", IF(AY39<70, IF(AZ39+BA39<70, AZ39+BA39, ""), ""), IF(AS39<>"", IF(AU39<70, AU39, ""), IF(AO39<70, AO39, ""))) -> 0 | BE39: =SUM(E39+M39+U39+AC39)/4 -> 0 | BF39: =SUM(G39+O39+W39+AE39)/4 -> 0 | BG39: =SUM(I39+Q39+Y39+AG39)/4 -> 0 | BH39: =SUM(K39+S39+AA39+AI39)/4 -> 0 | BI39: =AVERAGE(BE39:BH39) -> 0
A40: 30 | B40: 2A-D-30 | C40: RIVERAS CASTOR | D40: JUAN JESUS | AK40: =SUMIF(E40:E40, ">=70") / 4 +SUMIF(G40:G40, ">=70") / 4 +SUMIF(I40:I40, ">=70") / 4 +SUMIF(K40:K40, ">=70") / 4 + SUMIF(F40:F40, ">1") / 4 + SUMIF(H40:H40, ">1") / 4 + SUMIF(J40:J40, ">1") / 4 + SUMIF(L40:L40, ">1") / 4 -> 0 | AL40: =SUMIF(M40:M40, ">=70") / 4 +SUMIF(O40:O40, ">=70") / 4 +SUMIF(Q40:Q40, ">=70") / 4 +SUMIF(S40:S40, ">=70") / 4 + SUMIF(N40:N40, ">1") / 4 + SUMIF(P40:P40, ">1") / 4 + SUMIF(R40:R40, ">1") / 4 + SUMIF(T40:T40, ">1") / 4 -> 0 | AM40: =SUMIF(U40:U40, ">=70") / 4 +SUMIF(W40:W40, ">=70") / 4 +SUMIF(Y40:Y40, ">=70") / 4 +SUMIF(AA40:AA40, ">=70") / 4 + SUMIF(V40:V40, ">1") / 4 + SUMIF(X40:X40, ">1") / 4 + SUMIF(Z40:Z40, ">1") / 4 + SUMIF(AB40:AB40, ">1") / 4 -> 0 | AN40: =SUMIF(AC40:AC40, ">=65") / 4 +SUMIF(AE40:AE40, ">=65") / 4 +SUMIF(AG40:AG40, ">=65") / 4 +SUMIF(AI40:AI40, ">=65") / 4 + SUMIF(AD40:AD40, ">1") / 4 + SUMIF(AF40:AF40, ">1") / 4 + SUMIF(AH40:AH40, ">1") / 4 + SUMIF(AJ40:AJ40, ">1") / 4 -> 0 | AO40: =AVERAGE(AK40:AN40) -> 0 | AR40: =IF(AO40<70, AO40*0.5, "") -> 0 | AT40: =AS40*50% -> 0 | AU40: =IF(AS40<>"", IF(AR40="","",AR40+AT40), "") | AV40: =IF(AU40 < 70, AR40*30%, "") | AX40: =AW40*70% -> 0 | AY40: =IF(AW40<>"", IF(AV40="", "", AV40+AX40), "") | AZ40: =IF(AND(AU40<70, AY40<70), AO40, "") | BB40: =IF(AW40<>"", IF(AY40>=70, AY40, IF(AZ40+BA40>=70, AZ40+BA40, "")), IF(AS40<>"", IF(AU40>=70, AU40, ""), IF(AO40>=70, AO40, ""))) | BC40: =IF(AW40<>"", IF(AY40<70, IF(AZ40+BA40<70, AZ40+BA40, ""), ""), IF(AS40<>"", IF(AU40<70, AU40, ""), IF(AO40<70, AO40, ""))) -> 0 | BE40: =SUM(E40+M40+U40+AC40)/4 -> 0 | BF40: =SUM(G40+O40+W40+AE40)/4 -> 0 | BG40: =SUM(I40+Q40+Y40+AG40)/4 -> 0 | BH40: =SUM(K40+S40+AA40+AI40)/4 -> 0 | BI40: =AVERAGE(BE40:BH40) -> 0
A41: 31 | B41: 2A-D-31 | C41: SAINLOT | D41: MILOVE | E41: 81 | G41: 83 | I41: 80 | K41: 82 | M41: 83 | O41: 79 | Q41: 84 | S41: 83 | U41: 84 | W41: 83 | Y41: 86 | AA41: 84 | AC41: 83 | AE41: 82 | AG41: 86 | AI41: 84 | AK41: =SUMIF(E41:E41, ">=70") / 4 +SUMIF(G41:G41, ">=70") / 4 +SUMIF(I41:I41, ">=70") / 4 +SUMIF(K41:K41, ">=70") / 4 + SUMIF(F41:F41, ">1") / 4 + SUMIF(H41:H41, ">1") / 4 + SUMIF(J41:J41, ">1") / 4 + SUMIF(L41:L41, ">1") / 4 -> 81.5 | AL41: =SUMIF(M41:M41, ">=70") / 4 +SUMIF(O41:O41, ">=70") / 4 +SUMIF(Q41:Q41, ">=70") / 4 +SUMIF(S41:S41, ">=70") / 4 + SUMIF(N41:N41, ">1") / 4 + SUMIF(P41:P41, ">1") / 4 + SUMIF(R41:R41, ">1") / 4 + SUMIF(T41:T41, ">1") / 4 -> 82.25 | AM41: =SUMIF(U41:U41, ">=70") / 4 +SUMIF(W41:W41, ">=70") / 4 +SUMIF(Y41:Y41, ">=70") / 4 +SUMIF(AA41:AA41, ">=70") / 4 + SUMIF(V41:V41, ">1") / 4 + SUMIF(X41:X41, ">1") / 4 + SUMIF(Z41:Z41, ">1") / 4 + SUMIF(AB41:AB41, ">1") / 4 -> 84.25 | AN41: =SUMIF(AC41:AC41, ">=65") / 4 +SUMIF(AE41:AE41, ">=65") / 4 +SUMIF(AG41:AG41, ">=65") / 4 +SUMIF(AI41:AI41, ">=65") / 4 + SUMIF(AD41:AD41, ">1") / 4 + SUMIF(AF41:AF41, ">1") / 4 + SUMIF(AH41:AH41, ">1") / 4 + SUMIF(AJ41:AJ41, ">1") / 4 -> 83.75 | AO41: =AVERAGE(AK41:AN41) -> 82.9375 | AR41: =IF(AO41<70, AO41*0.5, "") | AT41: =AS41*50% -> 0 | AU41: =IF(AS41<>"", IF(AR41="","",AR41+AT41), "") | AV41: =IF(AU41 < 70, AR41*30%, "") | AX41: =AW41*70% -> 0 | AY41: =IF(AW41<>"", IF(AV41="", "", AV41+AX41), "") | AZ41: =IF(AND(AU41<70, AY41<70), AO41, "") | BB41: =IF(AW41<>"", IF(AY41>=70, AY41, IF(AZ41+BA41>=70, AZ41+BA41, "")), IF(AS41<>"", IF(AU41>=70, AU41, ""), IF(AO41>=70, AO41, ""))) -> 82.9375 | BC41: =IF(AW41<>"", IF(AY41<70, IF(AZ41+BA41<70, AZ41+BA41, ""), ""), IF(AS41<>"", IF(AU41<70, AU41, ""), IF(AO41<70, AO41, ""))) | BE41: =SUM(E41+M41+U41+AC41)/4 -> 82.75 | BF41: =SUM(G41+O41+W41+AE41)/4 -> 81.75 | BG41: =SUM(I41+Q41+Y41+AG41)/4 -> 84 | BH41: =SUM(K41+S41+AA41+AI41)/4 -> 83.25 | BI41: =AVERAGE(BE41:BH41) -> 82.9375
A42: 32 | B42: 2A-D-32 | C42: SELMO | D42: VLADIMIR | AK42: =SUMIF(E42:E42, ">=70") / 4 +SUMIF(G42:G42, ">=70") / 4 +SUMIF(I42:I42, ">=70") / 4 +SUMIF(K42:K42, ">=70") / 4 + SUMIF(F42:F42, ">1") / 4 + SUMIF(H42:H42, ">1") / 4 + SUMIF(J42:J42, ">1") / 4 + SUMIF(L42:L42, ">1") / 4 -> 0 | AL42: =SUMIF(M42:M42, ">=70") / 4 +SUMIF(O42:O42, ">=70") / 4 +SUMIF(Q42:Q42, ">=70") / 4 +SUMIF(S42:S42, ">=70") / 4 + SUMIF(N42:N42, ">1") / 4 + SUMIF(P42:P42, ">1") / 4 + SUMIF(R42:R42, ">1") / 4 + SUMIF(T42:T42, ">1") / 4 -> 0 | AM42: =SUMIF(U42:U42, ">=70") / 4 +SUMIF(W42:W42, ">=70") / 4 +SUMIF(Y42:Y42, ">=70") / 4 +SUMIF(AA42:AA42, ">=70") / 4 + SUMIF(V42:V42, ">1") / 4 + SUMIF(X42:X42, ">1") / 4 + SUMIF(Z42:Z42, ">1") / 4 + SUMIF(AB42:AB42, ">1") / 4 -> 0 | AN42: =SUMIF(AC42:AC42, ">=65") / 4 +SUMIF(AE42:AE42, ">=65") / 4 +SUMIF(AG42:AG42, ">=65") / 4 +SUMIF(AI42:AI42, ">=65") / 4 + SUMIF(AD42:AD42, ">1") / 4 + SUMIF(AF42:AF42, ">1") / 4 + SUMIF(AH42:AH42, ">1") / 4 + SUMIF(AJ42:AJ42, ">1") / 4 -> 0 | AO42: =AVERAGE(AK42:AN42) -> 0 | AR42: =IF(AO42<70, AO42*0.5, "") -> 0 | AT42: =AS42*50% -> 0 | AU42: =IF(AS42<>"", IF(AR42="","",AR42+AT42), "") | AV42: =IF(AU42 < 70, AR42*30%, "") | AX42: =AW42*70% -> 0 | AY42: =IF(AW42<>"", IF(AV42="", "", AV42+AX42), "") | AZ42: =IF(AND(AU42<70, AY42<70), AO42, "") | BB42: =IF(AW42<>"", IF(AY42>=70, AY42, IF(AZ42+BA42>=70, AZ42+BA42, "")), IF(AS42<>"", IF(AU42>=70, AU42, ""), IF(AO42>=70, AO42, ""))) | BC42: =IF(AW42<>"", IF(AY42<70, IF(AZ42+BA42<70, AZ42+BA42, ""), ""), IF(AS42<>"", IF(AU42<70, AU42, ""), IF(AO42<70, AO42, ""))) -> 0 | BE42: =SUM(E42+M42+U42+AC42)/4 -> 0 | BF42: =SUM(G42+O42+W42+AE42)/4 -> 0 | BG42: =SUM(I42+Q42+Y42+AG42)/4 -> 0 | BH42: =SUM(K42+S42+AA42+AI42)/4 -> 0 | BI42: =AVERAGE(BE42:BH42) -> 0
