Workbook

Sheet ESPANOL
D7: CALCULO DE NOTAS | AN7: Calificacion Final | AO7: % DE ASISTENCIA ANUAL | AQ7: CALIFICACION COMPLETIVA | AU7: CALIFICACION EXTRAORDINARIA | AY7: EVALUACION ESPECIAL | BA7: SITUACIONFINAL EN LA ASIGNATURA | BD7: PARA HOJA PERIODO C.F.
A9: NO | B9: NOMBRES | C9: APELLIDOS | D9: CE - LE1 | L9: CE - LE2, LE3 | T9: CE - LE4, LE6 | AB9: CE - LE5, LE7 | AJ9: PCP 1 | AK9: PCP 2 | AL9: PCP 3 | AM9: PCP 4 | AQ9: 50% C.F | AR9: C.E.C. | AS9: 50% C.E.C. | AT9: C.C.F | AU9: 30% C.F. | AV9: C.E.EX | AW9: 70% C.E.EX | AX9: C.EX.F | AY9: C.F. | AZ9: C.E. | BA9: A | BB9: R
D10: P1 | E10: RP1 | F10: P2 | G10: RP2 | H10: P3 | I10: RP3 | J10: P4 | K10: RP4 | L10: P1 | M10: RP1 | N10: P2 | O10: RP2 | P10: P3 | Q10: RP3 | R10: P4 | S10: RP4 | T10: P1 | U10: RP1 | V10: P2 | W10: RP3 | X10: P3 | Y10: RP4 | Z10: P4 | AA10: RP4 | AB10: P1 | AC10: RP1 | AD10: P2 | AE10: RP3 | AF10: P3 | AG10: RP4 | AH10: P4 | AI10: RP4
A11: 1 | B11: ABRIL | C11: GUZMAN VILORIO | AJ11: =SUMIF(D11:D11, ">=70") / 4 +SUMIF(F11:F11, ">=70") / 4 +SUMIF(H11:H11, ">=70") / 4 +SUMIF(J11:J11, ">=70") / 4 + SUMIF(E11:E11, ">1") / 4 + SUMIF(G11:G11, ">1") / 4 + SUMIF(I11:I11, ">1") / 4 + SUMIF(K11:K11, ">1") / 4 -> 0 | AK11: =SUMIF(L11:L11, ">=70") / 4 +SUMIF(N11:N11, ">=70") / 4 +SUMIF(P11:P11, ">=70") / 4 +SUMIF(R11:R11, ">=70") / 4 + SUMIF(M11:M11, ">1") / 4 + SUMIF(O11:O11, ">1") / 4 + SUMIF(Q11:Q11, ">1") / 4 + SUMIF(S11:S11, ">1") / 4 -> 0 | AL11: =SUMIF(T11:T11, ">=70") / 4 +SUMIF(V11:V11, ">=70") / 4 +SUMIF(X11:X11, ">=70") / 4 +SUMIF(Z11:Z11, ">=70") / 4 + SUMIF(U11:U11, ">1") / 4 + SUMIF(W11:W11, ">1") / 4 + SUMIF(Y11:Y11, ">1") / 4 + SUMIF(AA11:AA11, ">1") / 4 -> 0 | AM11: =SUMIF(AB11:AB11, ">=70") / 4 +SUMIF(AD11:AD11, ">=70") / 4 +SUMIF(AF11:AF11, ">=70") / 4 +SUMIF(AH11:AH11, ">=70") / 4 + SUMIF(AC11:AC11, ">1") / 4 + SUMIF(AE11:AE11, ">1") / 4 + SUMIF(AG11:AG11, ">1") / 4 + SUMIF(AI11:AI11, ">1") / 4 -> 0 | AN11: =AVERAGE(AJ11:AM11) -> 0 | AQ11: =IF(AN11<70, AN11*0.5, "") -> 0 | AS11: =AR11*50% -> 0 | AT11: =IF(AR11<>"", IF(AQ11="","",AQ11+AS11), "") | AU11: =IF(AT11 < 70, AQ11*30%, "") | AW11: =AV11*70% -> 0 | AX11: =IF(AV11<>"", IF(AU11="", "", AU11+AW11), "") | AY11: =IF(AND(AT11<70, AX11<70), AN11, "") | BA11: =IF(AV11<>"", IF(AX11>=70, AX11, IF(AY11+AZ11>=70, AY11+AZ11, "")), IF(AR11<>"", IF(AT11>=70, AT11, ""), IF(AN11>=70, AN11, ""))) | BB11: =IF(AV11<>"", IF(AX11<70, IF(AY11+AZ11<70, AY11+AZ11, ""), ""), IF(AR11<>"", IF(AT11<70, AT11, ""), IF(AN11<70, AN11, ""))) -> 0 | BD11: =IF(AND(NOT(ISBLANK(AY11)), NOT(ISBLANK(AZ11))), AY11 + AZ11, "")
A12: 2 | B12: ALBYS ANDRES | C12: SEVERINO MINIEL | AJ12: =SUMIF(D12:D12, ">=70") / 4 +SUMIF(F12:F12, ">=70") / 4 +SUMIF(H12:H12, ">=70") / 4 +SUMIF(J12:J12, ">=70") / 4 + SUMIF(E12:E12, ">1") / 4 + SUMIF(G12:G12, ">1") / 4 + SUMIF(I12:I12, ">1") / 4 + SUMIF(K12:K12, ">1") / 4 -> 0 | AK12: =SUMIF(L12:L12, ">=70") / 4 +SUMIF(N12:N12, ">=70") / 4 +SUMIF(P12:P12, ">=70") / 4 +SUMIF(R12:R12, ">=70") / 4 + SUMIF(M12:M12, ">1") / 4 + SUMIF(O12:O12, ">1") / 4 + SUMIF(Q12:Q12, ">1") / 4 + SUMIF(S12:S12, ">1") / 4 -> 0 | AL12: =SUMIF(T12:T12, ">=70") / 4 +SUMIF(V12:V12, ">=70") / 4 +SUMIF(X12:X12, ">=70") / 4 +SUMIF(Z12:Z12, ">=70") / 4 + SUMIF(U12:U12, ">1") / 4 + SUMIF(W12:W12, ">1") / 4 + SUMIF(Y12:Y12, ">1") / 4 + SUMIF(AA12:AA12, ">1") / 4 -> 0 | AM12: =SUMIF(AB12:AB12, ">=65") / 4 +SUMIF(AD12:AD12, ">=65") / 4 +SUMIF(AF12:AF12, ">=65") / 4 +SUMIF(AH12:AH12, ">=65") / 4 + SUMIF(AC12:AC12, ">1") / 4 + SUMIF(AE12:AE12, ">1") / 4 + SUMIF(AG12:AG12, ">1") / 4 + SUMIF(AI12:AI12, ">1") / 4 -> 0 | AN12: =AVERAGE(AJ12:AM12) -> 0 | AQ12: =IF(AN12<70, AN12*0.5, "") -> 0 | AS12: =AR12*50% -> 0 | AT12: =IF(AR12<>"", IF(AQ12="","",AQ12+AS12), "") | AU12: =IF(AT12 < 70, AQ12*30%, "") | AW12: =AV12*70% -> 0 | AX12: =IF(AV12<>"", IF(AU12="", "", AU12+AW12), "") | AY12: =IF(AND(AT12<70, AX12<70), AN12, "") | BA12: =IF(AV12<>"", IF(AX12>=70, AX12, IF(AY12+AZ12>=70, AY12+AZ12, "")), IF(AR12<>"", IF(AT12>=70, AT12, ""), IF(AN12>=70, AN12, ""))) | BB12: =IF(AV12<>"", IF(AX12<70, IF(AY12+AZ12<70, AY12+AZ12, ""), ""), IF(AR12<>"", IF(AT12<70, AT12, ""), IF(AN12<70, AN12, ""))) -> 0 | BD12: =IF(AND(NOT(ISBLANK(AY12)), NOT(ISBLANK(AZ12))), AY12 + AZ12, "")
A13: 3 | B13: ALFREDO | C13: CONTRERAS | AJ13: =SUMIF(D13:D13, ">=70") / 4 +SUMIF(F13:F13, ">=70") / 4 +SUMIF(H13:H13, ">=70") / 4 +SUMIF(J13:J13, ">=70") / 4 + SUMIF(E13:E13, ">1") / 4 + SUMIF(G13:G13, ">1") / 4 + SUMIF(I13:I13, ">1") / 4 + SUMIF(K13:K13, ">1") / 4 -> 0 | AK13: =SUMIF(L13:L13, ">=70") / 4 +SUMIF(N13:N13, ">=70") / 4 +SUMIF(P13:P13, ">=70") / 4 +SUMIF(R13:R13, ">=70") / 4 + SUMIF(M13:M13, ">1") / 4 + SUMIF(O13:O13, ">1") / 4 + SUMIF(Q13:Q13, ">1") / 4 + SUMIF(S13:S13, ">1") / 4 -> 0 | AL13: =SUMIF(T13:T13, ">=70") / 4 +SUMIF(V13:V13, ">=70") / 4 +SUMIF(X13:X13, ">=70") / 4 +SUMIF(Z13:Z13, ">=70") / 4 + SUMIF(U13:U13, ">1") / 4 + SUMIF(W13:W13, ">1") / 4 + SUMIF(Y13:Y13, ">1") / 4 + SUMIF(AA13:AA13, ">1") / 4 -> 0 | AM13: =SUMIF(AB13:AB13, ">=65") / 4 +SUMIF(AD13:AD13, ">=65") / 4 +SUMIF(AF13:AF13, ">=65") / 4 +SUMIF(AH13:AH13, ">=65") / 4 + SUMIF(AC13:AC13, ">1") / 4 + SUMIF(AE13:AE13, ">1") / 4 + SUMIF(AG13:AG13, ">1") / 4 + SUMIF(AI13:AI13, ">1") / 4 -> 0 | AN13: =AVERAGE(AJ13:AM13) -> 0 | AQ13: =IF(AN13<70, AN13*0.5, "") -> 0 | AS13: =AR13*50% -> 0 | AT13: =IF(AR13<>"", IF(AQ13="","",AQ13+AS13), "") | AU13: =IF(AT13 < 70, AQ13*30%, "") | AW13: =AV13*70% -> 0 | AX13: =IF(AV13<>"", IF(AU13="", "", AU13+AW13), "") | AY13: =IF(AND(AT13<70, AX13<70), AN13, "") | BA13: =IF(AV13<>"", IF(AX13>=70, AX13, IF(AY13+AZ13>=70, AY13+AZ13, "")), IF(AR13<>"", IF(AT13>=70, AT13, ""), IF(AN13>=70, AN13, ""))) | BB13: =IF(AV13<>"", IF(AX13<70, IF(AY13+AZ13<70, AY13+AZ13, ""), ""), IF(AR13<>"", IF(AT13<70, AT13, ""), IF(AN13<70, AN13, ""))) -> 0 | BD13: =IF(AND(NOT(ISBLANK(AY13)), NOT(ISBLANK(AZ13))), AY13 + AZ13, "")
A14: 4 | B14: ALIANNA MILAGROS | C14: DE JESUS | AJ14: =SUMIF(D14:D14, ">=70") / 4 +SUMIF(F14:F14, ">=70") / 4 +SUMIF(H14:H14, ">=70") / 4 +SUMIF(J14:J14, ">=70") / 4 + SUMIF(E14:E14, ">1") / 4 + SUMIF(G14:G14, ">1") / 4 + SUMIF(I14:I14, ">1") / 4 + SUMIF(K14:K14, ">1") / 4 -> 0 | AK14: =SUMIF(L14:L14, ">=70") / 4 +SUMIF(N14:N14, ">=70") / 4 +SUMIF(P14:P14, ">=70") / 4 +SUMIF(R14:R14, ">=70") / 4 + SUMIF(M14:M14, ">1") / 4 + SUMIF(O14:O14, ">1") / 4 + SUMIF(Q14:Q14, ">1") / 4 + SUMIF(S14:S14, ">1") / 4 -> 0 | AL14: =SUMIF(T14:T14, ">=70") / 4 +SUMIF(V14:V14, ">=70") / 4 +SUMIF(X14:X14, ">=70") / 4 +SUMIF(Z14:Z14, ">=70") / 4 + SUMIF(U14:U14, ">1") / 4 + SUMIF(W14:W14, ">1") / 4 + SUMIF(Y14:Y14, ">1") / 4 + SUMIF(AA14:AA14, ">1") / 4 -> 0 | AM14: =SUMIF(AB14:AB14, ">=65") / 4 +SUMIF(AD14:AD14, ">=65") / 4 +SUMIF(AF14:AF14, ">=65") / 4 +SUMIF(AH14:AH14, ">=65") / 4 + SUMIF(AC14:AC14, ">1") / 4 + SUMIF(AE14:AE14, ">1") / 4 + SUMIF(AG14:AG14, ">1") / 4 + SUMIF(AI14:AI14, ">1") / 4 -> 0 | AN14: =AVERAGE(AJ14:AM14) -> 0 | AQ14: =IF(AN14<70, AN14*0.5, "") -> 0 | AS14: =AR14*50% -> 0 | AT14: =IF(AR14<>"", IF(AQ14="","",AQ14+AS14), "") | AU14: =IF(AT14 < 70, AQ14*30%, "") | AW14: =AV14*70% -> 0 | AX14: =IF(AV14<>"", IF(AU14="", "", AU14+AW14), "") | AY14: =IF(AND(AT14<70, AX14<70), AN14, "") | BA14: =IF(AV14<>"", IF(AX14>=70, AX14, IF(AY14+AZ14>=70, AY14+AZ14, "")), IF(AR14<>"", IF(AT14>=70, AT14, ""), IF(AN14>=70, AN14, ""))) | BB14: =IF(AV14<>"", IF(AX14<70, IF(AY14+AZ14<70, AY14+AZ14, ""), ""), IF(AR14<>"", IF(AT14<70, AT14, ""), IF(AN14<70, AN14, ""))) -> 0 | BD14: =IF(AND(NOT(ISBLANK(AY14)), NOT(ISBLANK(AZ14))), AY14 + AZ14, "")
A15: 5 | B15: ANA YULISA | C15: FRIAS MARTE | AJ15: =SUMIF(D15:D15, ">=70") / 4 +SUMIF(F15:F15, ">=70") / 4 +SUMIF(H15:H15, ">=70") / 4 +SUMIF(J15:J15, ">=70") / 4 + SUMIF(E15:E15, ">1") / 4 + SUMIF(G15:G15, ">1") / 4 + SUMIF(I15:I15, ">1") / 4 + SUMIF(K15:K15, ">1") / 4 -> 0 | AK15: =SUMIF(L15:L15, ">=70") / 4 +SUMIF(N15:N15, ">=70") / 4 +SUMIF(P15:P15, ">=70") / 4 +SUMIF(R15:R15, ">=70") / 4 + SUMIF(M15:M15, ">1") / 4 + SUMIF(O15:O15, ">1") / 4 + SUMIF(Q15:Q15, ">1") / 4 + SUMIF(S15:S15, ">1") / 4 -> 0 | AL15: =SUMIF(T15:T15, ">=70") / 4 +SUMIF(V15:V15, ">=70") / 4 +SUMIF(X15:X15, ">=70") / 4 +SUMIF(Z15:Z15, ">=70") / 4 + SUMIF(U15:U15, ">1") / 4 + SUMIF(W15:W15, ">1") / 4 + SUMIF(Y15:Y15, ">1") / 4 + SUMIF(AA15:AA15, ">1") / 4 -> 0 | AM15: =SUMIF(AB15:AB15, ">=65") / 4 +SUMIF(AD15:AD15, ">=65") / 4 +SUMIF(AF15:AF15, ">=65") / 4 +SUMIF(AH15:AH15, ">=65") / 4 + SUMIF(AC15:AC15, ">1") / 4 + SUMIF(AE15:AE15, ">1") / 4 + SUMIF(AG15:AG15, ">1") / 4 + SUMIF(AI15:AI15, ">1") / 4 -> 0 | AN15: =AVERAGE(AJ15:AM15) -> 0 | AQ15: =IF(AN15<70, AN15*0.5, "") -> 0 | AS15: =AR15*50% -> 0 | AT15: =IF(AR15<>"", IF(AQ15="","",AQ15+AS15), "") | AU15: =IF(AT15 < 70, AQ15*30%, "") | AW15: =AV15*70% -> 0 | AX15: =IF(AV15<>"", IF(AU15="", "", AU15+AW15), "") | AY15: =IF(AND(AT15<70, AX15<70), AN15, "") | BA15: =IF(AV15<>"", IF(AX15>=70, AX15, IF(AY15+AZ15>=70, AY15+AZ15, "")), IF(AR15<>"", IF(AT15>=70, AT15, ""), IF(AN15>=70, AN15, ""))) | BB15: =IF(AV15<>"", IF(AX15<70, IF(AY15+AZ15<70, AY15+AZ15, ""), ""), IF(AR15<>"", IF(AT15<70, AT15, ""), IF(AN15<70, AN15, ""))) -> 0 | BD15: =IF(AND(NOT(ISBLANK(AY15)), NOT(ISBLANK(AZ15))), AY15 + AZ15, "")
A16: 6 | B16: ASHLEY NATALIE | C16: CUEVAS FRIAS | AJ16: =SUMIF(D16:D16, ">=70") / 4 +SUMIF(F16:F16, ">=70") / 4 +SUMIF(H16:H16, ">=70") / 4 +SUMIF(J16:J16, ">=70") / 4 + SUMIF(E16:E16, ">1") / 4 + SUMIF(G16:G16, ">1") / 4 + SUMIF(I16:I16, ">1") / 4 + SUMIF(K16:K16, ">1") / 4 -> 0 | AK16: =SUMIF(L16:L16, ">=70") / 4 +SUMIF(N16:N16, ">=70") / 4 +SUMIF(P16:P16, ">=70") / 4 +SUMIF(R16:R16, ">=70") / 4 + SUMIF(M16:M16, ">1") / 4 + SUMIF(O16:O16, ">1") / 4 + SUMIF(Q16:Q16, ">1") / 4 + SUMIF(S16:S16, ">1") / 4 -> 0 | AL16: =SUMIF(T16:T16, ">=70") / 4 +SUMIF(V16:V16, ">=70") / 4 +SUMIF(X16:X16, ">=70") / 4 +SUMIF(Z16:Z16, ">=70") / 4 + SUMIF(U16:U16, ">1") / 4 + SUMIF(W16:W16, ">1") / 4 + SUMIF(Y16:Y16, ">1") / 4 + SUMIF(AA16:AA16, ">1") / 4 -> 0 | AM16: =SUMIF(AB16:AB16, ">=65") / 4 +SUMIF(AD16:AD16, ">=65") / 4 +SUMIF(AF16:AF16, ">=65") / 4 +SUMIF(AH16:AH16, ">=65") / 4 + SUMIF(AC16:AC16, ">1") / 4 + SUMIF(AE16:AE16, ">1") / 4 + SUMIF(AG16:AG16, ">1") / 4 + SUMIF(AI16:AI16, ">1") / 4 -> 0 | AN16: =AVERAGE(AJ16:AM16) -> 0 | AQ16: =IF(AN16<70, AN16*0.5, "") -> 0 | AS16: =AR16*50% -> 0 | AT16: =IF(AR16<>"", IF(AQ16="","",AQ16+AS16), "") | AU16: =IF(AT16 < 70, AQ16*30%, "") | AW16: =AV16*70% -> 0 | AX16: =IF(AV16<>"", IF(AU16="", "", AU16+AW16), "") | AY16: =IF(AND(AT16<70, AX16<70), AN16, "") | BA16: =IF(AV16<>"", IF(AX16>=70, AX16, IF(AY16+AZ16>=70, AY16+AZ16, "")), IF(AR16<>"", IF(AT16>=70, AT16, ""), IF(AN16>=70, AN16, ""))) | BB16: =IF(AV16<>"", IF(AX16<70, IF(AY16+AZ16<70, AY16+AZ16, ""), ""), IF(AR16<>"", IF(AT16<70, AT16, ""), IF(AN16<70, AN16, ""))) -> 0 | BD16: =IF(AND(NOT(ISBLANK(AY16)), NOT(ISBLANK(AZ16))), AY16 + AZ16, "")
A17: 7 | B17: CATERIN CARINA | C17: DELGADO MANZUETA | AJ17: =SUMIF(D17:D17, ">=70") / 4 +SUMIF(F17:F17, ">=70") / 4 +SUMIF(H17:H17, ">=70") / 4 +SUMIF(J17:J17, ">=70") / 4 + SUMIF(E17:E17, ">1") / 4 + SUMIF(G17:G17, ">1") / 4 + SUMIF(I17:I17, ">1") / 4 + SUMIF(K17:K17, ">1") / 4 -> 0 | AK17: =SUMIF(L17:L17, ">=70") / 4 +SUMIF(N17:N17, ">=70") / 4 +SUMIF(P17:P17, ">=70") / 4 +SUMIF(R17:R17, ">=70") / 4 + SUMIF(M17:M17, ">1") / 4 + SUMIF(O17:O17, ">1") / 4 + SUMIF(Q17:Q17, ">1") / 4 + SUMIF(S17:S17, ">1") / 4 -> 0 | AL17: =SUMIF(T17:T17, ">=70") / 4 +SUMIF(V17:V17, ">=70") / 4 +SUMIF(X17:X17, ">=70") / 4 +SUMIF(Z17:Z17, ">=70") / 4 + SUMIF(U17:U17, ">1") / 4 + SUMIF(W17:W17, ">1") / 4 + SUMIF(Y17:Y17, ">1") / 4 + SUMIF(AA17:AA17, ">1") / 4 -> 0 | AM17: =SUMIF(AB17:AB17, ">=65") / 4 +SUMIF(AD17:AD17, ">=65") / 4 +SUMIF(AF17:AF17, ">=65") / 4 +SUMIF(AH17:AH17, ">=65") / 4 + SUMIF(AC17:AC17, ">1") / 4 + SUMIF(AE17:AE17, ">1") / 4 + SUMIF(AG17:AG17, ">1") / 4 + SUMIF(AI17:AI17, ">1") / 4 -> 0 | AN17: =AVERAGE(AJ17:AM17) -> 0 | AQ17: =IF(AN17<70, AN17*0.5, "") -> 0 | AS17: =AR17*50% -> 0 | AT17: =IF(AR17<>"", IF(AQ17="","",AQ17+AS17), "") | AU17: =IF(AT17 < 70, AQ17*30%, "") | AW17: =AV17*70% -> 0 | AX17: =IF(AV17<>"", IF(AU17="", "", AU17+AW17), "") | AY17: =IF(AND(AT17<70, AX17<70), AN17, "") | BA17: =IF(AV17<>"", IF(AX17>=70, AX17, IF(AY17+AZ17>=70, AY17+AZ17, "")), IF(AR17<>"", IF(AT17>=70, AT17, ""), IF(AN17>=70, AN17, ""))) | BB17: =IF(AV17<>"", IF(AX17<70, IF(AY17+AZ17<70, AY17+AZ17, ""), ""), IF(AR17<>"", IF(AT17<70, AT17, ""), IF(AN17<70, AN17, ""))) -> 0 | BD17: =IF(AND(NOT(ISBLANK(AY17)), NOT(ISBLANK(AZ17))), AY17 + AZ17, "")
A18: 8 | B18: CLARYS | C18: ALMANZAR BRAND | AJ18: =SUMIF(D18:D18, ">=70") / 4 +SUMIF(F18:F18, ">=70") / 4 +SUMIF(H18:H18, ">=70") / 4 +SUMIF(J18:J18, ">=70") / 4 + SUMIF(E18:E18, ">1") / 4 + SUMIF(G18:G18, ">1") / 4 + SUMIF(I18:I18, ">1") / 4 + SUMIF(K18:K18, ">1") / 4 -> 0 | AK18: =SUMIF(L18:L18, ">=70") / 4 +SUMIF(N18:N18, ">=70") / 4 +SUMIF(P18:P18, ">=70") / 4 +SUMIF(R18:R18, ">=70") / 4 + SUMIF(M18:M18, ">1") / 4 + SUMIF(O18:O18, ">1") / 4 + SUMIF(Q18:Q18, ">1") / 4 + SUMIF(S18:S18, ">1") / 4 -> 0 | AL18: =SUMIF(T18:T18, ">=70") / 4 +SUMIF(V18:V18, ">=70") / 4 +SUMIF(X18:X18, ">=70") / 4 +SUMIF(Z18:Z18, ">=70") / 4 + SUMIF(U18:U18, ">1") / 4 + SUMIF(W18:W18, ">1") / 4 + SUMIF(Y18:Y18, ">1") / 4 + SUMIF(AA18:AA18, ">1") / 4 -> 0 | AM18: =SUMIF(AB18:AB18, ">=65") / 4 +SUMIF(AD18:AD18, ">=65") / 4 +SUMIF(AF18:AF18, ">=65") / 4 +SUMIF(AH18:AH18, ">=65") / 4 + SUMIF(AC18:AC18, ">1") / 4 + SUMIF(AE18:AE18, ">1") / 4 + SUMIF(AG18:AG18, ">1") / 4 + SUMIF(AI18:AI18, ">1") / 4 -> 0 | AN18: =AVERAGE(AJ18:AM18) -> 0 | AQ18: =IF(AN18<70, AN18*0.5, "") -> 0 | AS18: =AR18*50% -> 0 | AT18: =IF(AR18<>"", IF(AQ18="","",AQ18+AS18), "") | AU18: =IF(AT18 < 70, AQ18*30%, "") | AW18: =AV18*70% -> 0 | AX18: =IF(AV18<>"", IF(AU18="", "", AU18+AW18), "") | AY18: =IF(AND(AT18<70, AX18<70), AN18, "") | BA18: =IF(AV18<>"", IF(AX18>=70, AX18, IF(AY18+AZ18>=70, AY18+AZ18, "")), IF(AR18<>"", IF(AT18>=70, AT18, ""), IF(AN18>=70, AN18, ""))) | BB18: =IF(AV18<>"", IF(AX18<70, IF(AY18+AZ18<70, AY18+AZ18, ""), ""), IF(AR18<>"", IF(AT18<70, AT18, ""), IF(AN18<70, AN18, ""))) -> 0 | BD18: =IF(AND(NOT(ISBLANK(AY18)), NOT(ISBLANK(AZ18))), AY18 + AZ18, "")
A19: 9 | B19: CRISTOFHER | C19: GOMEZ FELIZ | AJ19: =SUMIF(D19:D19, ">=70") / 4 +SUMIF(F19:F19, ">=70") / 4 +SUMIF(H19:H19, ">=70") / 4 +SUMIF(J19:J19, ">=70") / 4 + SUMIF(E19:E19, ">1") / 4 + SUMIF(G19:G19, ">1") / 4 + SUMIF(I19:I19, ">1") / 4 + SUMIF(K19:K19, ">1") / 4 -> 0 | AK19: =SUMIF(L19:L19, ">=70") / 4 +SUMIF(N19:N19, ">=70") / 4 +SUMIF(P19:P19, ">=70") / 4 +SUMIF(R19:R19, ">=70") / 4 + SUMIF(M19:M19, ">1") / 4 + SUMIF(O19:O19, ">1") / 4 + SUMIF(Q19:Q19, ">1") / 4 + SUMIF(S19:S19, ">1") / 4 -> 0 | AL19: =SUMIF(T19:T19, ">=70") / 4 +SUMIF(V19:V19, ">=70") / 4 +SUMIF(X19:X19, ">=70") / 4 +SUMIF(Z19:Z19, ">=70") / 4 + SUMIF(U19:U19, ">1") / 4 + SUMIF(W19:W19, ">1") / 4 + SUMIF(Y19:Y19, ">1") / 4 + SUMIF(AA19:AA19, ">1") / 4 -> 0 | AM19: =SUMIF(AB19:AB19, ">=65") / 4 +SUMIF(AD19:AD19, ">=65") / 4 +SUMIF(AF19:AF19, ">=65") / 4 +SUMIF(AH19:AH19, ">=65") / 4 + SUMIF(AC19:AC19, ">1") / 4 + SUMIF(AE19:AE19, ">1") / 4 + SUMIF(AG19:AG19, ">1") / 4 + SUMIF(AI19:AI19, ">1") / 4 -> 0 | AN19: =AVERAGE(AJ19:AM19) -> 0 | AQ19: =IF(AN19<70, AN19*0.5, "") -> 0 | AS19: =AR19*50% -> 0 | AT19: =IF(AR19<>"", IF(AQ19="","",AQ19+AS19), "") | AU19: =IF(AT19 < 70, AQ19*30%, "") | AW19: =AV19*70% -> 0 | AX19: =IF(AV19<>"", IF(AU19="", "", AU19+AW19), "") | AY19: =IF(AND(AT19<70, AX19<70), AN19, "") | BA19: =IF(AV19<>"", IF(AX19>=70, AX19, IF(AY19+AZ19>=70, AY19+AZ19, "")), IF(AR19<>"", IF(AT19>=70, AT19, ""), IF(AN19>=70, AN19, ""))) | BB19: =IF(AV19<>"", IF(AX19<70, IF(AY19+AZ19<70, AY19+AZ19, ""), ""), IF(AR19<>"", IF(AT19<70, AT19, ""), IF(AN19<70, AN19, ""))) -> 0 | BD19: =IF(AND(NOT(ISBLANK(AY19)), NOT(ISBLANK(AZ19))), AY19 + AZ19, "")
A20: 10 | B20: DARLIN | C20: ESTEPAN CAPELLAN | AJ20: =SUMIF(D20:D20, ">=70") / 4 +SUMIF(F20:F20, ">=70") / 4 +SUMIF(H20:H20, ">=70") / 4 +SUMIF(J20:J20, ">=70") / 4 + SUMIF(E20:E20, ">1") / 4 + SUMIF(G20:G20, ">1") / 4 + SUMIF(I20:I20, ">1") / 4 + SUMIF(K20:K20, ">1") / 4 -> 0 | AK20: =SUMIF(L20:L20, ">=70") / 4 +SUMIF(N20:N20, ">=70") / 4 +SUMIF(P20:P20, ">=70") / 4 +SUMIF(R20:R20, ">=70") / 4 + SUMIF(M20:M20, ">1") / 4 + SUMIF(O20:O20, ">1") / 4 + SUMIF(Q20:Q20, ">1") / 4 + SUMIF(S20:S20, ">1") / 4 -> 0 | AL20: =SUMIF(T20:T20, ">=70") / 4 +SUMIF(V20:V20, ">=70") / 4 +SUMIF(X20:X20, ">=70") / 4 +SUMIF(Z20:Z20, ">=70") / 4 + SUMIF(U20:U20, ">1") / 4 + SUMIF(W20:W20, ">1") / 4 + SUMIF(Y20:Y20, ">1") / 4 + SUMIF(AA20:AA20, ">1") / 4 -> 0 | AM20: =SUMIF(AB20:AB20, ">=65") / 4 +SUMIF(AD20:AD20, ">=65") / 4 +SUMIF(AF20:AF20, ">=65") / 4 +SUMIF(AH20:AH20, ">=65") / 4 + SUMIF(AC20:AC20, ">1") / 4 + SUMIF(AE20:AE20, ">1") / 4 + SUMIF(AG20:AG20, ">1") / 4 + SUMIF(AI20:AI20, ">1") / 4 -> 0 | AN20: =AVERAGE(AJ20:AM20) -> 0 | AQ20: =IF(AN20<70, AN20*0.5, "") -> 0 | AS20: =AR20*50% -> 0 | AT20: =IF(AR20<>"", IF(AQ20="","",AQ20+AS20), "") | AU20: =IF(AT20 < 70, AQ20*30%, "") | AW20: =AV20*70% -> 0 | AX20: =IF(AV20<>"", IF(AU20="", "", AU20+AW20), "") | AY20: =IF(AND(AT20<70, AX20<70), AN20, "") | BA20: =IF(AV20<>"", IF(AX20>=70, AX20, IF(AY20+AZ20>=70, AY20+AZ20, "")), IF(AR20<>"", IF(AT20>=70, AT20, ""), IF(AN20>=70, AN20, ""))) | BB20: =IF(AV20<>"", IF(AX20<70, IF(AY20+AZ20<70, AY20+AZ20, ""), ""), IF(AR20<>"", IF(AT20<70, AT20, ""), IF(AN20<70, AN20, ""))) -> 0 | BD20: =IF(AND(NOT(ISBLANK(AY20)), NOT(ISBLANK(AZ20))), AY20 + AZ20, "")
A21: 11 | B21: DIONICIO | C21: GARCIA DE LEON | AJ21: =SUMIF(D21:D21, ">=70") / 4 +SUMIF(F21:F21, ">=70") / 4 +SUMIF(H21:H21, ">=70") / 4 +SUMIF(J21:J21, ">=70") / 4 + SUMIF(E21:E21, ">1") / 4 + SUMIF(G21:G21, ">1") / 4 + SUMIF(I21:I21, ">1") / 4 + SUMIF(K21:K21, ">1") / 4 -> 0 | AK21: =SUMIF(L21:L21, ">=70") / 4 +SUMIF(N21:N21, ">=70") / 4 +SUMIF(P21:P21, ">=70") / 4 +SUMIF(R21:R21, ">=70") / 4 + SUMIF(M21:M21, ">1") / 4 + SUMIF(O21:O21, ">1") / 4 + SUMIF(Q21:Q21, ">1") / 4 + SUMIF(S21:S21, ">1") / 4 -> 0 | AL21: =SUMIF(T21:T21, ">=70") / 4 +SUMIF(V21:V21, ">=70") / 4 +SUMIF(X21:X21, ">=70") / 4 +SUMIF(Z21:Z21, ">=70") / 4 + SUMIF(U21:U21, ">1") / 4 + SUMIF(W21:W21, ">1") / 4 + SUMIF(Y21:Y21, ">1") / 4 + SUMIF(AA21:AA21, ">1") / 4 -> 0 | AM21: =SUMIF(AB21:AB21, ">=65") / 4 +SUMIF(AD21:AD21, ">=65") / 4 +SUMIF(AF21:AF21, ">=65") / 4 +SUMIF(AH21:AH21, ">=65") / 4 + SUMIF(AC21:AC21, ">1") / 4 + SUMIF(AE21:AE21, ">1") / 4 + SUMIF(AG21:AG21, ">1") / 4 + SUMIF(AI21:AI21, ">1") / 4 -> 0 | AN21: =AVERAGE(AJ21:AM21) -> 0 | AQ21: =IF(AN21<70, AN21*0.5, "") -> 0 | AS21: =AR21*50% -> 0 | AT21: =IF(AR21<>"", IF(AQ21="","",AQ21+AS21), "") | AU21: =IF(AT21 < 70, AQ21*30%, "") | AW21: =AV21*70% -> 0 | AX21: =IF(AV21<>"", IF(AU21="", "", AU21+AW21), "") | AY21: =IF(AND(AT21<70, AX21<70), AN21, "") | BA21: =IF(AV21<>"", IF(AX21>=70, AX21, IF(AY21+AZ21>=70, AY21+AZ21, "")), IF(AR21<>"", IF(AT21>=70, AT21, ""), IF(AN21>=70, AN21, ""))) | BB21: =IF(AV21<>"", IF(AX21<70, IF(AY21+AZ21<70, AY21+AZ21, ""), ""), IF(AR21<>"", IF(AT21<70, AT21, ""), IF(AN21<70, AN21, ""))) -> 0 | BD21: =IF(AND(NOT(ISBLANK(AY21)), NOT(ISBLANK(AZ21))), AY21 + AZ21, "")
A22: 12 | B22: DJOUME | C22: NOMBRE | AJ22: =SUMIF(D22:D22, ">=70") / 4 +SUMIF(F22:F22, ">=70") / 4 +SUMIF(H22:H22, ">=70") / 4 +SUMIF(J22:J22, ">=70") / 4 + SUMIF(E22:E22, ">1") / 4 + SUMIF(G22:G22, ">1") / 4 + SUMIF(I22:I22, ">1") / 4 + SUMIF(K22:K22, ">1") / 4 -> 0 | AK22: =SUMIF(L22:L22, ">=70") / 4 +SUMIF(N22:N22, ">=70") / 4 +SUMIF(P22:P22, ">=70") / 4 +SUMIF(R22:R22, ">=70") / 4 + SUMIF(M22:M22, ">1") / 4 + SUMIF(O22:O22, ">1") / 4 + SUMIF(Q22:Q22, ">1") / 4 + SUMIF(S22:S22, ">1") / 4 -> 0 | AL22: =SUMIF(T22:T22, ">=70") / 4 +SUMIF(V22:V22, ">=70") / 4 +SUMIF(X22:X22, ">=70") / 4 +SUMIF(Z22:Z22, ">=70") / 4 + SUMIF(U22:U22, ">1") / 4 + SUMIF(W22:W22, ">1") / 4 + SUMIF(Y22:Y22, ">1") / 4 + SUMIF(AA22:AA22, ">1") / 4 -> 0 | AM22: =SUMIF(AB22:AB22, ">=65") / 4 +SUMIF(AD22:AD22, ">=65") / 4 +SUMIF(AF22:AF22, ">=65") / 4 +SUMIF(AH22:AH22, ">=65") / 4 + SUMIF(AC22:AC22, ">1") / 4 + SUMIF(AE22:AE22, ">1") / 4 + SUMIF(AG22:AG22, ">1") / 4 + SUMIF(AI22:AI22, ">1") / 4 -> 0 | AN22: =AVERAGE(AJ22:AM22) -> 0 | AQ22: =IF(AN22<70, AN22*0.5, "") -> 0 | AS22: =AR22*50% -> 0 | AT22: =IF(AR22<>"", IF(AQ22="","",AQ22+AS22), "") | AU22: =IF(AT22 < 70, AQ22*30%, "") | AW22: =AV22*70% -> 0 | AX22: =IF(AV22<>"", IF(AU22="", "", AU22+AW22), "") | AY22: =IF(AND(AT22<70, AX22<70), AN22, "") | BA22: =IF(AV22<>"", IF(AX22>=70, AX22, IF(AY22+AZ22>=70, AY22+AZ22, "")), IF(AR22<>"", IF(AT22>=70, AT22, ""), IF(AN22>=70, AN22, ""))) | BB22: =IF(AV22<>"", IF(AX22<70, IF(AY22+AZ22<70, AY22+AZ22, ""), ""), IF(AR22<>"", IF(AT22<70, AT22, ""), IF(AN22<70, AN22, ""))) -> 0 | BD22: =IF(AND(NOT(ISBLANK(AY22)), NOT(ISBLANK(AZ22))), AY22 + AZ22, "")
A23: 13 | B23: EDDY MALVIN | C23: DE LA CRUZ | AJ23: =SUMIF(D23:D23, ">=70") / 4 +SUMIF(F23:F23, ">=70") / 4 +SUMIF(H23:H23, ">=70") / 4 +SUMIF(J23:J23, ">=70") / 4 + SUMIF(E23:E23, ">1") / 4 + SUMIF(G23:G23, ">1") / 4 + SUMIF(I23:I23, ">1") / 4 + SUMIF(K23:K23, ">1") / 4 -> 0 | AK23: =SUMIF(L23:L23, ">=70") / 4 +SUMIF(N23:N23, ">=70") / 4 +SUMIF(P23:P23, ">=70") / 4 +SUMIF(R23:R23, ">=70") / 4 + SUMIF(M23:M23, ">1") / 4 + SUMIF(O23:O23, ">1") / 4 + SUMIF(Q23:Q23, ">1") / 4 + SUMIF(S23:S23, ">1") / 4 -> 0 | AL23: =SUMIF(T23:T23, ">=70") / 4 +SUMIF(V23:V23, ">=70") / 4 +SUMIF(X23:X23, ">=70") / 4 +SUMIF(Z23:Z23, ">=70") / 4 + SUMIF(U23:U23, ">1") / 4 + SUMIF(W23:W23, ">1") / 4 + SUMIF(Y23:Y23, ">1") / 4 + SUMIF(AA23:AA23, ">1") / 4 -> 0 | AM23: =SUMIF(AB23:AB23, ">=65") / 4 +SUMIF(AD23:AD23, ">=65") / 4 +SUMIF(AF23:AF23, ">=65") / 4 +SUMIF(AH23:AH23, ">=65") / 4 + SUMIF(AC23:AC23, ">1") / 4 + SUMIF(AE23:AE23, ">1") / 4 + SUMIF(AG23:AG23, ">1") / 4 + SUMIF(AI23:AI23, ">1") / 4 -> 0 | AN23: =AVERAGE(AJ23:AM23) -> 0 | AQ23: =IF(AN23<70, AN23*0.5, "") -> 0 | AS23: =AR23*50% -> 0 | AT23: =IF(AR23<>"", IF(AQ23="","",AQ23+AS23), "") | AU23: =IF(AT23 < 70, AQ23*30%, "") | AW23: =AV23*70% -> 0 | AX23: =IF(AV23<>"", IF(AU23="", "", AU23+AW23), "") | AY23: =IF(AND(AT23<70, AX23<70), AN23, "") | BA23: =IF(AV23<>"", IF(AX23>=70, AX23, IF(AY23+AZ23>=70, AY23+AZ23, "")), IF(AR23<>"", IF(AT23>=70, AT23, ""), IF(AN23>=70, AN23, ""))) | BB23: =IF(AV23<>"", IF(AX23<70, IF(AY23+AZ23<70, AY23+AZ23, ""), ""), IF(AR23<>"", IF(AT23<70, AT23, ""), IF(AN23<70, AN23, ""))) -> 0 | BD23: =IF(AND(NOT(ISBLANK(AY23)), NOT(ISBLANK(AZ23))), AY23 + AZ23, "")
... A46: 36 | B46: NAIROBI ALEXANDRA | C46: FENELON | AJ46: =SUMIF(D46:D46, ">=70") / 4 +SUMIF(F46:F46, ">=70") / 4 +SUMIF(H46:H46, ">=70") / 4 +SUMIF(J46:J46, ">=70") / 4 + SUMIF(E46:E46, ">1") / 4 + SUMIF(G46:G46, ">1") / 4 + SUMIF(I46:I46, ">1") / 4 + SUMIF(K46:K46, ">1") / 4 -> 0 | AK46: =SUMIF(L46:L46, ">=70") / 4 +SUMIF(N46:N46, ">=70") / 4 +SUMIF(P46:P46, ">=70") / 4 +SUMIF(R46:R46, ">=70") / 4 + SUMIF(M46:M46, ">1") / 4 + SUMIF(O46:O46, ">1") / 4 + SUMIF(Q46:Q46, ">1") / 4 + SUMIF(S46:S46, ">1") / 4 -> 0 | AL46: =SUMIF(T46:T46, ">=70") / 4 +SUMIF(V46:V46, ">=70") / 4 +SUMIF(X46:X46, ">=70") / 4 +SUMIF(Z46:Z46, ">=70") / 4 + SUMIF(U46:U46, ">1") / 4 + SUMIF(W46:W46, ">1") / 4 + SUMIF(Y46:Y46, ">1") / 4 + SUMIF(AA46:AA46, ">1") / 4 -> 0 | AM46: =SUMIF(AB46:AB46, ">=65") / 4 +SUMIF(AD46:AD46, ">=65") / 4 +SUMIF(AF46:AF46, ">=65") / 4 +SUMIF(AH46:AH46, ">=65") / 4 + SUMIF(AC46:AC46, ">1") / 4 + SUMIF(AE46:AE46, ">1") / 4 + SUMIF(AG46:AG46, ">1") / 4 + SUMIF(AI46:AI46, ">1") / 4 -> 0 | AN46: =AVERAGE(AJ46:AM46) -> 0 | AQ46: =IF(AN46<70, AN46*0.5, "") -> 0 | AS46: =AR46*50% -> 0 | AT46: =IF(AR46<>"", IF(AQ46="","",AQ46+AS46), "") | AU46: =IF(AT46 < 70, AQ46*30%, "") | AW46: =AV46*70% -> 0 | AX46: =IF(AV46<>"", IF(AU46="", "", AU46+AW46), "") | AY46: =IF(AND(AT46<70, AX46<70), AN46, "") | BA46: =IF(AV46<>"", IF(AX46>=70, AX46, IF(AY46+AZ46>=70, AY46+AZ46, "")), IF(AR46<>"", IF(AT46>=70, AT46, ""), IF(AN46>=70, AN46, ""))) | BB46: =IF(AV46<>"", IF(AX46<70, IF(AY46+AZ46<70, AY46+AZ46, ""), ""), IF(AR46<>"", IF(AT46<70, AT46, ""), IF(AN46<70, AN46, ""))) -> 0 | BD46: =IF(AND(NOT(ISBLANK(AY46)), NOT(ISBLANK(AZ46))), AY46 + AZ46, "")
A47: 37 | AJ47: =SUMIF(D47:D47, ">=70") / 4 +SUMIF(F47:F47, ">=70") / 4 +SUMIF(H47:H47, ">=70") / 4 +SUMIF(J47:J47, ">=70") / 4 + SUMIF(E47:E47, ">1") / 4 + SUMIF(G47:G47, ">1") / 4 + SUMIF(I47:I47, ">1") / 4 + SUMIF(K47:K47, ">1") / 4 -> 0 | AK47: =SUMIF(L47:L47, ">=70") / 4 +SUMIF(N47:N47, ">=70") / 4 +SUMIF(P47:P47, ">=70") / 4 +SUMIF(R47:R47, ">=70") / 4 + SUMIF(M47:M47, ">1") / 4 + SUMIF(O47:O47, ">1") / 4 + SUMIF(Q47:Q47, ">1") / 4 + SUMIF(S47:S47, ">1") / 4 -> 0 | AL47: =SUMIF(T47:T47, ">=70") / 4 +SUMIF(V47:V47, ">=70") / 4 +SUMIF(X47:X47, ">=70") / 4 +SUMIF(Z47:Z47, ">=70") / 4 + SUMIF(U47:U47, ">1") / 4 + SUMIF(W47:W47, ">1") / 4 + SUMIF(Y47:Y47, ">1") / 4 + SUMIF(AA47:AA47, ">1") / 4 -> 0 | AM47: =SUMIF(AB47:AB47, ">=65") / 4 +SUMIF(AD47:AD47, ">=65") / 4 +SUMIF(AF47:AF47, ">=65") / 4 +SUMIF(AH47:AH47, ">=65") / 4 + SUMIF(AC47:AC47, ">1") / 4 + SUMIF(AE47:AE47, ">1") / 4 + SUMIF(AG47:AG47, ">1") / 4 + SUMIF(AI47:AI47, ">1") / 4 -> 0 | AN47: =AVERAGE(AJ47:AM47) -> 0 | AQ47: =IF(AN47<70, AN47*0.5, "") -> 0 | AS47: =AR47*50% -> 0 | AT47: =IF(AR47<>"", IF(AQ47="","",AQ47+AS47), "") | AU47: =IF(AT47 < 70, AQ47*30%, "") | AW47: =AV47*70% -> 0 | AX47: =IF(AV47<>"", IF(AU47="", "", AU47+AW47), "") | AY47: =IF(AND(AT47<70, AX47<70), AN47, "") | BA47: =IF(AV47<>"", IF(AX47>=70, AX47, IF(AY47+AZ47>=70, AY47+AZ47, "")), IF(AR47<>"", IF(AT47>=70, AT47, ""), IF(AN47>=70, AN47, ""))) | BB47: =IF(AV47<>"", IF(AX47<70, IF(AY47+AZ47<70, AY47+AZ47, ""), ""), IF(AR47<>"", IF(AT47<70, AT47, ""), IF(AN47<70, AN47, ""))) -> 0 | BD47: =IF(AND(NOT(ISBLANK(AY47)), NOT(ISBLANK(AZ47))), AY47 + AZ47, "")
A48: 38 | AJ48: =SUMIF(D48:D48, ">=70") / 4 +SUMIF(F48:F48, ">=70") / 4 +SUMIF(H48:H48, ">=70") / 4 +SUMIF(J48:J48, ">=70") / 4 + SUMIF(E48:E48, ">1") / 4 + SUMIF(G48:G48, ">1") / 4 + SUMIF(I48:I48, ">1") / 4 + SUMIF(K48:K48, ">1") / 4 -> 0 | AK48: =SUMIF(L48:L48, ">=70") / 4 +SUMIF(N48:N48, ">=70") / 4 +SUMIF(P48:P48, ">=70") / 4 +SUMIF(R48:R48, ">=70") / 4 + SUMIF(M48:M48, ">1") / 4 + SUMIF(O48:O48, ">1") / 4 + SUMIF(Q48:Q48, ">1") / 4 + SUMIF(S48:S48, ">1") / 4 -> 0 | AL48: =SUMIF(T48:T48, ">=70") / 4 +SUMIF(V48:V48, ">=70") / 4 +SUMIF(X48:X48, ">=70") / 4 +SUMIF(Z48:Z48, ">=70") / 4 + SUMIF(U48:U48, ">1") / 4 + SUMIF(W48:W48, ">1") / 4 + SUMIF(Y48:Y48, ">1") / 4 + SUMIF(AA48:AA48, ">1") / 4 -> 0 | AM48: =SUMIF(AB48:AB48, ">=65") / 4 +SUMIF(AD48:AD48, ">=65") / 4 +SUMIF(AF48:AF48, ">=65") / 4 +SUMIF(AH48:AH48, ">=65") / 4 + SUMIF(AC48:AC48, ">1") / 4 + SUMIF(AE48:AE48, ">1") / 4 + SUMIF(AG48:AG48, ">1") / 4 + SUMIF(AI48:AI48, ">1") / 4 -> 0 | AN48: =AVERAGE(AJ48:AM48) -> 0 | AQ48: =IF(AN48<70, AN48*0.5, "") -> 0 | AS48: =AR48*50% -> 0 | AT48: =IF(AR48<>"", IF(AQ48="","",AQ48+AS48), "") | AU48: =IF(AT48 < 70, AQ48*30%, "") | AW48: =AV48*70% -> 0 | AX48: =IF(AV48<>"", IF(AU48="", "", AU48+AW48), "") | AY48: =IF(AND(AT48<70, AX48<70), AN48, "") | BA48: =IF(AV48<>"", IF(AX48>=70, AX48, IF(AY48+AZ48>=70, AY48+AZ48, "")), IF(AR48<>"", IF(AT48>=70, AT48, ""), IF(AN48>=70, AN48, ""))) | BB48: =IF(AV48<>"", IF(AX48<70, IF(AY48+AZ48<70, AY48+AZ48, ""), ""), IF(AR48<>"", IF(AT48<70, AT48, ""), IF(AN48<70, AN48, ""))) -> 0 | BD48: =IF(AND(NOT(ISBLANK(AY48)), NOT(ISBLANK(AZ48))), AY48 + AZ48, "")
A49: 39 | AJ49: =SUMIF(D49:D49, ">=70") / 4 +SUMIF(F49:F49, ">=70") / 4 +SUMIF(H49:H49, ">=70") / 4 +SUMIF(J49:J49, ">=70") / 4 + SUMIF(E49:E49, ">1") / 4 + SUMIF(G49:G49, ">1") / 4 + SUMIF(I49:I49, ">1") / 4 + SUMIF(K49:K49, ">1") / 4 -> 0 | AK49: =SUMIF(L49:L49, ">=70") / 4 +SUMIF(N49:N49, ">=70") / 4 +SUMIF(P49:P49, ">=70") / 4 +SUMIF(R49:R49, ">=70") / 4 + SUMIF(M49:M49, ">1") / 4 + SUMIF(O49:O49, ">1") / 4 + SUMIF(Q49:Q49, ">1") / 4 + SUMIF(S49:S49, ">1") / 4 -> 0 | AL49: =SUMIF(T49:T49, ">=70") / 4 +SUMIF(V49:V49, ">=70") / 4 +SUMIF(X49:X49, ">=70") / 4 +SUMIF(Z49:Z49, ">=70") / 4 + SUMIF(U49:U49, ">1") / 4 + SUMIF(W49:W49, ">1") / 4 + SUMIF(Y49:Y49, ">1") / 4 + SUMIF(AA49:AA49, ">1") / 4 -> 0 | AM49: =SUMIF(AB49:AB49, ">=65") / 4 +SUMIF(AD49:AD49, ">=65") / 4 +SUMIF(AF49:AF49, ">=65") / 4 +SUMIF(AH49:AH49, ">=65") / 4 + SUMIF(AC49:AC49, ">1") / 4 + SUMIF(AE49:AE49, ">1") / 4 + SUMIF(AG49:AG49, ">1") / 4 + SUMIF(AI49:AI49, ">1") / 4 -> 0 | AN49: =AVERAGE(AJ49:AM49) -> 0 | AQ49: =IF(AN49<70, AN49*0.5, "") -> 0 | AS49: =AR49*50% -> 0 | AT49: =IF(AR49<>"", IF(AQ49="","",AQ49+AS49), "") | AU49: =IF(AT49 < 70, AQ49*30%, "") | AW49: =AV49*70% -> 0 | AX49: =IF(AV49<>"", IF(AU49="", "", AU49+AW49), "") | AY49: =IF(AND(AT49<70, AX49<70), AN49, "") | BA49: =IF(AV49<>"", IF(AX49>=70, AX49, IF(AY49+AZ49>=70, AY49+AZ49, "")), IF(AR49<>"", IF(AT49>=70, AT49, ""), IF(AN49>=70, AN49, ""))) | BB49: =IF(AV49<>"", IF(AX49<70, IF(AY49+AZ49<70, AY49+AZ49, ""), ""), IF(AR49<>"", IF(AT49<70, AT49, ""), IF(AN49<70, AN49, ""))) -> 0 | BD49: =IF(AND(NOT(ISBLANK(AY49)), NOT(ISBLANK(AZ49))), AY49 + AZ49, "")
A50: 40 | AJ50: =SUMIF(D50:D50, ">=70") / 4 +SUMIF(F50:F50, ">=70") / 4 +SUMIF(H50:H50, ">=70") / 4 +SUMIF(J50:J50, ">=70") / 4 + SUMIF(E50:E50, ">1") / 4 + SUMIF(G50:G50, ">1") / 4 + SUMIF(I50:I50, ">1") / 4 + SUMIF(K50:K50, ">1") / 4 -> 0 | AK50: =SUMIF(L50:L50, ">=70") / 4 +SUMIF(N50:N50, ">=70") / 4 +SUMIF(P50:P50, ">=70") / 4 +SUMIF(R50:R50, ">=70") / 4 + SUMIF(M50:M50, ">1") / 4 + SUMIF(O50:O50, ">1") / 4 + SUMIF(Q50:Q50, ">1") / 4 + SUMIF(S50:S50, ">1") / 4 -> 0 | AL50: =SUMIF(T50:T50, ">=70") / 4 +SUMIF(V50:V50, ">=70") / 4 +SUMIF(X50:X50, ">=70") / 4 +SUMIF(Z50:Z50, ">=70") / 4 + SUMIF(U50:U50, ">1") / 4 + SUMIF(W50:W50, ">1") / 4 + SUMIF(Y50:Y50, ">1") / 4 + SUMIF(AA50:AA50, ">1") / 4 -> 0 | AM50: =SUMIF(AB50:AB50, ">=65") / 4 +SUMIF(AD50:AD50, ">=65") / 4 +SUMIF(AF50:AF50, ">=65") / 4 +SUMIF(AH50:AH50, ">=65") / 4 + SUMIF(AC50:AC50, ">1") / 4 + SUMIF(AE50:AE50, ">1") / 4 + SUMIF(AG50:AG50, ">1") / 4 + SUMIF(AI50:AI50, ">1") / 4 -> 0 | AN50: =AVERAGE(AJ50:AM50) -> 0 | AQ50: =IF(AN50<70, AN50*0.5, "") -> 0 | AS50: =AR50*50% -> 0 | AT50: =IF(AR50<>"", IF(AQ50="","",AQ50+AS50), "") | AU50: =IF(AT50 < 70, AQ50*30%, "") | AW50: =AV50*70% -> 0 | AX50: =IF(AV50<>"", IF(AU50="", "", AU50+AW50), "") | AY50: =IF(AND(AT50<70, AX50<70), AN50, "") | BA50: =IF(AV50<>"", IF(AX50>=70, AX50, IF(AY50+AZ50>=70, AY50+AZ50, "")), IF(AR50<>"", IF(AT50>=70, AT50, ""), IF(AN50>=70, AN50, ""))) | BB50: =IF(AV50<>"", IF(AX50<70, IF(AY50+AZ50<70, AY50+AZ50, ""), ""), IF(AR50<>"", IF(AT50<70, AT50, ""), IF(AN50<70, AN50, ""))) -> 0 | BD50: =IF(AND(NOT(ISBLANK(AY50)), NOT(ISBLANK(AZ50))), AY50 + AZ50, "")
A51: 41 | AJ51: =SUMIF(D51:D51, ">=70") / 4 +SUMIF(F51:F51, ">=70") / 4 +SUMIF(H51:H51, ">=70") / 4 +SUMIF(J51:J51, ">=70") / 4 + SUMIF(E51:E51, ">1") / 4 + SUMIF(G51:G51, ">1") / 4 + SUMIF(I51:I51, ">1") / 4 + SUMIF(K51:K51, ">1") / 4 -> 0 | AK51: =SUMIF(L51:L51, ">=70") / 4 +SUMIF(N51:N51, ">=70") / 4 +SUMIF(P51:P51, ">=70") / 4 +SUMIF(R51:R51, ">=70") / 4 + SUMIF(M51:M51, ">1") / 4 + SUMIF(O51:O51, ">1") / 4 + SUMIF(Q51:Q51, ">1") / 4 + SUMIF(S51:S51, ">1") / 4 -> 0 | AL51: =SUMIF(T51:T51, ">=70") / 4 +SUMIF(V51:V51, ">=70") / 4 +SUMIF(X51:X51, ">=70") / 4 +SUMIF(Z51:Z51, ">=70") / 4 + SUMIF(U51:U51, ">1") / 4 + SUMIF(W51:W51, ">1") / 4 + SUMIF(Y51:Y51, ">1") / 4 + SUMIF(AA51:AA51, ">1") / 4 -> 0 | AM51: =SUMIF(AB51:AB51, ">=65") / 4 +SUMIF(AD51:AD51, ">=65") / 4 +SUMIF(AF51:AF51, ">=65") / 4 +SUMIF(AH51:AH51, ">=65") / 4 + SUMIF(AC51:AC51, ">1") / 4 + SUMIF(AE51:AE51, ">1") / 4 + SUMIF(AG51:AG51, ">1") / 4 + SUMIF(AI51:AI51, ">1") / 4 -> 0 | AN51: =AVERAGE(AJ51:AM51) -> 0 | AQ51: =IF(AN51<70, AN51*0.5, "") -> 0 | AS51: =AR51*50% -> 0 | AT51: =IF(AR51<>"", IF(AQ51="","",AQ51+AS51), "") | AU51: =IF(AT51 < 70, AQ51*30%, "") | AW51: =AV51*70% -> 0 | AX51: =IF(AV51<>"", IF(AU51="", "", AU51+AW51), "") | AY51: =IF(AND(AT51<70, AX51<70), AN51, "") | BA51: =IF(AV51<>"", IF(AX51>=70, AX51, IF(AY51+AZ51>=70, AY51+AZ51, "")), IF(AR51<>"", IF(AT51>=70, AT51, ""), IF(AN51>=70, AN51, ""))) | BB51: =IF(AV51<>"", IF(AX51<70, IF(AY51+AZ51<70, AY51+AZ51, ""), ""), IF(AR51<>"", IF(AT51<70, AT51, ""), IF(AN51<70, AN51, ""))) -> 0 | BD51: =IF(AND(NOT(ISBLANK(AY51)), NOT(ISBLANK(AZ51))), AY51 + AZ51, "")
A52: 42 | AJ52: =SUMIF(D52:D52, ">=70") / 4 +SUMIF(F52:F52, ">=70") / 4 +SUMIF(H52:H52, ">=70") / 4 +SUMIF(J52:J52, ">=70") / 4 + SUMIF(E52:E52, ">1") / 4 + SUMIF(G52:G52, ">1") / 4 + SUMIF(I52:I52, ">1") / 4 + SUMIF(K52:K52, ">1") / 4 -> 0 | AK52: =SUMIF(L52:L52, ">=70") / 4 +SUMIF(N52:N52, ">=70") / 4 +SUMIF(P52:P52, ">=70") / 4 +SUMIF(R52:R52, ">=70") / 4 + SUMIF(M52:M52, ">1") / 4 + SUMIF(O52:O52, ">1") / 4 + SUMIF(Q52:Q52, ">1") / 4 + SUMIF(S52:S52, ">1") / 4 -> 0 | AL52: =SUMIF(T52:T52, ">=70") / 4 +SUMIF(V52:V52, ">=70") / 4 +SUMIF(X52:X52, ">=70") / 4 +SUMIF(Z52:Z52, ">=70") / 4 + SUMIF(U52:U52, ">1") / 4 + SUMIF(W52:W52, ">1") / 4 + SUMIF(Y52:Y52, ">1") / 4 + SUMIF(AA52:AA52, ">1") / 4 -> 0 | AM52: =SUMIF(AB52:AB52, ">=65") / 4 +SUMIF(AD52:AD52, ">=65") / 4 +SUMIF(AF52:AF52, ">=65") / 4 +SUMIF(AH52:AH52, ">=65") / 4 + SUMIF(AC52:AC52, ">1") / 4 + SUMIF(AE52:AE52, ">1") / 4 + SUMIF(AG52:AG52, ">1") / 4 + SUMIF(AI52:AI52, ">1") / 4 -> 0 | AN52: =AVERAGE(AJ52:AM52) -> 0 | AQ52: =IF(AN52<70, AN52*0.5, "") -> 0 | AS52: =AR52*50% -> 0 | AT52: =IF(AR52<>"", IF(AQ52="","",AQ52+AS52), "") | AU52: =IF(AT52 < 70, AQ52*30%, "") | AW52: =AV52*70% -> 0 | AX52: =IF(AV52<>"", IF(AU52="", "", AU52+AW52), "") | AY52: =IF(AND(AT52<70, AX52<70), AN52, "") | BA52: =IF(AV52<>"", IF(AX52>=70, AX52, IF(AY52+AZ52>=70, AY52+AZ52, "")), IF(AR52<>"", IF(AT52>=70, AT52, ""), IF(AN52>=70, AN52, ""))) | BB52: =IF(AV52<>"", IF(AX52<70, IF(AY52+AZ52<70, AY52+AZ52, ""), ""), IF(AR52<>"", IF(AT52<70, AT52, ""), IF(AN52<70, AN52, ""))) -> 0 | BD52: =IF(AND(NOT(ISBLANK(AY52)), NOT(ISBLANK(AZ52))), AY52 + AZ52, "")
A53: 43 | AJ53: =SUMIF(D53:D53, ">=70") / 4 +SUMIF(F53:F53, ">=70") / 4 +SUMIF(H53:H53, ">=70") / 4 +SUMIF(J53:J53, ">=70") / 4 + SUMIF(E53:E53, ">1") / 4 + SUMIF(G53:G53, ">1") / 4 + SUMIF(I53:I53, ">1") / 4 + SUMIF(K53:K53, ">1") / 4 -> 0 | AK53: =SUMIF(L53:L53, ">=70") / 4 +SUMIF(N53:N53, ">=70") / 4 +SUMIF(P53:P53, ">=70") / 4 +SUMIF(R53:R53, ">=70") / 4 + SUMIF(M53:M53, ">1") / 4 + SUMIF(O53:O53, ">1") / 4 + SUMIF(Q53:Q53, ">1") / 4 + SUMIF(S53:S53, ">1") / 4 -> 0 | AL53: =SUMIF(T53:T53, ">=70") / 4 +SUMIF(V53:V53, ">=70") / 4 +SUMIF(X53:X53, ">=70") / 4 +SUMIF(Z53:Z53, ">=70") / 4 + SUMIF(U53:U53, ">1") / 4 + SUMIF(W53:W53, ">1") / 4 + SUMIF(Y53:Y53, ">1") / 4 + SUMIF(AA53:AA53, ">1") / 4 -> 0 | AM53: =SUMIF(AB53:AB53, ">=65") / 4 +SUMIF(AD53:AD53, ">=65") / 4 +SUMIF(AF53:AF53, ">=65") / 4 +SUMIF(AH53:AH53, ">=65") / 4 + SUMIF(AC53:AC53, ">1") / 4 + SUMIF(AE53:AE53, ">1") / 4 + SUMIF(AG53:AG53, ">1") / 4 + SUMIF(AI53:AI53, ">1") / 4 -> 0 | AN53: =AVERAGE(AJ53:AM53) -> 0 | AQ53: =IF(AN53<70, AN53*0.5, "") -> 0 | AS53: =AR53*50% -> 0 | AT53: =IF(AR53<>"", IF(AQ53="","",AQ53+AS53), "") | AU53: =IF(AT53 < 70, AQ53*30%, "") | AW53: =AV53*70% -> 0 | AX53: =IF(AV53<>"", IF(AU53="", "", AU53+AW53), "") | AY53: =IF(AND(AT53<70, AX53<70), AN53, "") | BA53: =IF(AV53<>"", IF(AX53>=70, AX53, IF(AY53+AZ53>=70, AY53+AZ53, "")), IF(AR53<>"", IF(AT53>=70, AT53, ""), IF(AN53>=70, AN53, ""))) | BB53: =IF(AV53<>"", IF(AX53<70, IF(AY53+AZ53<70, AY53+AZ53, ""), ""), IF(AR53<>"", IF(AT53<70, AT53, ""), IF(AN53<70, AN53, ""))) -> 0 | BD53: =IF(AND(NOT(ISBLANK(AY53)), NOT(ISBLANK(AZ53))), AY53 + AZ53, "")
A54: 44 | AJ54: =SUMIF(D54:D54, ">=70") / 4 +SUMIF(F54:F54, ">=70") / 4 +SUMIF(H54:H54, ">=70") / 4 +SUMIF(J54:J54, ">=70") / 4 + SUMIF(E54:E54, ">1") / 4 + SUMIF(G54:G54, ">1") / 4 + SUMIF(I54:I54, ">1") / 4 + SUMIF(K54:K54, ">1") / 4 -> 0 | AK54: =SUMIF(L54:L54, ">=70") / 4 +SUMIF(N54:N54, ">=70") / 4 +SUMIF(P54:P54, ">=70") / 4 +SUMIF(R54:R54, ">=70") / 4 + SUMIF(M54:M54, ">1") / 4 + SUMIF(O54:O54, ">1") / 4 + SUMIF(Q54:Q54, ">1") / 4 + SUMIF(S54:S54, ">1") / 4 -> 0 | AL54: =SUMIF(T54:T54, ">=70") / 4 +SUMIF(V54:V54, ">=70") / 4 +SUMIF(X54:X54, ">=70") / 4 +SUMIF(Z54:Z54, ">=70") / 4 + SUMIF(U54:U54, ">1") / 4 + SUMIF(W54:W54, ">1") / 4 + SUMIF(Y54:Y54, ">1") / 4 + SUMIF(AA54:AA54, ">1") / 4 -> 0 | AM54: =SUMIF(AB54:AB54, ">=65") / 4 +SUMIF(AD54:AD54, ">=65") / 4 +SUMIF(AF54:AF54, ">=65") / 4 +SUMIF(AH54:AH54, ">=65") / 4 + SUMIF(AC54:AC54, ">1") / 4 + SUMIF(AE54:AE54, ">1") / 4 + SUMIF(AG54:AG54, ">1") / 4 + SUMIF(AI54:AI54, ">1") / 4 -> 0 | AN54: =AVERAGE(AJ54:AM54) -> 0 | AQ54: =IF(AN54<70, AN54*0.5, "") -> 0 | AS54: =AR54*50% -> 0 | AT54: =IF(AR54<>"", IF(AQ54="","",AQ54+AS54), "") | AU54: =IF(AT54 < 70, AQ54*30%, "") | AW54: =AV54*70% -> 0 | AX54: =IF(AV54<>"", IF(AU54="", "", AU54+AW54), "") | AY54: =IF(AND(AT54<70, AX54<70), AN54, "") | BA54: =IF(AV54<>"", IF(AX54>=70, AX54, IF(AY54+AZ54>=70, AY54+AZ54, "")), IF(AR54<>"", IF(AT54>=70, AT54, ""), IF(AN54>=70, AN54, ""))) | BB54: =IF(AV54<>"", IF(AX54<70, IF(AY54+AZ54<70, AY54+AZ54, ""), ""), IF(AR54<>"", IF(AT54<70, AT54, ""), IF(AN54<70, AN54, ""))) -> 0 | BD54: =IF(AND(NOT(ISBLANK(AY54)), NOT(ISBLANK(AZ54))), AY54 + AZ54, "")
A55: 45 | AJ55: =SUMIF(D55:D55, ">=70") / 4 +SUMIF(F55:F55, ">=70") / 4 +SUMIF(H55:H55, ">=70") / 4 +SUMIF(J55:J55, ">=70") / 4 + SUMIF(E55:E55, ">1") / 4 + SUMIF(G55:G55, ">1") / 4 + SUMIF(I55:I55, ">1") / 4 + SUMIF(K55:K55, ">1") / 4 -> 0 | AK55: =SUMIF(L55:L55, ">=70") / 4 +SUMIF(N55:N55, ">=70") / 4 +SUMIF(P55:P55, ">=70") / 4 +SUMIF(R55:R55, ">=70") / 4 + SUMIF(M55:M55, ">1") / 4 + SUMIF(O55:O55, ">1") / 4 + SUMIF(Q55:Q55, ">1") / 4 + SUMIF(S55:S55, ">1") / 4 -> 0 | AL55: =SUMIF(T55:T55, ">=70") / 4 +SUMIF(V55:V55, ">=70") / 4 +SUMIF(X55:X55, ">=70") / 4 +SUMIF(Z55:Z55, ">=70") / 4 + SUMIF(U55:U55, ">1") / 4 + SUMIF(W55:W55, ">1") / 4 + SUMIF(Y55:Y55, ">1") / 4 + SUMIF(AA55:AA55, ">1") / 4 -> 0 | AM55: =SUMIF(AB55:AB55, ">=65") / 4 +SUMIF(AD55:AD55, ">=65") / 4 +SUMIF(AF55:AF55, ">=65") / 4 +SUMIF(AH55:AH55, ">=65") / 4 + SUMIF(AC55:AC55, ">1") / 4 + SUMIF(AE55:AE55, ">1") / 4 + SUMIF(AG55:AG55, ">1") / 4 + SUMIF(AI55:AI55, ">1") / 4 -> 0 | AN55: =AVERAGE(AJ55:AM55) -> 0 | AQ55: =IF(AN55<70, AN55*0.5, "") -> 0 | AS55: =AR55*50% -> 0 | AT55: =IF(AR55<>"", IF(AQ55="","",AQ55+AS55), "") | AU55: =IF(AT55 < 70, AQ55*30%, "") | AW55: =AV55*70% -> 0 | AX55: =IF(AV55<>"", IF(AU55="", "", AU55+AW55), "") | AY55: =IF(AND(AT55<70, AX55<70), AN55, "") | BA55: =IF(AV55<>"", IF(AX55>=70, AX55, IF(AY55+AZ55>=70, AY55+AZ55, "")), IF(AR55<>"", IF(AT55>=70, AT55, ""), IF(AN55>=70, AN55, ""))) | BB55: =IF(AV55<>"", IF(AX55<70, IF(AY55+AZ55<70, AY55+AZ55, ""), ""), IF(AR55<>"", IF(AT55<70, AT55, ""), IF(AN55<70, AN55, ""))) -> 0 | BD55: =IF(AND(NOT(ISBLANK(AY55)), NOT(ISBLANK(AZ55))), AY55 + AZ55, "")

Sheet INGLES
D7: CALCULO DE NOTAS | AN7: Calificacion Final | AO7: % DE ASISTENCIA ANUAL | AQ7: CALIFICACION COMPLETIVA | AU7: CALIFICACION EXTRAORDINARIA | AY7: EVALUACION ESPECIAL | BA7: SITUACIONFINAL EN LA ASIGNATURA | BD7: PARA HOJA PERIODO C.F.
A9: NO | B9: NOMBRES | C9: APELLIDOS | D9: CE - LE1 | L9: CE - LE2, LE3 | T9: CE - LE4, LE6 | AB9: CE - LE5, LE7 | AJ9: PCP 1 | AK9: PCP 2 | AL9: PCP 3 | AM9: PCP 4 | AQ9: 50% C.F | AR9: C.E.C. | AS9: 50% C.E.C. | AT9: C.C.F | AU9: 30% C.F. | AV9: C.E.EX | AW9: 70% C.E.EX | AX9: C.EX.F | AY9: C.F. | AZ9: C.E. | BA9: A | BB9: R
D10: P1 | E10: RP1 | F10: P2 | G10: RP2 | H10: P3 | I10: RP3 | J10: P4 | K10: RP4 | L10: P1 | M10: RP1 | N10: P2 | O10: RP2 | P10: P3 | Q10: RP3 | R10: P4 | S10: RP4 | T10: P1 | U10: RP1 | V10: P2 | W10: RP3 | X10: P3 | Y10: RP4 | Z10: P4 | AA10: RP4 | AB10: P1 | AC10: RP1 | AD10: P2 | AE10: RP3 | AF10: P3 | AG10: RP4 | AH10: P4 | AI10: RP4
A11: 1 | B11: ABRIL | C11: GUZMAN VILORIO | AJ11: =SUMIF(D11:D11, ">=70") / 4 +SUMIF(F11:F11, ">=70") / 4 +SUMIF(H11:H11, ">=70") / 4 +SUMIF(J11:J11, ">=70") / 4 + SUMIF(E11:E11, ">1") / 4 + SUMIF(G11:G11, ">1") / 4 + SUMIF(I11:I11, ">1") / 4 + SUMIF(K11:K11, ">1") / 4 -> 0 | AK11: =SUMIF(L11:L11, ">=70") / 4 +SUMIF(N11:N11, ">=70") / 4 +SUMIF(P11:P11, ">=70") / 4 +SUMIF(R11:R11, ">=70") / 4 + SUMIF(M11:M11, ">1") / 4 + SUMIF(O11:O11, ">1") / 4 + SUMIF(Q11:Q11, ">1") / 4 + SUMIF(S11:S11, ">1") / 4 -> 0 | AL11: =SUMIF(T11:T11, ">=70") / 4 +SUMIF(V11:V11, ">=70") / 4 +SUMIF(X11:X11, ">=70") / 4 +SUMIF(Z11:Z11, ">=70") / 4 + SUMIF(U11:U11, ">1") / 4 + SUMIF(W11:W11, ">1") / 4 + SUMIF(Y11:Y11, ">1") / 4 + SUMIF(AA11:AA11, ">1") / 4 -> 0 | AM11: =SUMIF(AB11:AB11, ">=70") / 4 +SUMIF(AD11:AD11, ">=70") / 4 +SUMIF(AF11:AF11, ">=70") / 4 +SUMIF(AH11:AH11, ">=70") / 4 + SUMIF(AC11:AC11, ">1") / 4 + SUMIF(AE11:AE11, ">1") / 4 + SUMIF(AG11:AG11, ">1") / 4 + SUMIF(AI11:AI11, ">1") / 4 -> 0 | AN11: =AVERAGE(AJ11:AM11) -> 0 | AQ11: =IF(AN11<70, AN11*0.5, "") -> 0 | AS11: =AR11*50% -> 0 | AT11: =IF(AR11<>"", IF(AQ11="","",AQ11+AS11), "") | AU11: =IF(AT11 < 70, AQ11*30%, "") | AW11: =AV11*70% -> 0 | AX11: =IF(AV11<>"", IF(AU11="", "", AU11+AW11), "") | AY11: =IF(AND(AT11<70, AX11<70), AN11, "") | BA11: =IF(AV11<>"", IF(AX11>=70, AX11, IF(AY11+AZ11>=70, AY11+AZ11, "")), IF(AR11<>"", IF(AT11>=70, AT11, ""), IF(AN11>=70, AN11, ""))) | BB11: =IF(AV11<>"", IF(AX11<70, IF(AY11+AZ11<70, AY11+AZ11, ""), ""), IF(AR11<>"", IF(AT11<70, AT11, ""), IF(AN11<70, AN11, ""))) -> 0 | BD11: =IF(AND(NOT(ISBLANK(AY11)), NOT(ISBLANK(AZ11))), AY11 + AZ11, "")
A12: 2 | B12: ALBYS ANDRES | C12: SEVERINO MINIEL | AJ12: =SUMIF(D12:D12, ">=70") / 4 +SUMIF(F12:F12, ">=70") / 4 +SUMIF(H12:H12, ">=70") / 4 +SUMIF(J12:J12, ">=70") / 4 + SUMIF(E12:E12, ">1") / 4 + SUMIF(G12:G12, ">1") / 4 + SUMIF(I12:I12, ">1") / 4 + SUMIF(K12:K12, ">1") / 4 -> 0 | AK12: =SUMIF(L12:L12, ">=70") / 4 +SUMIF(N12:N12, ">=70") / 4 +SUMIF(P12:P12, ">=70") / 4 +SUMIF(R12:R12, ">=70") / 4 + SUMIF(M12:M12, ">1") / 4 + SUMIF(O12:O12, ">1") / 4 + SUMIF(Q12:Q12, ">1") / 4 + SUMIF(S12:S12, ">1") / 4 -> 0 | AL12: =SUMIF(T12:T12, ">=70") / 4 +SUMIF(V12:V12, ">=70") / 4 +SUMIF(X12:X12, ">=70") / 4 +SUMIF(Z12:Z12, ">=70") / 4 + SUMIF(U12:U12, ">1") / 4 + SUMIF(W12:W12, ">1") / 4 + SUMIF(Y12:Y12, ">1") / 4 + SUMIF(AA12:AA12, ">1") / 4 -> 0 | AM12: =SUMIF(AB12:AB12, ">=65") / 4 +SUMIF(AD12:AD12, ">=65") / 4 +SUMIF(AF12:AF12, ">=65") / 4 +SUMIF(AH12:AH12, ">=65") / 4 + SUMIF(AC12:AC12, ">1") / 4 + SUMIF(AE12:AE12, ">1") / 4 + SUMIF(AG12:AG12, ">1") / 4 + SUMIF(AI12:AI12, ">1") / 4 -> 0 | AN12: =AVERAGE(AJ12:AM12) -> 0 | AQ12: =IF(AN12<70, AN12*0.5, "") -> 0 | AS12: =AR12*50% -> 0 | AT12: =IF(AR12<>"", IF(AQ12="","",AQ12+AS12), "") | AU12: =IF(AT12 < 70, AQ12*30%, "") | AW12: =AV12*70% -> 0 | AX12: =IF(AV12<>"", IF(AU12="", "", AU12+AW12), "") | AY12: =IF(AND(AT12<70, AX12<70), AN12, "") | BA12: =IF(AV12<>"", IF(AX12>=70, AX12, IF(AY12+AZ12>=70, AY12+AZ12, "")), IF(AR12<>"", IF(AT12>=70, AT12, ""), IF(AN12>=70, AN12, ""))) | BB12: =IF(AV12<>"", IF(AX12<70, IF(AY12+AZ12<70, AY12+AZ12, ""), ""), IF(AR12<>"", IF(AT12<70, AT12, ""), IF(AN12<70, AN12, ""))) -> 0 | BD12: =IF(AND(NOT(ISBLANK(AY12)), NOT(ISBLANK(AZ12))), AY12 + AZ12, "")
A13: 3 | B13: ALFREDO | C13: CONTRERAS | AJ13: =SUMIF(D13:D13, ">=70") / 4 +SUMIF(F13:F13, ">=70") / 4 +SUMIF(H13:H13, ">=70") / 4 +SUMIF(J13:J13, ">=70") / 4 + SUMIF(E13:E13, ">1") / 4 + SUMIF(G13:G13, ">1") / 4 + SUMIF(I13:I13, ">1") / 4 + SUMIF(K13:K13, ">1") / 4 -> 0 | AK13: =SUMIF(L13:L13, ">=70") / 4 +SUMIF(N13:N13, ">=70") / 4 +SUMIF(P13:P13, ">=70") / 4 +SUMIF(R13:R13, ">=70") / 4 + SUMIF(M13:M13, ">1") / 4 + SUMIF(O13:O13, ">1") / 4 + SUMIF(Q13:Q13, ">1") / 4 + SUMIF(S13:S13, ">1") / 4 -> 0 | AL13: =SUMIF(T13:T13, ">=70") / 4 +SUMIF(V13:V13, ">=70") / 4 +SUMIF(X13:X13, ">=70") / 4 +SUMIF(Z13:Z13, ">=70") / 4 + SUMIF(U13:U13, ">1") / 4 + SUMIF(W13:W13, ">1") / 4 + SUMIF(Y13:Y13, ">1") / 4 + SUMIF(AA13:AA13, ">1") / 4 -> 0 | AM13: =SUMIF(AB13:AB13, ">=65") / 4 +SUMIF(AD13:AD13, ">=65") / 4 +SUMIF(AF13:AF13, ">=65") / 4 +SUMIF(AH13:AH13, ">=65") / 4 + SUMIF(AC13:AC13, ">1") / 4 + SUMIF(AE13:AE13, ">1") / 4 + SUMIF(AG13:AG13, ">1") / 4 + SUMIF(AI13:AI13, ">1") / 4 -> 0 | AN13: =AVERAGE(AJ13:AM13) -> 0 | AQ13: =IF(AN13<70, AN13*0.5, "") -> 0 | AS13: =AR13*50% -> 0 | AT13: =IF(AR13<>"", IF(AQ13="","",AQ13+AS13), "") | AU13: =IF(AT13 < 70, AQ13*30%, "") | AW13: =AV13*70% -> 0 | AX13: =IF(AV13<>"", IF(AU13="", "", AU13+AW13), "") | AY13: =IF(AND(AT13<70, AX13<70), AN13, "") | BA13: =IF(AV13<>"", IF(AX13>=70, AX13, IF(AY13+AZ13>=70, AY13+AZ13, "")), IF(AR13<>"", IF(AT13>=70, AT13, ""), IF(AN13>=70, AN13, ""))) | BB13: =IF(AV13<>"", IF(AX13<70, IF(AY13+AZ13<70, AY13+AZ13, ""), ""), IF(AR13<>"", IF(AT13<70, AT13, ""), IF(AN13<70, AN13, ""))) -> 0 | BD13: =IF(AND(NOT(ISBLANK(AY13)), NOT(ISBLANK(AZ13))), AY13 + AZ13, "")
A14: 4 | B14: ALIANNA MILAGROS | C14: DE JESUS | AJ14: =SUMIF(D14:D14, ">=70") / 4 +SUMIF(F14:F14, ">=70") / 4 +SUMIF(H14:H14, ">=70") / 4 +SUMIF(J14:J14, ">=70") / 4 + SUMIF(E14:E14, ">1") / 4 + SUMIF(G14:G14, ">1") / 4 + SUMIF(I14:I14, ">1") / 4 + SUMIF(K14:K14, ">1") / 4 -> 0 | AK14: =SUMIF(L14:L14, ">=70") / 4 +SUMIF(N14:N14, ">=70") / 4 +SUMIF(P14:P14, ">=70") / 4 +SUMIF(R14:R14, ">=70") / 4 + SUMIF(M14:M14, ">1") / 4 + SUMIF(O14:O14, ">1") / 4 + SUMIF(Q14:Q14, ">1") / 4 + SUMIF(S14:S14, ">1") / 4 -> 0 | AL14: =SUMIF(T14:T14, ">=70") / 4 +SUMIF(V14:V14, ">=70") / 4 +SUMIF(X14:X14, ">=70") / 4 +SUMIF(Z14:Z14, ">=70") / 4 + SUMIF(U14:U14, ">1") / 4 + SUMIF(W14:W14, ">1") / 4 + SUMIF(Y14:Y14, ">1") / 4 + SUMIF(AA14:AA14, ">1") / 4 -> 0 | AM14: =SUMIF(AB14:AB14, ">=65") / 4 +SUMIF(AD14:AD14, ">=65") / 4 +SUMIF(AF14:AF14, ">=65") / 4 +SUMIF(AH14:AH14, ">=65") / 4 + SUMIF(AC14:AC14, ">1") / 4 + SUMIF(AE14:AE14, ">1") / 4 + SUMIF(AG14:AG14, ">1") / 4 + SUMIF(AI14:AI14, ">1") / 4 -> 0 | AN14: =AVERAGE(AJ14:AM14) -> 0 | AQ14: =IF(AN14<70, AN14*0.5, "") -> 0 | AS14: =AR14*50% -> 0 | AT14: =IF(AR14<>"", IF(AQ14="","",AQ14+AS14), "") | AU14: =IF(AT14 < 70, AQ14*30%, "") | AW14: =AV14*70% -> 0 | AX14: =IF(AV14<>"", IF(AU14="", "", AU14+AW14), "") | AY14: =IF(AND(AT14<70, AX14<70), AN14, "") | BA14: =IF(AV14<>"", IF(AX14>=70, AX14, IF(AY14+AZ14>=70, AY14+AZ14, "")), IF(AR14<>"", IF(AT14>=70, AT14, ""), IF(AN14>=70, AN14, ""))) | BB14: =IF(AV14<>"", IF(AX14<70, IF(AY14+AZ14<70, AY14+AZ14, ""), ""), IF(AR14<>"", IF(AT14<70, AT14, ""), IF(AN14<70, AN14, ""))) -> 0 | BD14: =IF(AND(NOT(ISBLANK(AY14)), NOT(ISBLANK(AZ14))), AY14 + AZ14, "")
A15: 5 | B15: ANA YULISA | C15: FRIAS MARTE | AJ15: =SUMIF(D15:D15, ">=70") / 4 +SUMIF(F15:F15, ">=70") / 4 +SUMIF(H15:H15, ">=70") / 4 +SUMIF(J15:J15, ">=70") / 4 + SUMIF(E15:E15, ">1") / 4 + SUMIF(G15:G15, ">1") / 4 + SUMIF(I15:I15, ">1") / 4 + SUMIF(K15:K15, ">1") / 4 -> 0 | AK15: =SUMIF(L15:L15, ">=70") / 4 +SUMIF(N15:N15, ">=70") / 4 +SUMIF(P15:P15, ">=70") / 4 +SUMIF(R15:R15, ">=70") / 4 + SUMIF(M15:M15, ">1") / 4 + SUMIF(O15:O15, ">1") / 4 + SUMIF(Q15:Q15, ">1") / 4 + SUMIF(S15:S15, ">1") / 4 -> 0 | AL15: =SUMIF(T15:T15, ">=70") / 4 +SUMIF(V15:V15, ">=70") / 4 +SUMIF(X15:X15, ">=70") / 4 +SUMIF(Z15:Z15, ">=70") / 4 + SUMIF(U15:U15, ">1") / 4 + SUMIF(W15:W15, ">1") / 4 + SUMIF(Y15:Y15, ">1") / 4 + SUMIF(AA15:AA15, ">1") / 4 -> 0 | AM15: =SUMIF(AB15:AB15, ">=65") / 4 +SUMIF(AD15:AD15, ">=65") / 4 +SUMIF(AF15:AF15, ">=65") / 4 +SUMIF(AH15:AH15, ">=65") / 4 + SUMIF(AC15:AC15, ">1") / 4 + SUMIF(AE15:AE15, ">1") / 4 + SUMIF(AG15:AG15, ">1") / 4 + SUMIF(AI15:AI15, ">1") / 4 -> 0 | AN15: =AVERAGE(AJ15:AM15) -> 0 | AQ15: =IF(AN15<70, AN15*0.5, "") -> 0 | AS15: =AR15*50% -> 0 | AT15: =IF(AR15<>"", IF(AQ15="","",AQ15+AS15), "") | AU15: =IF(AT15 < 70, AQ15*30%, "") | AW15: =AV15*70% -> 0 | AX15: =IF(AV15<>"", IF(AU15="", "", AU15+AW15), "") | AY15: =IF(AND(AT15<70, AX15<70), AN15, "") | BA15: =IF(AV15<>"", IF(AX15>=70, AX15, IF(AY15+AZ15>=70, AY15+AZ15, "")), IF(AR15<>"", IF(AT15>=70, AT15, ""), IF(AN15>=70, AN15, ""))) | BB15: =IF(AV15<>"", IF(AX15<70, IF(AY15+AZ15<70, AY15+AZ15, ""), ""), IF(AR15<>"", IF(AT15<70, AT15, ""), IF(AN15<70, AN15, ""))) -> 0 | BD15: =IF(AND(NOT(ISBLANK(AY15)), NOT(ISBLANK(AZ15))), AY15 + AZ15, "")
A16: 6 | B16: ASHLEY NATALIE | C16: CUEVAS FRIAS | AJ16: =SUMIF(D16:D16, ">=70") / 4 +SUMIF(F16:F16, ">=70") / 4 +SUMIF(H16:H16, ">=70") / 4 +SUMIF(J16:J16, ">=70") / 4 + SUMIF(E16:E16, ">1") / 4 + SUMIF(G16:G16, ">1") / 4 + SUMIF(I16:I16, ">1") / 4 + SUMIF(K16:K16, ">1") / 4 -> 0 | AK16: =SUMIF(L16:L16, ">=70") / 4 +SUMIF(N16:N16, ">=70") / 4 +SUMIF(P16:P16, ">=70") / 4 +SUMIF(R16:R16, ">=70") / 4 + SUMIF(M16:M16, ">1") / 4 + SUMIF(O16:O16, ">1") / 4 + SUMIF(Q16:Q16, ">1") / 4 + SUMIF(S16:S16, ">1") / 4 -> 0 | AL16: =SUMIF(T16:T16, ">=70") / 4 +SUMIF(V16:V16, ">=70") / 4 +SUMIF(X16:X16, ">=70") / 4 +SUMIF(Z16:Z16, ">=70") / 4 + SUMIF(U16:U16, ">1") / 4 + SUMIF(W16:W16, ">1") / 4 + SUMIF(Y16:Y16, ">1") / 4 + SUMIF(AA16:AA16, ">1") / 4 -> 0 | AM16: =SUMIF(AB16:AB16, ">=65") / 4 +SUMIF(AD16:AD16, ">=65") / 4 +SUMIF(AF16:AF16, ">=65") / 4 +SUMIF(AH16:AH16, ">=65") / 4 + SUMIF(AC16:AC16, ">1") / 4 + SUMIF(AE16:AE16, ">1") / 4 + SUMIF(AG16:AG16, ">1") / 4 + SUMIF(AI16:AI16, ">1") / 4 -> 0 | AN16: =AVERAGE(AJ16:AM16) -> 0 | AQ16: =IF(AN16<70, AN16*0.5, "") -> 0 | AS16: =AR16*50% -> 0 | AT16: =IF(AR16<>"", IF(AQ16="","",AQ16+AS16), "") | AU16: =IF(AT16 < 70, AQ16*30%, "") | AW16: =AV16*70% -> 0 | AX16: =IF(AV16<>"", IF(AU16="", "", AU16+AW16), "") | AY16: =IF(AND(AT16<70, AX16<70), AN16, "") | BA16: =IF(AV16<>"", IF(AX16>=70, AX16, IF(AY16+AZ16>=70, AY16+AZ16, "")), IF(AR16<>"", IF(AT16>=70, AT16, ""), IF(AN16>=70, AN16, ""))) | BB16: =IF(AV16<>"", IF(AX16<70, IF(AY16+AZ16<70, AY16+AZ16, ""), ""), IF(AR16<>"", IF(AT16<70, AT16, ""), IF(AN16<70, AN16, ""))) -> 0 | BD16: =IF(AND(NOT(ISBLANK(AY16)), NOT(ISBLANK(AZ16))), AY16 + AZ16, "")
A17: 7 | B17: CATERIN CARINA | C17: DELGADO MANZUETA | AJ17: =SUMIF(D17:D17, ">=70") / 4 +SUMIF(F17:F17, ">=70") / 4 +SUMIF(H17:H17, ">=70") / 4 +SUMIF(J17:J17, ">=70") / 4 + SUMIF(E17:E17, ">1") / 4 + SUMIF(G17:G17, ">1") / 4 + SUMIF(I17:I17, ">1") / 4 + SUMIF(K17:K17, ">1") / 4 -> 0 | AK17: =SUMIF(L17:L17, ">=70") / 4 +SUMIF(N17:N17, ">=70") / 4 +SUMIF(P17:P17, ">=70") / 4 +SUMIF(R17:R17, ">=70") / 4 + SUMIF(M17:M17, ">1") / 4 + SUMIF(O17:O17, ">1") / 4 + SUMIF(Q17:Q17, ">1") / 4 + SUMIF(S17:S17, ">1") / 4 -> 0 | AL17: =SUMIF(T17:T17, ">=70") / 4 +SUMIF(V17:V17, ">=70") / 4 +SUMIF(X17:X17, ">=70") / 4 +SUMIF(Z17:Z17, ">=70") / 4 + SUMIF(U17:U17, ">1") / 4 + SUMIF(W17:W17, ">1") / 4 + SUMIF(Y17:Y17, ">1") / 4 + SUMIF(AA17:AA17, ">1") / 4 -> 0 | AM17: =SUMIF(AB17:AB17, ">=65") / 4 +SUMIF(AD17:AD17, ">=65") / 4 +SUMIF(AF17:AF17, ">=65") / 4 +SUMIF(AH17:AH17, ">=65") / 4 + SUMIF(AC17:AC17, ">1") / 4 + SUMIF(AE17:AE17, ">1") / 4 + SUMIF(AG17:AG17, ">1") / 4 + SUMIF(AI17:AI17, ">1") / 4 -> 0 | AN17: =AVERAGE(AJ17:AM17) -> 0 | AQ17: =IF(AN17<70, AN17*0.5, "") -> 0 | AS17: =AR17*50% -> 0 | AT17: =IF(AR17<>"", IF(AQ17="","",AQ17+AS17), "") | AU17: =IF(AT17 < 70, AQ17*30%, "") | AW17: =AV17*70% -> 0 | AX17: =IF(AV17<>"", IF(AU17="", "", AU17+AW17), "") | AY17: =IF(AND(AT17<70, AX17<70), AN17, "") | BA17: =IF(AV17<>"", IF(AX17>=70, AX17, IF(AY17+AZ17>=70, AY17+AZ17, "")), IF(AR17<>"", IF(AT17>=70, AT17, ""), IF(AN17>=70, AN17, ""))) | BB17: =IF(AV17<>"", IF(AX17<70, IF(AY17+AZ17<70, AY17+AZ17, ""), ""), IF(AR17<>"", IF(AT17<70, AT17, ""), IF(AN17<70, AN17, ""))) -> 0 | BD17: =IF(AND(NOT(ISBLANK(AY17)), NOT(ISBLANK(AZ17))), AY17 + AZ17, "")
A18: 8 | B18: CLARYS | C18: ALMANZAR BRAND | AJ18: =SUMIF(D18:D18, ">=70") / 4 +SUMIF(F18:F18, ">=70") / 4 +SUMIF(H18:H18, ">=70") / 4 +SUMIF(J18:J18, ">=70") / 4 + SUMIF(E18:E18, ">1") / 4 + SUMIF(G18:G18, ">1") / 4 + SUMIF(I18:I18, ">1") / 4 + SUMIF(K18:K18, ">1") / 4 -> 0 | AK18: =SUMIF(L18:L18, ">=70") / 4 +SUMIF(N18:N18, ">=70") / 4 +SUMIF(P18:P18, ">=70") / 4 +SUMIF(R18:R18, ">=70") / 4 + SUMIF(M18:M18, ">1") / 4 + SUMIF(O18:O18, ">1") / 4 + SUMIF(Q18:Q18, ">1") / 4 + SUMIF(S18:S18, ">1") / 4 -> 0 | AL18: =SUMIF(T18:T18, ">=70") / 4 +SUMIF(V18:V18, ">=70") / 4 +SUMIF(X18:X18, ">=70") / 4 +SUMIF(Z18:Z18, ">=70") / 4 + SUMIF(U18:U18, ">1") / 4 + SUMIF(W18:W18, ">1") / 4 + SUMIF(Y18:Y18, ">1") / 4 + SUMIF(AA18:AA18, ">1") / 4 -> 0 | AM18: =SUMIF(AB18:AB18, ">=65") / 4 +SUMIF(AD18:AD18, ">=65") / 4 +SUMIF(AF18:AF18, ">=65") / 4 +SUMIF(AH18:AH18, ">=65") / 4 + SUMIF(AC18:AC18, ">1") / 4 + SUMIF(AE18:AE18, ">1") / 4 + SUMIF(AG18:AG18, ">1") / 4 + SUMIF(AI18:AI18, ">1") / 4 -> 0 | AN18: =AVERAGE(AJ18:AM18) -> 0 | AQ18: =IF(AN18<70, AN18*0.5, "") -> 0 | AS18: =AR18*50% -> 0 | AT18: =IF(AR18<>"", IF(AQ18="","",AQ18+AS18), "") | AU18: =IF(AT18 < 70, AQ18*30%, "") | AW18: =AV18*70% -> 0 | AX18: =IF(AV18<>"", IF(AU18="", "", AU18+AW18), "") | AY18: =IF(AND(AT18<70, AX18<70), AN18, "") | BA18: =IF(AV18<>"", IF(AX18>=70, AX18, IF(AY18+AZ18>=70, AY18+AZ18, "")), IF(AR18<>"", IF(AT18>=70, AT18, ""), IF(AN18>=70, AN18, ""))) | BB18: =IF(AV18<>"", IF(AX18<70, IF(AY18+AZ18<70, AY18+AZ18, ""), ""), IF(AR18<>"", IF(AT18<70, AT18, ""), IF(AN18<70, AN18, ""))) -> 0 | BD18: =IF(AND(NOT(ISBLANK(AY18)), NOT(ISBLANK(AZ18))), AY18 + AZ18, "")
A19: 9 | B19: CRISTOFHER | C19: GOMEZ FELIZ | AJ19: =SUMIF(D19:D19, ">=70") / 4 +SUMIF(F19:F19, ">=70") / 4 +SUMIF(H19:H19, ">=70") / 4 +SUMIF(J19:J19, ">=70") / 4 + SUMIF(E19:E19, ">1") / 4 + SUMIF(G19:G19, ">1") / 4 + SUMIF(I19:I19, ">1") / 4 + SUMIF(K19:K19, ">1") / 4 -> 0 | AK19: =SUMIF(L19:L19, ">=70") / 4 +SUMIF(N19:N19, ">=70") / 4 +SUMIF(P19:P19, ">=70") / 4 +SUMIF(R19:R19, ">=70") / 4 + SUMIF(M19:M19, ">1") / 4 + SUMIF(O19:O19, ">1") / 4 + SUMIF(Q19:Q19, ">1") / 4 + SUMIF(S19:S19, ">1") / 4 -> 0 | AL19: =SUMIF(T19:T19, ">=70") / 4 +SUMIF(V19:V19, ">=70") / 4 +SUMIF(X19:X19, ">=70") / 4 +SUMIF(Z19:Z19, ">=70") / 4 + SUMIF(U19:U19, ">1") / 4 + SUMIF(W19:W19, ">1") / 4 + SUMIF(Y19:Y19, ">1") / 4 + SUMIF(AA19:AA19, ">1") / 4 -> 0 | AM19: =SUMIF(AB19:AB19, ">=65") / 4 +SUMIF(AD19:AD19, ">=65") / 4 +SUMIF(AF19:AF19, ">=65") / 4 +SUMIF(AH19:AH19, ">=65") / 4 + SUMIF(AC19:AC19, ">1") / 4 + SUMIF(AE19:AE19, ">1") / 4 + SUMIF(AG19:AG19, ">1") / 4 + SUMIF(AI19:AI19, ">1") / 4 -> 0 | AN19: =AVERAGE(AJ19:AM19) -> 0 | AQ19: =IF(AN19<70, AN19*0.5, "") -> 0 | AS19: =AR19*50% -> 0 | AT19: =IF(AR19<>"", IF(AQ19="","",AQ19+AS19), "") | AU19: =IF(AT19 < 70, AQ19*30%, "") | AW19: =AV19*70% -> 0 | AX19: =IF(AV19<>"", IF(AU19="", "", AU19+AW19), "") | AY19: =IF(AND(AT19<70, AX19<70), AN19, "") | BA19: =IF(AV19<>"", IF(AX19>=70, AX19, IF(AY19+AZ19>=70, AY19+AZ19, "")), IF(AR19<>"", IF(AT19>=70, AT19, ""), IF(AN19>=70, AN19, ""))) | BB19: =IF(AV19<>"", IF(AX19<70, IF(AY19+AZ19<70, AY19+AZ19, ""), ""), IF(AR19<>"", IF(AT19<70, AT19, ""), IF(AN19<70, AN19, ""))) -> 0 | BD19: =IF(AND(NOT(ISBLANK(AY19)), NOT(ISBLANK(AZ19))), AY19 + AZ19, "")
A20: 10 | B20: DARLIN | C20: ESTEPAN CAPELLAN | AJ20: =SUMIF(D20:D20, ">=70") / 4 +SUMIF(F20:F20, ">=70") / 4 +SUMIF(H20:H20, ">=70") / 4 +SUMIF(J20:J20, ">=70") / 4 + SUMIF(E20:E20, ">1") / 4 + SUMIF(G20:G20, ">1") / 4 + SUMIF(I20:I20, ">1") / 4 + SUMIF(K20:K20, ">1") / 4 -> 0 | AK20: =SUMIF(L20:L20, ">=70") / 4 +SUMIF(N20:N20, ">=70") / 4 +SUMIF(P20:P20, ">=70") / 4 +SUMIF(R20:R20, ">=70") / 4 + SUMIF(M20:M20, ">1") / 4 + SUMIF(O20:O20, ">1") / 4 + SUMIF(Q20:Q20, ">1") / 4 + SUMIF(S20:S20, ">1") / 4 -> 0 | AL20: =SUMIF(T20:T20, ">=70") / 4 +SUMIF(V20:V20, ">=70") / 4 +SUMIF(X20:X20, ">=70") / 4 +SUMIF(Z20:Z20, ">=70") / 4 + SUMIF(U20:U20, ">1") / 4 + SUMIF(W20:W20, ">1") / 4 + SUMIF(Y20:Y20, ">1") / 4 + SUMIF(AA20:AA20, ">1") / 4 -> 0 | AM20: =SUMIF(AB20:AB20, ">=65") / 4 +SUMIF(AD20:AD20, ">=65") / 4 +SUMIF(AF20:AF20, ">=65") / 4 +SUMIF(AH20:AH20, ">=65") / 4 + SUMIF(AC20:AC20, ">1") / 4 + SUMIF(AE20:AE20, ">1") / 4 + SUMIF(AG20:AG20, ">1") / 4 + SUMIF(AI20:AI20, ">1") / 4 -> 0 | AN20: =AVERAGE(AJ20:AM20) -> 0 | AQ20: =IF(AN20<70, AN20*0.5, "") -> 0 | AS20: =AR20*50% -> 0 | AT20: =IF(AR20<>"", IF(AQ20="","",AQ20+AS20), "") | AU20: =IF(AT20 < 70, AQ20*30%, "") | AW20: =AV20*70% -> 0 | AX20: =IF(AV20<>"", IF(AU20="", "", AU20+AW20), "") | AY20: =IF(AND(AT20<70, AX20<70), AN20, "") | BA20: =IF(AV20<>"", IF(AX20>=70, AX20, IF(AY20+AZ20>=70, AY20+AZ20, "")), IF(AR20<>"", IF(AT20>=70, AT20, ""), IF(AN20>=70, AN20, ""))) | BB20: =IF(AV20<>"", IF(AX20<70, IF(AY20+AZ20<70, AY20+AZ20, ""), ""), IF(AR20<>"", IF(AT20<70, AT20, ""), IF(AN20<70, AN20, ""))) -> 0 | BD20: =IF(AND(NOT(ISBLANK(AY20)), NOT(ISBLANK(AZ20))), AY20 + AZ20, "")
A21: 11 | B21: DIONICIO | C21: GARCIA DE LEON | AJ21: =SUMIF(D21:D21, ">=70") / 4 +SUMIF(F21:F21, ">=70") / 4 +SUMIF(H21:H21, ">=70") / 4 +SUMIF(J21:J21, ">=70") / 4 + SUMIF(E21:E21, ">1") / 4 + SUMIF(G21:G21, ">1") / 4 + SUMIF(I21:I21, ">1") / 4 + SUMIF(K21:K21, ">1") / 4 -> 0 | AK21: =SUMIF(L21:L21, ">=70") / 4 +SUMIF(N21:N21, ">=70") / 4 +SUMIF(P21:P21, ">=70") / 4 +SUMIF(R21:R21, ">=70") / 4 + SUMIF(M21:M21, ">1") / 4 + SUMIF(O21:O21, ">1") / 4 + SUMIF(Q21:Q21, ">1") / 4 + SUMIF(S21:S21, ">1") / 4 -> 0 | AL21: =SUMIF(T21:T21, ">=70") / 4 +SUMIF(V21:V21, ">=70") / 4 +SUMIF(X21:X21, ">=70") / 4 +SUMIF(Z21:Z21, ">=70") / 4 + SUMIF(U21:U21, ">1") / 4 + SUMIF(W21:W21, ">1") / 4 + SUMIF(Y21:Y21, ">1") / 4 + SUMIF(AA21:AA21, ">1") / 4 -> 0 | AM21: =SUMIF(AB21:AB21, ">=65") / 4 +SUMIF(AD21:AD21, ">=65") / 4 +SUMIF(AF21:AF21, ">=65") / 4 +SUMIF(AH21:AH21, ">=65") / 4 + SUMIF(AC21:AC21, ">1") / 4 + SUMIF(AE21:AE21, ">1") / 4 + SUMIF(AG21:AG21, ">1") / 4 + SUMIF(AI21:AI21, ">1") / 4 -> 0 | AN21: =AVERAGE(AJ21:AM21) -> 0 | AQ21: =IF(AN21<70, AN21*0.5, "") -> 0 | AS21: =AR21*50% -> 0 | AT21: =IF(AR21<>"", IF(AQ21="","",AQ21+AS21), "") | AU21: =IF(AT21 < 70, AQ21*30%, "") | AW21: =AV21*70% -> 0 | AX21: =IF(AV21<>"", IF(AU21="", "", AU21+AW21), "") | AY21: =IF(AND(AT21<70, AX21<70), AN21, "") | BA21: =IF(AV21<>"", IF(AX21>=70, AX21, IF(AY21+AZ21>=70, AY21+AZ21, "")), IF(AR21<>"", IF(AT21>=70, AT21, ""), IF(AN21>=70, AN21, ""))) | BB21: =IF(AV21<>"", IF(AX21<70, IF(AY21+AZ21<70, AY21+AZ21, ""), ""), IF(AR21<>"", IF(AT21<70, AT21, ""), IF(AN21<70, AN21, ""))) -> 0 | BD21: =IF(AND(NOT(ISBLANK(AY21)), NOT(ISBLANK(AZ21))), AY21 + AZ21, "")
A22: 12 | B22: DJOUME | C22: NOMBRE | AJ22: =SUMIF(D22:D22, ">=70") / 4 +SUMIF(F22:F22, ">=70") / 4 +SUMIF(H22:H22, ">=70") / 4 +SUMIF(J22:J22, ">=70") / 4 + SUMIF(E22:E22, ">1") / 4 + SUMIF(G22:G22, ">1") / 4 + SUMIF(I22:I22, ">1") / 4 + SUMIF(K22:K22, ">1") / 4 -> 0 | AK22: =SUMIF(L22:L22, ">=70") / 4 +SUMIF(N22:N22, ">=70") / 4 +SUMIF(P22:P22, ">=70") / 4 +SUMIF(R22:R22, ">=70") / 4 + SUMIF(M22:M22, ">1") / 4 + SUMIF(O22:O22, ">1") / 4 + SUMIF(Q22:Q22, ">1") / 4 + SUMIF(S22:S22, ">1") / 4 -> 0 | AL22: =SUMIF(T22:T22, ">=70") / 4 +SUMIF(V22:V22, ">=70") / 4 +SUMIF(X22:X22, ">=70") / 4 +SUMIF(Z22:Z22, ">=70") / 4 + SUMIF(U22:U22, ">1") / 4 + SUMIF(W22:W22, ">1") / 4 + SUMIF(Y22:Y22, ">1") / 4 + SUMIF(AA22:AA22, ">1") / 4 -> 0 | AM22: =SUMIF(AB22:AB22, ">=65") / 4 +SUMIF(AD22:AD22, ">=65") / 4 +SUMIF(AF22:AF22, ">=65") / 4 +SUMIF(AH22:AH22, ">=65") / 4 + SUMIF(AC22:AC22, ">1") / 4 + SUMIF(AE22:AE22, ">1") / 4 + SUMIF(AG22:AG22, ">1") / 4 + SUMIF(AI22:AI22, ">1") / 4 -> 0 | AN22: =AVERAGE(AJ22:AM22) -> 0 | AQ22: =IF(AN22<70, AN22*0.5, "") -> 0 | AS22: =AR22*50% -> 0 | AT22: =IF(AR22<>"", IF(AQ22="","",AQ22+AS22), "") | AU22: =IF(AT22 < 70, AQ22*30%, "") | AW22: =AV22*70% -> 0 | AX22: =IF(AV22<>"", IF(AU22="", "", AU22+AW22), "") | AY22: =IF(AND(AT22<70, AX22<70), AN22, "") | BA22: =IF(AV22<>"", IF(AX22>=70, AX22, IF(AY22+AZ22>=70, AY22+AZ22, "")), IF(AR22<>"", IF(AT22>=70, AT22, ""), IF(AN22>=70, AN22, ""))) | BB22: =IF(AV22<>"", IF(AX22<70, IF(AY22+AZ22<70, AY22+AZ22, ""), ""), IF(AR22<>"", IF(AT22<70, AT22, ""), IF(AN22<70, AN22, ""))) -> 0 | BD22: =IF(AND(NOT(ISBLANK(AY22)), NOT(ISBLANK(AZ22))), AY22 + AZ22, "")
